{
  "version": 8,
  "blockIdVersion": 11,
  "anchorX": 0,
  "anchorY": 9,
  "anchorZ": 1,
  "blocks": [
    {
      "x": -6,
      "y": 7,
      "z": -4,
      "name": "Soil_Dirt"
    },
    {
      "x": -6,
      "y": 8,
      "z": -4,
      "name": "Soil_Dirt"
    },
    {
      "x": -6,
      "y": 9,
      "z": -4,
      "name": "Soil_Grass_Deep"
    },
    {
      "x": -6,
      "y": 10,
      "z": -4,
      "name": "*Wood_Hardwood_Fence_State_Definitions_Corner",
      "rotation": 1
    },
    {
      "x": -6,
      "y": 11,
      "z": -4,
      "name": "Empty"
    },
    {
      "x": -6,
      "y": 12,
      "z": -4,
      "name": "Empty"
    },
    {
      "x": -6,
      "y": 7,
      "z": -3,
      "name": "Soil_Dirt"
    },
    {
      "x": -6,
      "y": 8,
      "z": -3,
      "name": "Soil_Dirt"
    },
    {
      "x": -6,
      "y": 9,
      "z": -3,
      "name": "Soil_Grass_Deep"
    },
    {
      "x": -6,
      "y": 10,
      "z": -3,
      "name": "Wood_Hardwood_Fence",
      "rotation": 3
    },
    {
      "x": -6,
      "y": 11,
      "z": -3,
      "name": "Empty"
    },
    {
      "x": -6,
      "y": 12,
      "z": -3,
      "name": "Empty"
    },
    {
      "x": -6,
      "y": 6,
      "z": -2,
      "name": "Soil_Dirt"
    },
    {
      "x": -6,
      "y": 7,
      "z": -2,
      "name": "Soil_Dirt"
    },
    {
      "x": -6,
      "y": 8,
      "z": -2,
      "name": "Soil_Dirt"
    },
    {
      "x": -6,
      "y": 9,
      "z": -2,
      "name": "Soil_Mud_Dry"
    },
    {
      "x": -6,
      "y": 10,
      "z": -2,
      "name": "Wood_Hardwood_Fence",
      "rotation": 3
    },
    {
      "x": -6,
      "y": 11,
      "z": -2,
      "name": "Empty"
    },
    {
      "x": -6,
      "y": 12,
      "z": -2,
      "name": "Empty"
    },
    {
      "x": -6,
      "y": 6,
      "z": -1,
      "name": "Soil_Dirt"
    },
    {
      "x": -6,
      "y": 7,
      "z": -1,
      "name": "Soil_Dirt"
    },
    {
      "x": -6,
      "y": 8,
      "z": -1,
      "name": "Soil_Dirt"
    },
    {
      "x": -6,
      "y": 9,
      "z": -1,
      "name": "Soil_Mud_Dry"
    },
    {
      "x": -6,
      "y": 10,
      "z": -1,
      "name": "Wood_Hardwood_Fence",
      "rotation": 3
    },
    {
      "x": -6,
      "y": 11,
      "z": -1,
      "name": "Empty"
    },
    {
      "x": -6,
      "y": 12,
      "z": -1,
      "name": "Empty"
    },
    {
      "x": -6,
      "y": 6,
      "z": 0,
      "name": "Soil_Dirt"
    },
    {
      "x": -6,
      "y": 7,
      "z": 0,
      "name": "Soil_Dirt"
    },
    {
      "x": -6,
      "y": 8,
      "z": 0,
      "name": "Soil_Dirt"
    },
    {
      "x": -6,
      "y": 9,
      "z": 0,
      "name": "Soil_Grass_Deep"
    },
    {
      "x": -6,
      "y": 10,
      "z": 0,
      "name": "Wood_Hardwood_Fence",
      "rotation": 3
    },
    {
      "x": -6,
      "y": 11,
      "z": 0,
      "name": "Empty"
    },
    {
      "x": -6,
      "y": 12,
      "z": 0,
      "name": "Empty"
    },
    {
      "x": -6,
      "y": 6,
      "z": 1,
      "name": "Soil_Dirt"
    },
    {
      "x": -6,
      "y": 7,
      "z": 1,
      "name": "Soil_Dirt"
    },
    {
      "x": -6,
      "y": 8,
      "z": 1,
      "name": "Soil_Dirt"
    },
    {
      "x": -6,
      "y": 9,
      "z": 1,
      "name": "Soil_Grass_Deep"
    },
    {
      "x": -6,
      "y": 10,
      "z": 1,
      "name": "Wood_Hardwood_Fence",
      "rotation": 3
    },
    {
      "x": -6,
      "y": 11,
      "z": 1,
      "name": "Empty"
    },
    {
      "x": -6,
      "y": 12,
      "z": 1,
      "name": "Empty"
    },
    {
      "x": -6,
      "y": 6,
      "z": 2,
      "name": "Soil_Dirt"
    },
    {
      "x": -6,
      "y": 7,
      "z": 2,
      "name": "Soil_Dirt"
    },
    {
      "x": -6,
      "y": 8,
      "z": 2,
      "name": "Soil_Dirt"
    },
    {
      "x": -6,
      "y": 9,
      "z": 2,
      "name": "Soil_Grass_Deep"
    },
    {
      "x": -6,
      "y": 10,
      "z": 2,
      "name": "*Wood_Hardwood_Fence_State_Definitions_Corner",
      "rotation": 2
    },
    {
      "x": -6,
      "y": 11,
      "z": 2,
      "name": "Empty"
    },
    {
      "x": -6,
      "y": 12,
      "z": 2,
      "name": "Empty"
    },
    {
      "x": -5,
      "y": 7,
      "z": -4,
      "name": "Soil_Dirt"
    },
    {
      "x": -5,
      "y": 8,
      "z": -4,
      "name": "Soil_Dirt"
    },
    {
      "x": -5,
      "y": 9,
      "z": -4,
      "name": "Soil_Grass_Deep"
    },
    {
      "x": -5,
      "y": 10,
      "z": -4,
      "name": "Wood_Hardwood_Fence",
      "rotation": 2
    },
    {
      "x": -5,
      "y": 11,
      "z": -4,
      "name": "Empty"
    },
    {
      "x": -5,
      "y": 12,
      "z": -4,
      "name": "Empty"
    },
    {
      "x": -5,
      "y": 5,
      "z": -3,
      "name": "Soil_Dirt"
    },
    {
      "x": -5,
      "y": 6,
      "z": -3,
      "name": "Soil_Dirt"
    },
    {
      "x": -5,
      "y": 7,
      "z": -3,
      "name": "Soil_Dirt"
    },
    {
      "x": -5,
      "y": 8,
      "z": -3,
      "name": "Soil_Dirt"
    },
    {
      "x": -5,
      "y": 9,
      "z": -3,
      "name": "Soil_Grass_Deep"
    },
    {
      "x": -5,
      "y": 10,
      "z": -3,
      "name": "Empty"
    },
    {
      "x": -5,
      "y": 11,
      "z": -3,
      "name": "Empty"
    },
    {
      "x": -5,
      "y": 12,
      "z": -3,
      "name": "Empty"
    },
    {
      "x": -5,
      "y": 5,
      "z": -2,
      "name": "Soil_Dirt"
    },
    {
      "x": -5,
      "y": 6,
      "z": -2,
      "name": "Soil_Dirt"
    },
    {
      "x": -5,
      "y": 7,
      "z": -2,
      "name": "Soil_Dirt"
    },
    {
      "x": -5,
      "y": 8,
      "z": -2,
      "name": "Soil_Dirt"
    },
    {
      "x": -5,
      "y": 9,
      "z": -2,
      "name": "Soil_Mud_Dry"
    },
    {
      "x": -5,
      "y": 10,
      "z": -2,
      "name": "Empty"
    },
    {
      "x": -5,
      "y": 11,
      "z": -2,
      "name": "Empty"
    },
    {
      "x": -5,
      "y": 12,
      "z": -2,
      "name": "Empty"
    },
    {
      "x": -5,
      "y": 5,
      "z": -1,
      "name": "Soil_Dirt"
    },
    {
      "x": -5,
      "y": 6,
      "z": -1,
      "name": "Soil_Dirt"
    },
    {
      "x": -5,
      "y": 7,
      "z": -1,
      "name": "Soil_Dirt"
    },
    {
      "x": -5,
      "y": 8,
      "z": -1,
      "name": "Soil_Dirt"
    },
    {
      "x": -5,
      "y": 9,
      "z": -1,
      "name": "Soil_Mud_Dry"
    },
    {
      "x": -5,
      "y": 10,
      "z": -1,
      "name": "Empty"
    },
    {
      "x": -5,
      "y": 11,
      "z": -1,
      "name": "Empty"
    },
    {
      "x": -5,
      "y": 12,
      "z": -1,
      "name": "Empty"
    },
    {
      "x": -5,
      "y": 5,
      "z": 0,
      "name": "Soil_Dirt"
    },
    {
      "x": -5,
      "y": 6,
      "z": 0,
      "name": "Soil_Dirt"
    },
    {
      "x": -5,
      "y": 7,
      "z": 0,
      "name": "Soil_Dirt"
    },
    {
      "x": -5,
      "y": 8,
      "z": 0,
      "name": "Soil_Dirt"
    },
    {
      "x": -5,
      "y": 9,
      "z": 0,
      "name": "Soil_Dirt"
    },
    {
      "x": -5,
      "y": 10,
      "z": 0,
      "name": "Empty"
    },
    {
      "x": -5,
      "y": 11,
      "z": 0,
      "name": "Empty"
    },
    {
      "x": -5,
      "y": 12,
      "z": 0,
      "name": "Empty"
    },
    {
      "x": -5,
      "y": 6,
      "z": 1,
      "name": "Soil_Dirt"
    },
    {
      "x": -5,
      "y": 7,
      "z": 1,
      "name": "Soil_Dirt"
    },
    {
      "x": -5,
      "y": 8,
      "z": 1,
      "name": "Soil_Dirt"
    },
    {
      "x": -5,
      "y": 9,
      "z": 1,
      "name": "Soil_Grass_Deep"
    },
    {
      "x": -5,
      "y": 10,
      "z": 1,
      "name": "*Wood_Hardwood_Fence_State_Definitions_Corner",
      "rotation": 1
    },
    {
      "x": -5,
      "y": 11,
      "z": 1,
      "name": "Empty"
    },
    {
      "x": -5,
      "y": 12,
      "z": 1,
      "name": "Empty"
    },
    {
      "x": -5,
      "y": 6,
      "z": 2,
      "name": "Soil_Dirt"
    },
    {
      "x": -5,
      "y": 7,
      "z": 2,
      "name": "Soil_Dirt"
    },
    {
      "x": -5,
      "y": 8,
      "z": 2,
      "name": "Soil_Dirt"
    },
    {
      "x": -5,
      "y": 9,
      "z": 2,
      "name": "Soil_Grass_Deep"
    },
    {
      "x": -5,
      "y": 10,
      "z": 2,
      "name": "*Wood_Hardwood_Fence_State_Definitions_Corner",
      "rotation": 3
    },
    {
      "x": -5,
      "y": 11,
      "z": 2,
      "name": "Empty"
    },
    {
      "x": -5,
      "y": 12,
      "z": 2,
      "name": "Empty"
    },
    {
      "x": -4,
      "y": 5,
      "z": -4,
      "name": "Soil_Dirt"
    },
    {
      "x": -4,
      "y": 6,
      "z": -4,
      "name": "Soil_Dirt"
    },
    {
      "x": -4,
      "y": 7,
      "z": -4,
      "name": "Soil_Dirt"
    },
    {
      "x": -4,
      "y": 8,
      "z": -4,
      "name": "Soil_Dirt"
    },
    {
      "x": -4,
      "y": 9,
      "z": -4,
      "name": "Soil_Grass_Deep"
    },
    {
      "x": -4,
      "y": 10,
      "z": -4,
      "name": "Wood_Hardwood_Fence",
      "rotation": 2
    },
    {
      "x": -4,
      "y": 11,
      "z": -4,
      "name": "Empty"
    },
    {
      "x": -4,
      "y": 12,
      "z": -4,
      "name": "Empty"
    },
    {
      "x": -4,
      "y": 4,
      "z": -3,
      "name": "Soil_Dirt"
    },
    {
      "x": -4,
      "y": 5,
      "z": -3,
      "name": "Soil_Dirt"
    },
    {
      "x": -4,
      "y": 6,
      "z": -3,
      "name": "Soil_Dirt"
    },
    {
      "x": -4,
      "y": 7,
      "z": -3,
      "name": "Soil_Dirt"
    },
    {
      "x": -4,
      "y": 8,
      "z": -3,
      "name": "Soil_Dirt"
    },
    {
      "x": -4,
      "y": 9,
      "z": -3,
      "name": "Soil_Mud_Dry"
    },
    {
      "x": -4,
      "y": 10,
      "z": -3,
      "name": "Empty"
    },
    {
      "x": -4,
      "y": 11,
      "z": -3,
      "name": "Empty"
    },
    {
      "x": -4,
      "y": 12,
      "z": -3,
      "name": "Empty"
    },
    {
      "x": -4,
      "y": 4,
      "z": -2,
      "name": "Soil_Dirt"
    },
    {
      "x": -4,
      "y": 5,
      "z": -2,
      "name": "Soil_Dirt"
    },
    {
      "x": -4,
      "y": 6,
      "z": -2,
      "name": "Soil_Dirt"
    },
    {
      "x": -4,
      "y": 7,
      "z": -2,
      "name": "Soil_Dirt"
    },
    {
      "x": -4,
      "y": 8,
      "z": -2,
      "name": "Soil_Dirt"
    },
    {
      "x": -4,
      "y": 9,
      "z": -2,
      "name": "Soil_Mud_Dry"
    },
    {
      "x": -4,
      "y": 10,
      "z": -2,
      "name": "Empty"
    },
    {
      "x": -4,
      "y": 11,
      "z": -2,
      "name": "Empty"
    },
    {
      "x": -4,
      "y": 12,
      "z": -2,
      "name": "Empty"
    },
    {
      "x": -4,
      "y": 4,
      "z": -1,
      "name": "Soil_Dirt"
    },
    {
      "x": -4,
      "y": 5,
      "z": -1,
      "name": "Soil_Dirt"
    },
    {
      "x": -4,
      "y": 6,
      "z": -1,
      "name": "Soil_Dirt"
    },
    {
      "x": -4,
      "y": 7,
      "z": -1,
      "name": "Soil_Dirt"
    },
    {
      "x": -4,
      "y": 8,
      "z": -1,
      "name": "Soil_Dirt"
    },
    {
      "x": -4,
      "y": 9,
      "z": -1,
      "name": "Soil_Mud_Dry"
    },
    {
      "x": -4,
      "y": 10,
      "z": -1,
      "name": "Empty"
    },
    {
      "x": -4,
      "y": 11,
      "z": -1,
      "name": "Empty"
    },
    {
      "x": -4,
      "y": 12,
      "z": -1,
      "name": "Empty"
    },
    {
      "x": -4,
      "y": 4,
      "z": 0,
      "name": "Soil_Dirt"
    },
    {
      "x": -4,
      "y": 5,
      "z": 0,
      "name": "Soil_Dirt"
    },
    {
      "x": -4,
      "y": 6,
      "z": 0,
      "name": "Soil_Dirt"
    },
    {
      "x": -4,
      "y": 7,
      "z": 0,
      "name": "Soil_Dirt"
    },
    {
      "x": -4,
      "y": 8,
      "z": 0,
      "name": "Soil_Dirt"
    },
    {
      "x": -4,
      "y": 9,
      "z": 0,
      "name": "Soil_Dirt"
    },
    {
      "x": -4,
      "y": 10,
      "z": 0,
      "name": "Empty"
    },
    {
      "x": -4,
      "y": 11,
      "z": 0,
      "name": "Empty"
    },
    {
      "x": -4,
      "y": 12,
      "z": 0,
      "name": "Empty"
    },
    {
      "x": -4,
      "y": 5,
      "z": 1,
      "name": "Soil_Dirt"
    },
    {
      "x": -4,
      "y": 6,
      "z": 1,
      "name": "Soil_Dirt"
    },
    {
      "x": -4,
      "y": 7,
      "z": 1,
      "name": "Soil_Dirt"
    },
    {
      "x": -4,
      "y": 8,
      "z": 1,
      "name": "Soil_Dirt"
    },
    {
      "x": -4,
      "y": 9,
      "z": 1,
      "name": "Soil_Dirt"
    },
    {
      "x": -4,
      "y": 10,
      "z": 1,
      "name": "*Wood_Hardwood_Fence_State_Definitions_Corner"
    },
    {
      "x": -4,
      "y": 11,
      "z": 1,
      "name": "Empty"
    },
    {
      "x": -4,
      "y": 12,
      "z": 1,
      "name": "Empty"
    },
    {
      "x": -4,
      "y": 5,
      "z": 2,
      "name": "Soil_Dirt"
    },
    {
      "x": -4,
      "y": 6,
      "z": 2,
      "name": "Soil_Dirt"
    },
    {
      "x": -4,
      "y": 7,
      "z": 2,
      "name": "Soil_Dirt"
    },
    {
      "x": -4,
      "y": 8,
      "z": 2,
      "name": "Soil_Dirt"
    },
    {
      "x": -4,
      "y": 9,
      "z": 2,
      "name": "Soil_Mud_Dry"
    },
    {
      "x": -4,
      "y": 10,
      "z": 2,
      "name": "Wood_Hardwood_Fence",
      "rotation": 3
    },
    {
      "x": -4,
      "y": 11,
      "z": 2,
      "name": "Empty"
    },
    {
      "x": -4,
      "y": 12,
      "z": 2,
      "name": "Empty"
    },
    {
      "x": -4,
      "y": 5,
      "z": 3,
      "name": "Soil_Dirt"
    },
    {
      "x": -4,
      "y": 6,
      "z": 3,
      "name": "Soil_Dirt"
    },
    {
      "x": -4,
      "y": 7,
      "z": 3,
      "name": "Soil_Dirt"
    },
    {
      "x": -4,
      "y": 8,
      "z": 3,
      "name": "Soil_Dirt"
    },
    {
      "x": -4,
      "y": 9,
      "z": 3,
      "name": "Soil_Mud_Dry"
    },
    {
      "x": -4,
      "y": 10,
      "z": 3,
      "name": "Wood_Hardwood_Fence",
      "rotation": 3
    },
    {
      "x": -4,
      "y": 11,
      "z": 3,
      "name": "Empty"
    },
    {
      "x": -4,
      "y": 12,
      "z": 3,
      "name": "Empty"
    },
    {
      "x": -4,
      "y": 6,
      "z": 4,
      "name": "Soil_Dirt"
    },
    {
      "x": -4,
      "y": 7,
      "z": 4,
      "name": "Soil_Dirt"
    },
    {
      "x": -4,
      "y": 8,
      "z": 4,
      "name": "Soil_Dirt"
    },
    {
      "x": -4,
      "y": 9,
      "z": 4,
      "name": "Soil_Grass_Deep"
    },
    {
      "x": -4,
      "y": 10,
      "z": 4,
      "name": "Wood_Hardwood_Fence",
      "rotation": 3
    },
    {
      "x": -4,
      "y": 11,
      "z": 4,
      "name": "Empty"
    },
    {
      "x": -4,
      "y": 12,
      "z": 4,
      "name": "Empty"
    },
    {
      "x": -4,
      "y": 7,
      "z": 5,
      "name": "Soil_Dirt"
    },
    {
      "x": -4,
      "y": 8,
      "z": 5,
      "name": "Soil_Dirt"
    },
    {
      "x": -4,
      "y": 9,
      "z": 5,
      "name": "Soil_Dirt"
    },
    {
      "x": -4,
      "y": 10,
      "z": 5,
      "name": "Wood_Hardwood_Fence",
      "rotation": 3
    },
    {
      "x": -4,
      "y": 11,
      "z": 5,
      "name": "Empty"
    },
    {
      "x": -4,
      "y": 12,
      "z": 5,
      "name": "Empty"
    },
    {
      "x": -4,
      "y": 7,
      "z": 6,
      "name": "Soil_Dirt"
    },
    {
      "x": -4,
      "y": 8,
      "z": 6,
      "name": "Soil_Dirt"
    },
    {
      "x": -4,
      "y": 9,
      "z": 6,
      "name": "Soil_Grass_Deep"
    },
    {
      "x": -4,
      "y": 10,
      "z": 6,
      "name": "Wood_Hardwood_Fence",
      "rotation": 3
    },
    {
      "x": -4,
      "y": 11,
      "z": 6,
      "name": "Empty"
    },
    {
      "x": -4,
      "y": 12,
      "z": 6,
      "name": "Empty"
    },
    {
      "x": -4,
      "y": 7,
      "z": 7,
      "name": "Soil_Dirt"
    },
    {
      "x": -4,
      "y": 8,
      "z": 7,
      "name": "Soil_Dirt"
    },
    {
      "x": -4,
      "y": 9,
      "z": 7,
      "name": "Soil_Grass_Deep"
    },
    {
      "x": -4,
      "y": 10,
      "z": 7,
      "name": "*Wood_Hardwood_Fence_State_Definitions_Corner",
      "rotation": 2
    },
    {
      "x": -4,
      "y": 11,
      "z": 7,
      "name": "Empty"
    },
    {
      "x": -4,
      "y": 12,
      "z": 7,
      "name": "Empty"
    },
    {
      "x": -3,
      "y": 4,
      "z": -4,
      "name": "Soil_Dirt"
    },
    {
      "x": -3,
      "y": 5,
      "z": -4,
      "name": "Soil_Dirt"
    },
    {
      "x": -3,
      "y": 6,
      "z": -4,
      "name": "Soil_Dirt"
    },
    {
      "x": -3,
      "y": 7,
      "z": -4,
      "name": "Soil_Dirt"
    },
    {
      "x": -3,
      "y": 8,
      "z": -4,
      "name": "Soil_Dirt"
    },
    {
      "x": -3,
      "y": 9,
      "z": -4,
      "name": "Soil_Dirt"
    },
    {
      "x": -3,
      "y": 10,
      "z": -4,
      "name": "Wood_Hardwood_Fence",
      "rotation": 2
    },
    {
      "x": -3,
      "y": 11,
      "z": -4,
      "name": "Empty"
    },
    {
      "x": -3,
      "y": 12,
      "z": -4,
      "name": "Empty"
    },
    {
      "x": -3,
      "y": 4,
      "z": -3,
      "name": "Soil_Dirt"
    },
    {
      "x": -3,
      "y": 5,
      "z": -3,
      "name": "Soil_Dirt"
    },
    {
      "x": -3,
      "y": 6,
      "z": -3,
      "name": "Soil_Dirt"
    },
    {
      "x": -3,
      "y": 7,
      "z": -3,
      "name": "Soil_Dirt"
    },
    {
      "x": -3,
      "y": 8,
      "z": -3,
      "name": "Soil_Dirt"
    },
    {
      "x": -3,
      "y": 9,
      "z": -3,
      "name": "Soil_Mud_Dry"
    },
    {
      "x": -3,
      "y": 10,
      "z": -3,
      "name": "Empty"
    },
    {
      "x": -3,
      "y": 11,
      "z": -3,
      "name": "Empty"
    },
    {
      "x": -3,
      "y": 12,
      "z": -3,
      "name": "Empty"
    },
    {
      "x": -3,
      "y": 4,
      "z": -2,
      "name": "Soil_Dirt"
    },
    {
      "x": -3,
      "y": 5,
      "z": -2,
      "name": "Soil_Dirt"
    },
    {
      "x": -3,
      "y": 6,
      "z": -2,
      "name": "Soil_Dirt"
    },
    {
      "x": -3,
      "y": 7,
      "z": -2,
      "name": "Soil_Dirt"
    },
    {
      "x": -3,
      "y": 8,
      "z": -2,
      "name": "Soil_Dirt"
    },
    {
      "x": -3,
      "y": 9,
      "z": -2,
      "name": "Soil_Mud_Dry"
    },
    {
      "x": -3,
      "y": 10,
      "z": -2,
      "name": "Empty"
    },
    {
      "x": -3,
      "y": 11,
      "z": -2,
      "name": "Empty"
    },
    {
      "x": -3,
      "y": 12,
      "z": -2,
      "name": "Empty"
    },
    {
      "x": -3,
      "y": 4,
      "z": -1,
      "name": "Soil_Dirt"
    },
    {
      "x": -3,
      "y": 5,
      "z": -1,
      "name": "Soil_Dirt"
    },
    {
      "x": -3,
      "y": 6,
      "z": -1,
      "name": "Soil_Dirt"
    },
    {
      "x": -3,
      "y": 7,
      "z": -1,
      "name": "Soil_Dirt"
    },
    {
      "x": -3,
      "y": 8,
      "z": -1,
      "name": "Soil_Dirt"
    },
    {
      "x": -3,
      "y": 9,
      "z": -1,
      "name": "Soil_Mud_Dry"
    },
    {
      "x": -3,
      "y": 10,
      "z": -1,
      "name": "Empty"
    },
    {
      "x": -3,
      "y": 11,
      "z": -1,
      "name": "Empty"
    },
    {
      "x": -3,
      "y": 12,
      "z": -1,
      "name": "Empty"
    },
    {
      "x": -3,
      "y": 4,
      "z": 0,
      "name": "Soil_Dirt"
    },
    {
      "x": -3,
      "y": 5,
      "z": 0,
      "name": "Soil_Dirt"
    },
    {
      "x": -3,
      "y": 6,
      "z": 0,
      "name": "Soil_Dirt"
    },
    {
      "x": -3,
      "y": 7,
      "z": 0,
      "name": "Soil_Dirt"
    },
    {
      "x": -3,
      "y": 8,
      "z": 0,
      "name": "Soil_Dirt"
    },
    {
      "x": -3,
      "y": 9,
      "z": 0,
      "name": "Soil_Dirt"
    },
    {
      "x": -3,
      "y": 10,
      "z": 0,
      "name": "Empty"
    },
    {
      "x": -3,
      "y": 11,
      "z": 0,
      "name": "Empty"
    },
    {
      "x": -3,
      "y": 12,
      "z": 0,
      "name": "Empty"
    },
    {
      "x": -3,
      "y": 4,
      "z": 1,
      "name": "Soil_Dirt"
    },
    {
      "x": -3,
      "y": 5,
      "z": 1,
      "name": "Soil_Dirt"
    },
    {
      "x": -3,
      "y": 6,
      "z": 1,
      "name": "Soil_Dirt"
    },
    {
      "x": -3,
      "y": 7,
      "z": 1,
      "name": "Soil_Dirt"
    },
    {
      "x": -3,
      "y": 8,
      "z": 1,
      "name": "Soil_Dirt"
    },
    {
      "x": -3,
      "y": 9,
      "z": 1,
      "name": "Soil_Mud_Dry"
    },
    {
      "x": -3,
      "y": 10,
      "z": 1,
      "name": "Empty"
    },
    {
      "x": -3,
      "y": 11,
      "z": 1,
      "name": "Empty"
    },
    {
      "x": -3,
      "y": 12,
      "z": 1,
      "name": "Empty"
    },
    {
      "x": -3,
      "y": 4,
      "z": 2,
      "name": "Soil_Dirt"
    },
    {
      "x": -3,
      "y": 5,
      "z": 2,
      "name": "Soil_Dirt"
    },
    {
      "x": -3,
      "y": 6,
      "z": 2,
      "name": "Soil_Dirt"
    },
    {
      "x": -3,
      "y": 7,
      "z": 2,
      "name": "Soil_Dirt"
    },
    {
      "x": -3,
      "y": 8,
      "z": 2,
      "name": "Soil_Dirt"
    },
    {
      "x": -3,
      "y": 9,
      "z": 2,
      "name": "Soil_Mud_Dry"
    },
    {
      "x": -3,
      "y": 10,
      "z": 2,
      "name": "Empty"
    },
    {
      "x": -3,
      "y": 11,
      "z": 2,
      "name": "Empty"
    },
    {
      "x": -3,
      "y": 12,
      "z": 2,
      "name": "Empty"
    },
    {
      "x": -3,
      "y": 5,
      "z": 3,
      "name": "Soil_Dirt"
    },
    {
      "x": -3,
      "y": 6,
      "z": 3,
      "name": "Soil_Dirt"
    },
    {
      "x": -3,
      "y": 7,
      "z": 3,
      "name": "Soil_Dirt"
    },
    {
      "x": -3,
      "y": 8,
      "z": 3,
      "name": "Soil_Dirt"
    },
    {
      "x": -3,
      "y": 9,
      "z": 3,
      "name": "Soil_Mud_Dry"
    },
    {
      "x": -3,
      "y": 10,
      "z": 3,
      "name": "Empty"
    },
    {
      "x": -3,
      "y": 11,
      "z": 3,
      "name": "Empty"
    },
    {
      "x": -3,
      "y": 12,
      "z": 3,
      "name": "Empty"
    },
    {
      "x": -3,
      "y": 5,
      "z": 4,
      "name": "Soil_Dirt"
    },
    {
      "x": -3,
      "y": 6,
      "z": 4,
      "name": "Soil_Dirt"
    },
    {
      "x": -3,
      "y": 7,
      "z": 4,
      "name": "Soil_Dirt"
    },
    {
      "x": -3,
      "y": 8,
      "z": 4,
      "name": "Soil_Dirt"
    },
    {
      "x": -3,
      "y": 9,
      "z": 4,
      "name": "Soil_Dirt"
    },
    {
      "x": -3,
      "y": 10,
      "z": 4,
      "name": "Empty"
    },
    {
      "x": -3,
      "y": 11,
      "z": 4,
      "name": "Empty"
    },
    {
      "x": -3,
      "y": 12,
      "z": 4,
      "name": "Empty"
    },
    {
      "x": -3,
      "y": 5,
      "z": 5,
      "name": "Soil_Dirt"
    },
    {
      "x": -3,
      "y": 6,
      "z": 5,
      "name": "Soil_Dirt"
    },
    {
      "x": -3,
      "y": 7,
      "z": 5,
      "name": "Soil_Dirt"
    },
    {
      "x": -3,
      "y": 8,
      "z": 5,
      "name": "Soil_Dirt"
    },
    {
      "x": -3,
      "y": 9,
      "z": 5,
      "name": "Soil_Dirt"
    },
    {
      "x": -3,
      "y": 10,
      "z": 5,
      "name": "Empty"
    },
    {
      "x": -3,
      "y": 11,
      "z": 5,
      "name": "Empty"
    },
    {
      "x": -3,
      "y": 12,
      "z": 5,
      "name": "Empty"
    },
    {
      "x": -3,
      "y": 5,
      "z": 6,
      "name": "Soil_Dirt"
    },
    {
      "x": -3,
      "y": 6,
      "z": 6,
      "name": "Soil_Dirt"
    },
    {
      "x": -3,
      "y": 7,
      "z": 6,
      "name": "Soil_Dirt"
    },
    {
      "x": -3,
      "y": 8,
      "z": 6,
      "name": "Soil_Dirt"
    },
    {
      "x": -3,
      "y": 9,
      "z": 6,
      "name": "Soil_Grass_Deep"
    },
    {
      "x": -3,
      "y": 10,
      "z": 6,
      "name": "Empty"
    },
    {
      "x": -3,
      "y": 11,
      "z": 6,
      "name": "Empty"
    },
    {
      "x": -3,
      "y": 12,
      "z": 6,
      "name": "Empty"
    },
    {
      "x": -3,
      "y": 7,
      "z": 7,
      "name": "Soil_Dirt"
    },
    {
      "x": -3,
      "y": 8,
      "z": 7,
      "name": "Soil_Dirt"
    },
    {
      "x": -3,
      "y": 9,
      "z": 7,
      "name": "Soil_Grass_Deep"
    },
    {
      "x": -3,
      "y": 10,
      "z": 7,
      "name": "Wood_Hardwood_Fence"
    },
    {
      "x": -3,
      "y": 11,
      "z": 7,
      "name": "Empty"
    },
    {
      "x": -3,
      "y": 12,
      "z": 7,
      "name": "Empty"
    },
    {
      "x": -2,
      "y": 4,
      "z": -5,
      "name": "Soil_Dirt"
    },
    {
      "x": -2,
      "y": 5,
      "z": -5,
      "name": "Soil_Dirt"
    },
    {
      "x": -2,
      "y": 6,
      "z": -5,
      "name": "Soil_Dirt"
    },
    {
      "x": -2,
      "y": 7,
      "z": -5,
      "name": "Soil_Dirt"
    },
    {
      "x": -2,
      "y": 8,
      "z": -5,
      "name": "Soil_Dirt"
    },
    {
      "x": -2,
      "y": 9,
      "z": -5,
      "name": "Soil_Dirt"
    },
    {
      "x": -2,
      "y": 10,
      "z": -5,
      "name": "*Wood_Hardwood_Fence_State_Definitions_Corner",
      "rotation": 1
    },
    {
      "x": -2,
      "y": 11,
      "z": -5,
      "name": "Empty"
    },
    {
      "x": -2,
      "y": 12,
      "z": -5,
      "name": "Empty"
    },
    {
      "x": -2,
      "y": 4,
      "z": -4,
      "name": "Soil_Dirt"
    },
    {
      "x": -2,
      "y": 5,
      "z": -4,
      "name": "Soil_Dirt"
    },
    {
      "x": -2,
      "y": 6,
      "z": -4,
      "name": "Soil_Dirt"
    },
    {
      "x": -2,
      "y": 7,
      "z": -4,
      "name": "Soil_Dirt"
    },
    {
      "x": -2,
      "y": 8,
      "z": -4,
      "name": "Soil_Dirt"
    },
    {
      "x": -2,
      "y": 9,
      "z": -4,
      "name": "Soil_Mud_Dry"
    },
    {
      "x": -2,
      "y": 10,
      "z": -4,
      "name": "*Wood_Hardwood_Fence_State_Definitions_Corner",
      "rotation": 3
    },
    {
      "x": -2,
      "y": 11,
      "z": -4,
      "name": "Empty"
    },
    {
      "x": -2,
      "y": 12,
      "z": -4,
      "name": "Empty"
    },
    {
      "x": -2,
      "y": 4,
      "z": -3,
      "name": "Soil_Dirt"
    },
    {
      "x": -2,
      "y": 5,
      "z": -3,
      "name": "Soil_Dirt"
    },
    {
      "x": -2,
      "y": 6,
      "z": -3,
      "name": "Soil_Dirt"
    },
    {
      "x": -2,
      "y": 7,
      "z": -3,
      "name": "Soil_Dirt"
    },
    {
      "x": -2,
      "y": 8,
      "z": -3,
      "name": "Soil_Dirt"
    },
    {
      "x": -2,
      "y": 9,
      "z": -3,
      "name": "Soil_Mud_Dry"
    },
    {
      "x": -2,
      "y": 10,
      "z": -3,
      "name": "Empty"
    },
    {
      "x": -2,
      "y": 11,
      "z": -3,
      "name": "Empty"
    },
    {
      "x": -2,
      "y": 12,
      "z": -3,
      "name": "Empty"
    },
    {
      "x": -2,
      "y": 4,
      "z": -2,
      "name": "Soil_Dirt"
    },
    {
      "x": -2,
      "y": 5,
      "z": -2,
      "name": "Soil_Dirt"
    },
    {
      "x": -2,
      "y": 6,
      "z": -2,
      "name": "Soil_Dirt"
    },
    {
      "x": -2,
      "y": 7,
      "z": -2,
      "name": "Soil_Dirt"
    },
    {
      "x": -2,
      "y": 8,
      "z": -2,
      "name": "Soil_Dirt"
    },
    {
      "x": -2,
      "y": 9,
      "z": -2,
      "name": "Soil_Mud_Dry"
    },
    {
      "x": -2,
      "y": 10,
      "z": -2,
      "name": "Empty"
    },
    {
      "x": -2,
      "y": 11,
      "z": -2,
      "name": "Empty"
    },
    {
      "x": -2,
      "y": 12,
      "z": -2,
      "name": "Empty"
    },
    {
      "x": -2,
      "y": 4,
      "z": -1,
      "name": "Soil_Dirt"
    },
    {
      "x": -2,
      "y": 5,
      "z": -1,
      "name": "Soil_Dirt"
    },
    {
      "x": -2,
      "y": 6,
      "z": -1,
      "name": "Soil_Dirt"
    },
    {
      "x": -2,
      "y": 7,
      "z": -1,
      "name": "Soil_Dirt"
    },
    {
      "x": -2,
      "y": 8,
      "z": -1,
      "name": "Soil_Dirt"
    },
    {
      "x": -2,
      "y": 9,
      "z": -1,
      "name": "Soil_Dirt_Tilled",
      "components": {
        "Components": {
          "TilledSoil": {
            "Version": 1,
            "DecayTime": "0001-01-02T19:24:01Z"
          }
        }
      }
    },
    {
      "x": -2,
      "y": 10,
      "z": -1,
      "name": "Empty"
    },
    {
      "x": -2,
      "y": 11,
      "z": -1,
      "name": "Empty"
    },
    {
      "x": -2,
      "y": 12,
      "z": -1,
      "name": "Empty"
    },
    {
      "x": -2,
      "y": 4,
      "z": 0,
      "name": "Soil_Dirt"
    },
    {
      "x": -2,
      "y": 5,
      "z": 0,
      "name": "Soil_Dirt"
    },
    {
      "x": -2,
      "y": 6,
      "z": 0,
      "name": "Soil_Dirt"
    },
    {
      "x": -2,
      "y": 7,
      "z": 0,
      "name": "Soil_Dirt"
    },
    {
      "x": -2,
      "y": 8,
      "z": 0,
      "name": "Soil_Dirt"
    },
    {
      "x": -2,
      "y": 9,
      "z": 0,
      "name": "Soil_Dirt_Tilled",
      "components": {
        "Components": {
          "TilledSoil": {
            "Version": 1,
            "DecayTime": "0001-01-02T22:36:02Z"
          }
        }
      }
    },
    {
      "x": -2,
      "y": 10,
      "z": 0,
      "name": "Empty"
    },
    {
      "x": -2,
      "y": 11,
      "z": 0,
      "name": "Empty"
    },
    {
      "x": -2,
      "y": 12,
      "z": 0,
      "name": "Empty"
    },
    {
      "x": -2,
      "y": 4,
      "z": 1,
      "name": "Soil_Dirt"
    },
    {
      "x": -2,
      "y": 5,
      "z": 1,
      "name": "Soil_Dirt"
    },
    {
      "x": -2,
      "y": 6,
      "z": 1,
      "name": "Soil_Dirt"
    },
    {
      "x": -2,
      "y": 7,
      "z": 1,
      "name": "Soil_Dirt"
    },
    {
      "x": -2,
      "y": 8,
      "z": 1,
      "name": "Soil_Dirt"
    },
    {
      "x": -2,
      "y": 9,
      "z": 1,
      "name": "Soil_Mud_Dry"
    },
    {
      "x": -2,
      "y": 10,
      "z": 1,
      "name": "Empty"
    },
    {
      "x": -2,
      "y": 11,
      "z": 1,
      "name": "Empty"
    },
    {
      "x": -2,
      "y": 12,
      "z": 1,
      "name": "Empty"
    },
    {
      "x": -2,
      "y": 4,
      "z": 2,
      "name": "Soil_Dirt"
    },
    {
      "x": -2,
      "y": 5,
      "z": 2,
      "name": "Soil_Dirt"
    },
    {
      "x": -2,
      "y": 6,
      "z": 2,
      "name": "Soil_Dirt"
    },
    {
      "x": -2,
      "y": 7,
      "z": 2,
      "name": "Soil_Dirt"
    },
    {
      "x": -2,
      "y": 8,
      "z": 2,
      "name": "Soil_Dirt"
    },
    {
      "x": -2,
      "y": 9,
      "z": 2,
      "name": "Soil_Dirt"
    },
    {
      "x": -2,
      "y": 10,
      "z": 2,
      "name": "Empty"
    },
    {
      "x": -2,
      "y": 11,
      "z": 2,
      "name": "Empty"
    },
    {
      "x": -2,
      "y": 12,
      "z": 2,
      "name": "Empty"
    },
    {
      "x": -2,
      "y": 4,
      "z": 3,
      "name": "Soil_Dirt"
    },
    {
      "x": -2,
      "y": 5,
      "z": 3,
      "name": "Soil_Dirt"
    },
    {
      "x": -2,
      "y": 6,
      "z": 3,
      "name": "Soil_Dirt"
    },
    {
      "x": -2,
      "y": 7,
      "z": 3,
      "name": "Soil_Dirt"
    },
    {
      "x": -2,
      "y": 8,
      "z": 3,
      "name": "Soil_Dirt"
    },
    {
      "x": -2,
      "y": 9,
      "z": 3,
      "name": "Soil_Dirt"
    },
    {
      "x": -2,
      "y": 10,
      "z": 3,
      "name": "Empty"
    },
    {
      "x": -2,
      "y": 11,
      "z": 3,
      "name": "Empty"
    },
    {
      "x": -2,
      "y": 12,
      "z": 3,
      "name": "Empty"
    },
    {
      "x": -2,
      "y": 4,
      "z": 4,
      "name": "Soil_Dirt"
    },
    {
      "x": -2,
      "y": 5,
      "z": 4,
      "name": "Soil_Dirt"
    },
    {
      "x": -2,
      "y": 6,
      "z": 4,
      "name": "Soil_Dirt"
    },
    {
      "x": -2,
      "y": 7,
      "z": 4,
      "name": "Soil_Dirt"
    },
    {
      "x": -2,
      "y": 8,
      "z": 4,
      "name": "Soil_Dirt"
    },
    {
      "x": -2,
      "y": 9,
      "z": 4,
      "name": "Soil_Mud_Dry"
    },
    {
      "x": -2,
      "y": 10,
      "z": 4,
      "name": "Empty"
    },
    {
      "x": -2,
      "y": 11,
      "z": 4,
      "name": "Empty"
    },
    {
      "x": -2,
      "y": 12,
      "z": 4,
      "name": "Empty"
    },
    {
      "x": -2,
      "y": 4,
      "z": 5,
      "name": "Soil_Dirt"
    },
    {
      "x": -2,
      "y": 5,
      "z": 5,
      "name": "Soil_Dirt"
    },
    {
      "x": -2,
      "y": 6,
      "z": 5,
      "name": "Soil_Dirt"
    },
    {
      "x": -2,
      "y": 7,
      "z": 5,
      "name": "Soil_Dirt"
    },
    {
      "x": -2,
      "y": 8,
      "z": 5,
      "name": "Soil_Dirt"
    },
    {
      "x": -2,
      "y": 9,
      "z": 5,
      "name": "Soil_Mud_Dry"
    },
    {
      "x": -2,
      "y": 10,
      "z": 5,
      "name": "Empty"
    },
    {
      "x": -2,
      "y": 11,
      "z": 5,
      "name": "Empty"
    },
    {
      "x": -2,
      "y": 12,
      "z": 5,
      "name": "Empty"
    },
    {
      "x": -2,
      "y": 5,
      "z": 6,
      "name": "Soil_Dirt"
    },
    {
      "x": -2,
      "y": 6,
      "z": 6,
      "name": "Soil_Dirt"
    },
    {
      "x": -2,
      "y": 7,
      "z": 6,
      "name": "Soil_Dirt"
    },
    {
      "x": -2,
      "y": 8,
      "z": 6,
      "name": "Soil_Dirt"
    },
    {
      "x": -2,
      "y": 9,
      "z": 6,
      "name": "Soil_Dirt"
    },
    {
      "x": -2,
      "y": 10,
      "z": 6,
      "name": "Empty"
    },
    {
      "x": -2,
      "y": 11,
      "z": 6,
      "name": "Empty"
    },
    {
      "x": -2,
      "y": 12,
      "z": 6,
      "name": "Empty"
    },
    {
      "x": -2,
      "y": 6,
      "z": 7,
      "name": "Soil_Dirt"
    },
    {
      "x": -2,
      "y": 7,
      "z": 7,
      "name": "Soil_Dirt"
    },
    {
      "x": -2,
      "y": 8,
      "z": 7,
      "name": "Soil_Dirt"
    },
    {
      "x": -2,
      "y": 9,
      "z": 7,
      "name": "Soil_Grass_Deep"
    },
    {
      "x": -2,
      "y": 10,
      "z": 7,
      "name": "Wood_Hardwood_Fence"
    },
    {
      "x": -2,
      "y": 11,
      "z": 7,
      "name": "Empty"
    },
    {
      "x": -2,
      "y": 12,
      "z": 7,
      "name": "Empty"
    },
    {
      "x": -1,
      "y": 4,
      "z": -5,
      "name": "Soil_Dirt"
    },
    {
      "x": -1,
      "y": 5,
      "z": -5,
      "name": "Soil_Dirt"
    },
    {
      "x": -1,
      "y": 6,
      "z": -5,
      "name": "Soil_Dirt"
    },
    {
      "x": -1,
      "y": 7,
      "z": -5,
      "name": "Soil_Dirt"
    },
    {
      "x": -1,
      "y": 8,
      "z": -5,
      "name": "Soil_Dirt"
    },
    {
      "x": -1,
      "y": 9,
      "z": -5,
      "name": "Soil_Grass_Deep"
    },
    {
      "x": -1,
      "y": 10,
      "z": -5,
      "name": "Wood_Hardwood_Fence",
      "rotation": 2
    },
    {
      "x": -1,
      "y": 11,
      "z": -5,
      "name": "Empty"
    },
    {
      "x": -1,
      "y": 12,
      "z": -5,
      "name": "Empty"
    },
    {
      "x": -1,
      "y": 4,
      "z": -4,
      "name": "Soil_Dirt"
    },
    {
      "x": -1,
      "y": 5,
      "z": -4,
      "name": "Soil_Dirt"
    },
    {
      "x": -1,
      "y": 6,
      "z": -4,
      "name": "Soil_Dirt"
    },
    {
      "x": -1,
      "y": 7,
      "z": -4,
      "name": "Soil_Dirt"
    },
    {
      "x": -1,
      "y": 8,
      "z": -4,
      "name": "Soil_Dirt"
    },
    {
      "x": -1,
      "y": 9,
      "z": -4,
      "name": "Soil_Mud_Dry"
    },
    {
      "x": -1,
      "y": 10,
      "z": -4,
      "name": "Empty"
    },
    {
      "x": -1,
      "y": 11,
      "z": -4,
      "name": "Empty"
    },
    {
      "x": -1,
      "y": 12,
      "z": -4,
      "name": "Empty"
    },
    {
      "x": -1,
      "y": 4,
      "z": -3,
      "name": "Soil_Dirt"
    },
    {
      "x": -1,
      "y": 5,
      "z": -3,
      "name": "Soil_Dirt"
    },
    {
      "x": -1,
      "y": 6,
      "z": -3,
      "name": "Soil_Dirt"
    },
    {
      "x": -1,
      "y": 7,
      "z": -3,
      "name": "Soil_Dirt"
    },
    {
      "x": -1,
      "y": 8,
      "z": -3,
      "name": "Soil_Dirt"
    },
    {
      "x": -1,
      "y": 9,
      "z": -3,
      "name": "Soil_Dirt_Tilled",
      "components": {
        "Components": {
          "TilledSoil": {
            "Version": 1,
            "DecayTime": "0001-01-02T21:56:13Z"
          }
        }
      }
    },
    {
      "x": -1,
      "y": 10,
      "z": -3,
      "name": "Empty"
    },
    {
      "x": -1,
      "y": 11,
      "z": -3,
      "name": "Empty"
    },
    {
      "x": -1,
      "y": 12,
      "z": -3,
      "name": "Empty"
    },
    {
      "x": -1,
      "y": 4,
      "z": -2,
      "name": "Soil_Dirt"
    },
    {
      "x": -1,
      "y": 5,
      "z": -2,
      "name": "Soil_Dirt"
    },
    {
      "x": -1,
      "y": 6,
      "z": -2,
      "name": "Soil_Dirt"
    },
    {
      "x": -1,
      "y": 7,
      "z": -2,
      "name": "Soil_Dirt"
    },
    {
      "x": -1,
      "y": 8,
      "z": -2,
      "name": "Soil_Dirt"
    },
    {
      "x": -1,
      "y": 9,
      "z": -2,
      "name": "Soil_Dirt_Tilled",
      "components": {
        "Components": {
          "TilledSoil": {
            "Version": 1,
            "DecayTime": "0001-01-02T20:53:20Z"
          }
        }
      }
    },
    {
      "x": -1,
      "y": 10,
      "z": -2,
      "name": "Empty"
    },
    {
      "x": -1,
      "y": 11,
      "z": -2,
      "name": "Empty"
    },
    {
      "x": -1,
      "y": 12,
      "z": -2,
      "name": "Empty"
    },
    {
      "x": -1,
      "y": 4,
      "z": -1,
      "name": "Soil_Dirt"
    },
    {
      "x": -1,
      "y": 5,
      "z": -1,
      "name": "Soil_Dirt"
    },
    {
      "x": -1,
      "y": 6,
      "z": -1,
      "name": "Soil_Dirt"
    },
    {
      "x": -1,
      "y": 7,
      "z": -1,
      "name": "Soil_Dirt"
    },
    {
      "x": -1,
      "y": 8,
      "z": -1,
      "name": "Soil_Dirt"
    },
    {
      "x": -1,
      "y": 9,
      "z": -1,
      "name": "Soil_Dirt_Tilled",
      "components": {
        "Components": {
          "TilledSoil": {
            "Version": 1,
            "DecayTime": "0001-01-02T22:48:21Z"
          }
        }
      }
    },
    {
      "x": -1,
      "y": 10,
      "z": -1,
      "name": "Empty"
    },
    {
      "x": -1,
      "y": 11,
      "z": -1,
      "name": "Empty"
    },
    {
      "x": -1,
      "y": 12,
      "z": -1,
      "name": "Empty"
    },
    {
      "x": -1,
      "y": 4,
      "z": 0,
      "name": "Soil_Dirt"
    },
    {
      "x": -1,
      "y": 5,
      "z": 0,
      "name": "Soil_Dirt"
    },
    {
      "x": -1,
      "y": 6,
      "z": 0,
      "name": "Soil_Dirt"
    },
    {
      "x": -1,
      "y": 7,
      "z": 0,
      "name": "Soil_Dirt"
    },
    {
      "x": -1,
      "y": 8,
      "z": 0,
      "name": "Soil_Dirt"
    },
    {
      "x": -1,
      "y": 9,
      "z": 0,
      "name": "Soil_Dirt_Tilled",
      "components": {
        "Components": {
          "TilledSoil": {
            "Version": 1,
            "DecayTime": "0001-01-02T17:34:25Z"
          }
        }
      }
    },
    {
      "x": -1,
      "y": 10,
      "z": 0,
      "name": "*Plant_Crop_Carrot_Block_State_Definitions_Stage2",
      "components": {
        "Components": {
          "FarmingBlock": {
            "GrowthProgress": 2.0,
            "LastTickGameTime": "0001-01-01T12:00:00Z"
          }
        }
      }
    },
    {
      "x": -1,
      "y": 11,
      "z": 0,
      "name": "Empty"
    },
    {
      "x": -1,
      "y": 12,
      "z": 0,
      "name": "Empty"
    },
    {
      "x": -1,
      "y": 4,
      "z": 1,
      "name": "Soil_Dirt"
    },
    {
      "x": -1,
      "y": 5,
      "z": 1,
      "name": "Soil_Dirt"
    },
    {
      "x": -1,
      "y": 6,
      "z": 1,
      "name": "Soil_Dirt"
    },
    {
      "x": -1,
      "y": 7,
      "z": 1,
      "name": "Soil_Dirt"
    },
    {
      "x": -1,
      "y": 8,
      "z": 1,
      "name": "Soil_Dirt"
    },
    {
      "x": -1,
      "y": 9,
      "z": 1,
      "name": "Soil_Dirt_Tilled",
      "components": {
        "Components": {
          "TilledSoil": {
            "Version": 1,
            "DecayTime": "0001-01-02T20:15:21Z"
          }
        }
      }
    },
    {
      "x": -1,
      "y": 10,
      "z": 1,
      "name": "*Plant_Crop_Carrot_Block_State_Definitions_StageFinal"
    },
    {
      "x": -1,
      "y": 11,
      "z": 1,
      "name": "Empty"
    },
    {
      "x": -1,
      "y": 12,
      "z": 1,
      "name": "Empty"
    },
    {
      "x": -1,
      "y": 4,
      "z": 2,
      "name": "Soil_Dirt"
    },
    {
      "x": -1,
      "y": 5,
      "z": 2,
      "name": "Soil_Dirt"
    },
    {
      "x": -1,
      "y": 6,
      "z": 2,
      "name": "Soil_Dirt"
    },
    {
      "x": -1,
      "y": 7,
      "z": 2,
      "name": "Soil_Dirt"
    },
    {
      "x": -1,
      "y": 8,
      "z": 2,
      "name": "Soil_Dirt"
    },
    {
      "x": -1,
      "y": 9,
      "z": 2,
      "name": "Soil_Dirt"
    },
    {
      "x": -1,
      "y": 10,
      "z": 2,
      "name": "Empty"
    },
    {
      "x": -1,
      "y": 11,
      "z": 2,
      "name": "Empty"
    },
    {
      "x": -1,
      "y": 12,
      "z": 2,
      "name": "Empty"
    },
    {
      "x": -1,
      "y": 4,
      "z": 3,
      "name": "Soil_Dirt"
    },
    {
      "x": -1,
      "y": 5,
      "z": 3,
      "name": "Soil_Dirt"
    },
    {
      "x": -1,
      "y": 6,
      "z": 3,
      "name": "Soil_Dirt"
    },
    {
      "x": -1,
      "y": 7,
      "z": 3,
      "name": "Soil_Dirt"
    },
    {
      "x": -1,
      "y": 8,
      "z": 3,
      "name": "Soil_Dirt"
    },
    {
      "x": -1,
      "y": 9,
      "z": 3,
      "name": "Soil_Dirt"
    },
    {
      "x": -1,
      "y": 10,
      "z": 3,
      "name": "Empty"
    },
    {
      "x": -1,
      "y": 11,
      "z": 3,
      "name": "Empty"
    },
    {
      "x": -1,
      "y": 12,
      "z": 3,
      "name": "Empty"
    },
    {
      "x": -1,
      "y": 4,
      "z": 4,
      "name": "Soil_Dirt"
    },
    {
      "x": -1,
      "y": 5,
      "z": 4,
      "name": "Soil_Dirt"
    },
    {
      "x": -1,
      "y": 6,
      "z": 4,
      "name": "Soil_Dirt"
    },
    {
      "x": -1,
      "y": 7,
      "z": 4,
      "name": "Soil_Dirt"
    },
    {
      "x": -1,
      "y": 8,
      "z": 4,
      "name": "Soil_Dirt"
    },
    {
      "x": -1,
      "y": 9,
      "z": 4,
      "name": "Soil_Mud_Dry"
    },
    {
      "x": -1,
      "y": 10,
      "z": 4,
      "name": "Empty"
    },
    {
      "x": -1,
      "y": 11,
      "z": 4,
      "name": "Empty"
    },
    {
      "x": -1,
      "y": 12,
      "z": 4,
      "name": "Empty"
    },
    {
      "x": -1,
      "y": 4,
      "z": 5,
      "name": "Soil_Dirt"
    },
    {
      "x": -1,
      "y": 5,
      "z": 5,
      "name": "Soil_Dirt"
    },
    {
      "x": -1,
      "y": 6,
      "z": 5,
      "name": "Soil_Dirt"
    },
    {
      "x": -1,
      "y": 7,
      "z": 5,
      "name": "Soil_Dirt"
    },
    {
      "x": -1,
      "y": 8,
      "z": 5,
      "name": "Soil_Dirt"
    },
    {
      "x": -1,
      "y": 9,
      "z": 5,
      "name": "Soil_Mud_Dry"
    },
    {
      "x": -1,
      "y": 10,
      "z": 5,
      "name": "Empty"
    },
    {
      "x": -1,
      "y": 11,
      "z": 5,
      "name": "Empty"
    },
    {
      "x": -1,
      "y": 12,
      "z": 5,
      "name": "Empty"
    },
    {
      "x": -1,
      "y": 5,
      "z": 6,
      "name": "Soil_Dirt"
    },
    {
      "x": -1,
      "y": 6,
      "z": 6,
      "name": "Soil_Dirt"
    },
    {
      "x": -1,
      "y": 7,
      "z": 6,
      "name": "Soil_Dirt"
    },
    {
      "x": -1,
      "y": 8,
      "z": 6,
      "name": "Soil_Dirt"
    },
    {
      "x": -1,
      "y": 9,
      "z": 6,
      "name": "Soil_Dirt"
    },
    {
      "x": -1,
      "y": 10,
      "z": 6,
      "name": "Empty"
    },
    {
      "x": -1,
      "y": 11,
      "z": 6,
      "name": "Empty"
    },
    {
      "x": -1,
      "y": 12,
      "z": 6,
      "name": "Empty"
    },
    {
      "x": -1,
      "y": 6,
      "z": 7,
      "name": "Soil_Dirt"
    },
    {
      "x": -1,
      "y": 7,
      "z": 7,
      "name": "Soil_Dirt"
    },
    {
      "x": -1,
      "y": 8,
      "z": 7,
      "name": "Soil_Dirt"
    },
    {
      "x": -1,
      "y": 9,
      "z": 7,
      "name": "Soil_Dirt"
    },
    {
      "x": -1,
      "y": 10,
      "z": 7,
      "name": "Wood_Hardwood_Fence"
    },
    {
      "x": -1,
      "y": 11,
      "z": 7,
      "name": "Empty"
    },
    {
      "x": -1,
      "y": 12,
      "z": 7,
      "name": "Empty"
    },
    {
      "x": 0,
      "y": 4,
      "z": -5,
      "name": "Soil_Dirt"
    },
    {
      "x": 0,
      "y": 5,
      "z": -5,
      "name": "Soil_Dirt"
    },
    {
      "x": 0,
      "y": 6,
      "z": -5,
      "name": "Soil_Dirt"
    },
    {
      "x": 0,
      "y": 7,
      "z": -5,
      "name": "Soil_Dirt"
    },
    {
      "x": 0,
      "y": 8,
      "z": -5,
      "name": "Soil_Dirt"
    },
    {
      "x": 0,
      "y": 9,
      "z": -5,
      "name": "Soil_Grass_Deep"
    },
    {
      "x": 0,
      "y": 10,
      "z": -5,
      "name": "Wood_Hardwood_Fence",
      "rotation": 2
    },
    {
      "x": 0,
      "y": 11,
      "z": -5,
      "name": "Empty"
    },
    {
      "x": 0,
      "y": 12,
      "z": -5,
      "name": "Empty"
    },
    {
      "x": 0,
      "y": 4,
      "z": -4,
      "name": "Soil_Dirt"
    },
    {
      "x": 0,
      "y": 5,
      "z": -4,
      "name": "Soil_Dirt"
    },
    {
      "x": 0,
      "y": 6,
      "z": -4,
      "name": "Soil_Dirt"
    },
    {
      "x": 0,
      "y": 7,
      "z": -4,
      "name": "Soil_Dirt"
    },
    {
      "x": 0,
      "y": 8,
      "z": -4,
      "name": "Soil_Dirt"
    },
    {
      "x": 0,
      "y": 9,
      "z": -4,
      "name": "Soil_Mud_Dry"
    },
    {
      "x": 0,
      "y": 10,
      "z": -4,
      "name": "Empty"
    },
    {
      "x": 0,
      "y": 11,
      "z": -4,
      "name": "Empty"
    },
    {
      "x": 0,
      "y": 12,
      "z": -4,
      "name": "Empty"
    },
    {
      "x": 0,
      "y": 4,
      "z": -3,
      "name": "Soil_Dirt"
    },
    {
      "x": 0,
      "y": 5,
      "z": -3,
      "name": "Soil_Dirt"
    },
    {
      "x": 0,
      "y": 6,
      "z": -3,
      "name": "Soil_Dirt"
    },
    {
      "x": 0,
      "y": 7,
      "z": -3,
      "name": "Soil_Dirt"
    },
    {
      "x": 0,
      "y": 8,
      "z": -3,
      "name": "Soil_Dirt"
    },
    {
      "x": 0,
      "y": 9,
      "z": -3,
      "name": "Soil_Mud_Dry"
    },
    {
      "x": 0,
      "y": 10,
      "z": -3,
      "name": "Empty"
    },
    {
      "x": 0,
      "y": 11,
      "z": -3,
      "name": "Empty"
    },
    {
      "x": 0,
      "y": 12,
      "z": -3,
      "name": "Empty"
    },
    {
      "x": 0,
      "y": 4,
      "z": -2,
      "name": "Soil_Dirt"
    },
    {
      "x": 0,
      "y": 5,
      "z": -2,
      "name": "Soil_Dirt"
    },
    {
      "x": 0,
      "y": 6,
      "z": -2,
      "name": "Soil_Dirt"
    },
    {
      "x": 0,
      "y": 7,
      "z": -2,
      "name": "Soil_Dirt"
    },
    {
      "x": 0,
      "y": 8,
      "z": -2,
      "name": "Soil_Dirt"
    },
    {
      "x": 0,
      "y": 9,
      "z": -2,
      "name": "Soil_Dirt_Tilled",
      "components": {
        "Components": {
          "TilledSoil": {
            "Version": 1,
            "DecayTime": "0001-01-02T22:47:29Z"
          }
        }
      }
    },
    {
      "x": 0,
      "y": 10,
      "z": -2,
      "name": "*Plant_Crop_Carrot_Block_State_Definitions_Stage2",
      "components": {
        "Components": {
          "FarmingBlock": {
            "GrowthProgress": 2.0,
            "LastTickGameTime": "0001-01-01T12:00:00Z"
          }
        }
      }
    },
    {
      "x": 0,
      "y": 11,
      "z": -2,
      "name": "Empty"
    },
    {
      "x": 0,
      "y": 12,
      "z": -2,
      "name": "Empty"
    },
    {
      "x": 0,
      "y": 4,
      "z": -1,
      "name": "Soil_Dirt"
    },
    {
      "x": 0,
      "y": 5,
      "z": -1,
      "name": "Soil_Dirt"
    },
    {
      "x": 0,
      "y": 6,
      "z": -1,
      "name": "Soil_Dirt"
    },
    {
      "x": 0,
      "y": 7,
      "z": -1,
      "name": "Soil_Dirt"
    },
    {
      "x": 0,
      "y": 8,
      "z": -1,
      "name": "Soil_Dirt"
    },
    {
      "x": 0,
      "y": 9,
      "z": -1,
      "name": "Soil_Dirt_Tilled",
      "components": {
        "Components": {
          "TilledSoil": {
            "Version": 1,
            "DecayTime": "0001-01-02T21:23:38Z"
          }
        }
      }
    },
    {
      "x": 0,
      "y": 10,
      "z": -1,
      "name": "Empty"
    },
    {
      "x": 0,
      "y": 11,
      "z": -1,
      "name": "Empty"
    },
    {
      "x": 0,
      "y": 12,
      "z": -1,
      "name": "Empty"
    },
    {
      "x": 0,
      "y": 4,
      "z": 0,
      "name": "Soil_Dirt"
    },
    {
      "x": 0,
      "y": 5,
      "z": 0,
      "name": "Soil_Dirt"
    },
    {
      "x": 0,
      "y": 6,
      "z": 0,
      "name": "Soil_Dirt"
    },
    {
      "x": 0,
      "y": 7,
      "z": 0,
      "name": "Soil_Dirt"
    },
    {
      "x": 0,
      "y": 8,
      "z": 0,
      "name": "Soil_Dirt"
    },
    {
      "x": 0,
      "y": 9,
      "z": 0,
      "name": "Soil_Dirt_Tilled",
      "components": {
        "Components": {
          "TilledSoil": {
            "Version": 1,
            "DecayTime": "0001-01-02T19:07:47Z"
          }
        }
      }
    },
    {
      "x": 0,
      "y": 10,
      "z": 0,
      "name": "*Plant_Crop_Carrot_Block_State_Definitions_StageFinal"
    },
    {
      "x": 0,
      "y": 11,
      "z": 0,
      "name": "Empty"
    },
    {
      "x": 0,
      "y": 12,
      "z": 0,
      "name": "Empty"
    },
    {
      "x": 0,
      "y": 4,
      "z": 1,
      "name": "Soil_Dirt"
    },
    {
      "x": 0,
      "y": 5,
      "z": 1,
      "name": "Soil_Dirt"
    },
    {
      "x": 0,
      "y": 6,
      "z": 1,
      "name": "Soil_Dirt"
    },
    {
      "x": 0,
      "y": 7,
      "z": 1,
      "name": "Soil_Dirt"
    },
    {
      "x": 0,
      "y": 8,
      "z": 1,
      "name": "Soil_Dirt"
    },
    {
      "x": 0,
      "y": 9,
      "z": 1,
      "name": "Soil_Dirt"
    },
    {
      "x": 0,
      "y": 10,
      "z": 1,
      "name": "Empty"
    },
    {
      "x": 0,
      "y": 11,
      "z": 1,
      "name": "Empty"
    },
    {
      "x": 0,
      "y": 12,
      "z": 1,
      "name": "Empty"
    },
    {
      "x": 0,
      "y": 4,
      "z": 2,
      "name": "Soil_Dirt"
    },
    {
      "x": 0,
      "y": 5,
      "z": 2,
      "name": "Soil_Dirt"
    },
    {
      "x": 0,
      "y": 6,
      "z": 2,
      "name": "Soil_Dirt"
    },
    {
      "x": 0,
      "y": 7,
      "z": 2,
      "name": "Soil_Dirt"
    },
    {
      "x": 0,
      "y": 8,
      "z": 2,
      "name": "Soil_Dirt"
    },
    {
      "x": 0,
      "y": 9,
      "z": 2,
      "name": "Soil_Dirt"
    },
    {
      "x": 0,
      "y": 10,
      "z": 2,
      "name": "Empty"
    },
    {
      "x": 0,
      "y": 11,
      "z": 2,
      "name": "Empty"
    },
    {
      "x": 0,
      "y": 12,
      "z": 2,
      "name": "Empty"
    },
    {
      "x": 0,
      "y": 4,
      "z": 3,
      "name": "Soil_Dirt"
    },
    {
      "x": 0,
      "y": 5,
      "z": 3,
      "name": "Soil_Dirt"
    },
    {
      "x": 0,
      "y": 6,
      "z": 3,
      "name": "Soil_Dirt"
    },
    {
      "x": 0,
      "y": 7,
      "z": 3,
      "name": "Soil_Dirt"
    },
    {
      "x": 0,
      "y": 8,
      "z": 3,
      "name": "Soil_Dirt"
    },
    {
      "x": 0,
      "y": 9,
      "z": 3,
      "name": "Soil_Dirt"
    },
    {
      "x": 0,
      "y": 10,
      "z": 3,
      "name": "Empty"
    },
    {
      "x": 0,
      "y": 11,
      "z": 3,
      "name": "Empty"
    },
    {
      "x": 0,
      "y": 12,
      "z": 3,
      "name": "Empty"
    },
    {
      "x": 0,
      "y": 4,
      "z": 4,
      "name": "Soil_Dirt"
    },
    {
      "x": 0,
      "y": 5,
      "z": 4,
      "name": "Soil_Dirt"
    },
    {
      "x": 0,
      "y": 6,
      "z": 4,
      "name": "Soil_Dirt"
    },
    {
      "x": 0,
      "y": 7,
      "z": 4,
      "name": "Soil_Dirt"
    },
    {
      "x": 0,
      "y": 8,
      "z": 4,
      "name": "Soil_Dirt"
    },
    {
      "x": 0,
      "y": 9,
      "z": 4,
      "name": "Soil_Mud_Dry"
    },
    {
      "x": 0,
      "y": 10,
      "z": 4,
      "name": "Empty"
    },
    {
      "x": 0,
      "y": 11,
      "z": 4,
      "name": "Empty"
    },
    {
      "x": 0,
      "y": 12,
      "z": 4,
      "name": "Empty"
    },
    {
      "x": 0,
      "y": 4,
      "z": 5,
      "name": "Soil_Dirt"
    },
    {
      "x": 0,
      "y": 5,
      "z": 5,
      "name": "Soil_Dirt"
    },
    {
      "x": 0,
      "y": 6,
      "z": 5,
      "name": "Soil_Dirt"
    },
    {
      "x": 0,
      "y": 7,
      "z": 5,
      "name": "Soil_Dirt"
    },
    {
      "x": 0,
      "y": 8,
      "z": 5,
      "name": "Soil_Dirt"
    },
    {
      "x": 0,
      "y": 9,
      "z": 5,
      "name": "Soil_Mud_Dry"
    },
    {
      "x": 0,
      "y": 10,
      "z": 5,
      "name": "Empty"
    },
    {
      "x": 0,
      "y": 11,
      "z": 5,
      "name": "Empty"
    },
    {
      "x": 0,
      "y": 12,
      "z": 5,
      "name": "Empty"
    },
    {
      "x": 0,
      "y": 5,
      "z": 6,
      "name": "Soil_Dirt"
    },
    {
      "x": 0,
      "y": 6,
      "z": 6,
      "name": "Soil_Dirt"
    },
    {
      "x": 0,
      "y": 7,
      "z": 6,
      "name": "Soil_Dirt"
    },
    {
      "x": 0,
      "y": 8,
      "z": 6,
      "name": "Soil_Dirt"
    },
    {
      "x": 0,
      "y": 9,
      "z": 6,
      "name": "Soil_Mud_Dry"
    },
    {
      "x": 0,
      "y": 10,
      "z": 6,
      "name": "Empty"
    },
    {
      "x": 0,
      "y": 11,
      "z": 6,
      "name": "Empty"
    },
    {
      "x": 0,
      "y": 12,
      "z": 6,
      "name": "Empty"
    },
    {
      "x": 0,
      "y": 6,
      "z": 7,
      "name": "Soil_Dirt"
    },
    {
      "x": 0,
      "y": 7,
      "z": 7,
      "name": "Soil_Dirt"
    },
    {
      "x": 0,
      "y": 8,
      "z": 7,
      "name": "Soil_Dirt"
    },
    {
      "x": 0,
      "y": 9,
      "z": 7,
      "name": "Soil_Mud_Dry"
    },
    {
      "x": 0,
      "y": 10,
      "z": 7,
      "name": "Wood_Hardwood_Fence"
    },
    {
      "x": 0,
      "y": 11,
      "z": 7,
      "name": "Empty"
    },
    {
      "x": 0,
      "y": 12,
      "z": 7,
      "name": "Empty"
    },
    {
      "x": 1,
      "y": 6,
      "z": -5,
      "name": "Soil_Dirt"
    },
    {
      "x": 1,
      "y": 7,
      "z": -5,
      "name": "Soil_Dirt"
    },
    {
      "x": 1,
      "y": 8,
      "z": -5,
      "name": "Soil_Dirt"
    },
    {
      "x": 1,
      "y": 9,
      "z": -5,
      "name": "Soil_Mud_Dry"
    },
    {
      "x": 1,
      "y": 10,
      "z": -5,
      "name": "Wood_Hardwood_Fence",
      "rotation": 2
    },
    {
      "x": 1,
      "y": 11,
      "z": -5,
      "name": "Empty"
    },
    {
      "x": 1,
      "y": 12,
      "z": -5,
      "name": "Empty"
    },
    {
      "x": 1,
      "y": 4,
      "z": -4,
      "name": "Soil_Dirt"
    },
    {
      "x": 1,
      "y": 5,
      "z": -4,
      "name": "Soil_Dirt"
    },
    {
      "x": 1,
      "y": 6,
      "z": -4,
      "name": "Soil_Dirt"
    },
    {
      "x": 1,
      "y": 7,
      "z": -4,
      "name": "Soil_Dirt"
    },
    {
      "x": 1,
      "y": 8,
      "z": -4,
      "name": "Soil_Dirt"
    },
    {
      "x": 1,
      "y": 9,
      "z": -4,
      "name": "Soil_Mud_Dry"
    },
    {
      "x": 1,
      "y": 10,
      "z": -4,
      "name": "Empty"
    },
    {
      "x": 1,
      "y": 11,
      "z": -4,
      "name": "Empty"
    },
    {
      "x": 1,
      "y": 12,
      "z": -4,
      "name": "Empty"
    },
    {
      "x": 1,
      "y": 4,
      "z": -3,
      "name": "Soil_Dirt"
    },
    {
      "x": 1,
      "y": 5,
      "z": -3,
      "name": "Soil_Dirt"
    },
    {
      "x": 1,
      "y": 6,
      "z": -3,
      "name": "Soil_Dirt"
    },
    {
      "x": 1,
      "y": 7,
      "z": -3,
      "name": "Soil_Dirt"
    },
    {
      "x": 1,
      "y": 8,
      "z": -3,
      "name": "Soil_Dirt"
    },
    {
      "x": 1,
      "y": 9,
      "z": -3,
      "name": "Soil_Mud_Dry"
    },
    {
      "x": 1,
      "y": 10,
      "z": -3,
      "name": "Empty"
    },
    {
      "x": 1,
      "y": 11,
      "z": -3,
      "name": "Empty"
    },
    {
      "x": 1,
      "y": 12,
      "z": -3,
      "name": "Empty"
    },
    {
      "x": 1,
      "y": 4,
      "z": -2,
      "name": "Soil_Dirt"
    },
    {
      "x": 1,
      "y": 5,
      "z": -2,
      "name": "Soil_Dirt"
    },
    {
      "x": 1,
      "y": 6,
      "z": -2,
      "name": "Soil_Dirt"
    },
    {
      "x": 1,
      "y": 7,
      "z": -2,
      "name": "Soil_Dirt"
    },
    {
      "x": 1,
      "y": 8,
      "z": -2,
      "name": "Soil_Dirt"
    },
    {
      "x": 1,
      "y": 9,
      "z": -2,
      "name": "Soil_Dirt_Tilled",
      "components": {
        "Components": {
          "TilledSoil": {
            "Version": 1,
            "DecayTime": "0001-01-02T20:08:51Z"
          }
        }
      }
    },
    {
      "x": 1,
      "y": 10,
      "z": -2,
      "name": "*Plant_Crop_Carrot_Block_State_Definitions_Stage1",
      "components": {
        "Components": {
          "FarmingBlock": {
            "GrowthProgress": 1.0,
            "LastTickGameTime": "0001-01-01T12:00:00Z"
          }
        }
      }
    },
    {
      "x": 1,
      "y": 11,
      "z": -2,
      "name": "Empty"
    },
    {
      "x": 1,
      "y": 12,
      "z": -2,
      "name": "Empty"
    },
    {
      "x": 1,
      "y": 4,
      "z": -1,
      "name": "Soil_Dirt"
    },
    {
      "x": 1,
      "y": 5,
      "z": -1,
      "name": "Soil_Dirt"
    },
    {
      "x": 1,
      "y": 6,
      "z": -1,
      "name": "Soil_Dirt"
    },
    {
      "x": 1,
      "y": 7,
      "z": -1,
      "name": "Soil_Dirt"
    },
    {
      "x": 1,
      "y": 8,
      "z": -1,
      "name": "Soil_Dirt"
    },
    {
      "x": 1,
      "y": 9,
      "z": -1,
      "name": "Soil_Dirt"
    },
    {
      "x": 1,
      "y": 10,
      "z": -1,
      "name": "Empty"
    },
    {
      "x": 1,
      "y": 11,
      "z": -1,
      "name": "Empty"
    },
    {
      "x": 1,
      "y": 12,
      "z": -1,
      "name": "Empty"
    },
    {
      "x": 1,
      "y": 4,
      "z": 0,
      "name": "Soil_Dirt"
    },
    {
      "x": 1,
      "y": 5,
      "z": 0,
      "name": "Soil_Dirt"
    },
    {
      "x": 1,
      "y": 6,
      "z": 0,
      "name": "Soil_Dirt"
    },
    {
      "x": 1,
      "y": 7,
      "z": 0,
      "name": "Soil_Dirt"
    },
    {
      "x": 1,
      "y": 8,
      "z": 0,
      "name": "Soil_Dirt"
    },
    {
      "x": 1,
      "y": 9,
      "z": 0,
      "name": "Soil_Dirt"
    },
    {
      "x": 1,
      "y": 10,
      "z": 0,
      "name": "Empty"
    },
    {
      "x": 1,
      "y": 11,
      "z": 0,
      "name": "Empty"
    },
    {
      "x": 1,
      "y": 12,
      "z": 0,
      "name": "Empty"
    },
    {
      "x": 1,
      "y": 4,
      "z": 1,
      "name": "Soil_Dirt"
    },
    {
      "x": 1,
      "y": 5,
      "z": 1,
      "name": "Soil_Dirt"
    },
    {
      "x": 1,
      "y": 6,
      "z": 1,
      "name": "Soil_Dirt"
    },
    {
      "x": 1,
      "y": 7,
      "z": 1,
      "name": "Soil_Dirt"
    },
    {
      "x": 1,
      "y": 8,
      "z": 1,
      "name": "Soil_Dirt"
    },
    {
      "x": 1,
      "y": 9,
      "z": 1,
      "name": "Soil_Dirt"
    },
    {
      "x": 1,
      "y": 10,
      "z": 1,
      "name": "Empty"
    },
    {
      "x": 1,
      "y": 11,
      "z": 1,
      "name": "Empty"
    },
    {
      "x": 1,
      "y": 12,
      "z": 1,
      "name": "Empty"
    },
    {
      "x": 1,
      "y": 4,
      "z": 2,
      "name": "Soil_Dirt"
    },
    {
      "x": 1,
      "y": 5,
      "z": 2,
      "name": "Soil_Dirt"
    },
    {
      "x": 1,
      "y": 6,
      "z": 2,
      "name": "Soil_Dirt"
    },
    {
      "x": 1,
      "y": 7,
      "z": 2,
      "name": "Soil_Dirt"
    },
    {
      "x": 1,
      "y": 8,
      "z": 2,
      "name": "Soil_Dirt"
    },
    {
      "x": 1,
      "y": 9,
      "z": 2,
      "name": "Soil_Dirt"
    },
    {
      "x": 1,
      "y": 10,
      "z": 2,
      "name": "Empty"
    },
    {
      "x": 1,
      "y": 11,
      "z": 2,
      "name": "Empty"
    },
    {
      "x": 1,
      "y": 12,
      "z": 2,
      "name": "Empty"
    },
    {
      "x": 1,
      "y": 4,
      "z": 3,
      "name": "Soil_Dirt"
    },
    {
      "x": 1,
      "y": 5,
      "z": 3,
      "name": "Soil_Dirt"
    },
    {
      "x": 1,
      "y": 6,
      "z": 3,
      "name": "Soil_Dirt"
    },
    {
      "x": 1,
      "y": 7,
      "z": 3,
      "name": "Soil_Dirt"
    },
    {
      "x": 1,
      "y": 8,
      "z": 3,
      "name": "Soil_Dirt"
    },
    {
      "x": 1,
      "y": 9,
      "z": 3,
      "name": "Soil_Mud_Dry"
    },
    {
      "x": 1,
      "y": 10,
      "z": 3,
      "name": "Empty"
    },
    {
      "x": 1,
      "y": 11,
      "z": 3,
      "name": "Empty"
    },
    {
      "x": 1,
      "y": 12,
      "z": 3,
      "name": "Empty"
    },
    {
      "x": 1,
      "y": 4,
      "z": 4,
      "name": "Soil_Dirt"
    },
    {
      "x": 1,
      "y": 5,
      "z": 4,
      "name": "Soil_Dirt"
    },
    {
      "x": 1,
      "y": 6,
      "z": 4,
      "name": "Soil_Dirt"
    },
    {
      "x": 1,
      "y": 7,
      "z": 4,
      "name": "Soil_Dirt"
    },
    {
      "x": 1,
      "y": 8,
      "z": 4,
      "name": "Soil_Dirt"
    },
    {
      "x": 1,
      "y": 9,
      "z": 4,
      "name": "Soil_Mud_Dry"
    },
    {
      "x": 1,
      "y": 10,
      "z": 4,
      "name": "Empty"
    },
    {
      "x": 1,
      "y": 11,
      "z": 4,
      "name": "Empty"
    },
    {
      "x": 1,
      "y": 12,
      "z": 4,
      "name": "Empty"
    },
    {
      "x": 1,
      "y": 4,
      "z": 5,
      "name": "Soil_Dirt"
    },
    {
      "x": 1,
      "y": 5,
      "z": 5,
      "name": "Soil_Dirt"
    },
    {
      "x": 1,
      "y": 6,
      "z": 5,
      "name": "Soil_Dirt"
    },
    {
      "x": 1,
      "y": 7,
      "z": 5,
      "name": "Soil_Dirt"
    },
    {
      "x": 1,
      "y": 8,
      "z": 5,
      "name": "Soil_Dirt"
    },
    {
      "x": 1,
      "y": 9,
      "z": 5,
      "name": "Soil_Mud_Dry"
    },
    {
      "x": 1,
      "y": 10,
      "z": 5,
      "name": "Empty"
    },
    {
      "x": 1,
      "y": 11,
      "z": 5,
      "name": "Empty"
    },
    {
      "x": 1,
      "y": 12,
      "z": 5,
      "name": "Empty"
    },
    {
      "x": 1,
      "y": 5,
      "z": 6,
      "name": "Soil_Dirt"
    },
    {
      "x": 1,
      "y": 6,
      "z": 6,
      "name": "Soil_Dirt"
    },
    {
      "x": 1,
      "y": 7,
      "z": 6,
      "name": "Soil_Dirt"
    },
    {
      "x": 1,
      "y": 8,
      "z": 6,
      "name": "Soil_Dirt"
    },
    {
      "x": 1,
      "y": 9,
      "z": 6,
      "name": "Soil_Mud_Dry"
    },
    {
      "x": 1,
      "y": 10,
      "z": 6,
      "name": "Empty"
    },
    {
      "x": 1,
      "y": 11,
      "z": 6,
      "name": "Empty"
    },
    {
      "x": 1,
      "y": 12,
      "z": 6,
      "name": "Empty"
    },
    {
      "x": 1,
      "y": 6,
      "z": 7,
      "name": "Soil_Dirt"
    },
    {
      "x": 1,
      "y": 7,
      "z": 7,
      "name": "Soil_Dirt"
    },
    {
      "x": 1,
      "y": 8,
      "z": 7,
      "name": "Soil_Dirt"
    },
    {
      "x": 1,
      "y": 9,
      "z": 7,
      "name": "Soil_Mud_Dry"
    },
    {
      "x": 1,
      "y": 10,
      "z": 7,
      "name": "Wood_Hardwood_Fence"
    },
    {
      "x": 1,
      "y": 11,
      "z": 7,
      "name": "Empty"
    },
    {
      "x": 1,
      "y": 12,
      "z": 7,
      "name": "Empty"
    },
    {
      "x": 2,
      "y": 6,
      "z": -5,
      "name": "Soil_Dirt"
    },
    {
      "x": 2,
      "y": 7,
      "z": -5,
      "name": "Soil_Dirt"
    },
    {
      "x": 2,
      "y": 8,
      "z": -5,
      "name": "Soil_Dirt"
    },
    {
      "x": 2,
      "y": 9,
      "z": -5,
      "name": "Soil_Mud_Dry"
    },
    {
      "x": 2,
      "y": 10,
      "z": -5,
      "name": "Wood_Hardwood_Fence",
      "rotation": 2
    },
    {
      "x": 2,
      "y": 11,
      "z": -5,
      "name": "Empty"
    },
    {
      "x": 2,
      "y": 12,
      "z": -5,
      "name": "Empty"
    },
    {
      "x": 2,
      "y": 5,
      "z": -4,
      "name": "Soil_Dirt"
    },
    {
      "x": 2,
      "y": 6,
      "z": -4,
      "name": "Soil_Dirt"
    },
    {
      "x": 2,
      "y": 7,
      "z": -4,
      "name": "Soil_Dirt"
    },
    {
      "x": 2,
      "y": 8,
      "z": -4,
      "name": "Soil_Dirt"
    },
    {
      "x": 2,
      "y": 9,
      "z": -4,
      "name": "Soil_Mud_Dry"
    },
    {
      "x": 2,
      "y": 10,
      "z": -4,
      "name": "Empty"
    },
    {
      "x": 2,
      "y": 11,
      "z": -4,
      "name": "Empty"
    },
    {
      "x": 2,
      "y": 12,
      "z": -4,
      "name": "Empty"
    },
    {
      "x": 2,
      "y": 4,
      "z": -3,
      "name": "Soil_Dirt"
    },
    {
      "x": 2,
      "y": 5,
      "z": -3,
      "name": "Soil_Dirt"
    },
    {
      "x": 2,
      "y": 6,
      "z": -3,
      "name": "Soil_Dirt"
    },
    {
      "x": 2,
      "y": 7,
      "z": -3,
      "name": "Soil_Dirt"
    },
    {
      "x": 2,
      "y": 8,
      "z": -3,
      "name": "Soil_Dirt"
    },
    {
      "x": 2,
      "y": 9,
      "z": -3,
      "name": "Soil_Mud_Dry"
    },
    {
      "x": 2,
      "y": 10,
      "z": -3,
      "name": "Empty"
    },
    {
      "x": 2,
      "y": 11,
      "z": -3,
      "name": "Empty"
    },
    {
      "x": 2,
      "y": 12,
      "z": -3,
      "name": "Empty"
    },
    {
      "x": 2,
      "y": 4,
      "z": -2,
      "name": "Soil_Dirt"
    },
    {
      "x": 2,
      "y": 5,
      "z": -2,
      "name": "Soil_Dirt"
    },
    {
      "x": 2,
      "y": 6,
      "z": -2,
      "name": "Soil_Dirt"
    },
    {
      "x": 2,
      "y": 7,
      "z": -2,
      "name": "Soil_Dirt"
    },
    {
      "x": 2,
      "y": 8,
      "z": -2,
      "name": "Soil_Dirt"
    },
    {
      "x": 2,
      "y": 9,
      "z": -2,
      "name": "Soil_Dirt"
    },
    {
      "x": 2,
      "y": 10,
      "z": -2,
      "name": "Empty"
    },
    {
      "x": 2,
      "y": 11,
      "z": -2,
      "name": "Empty"
    },
    {
      "x": 2,
      "y": 12,
      "z": -2,
      "name": "Empty"
    },
    {
      "x": 2,
      "y": 4,
      "z": -1,
      "name": "Soil_Dirt"
    },
    {
      "x": 2,
      "y": 5,
      "z": -1,
      "name": "Soil_Dirt"
    },
    {
      "x": 2,
      "y": 6,
      "z": -1,
      "name": "Soil_Dirt"
    },
    {
      "x": 2,
      "y": 7,
      "z": -1,
      "name": "Soil_Dirt"
    },
    {
      "x": 2,
      "y": 8,
      "z": -1,
      "name": "Soil_Dirt"
    },
    {
      "x": 2,
      "y": 9,
      "z": -1,
      "name": "Soil_Dirt"
    },
    {
      "x": 2,
      "y": 10,
      "z": -1,
      "name": "Empty"
    },
    {
      "x": 2,
      "y": 11,
      "z": -1,
      "name": "Empty"
    },
    {
      "x": 2,
      "y": 12,
      "z": -1,
      "name": "Empty"
    },
    {
      "x": 2,
      "y": 4,
      "z": 0,
      "name": "Soil_Dirt"
    },
    {
      "x": 2,
      "y": 5,
      "z": 0,
      "name": "Soil_Dirt"
    },
    {
      "x": 2,
      "y": 6,
      "z": 0,
      "name": "Soil_Dirt"
    },
    {
      "x": 2,
      "y": 7,
      "z": 0,
      "name": "Soil_Dirt"
    },
    {
      "x": 2,
      "y": 8,
      "z": 0,
      "name": "Soil_Dirt"
    },
    {
      "x": 2,
      "y": 9,
      "z": 0,
      "name": "Soil_Dirt"
    },
    {
      "x": 2,
      "y": 10,
      "z": 0,
      "name": "Empty"
    },
    {
      "x": 2,
      "y": 11,
      "z": 0,
      "name": "Empty"
    },
    {
      "x": 2,
      "y": 12,
      "z": 0,
      "name": "Empty"
    },
    {
      "x": 2,
      "y": 4,
      "z": 1,
      "name": "Soil_Dirt"
    },
    {
      "x": 2,
      "y": 5,
      "z": 1,
      "name": "Soil_Dirt"
    },
    {
      "x": 2,
      "y": 6,
      "z": 1,
      "name": "Soil_Dirt"
    },
    {
      "x": 2,
      "y": 7,
      "z": 1,
      "name": "Soil_Dirt"
    },
    {
      "x": 2,
      "y": 8,
      "z": 1,
      "name": "Soil_Dirt"
    },
    {
      "x": 2,
      "y": 9,
      "z": 1,
      "name": "Soil_Dirt"
    },
    {
      "x": 2,
      "y": 10,
      "z": 1,
      "name": "Empty"
    },
    {
      "x": 2,
      "y": 11,
      "z": 1,
      "name": "Empty"
    },
    {
      "x": 2,
      "y": 12,
      "z": 1,
      "name": "Empty"
    },
    {
      "x": 2,
      "y": 4,
      "z": 2,
      "name": "Soil_Dirt"
    },
    {
      "x": 2,
      "y": 5,
      "z": 2,
      "name": "Soil_Dirt"
    },
    {
      "x": 2,
      "y": 6,
      "z": 2,
      "name": "Soil_Dirt"
    },
    {
      "x": 2,
      "y": 7,
      "z": 2,
      "name": "Soil_Dirt"
    },
    {
      "x": 2,
      "y": 8,
      "z": 2,
      "name": "Soil_Dirt"
    },
    {
      "x": 2,
      "y": 9,
      "z": 2,
      "name": "Soil_Dirt_Tilled",
      "components": {
        "Components": {
          "TilledSoil": {
            "Version": 1,
            "DecayTime": "0001-01-02T22:08:55Z"
          }
        }
      }
    },
    {
      "x": 2,
      "y": 10,
      "z": 2,
      "name": "*Plant_Crop_Carrot_Block_State_Definitions_StageFinal"
    },
    {
      "x": 2,
      "y": 11,
      "z": 2,
      "name": "Empty"
    },
    {
      "x": 2,
      "y": 12,
      "z": 2,
      "name": "Empty"
    },
    {
      "x": 2,
      "y": 4,
      "z": 3,
      "name": "Soil_Dirt"
    },
    {
      "x": 2,
      "y": 5,
      "z": 3,
      "name": "Soil_Dirt"
    },
    {
      "x": 2,
      "y": 6,
      "z": 3,
      "name": "Soil_Dirt"
    },
    {
      "x": 2,
      "y": 7,
      "z": 3,
      "name": "Soil_Dirt"
    },
    {
      "x": 2,
      "y": 8,
      "z": 3,
      "name": "Soil_Dirt"
    },
    {
      "x": 2,
      "y": 9,
      "z": 3,
      "name": "Soil_Mud_Dry"
    },
    {
      "x": 2,
      "y": 10,
      "z": 3,
      "name": "Empty"
    },
    {
      "x": 2,
      "y": 11,
      "z": 3,
      "name": "Empty"
    },
    {
      "x": 2,
      "y": 12,
      "z": 3,
      "name": "Empty"
    },
    {
      "x": 2,
      "y": 4,
      "z": 4,
      "name": "Soil_Dirt"
    },
    {
      "x": 2,
      "y": 5,
      "z": 4,
      "name": "Soil_Dirt"
    },
    {
      "x": 2,
      "y": 6,
      "z": 4,
      "name": "Soil_Dirt"
    },
    {
      "x": 2,
      "y": 7,
      "z": 4,
      "name": "Soil_Dirt"
    },
    {
      "x": 2,
      "y": 8,
      "z": 4,
      "name": "Soil_Dirt"
    },
    {
      "x": 2,
      "y": 9,
      "z": 4,
      "name": "Soil_Dirt_Tilled",
      "components": {
        "Components": {
          "TilledSoil": {
            "Version": 1,
            "DecayTime": "0001-01-02T17:53:31Z"
          }
        }
      }
    },
    {
      "x": 2,
      "y": 10,
      "z": 4,
      "name": "Empty"
    },
    {
      "x": 2,
      "y": 11,
      "z": 4,
      "name": "Empty"
    },
    {
      "x": 2,
      "y": 12,
      "z": 4,
      "name": "Empty"
    },
    {
      "x": 2,
      "y": 4,
      "z": 5,
      "name": "Soil_Dirt"
    },
    {
      "x": 2,
      "y": 5,
      "z": 5,
      "name": "Soil_Dirt"
    },
    {
      "x": 2,
      "y": 6,
      "z": 5,
      "name": "Soil_Dirt"
    },
    {
      "x": 2,
      "y": 7,
      "z": 5,
      "name": "Soil_Dirt"
    },
    {
      "x": 2,
      "y": 8,
      "z": 5,
      "name": "Soil_Dirt"
    },
    {
      "x": 2,
      "y": 9,
      "z": 5,
      "name": "Soil_Dirt_Tilled",
      "components": {
        "Components": {
          "TilledSoil": {
            "Version": 1,
            "DecayTime": "0001-01-02T23:04:39Z"
          }
        }
      }
    },
    {
      "x": 2,
      "y": 10,
      "z": 5,
      "name": "Empty"
    },
    {
      "x": 2,
      "y": 11,
      "z": 5,
      "name": "Empty"
    },
    {
      "x": 2,
      "y": 12,
      "z": 5,
      "name": "Empty"
    },
    {
      "x": 2,
      "y": 5,
      "z": 6,
      "name": "Soil_Dirt"
    },
    {
      "x": 2,
      "y": 6,
      "z": 6,
      "name": "Soil_Dirt"
    },
    {
      "x": 2,
      "y": 7,
      "z": 6,
      "name": "Soil_Dirt"
    },
    {
      "x": 2,
      "y": 8,
      "z": 6,
      "name": "Soil_Dirt"
    },
    {
      "x": 2,
      "y": 9,
      "z": 6,
      "name": "Soil_Grass_Deep"
    },
    {
      "x": 2,
      "y": 10,
      "z": 6,
      "name": "*Wood_Hardwood_Fence_State_Definitions_Corner",
      "rotation": 1
    },
    {
      "x": 2,
      "y": 11,
      "z": 6,
      "name": "Empty"
    },
    {
      "x": 2,
      "y": 12,
      "z": 6,
      "name": "Empty"
    },
    {
      "x": 2,
      "y": 6,
      "z": 7,
      "name": "Soil_Dirt"
    },
    {
      "x": 2,
      "y": 8,
      "z": 7,
      "name": "Soil_Dirt"
    },
    {
      "x": 2,
      "y": 9,
      "z": 7,
      "name": "Soil_Grass_Deep"
    },
    {
      "x": 2,
      "y": 10,
      "z": 7,
      "name": "*Wood_Hardwood_Fence_State_Definitions_Corner",
      "rotation": 3
    },
    {
      "x": 2,
      "y": 11,
      "z": 7,
      "name": "Empty"
    },
    {
      "x": 2,
      "y": 12,
      "z": 7,
      "name": "Empty"
    },
    {
      "x": 3,
      "y": 6,
      "z": -5,
      "name": "Soil_Dirt"
    },
    {
      "x": 3,
      "y": 7,
      "z": -5,
      "name": "Soil_Dirt"
    },
    {
      "x": 3,
      "y": 8,
      "z": -5,
      "name": "Soil_Dirt"
    },
    {
      "x": 3,
      "y": 9,
      "z": -5,
      "name": "Soil_Leaves"
    },
    {
      "x": 3,
      "y": 10,
      "z": -5,
      "name": "Wood_Hardwood_Fence",
      "rotation": 2
    },
    {
      "x": 3,
      "y": 11,
      "z": -5,
      "name": "Empty"
    },
    {
      "x": 3,
      "y": 12,
      "z": -5,
      "name": "Empty"
    },
    {
      "x": 3,
      "y": 5,
      "z": -4,
      "name": "Soil_Dirt"
    },
    {
      "x": 3,
      "y": 6,
      "z": -4,
      "name": "Soil_Dirt"
    },
    {
      "x": 3,
      "y": 7,
      "z": -4,
      "name": "Soil_Dirt"
    },
    {
      "x": 3,
      "y": 8,
      "z": -4,
      "name": "Soil_Dirt"
    },
    {
      "x": 3,
      "y": 9,
      "z": -4,
      "name": "Soil_Mud_Dry"
    },
    {
      "x": 3,
      "y": 10,
      "z": -4,
      "name": "Empty"
    },
    {
      "x": 3,
      "y": 11,
      "z": -4,
      "name": "Empty"
    },
    {
      "x": 3,
      "y": 12,
      "z": -4,
      "name": "Empty"
    },
    {
      "x": 3,
      "y": 4,
      "z": -3,
      "name": "Soil_Dirt"
    },
    {
      "x": 3,
      "y": 5,
      "z": -3,
      "name": "Soil_Dirt"
    },
    {
      "x": 3,
      "y": 6,
      "z": -3,
      "name": "Soil_Dirt"
    },
    {
      "x": 3,
      "y": 7,
      "z": -3,
      "name": "Soil_Dirt"
    },
    {
      "x": 3,
      "y": 8,
      "z": -3,
      "name": "Soil_Dirt"
    },
    {
      "x": 3,
      "y": 9,
      "z": -3,
      "name": "Soil_Mud_Dry"
    },
    {
      "x": 3,
      "y": 10,
      "z": -3,
      "name": "Empty"
    },
    {
      "x": 3,
      "y": 11,
      "z": -3,
      "name": "Empty"
    },
    {
      "x": 3,
      "y": 12,
      "z": -3,
      "name": "Empty"
    },
    {
      "x": 3,
      "y": 4,
      "z": -2,
      "name": "Soil_Dirt"
    },
    {
      "x": 3,
      "y": 5,
      "z": -2,
      "name": "Soil_Dirt"
    },
    {
      "x": 3,
      "y": 6,
      "z": -2,
      "name": "Soil_Dirt"
    },
    {
      "x": 3,
      "y": 7,
      "z": -2,
      "name": "Soil_Dirt"
    },
    {
      "x": 3,
      "y": 8,
      "z": -2,
      "name": "Soil_Dirt"
    },
    {
      "x": 3,
      "y": 9,
      "z": -2,
      "name": "Soil_Mud_Dry"
    },
    {
      "x": 3,
      "y": 10,
      "z": -2,
      "name": "Empty"
    },
    {
      "x": 3,
      "y": 11,
      "z": -2,
      "name": "Empty"
    },
    {
      "x": 3,
      "y": 12,
      "z": -2,
      "name": "Empty"
    },
    {
      "x": 3,
      "y": 4,
      "z": -1,
      "name": "Soil_Dirt"
    },
    {
      "x": 3,
      "y": 5,
      "z": -1,
      "name": "Soil_Dirt"
    },
    {
      "x": 3,
      "y": 6,
      "z": -1,
      "name": "Soil_Dirt"
    },
    {
      "x": 3,
      "y": 7,
      "z": -1,
      "name": "Soil_Dirt"
    },
    {
      "x": 3,
      "y": 8,
      "z": -1,
      "name": "Soil_Dirt"
    },
    {
      "x": 3,
      "y": 9,
      "z": -1,
      "name": "Soil_Dirt"
    },
    {
      "x": 3,
      "y": 10,
      "z": -1,
      "name": "Empty"
    },
    {
      "x": 3,
      "y": 11,
      "z": -1,
      "name": "Empty"
    },
    {
      "x": 3,
      "y": 12,
      "z": -1,
      "name": "Empty"
    },
    {
      "x": 3,
      "y": 4,
      "z": 0,
      "name": "Soil_Dirt"
    },
    {
      "x": 3,
      "y": 5,
      "z": 0,
      "name": "Soil_Dirt"
    },
    {
      "x": 3,
      "y": 6,
      "z": 0,
      "name": "Soil_Dirt"
    },
    {
      "x": 3,
      "y": 7,
      "z": 0,
      "name": "Soil_Dirt"
    },
    {
      "x": 3,
      "y": 8,
      "z": 0,
      "name": "Soil_Dirt"
    },
    {
      "x": 3,
      "y": 9,
      "z": 0,
      "name": "Soil_Dirt"
    },
    {
      "x": 3,
      "y": 10,
      "z": 0,
      "name": "Empty"
    },
    {
      "x": 3,
      "y": 11,
      "z": 0,
      "name": "Empty"
    },
    {
      "x": 3,
      "y": 12,
      "z": 0,
      "name": "Empty"
    },
    {
      "x": 3,
      "y": 4,
      "z": 1,
      "name": "Soil_Dirt"
    },
    {
      "x": 3,
      "y": 5,
      "z": 1,
      "name": "Soil_Dirt"
    },
    {
      "x": 3,
      "y": 6,
      "z": 1,
      "name": "Soil_Dirt"
    },
    {
      "x": 3,
      "y": 7,
      "z": 1,
      "name": "Soil_Dirt"
    },
    {
      "x": 3,
      "y": 8,
      "z": 1,
      "name": "Soil_Dirt"
    },
    {
      "x": 3,
      "y": 9,
      "z": 1,
      "name": "Soil_Dirt"
    },
    {
      "x": 3,
      "y": 10,
      "z": 1,
      "name": "Empty"
    },
    {
      "x": 3,
      "y": 11,
      "z": 1,
      "name": "Empty"
    },
    {
      "x": 3,
      "y": 12,
      "z": 1,
      "name": "Empty"
    },
    {
      "x": 3,
      "y": 4,
      "z": 2,
      "name": "Soil_Dirt"
    },
    {
      "x": 3,
      "y": 5,
      "z": 2,
      "name": "Soil_Dirt"
    },
    {
      "x": 3,
      "y": 6,
      "z": 2,
      "name": "Soil_Dirt"
    },
    {
      "x": 3,
      "y": 7,
      "z": 2,
      "name": "Soil_Dirt"
    },
    {
      "x": 3,
      "y": 8,
      "z": 2,
      "name": "Soil_Dirt"
    },
    {
      "x": 3,
      "y": 9,
      "z": 2,
      "name": "Soil_Dirt_Tilled",
      "components": {
        "Components": {
          "TilledSoil": {
            "Version": 1,
            "DecayTime": "0001-01-02T20:42:47Z"
          }
        }
      }
    },
    {
      "x": 3,
      "y": 10,
      "z": 2,
      "name": "*Plant_Crop_Carrot_Block_State_Definitions_Stage2",
      "components": {
        "Components": {
          "FarmingBlock": {
            "GrowthProgress": 2.0,
            "LastTickGameTime": "0001-01-01T12:00:00Z"
          }
        }
      }
    },
    {
      "x": 3,
      "y": 11,
      "z": 2,
      "name": "Empty"
    },
    {
      "x": 3,
      "y": 12,
      "z": 2,
      "name": "Empty"
    },
    {
      "x": 3,
      "y": 4,
      "z": 3,
      "name": "Soil_Dirt"
    },
    {
      "x": 3,
      "y": 5,
      "z": 3,
      "name": "Soil_Dirt"
    },
    {
      "x": 3,
      "y": 6,
      "z": 3,
      "name": "Soil_Dirt"
    },
    {
      "x": 3,
      "y": 7,
      "z": 3,
      "name": "Soil_Dirt"
    },
    {
      "x": 3,
      "y": 8,
      "z": 3,
      "name": "Soil_Dirt"
    },
    {
      "x": 3,
      "y": 9,
      "z": 3,
      "name": "Soil_Dirt_Tilled",
      "components": {
        "Components": {
          "TilledSoil": {
            "Version": 1,
            "DecayTime": "0001-01-02T23:58:09Z"
          }
        }
      }
    },
    {
      "x": 3,
      "y": 10,
      "z": 3,
      "name": "Empty"
    },
    {
      "x": 3,
      "y": 11,
      "z": 3,
      "name": "Empty"
    },
    {
      "x": 3,
      "y": 12,
      "z": 3,
      "name": "Empty"
    },
    {
      "x": 3,
      "y": 4,
      "z": 4,
      "name": "Soil_Dirt"
    },
    {
      "x": 3,
      "y": 5,
      "z": 4,
      "name": "Soil_Dirt"
    },
    {
      "x": 3,
      "y": 6,
      "z": 4,
      "name": "Soil_Dirt"
    },
    {
      "x": 3,
      "y": 7,
      "z": 4,
      "name": "Soil_Dirt"
    },
    {
      "x": 3,
      "y": 8,
      "z": 4,
      "name": "Soil_Dirt"
    },
    {
      "x": 3,
      "y": 9,
      "z": 4,
      "name": "Soil_Dirt_Tilled",
      "components": {
        "Components": {
          "TilledSoil": {
            "Version": 1,
            "DecayTime": "0001-01-02T23:21:14Z"
          }
        }
      }
    },
    {
      "x": 3,
      "y": 10,
      "z": 4,
      "name": "Empty"
    },
    {
      "x": 3,
      "y": 11,
      "z": 4,
      "name": "Empty"
    },
    {
      "x": 3,
      "y": 12,
      "z": 4,
      "name": "Empty"
    },
    {
      "x": 3,
      "y": 4,
      "z": 5,
      "name": "Soil_Dirt"
    },
    {
      "x": 3,
      "y": 5,
      "z": 5,
      "name": "Soil_Dirt"
    },
    {
      "x": 3,
      "y": 6,
      "z": 5,
      "name": "Soil_Dirt"
    },
    {
      "x": 3,
      "y": 7,
      "z": 5,
      "name": "Soil_Dirt"
    },
    {
      "x": 3,
      "y": 8,
      "z": 5,
      "name": "Soil_Dirt"
    },
    {
      "x": 3,
      "y": 9,
      "z": 5,
      "name": "Soil_Dirt_Tilled",
      "components": {
        "Components": {
          "TilledSoil": {
            "Version": 1,
            "DecayTime": "0001-01-02T22:00:14Z"
          }
        }
      }
    },
    {
      "x": 3,
      "y": 10,
      "z": 5,
      "name": "Empty"
    },
    {
      "x": 3,
      "y": 11,
      "z": 5,
      "name": "Empty"
    },
    {
      "x": 3,
      "y": 12,
      "z": 5,
      "name": "Empty"
    },
    {
      "x": 3,
      "y": 6,
      "z": 6,
      "name": "Soil_Dirt"
    },
    {
      "x": 3,
      "y": 7,
      "z": 6,
      "name": "Soil_Dirt"
    },
    {
      "x": 3,
      "y": 8,
      "z": 6,
      "name": "Soil_Dirt"
    },
    {
      "x": 3,
      "y": 9,
      "z": 6,
      "name": "Soil_Grass_Deep"
    },
    {
      "x": 3,
      "y": 10,
      "z": 6,
      "name": "Wood_Hardwood_Fence"
    },
    {
      "x": 3,
      "y": 11,
      "z": 6,
      "name": "Empty"
    },
    {
      "x": 3,
      "y": 12,
      "z": 6,
      "name": "Empty"
    },
    {
      "x": 4,
      "y": 8,
      "z": -5,
      "name": "Soil_Dirt"
    },
    {
      "x": 4,
      "y": 9,
      "z": -5,
      "name": "Soil_Leaves"
    },
    {
      "x": 4,
      "y": 10,
      "z": -5,
      "name": "*Wood_Hardwood_Fence_State_Definitions_Corner"
    },
    {
      "x": 4,
      "y": 11,
      "z": -5,
      "name": "Empty"
    },
    {
      "x": 4,
      "y": 12,
      "z": -5,
      "name": "Empty"
    },
    {
      "x": 4,
      "y": 6,
      "z": -4,
      "name": "Soil_Dirt"
    },
    {
      "x": 4,
      "y": 7,
      "z": -4,
      "name": "Soil_Dirt"
    },
    {
      "x": 4,
      "y": 8,
      "z": -4,
      "name": "Soil_Dirt"
    },
    {
      "x": 4,
      "y": 9,
      "z": -4,
      "name": "Soil_Leaves"
    },
    {
      "x": 4,
      "y": 10,
      "z": -4,
      "name": "*Wood_Hardwood_Fence_State_Definitions_Corner",
      "rotation": 2
    },
    {
      "x": 4,
      "y": 11,
      "z": -4,
      "name": "Empty"
    },
    {
      "x": 4,
      "y": 12,
      "z": -4,
      "name": "Empty"
    },
    {
      "x": 4,
      "y": 5,
      "z": -3,
      "name": "Soil_Dirt"
    },
    {
      "x": 4,
      "y": 6,
      "z": -3,
      "name": "Soil_Dirt"
    },
    {
      "x": 4,
      "y": 7,
      "z": -3,
      "name": "Soil_Dirt"
    },
    {
      "x": 4,
      "y": 8,
      "z": -3,
      "name": "Soil_Dirt"
    },
    {
      "x": 4,
      "y": 9,
      "z": -3,
      "name": "Soil_Mud_Dry"
    },
    {
      "x": 4,
      "y": 10,
      "z": -3,
      "name": "Empty"
    },
    {
      "x": 4,
      "y": 11,
      "z": -3,
      "name": "Empty"
    },
    {
      "x": 4,
      "y": 12,
      "z": -3,
      "name": "Empty"
    },
    {
      "x": 4,
      "y": 4,
      "z": -2,
      "name": "Soil_Dirt"
    },
    {
      "x": 4,
      "y": 5,
      "z": -2,
      "name": "Soil_Dirt"
    },
    {
      "x": 4,
      "y": 6,
      "z": -2,
      "name": "Soil_Dirt"
    },
    {
      "x": 4,
      "y": 7,
      "z": -2,
      "name": "Soil_Dirt"
    },
    {
      "x": 4,
      "y": 8,
      "z": -2,
      "name": "Soil_Dirt"
    },
    {
      "x": 4,
      "y": 9,
      "z": -2,
      "name": "Soil_Mud_Dry"
    },
    {
      "x": 4,
      "y": 10,
      "z": -2,
      "name": "Empty"
    },
    {
      "x": 4,
      "y": 11,
      "z": -2,
      "name": "Empty"
    },
    {
      "x": 4,
      "y": 12,
      "z": -2,
      "name": "Empty"
    },
    {
      "x": 4,
      "y": 4,
      "z": -1,
      "name": "Soil_Dirt"
    },
    {
      "x": 4,
      "y": 5,
      "z": -1,
      "name": "Soil_Dirt"
    },
    {
      "x": 4,
      "y": 6,
      "z": -1,
      "name": "Soil_Dirt"
    },
    {
      "x": 4,
      "y": 7,
      "z": -1,
      "name": "Soil_Dirt"
    },
    {
      "x": 4,
      "y": 8,
      "z": -1,
      "name": "Soil_Dirt"
    },
    {
      "x": 4,
      "y": 9,
      "z": -1,
      "name": "Soil_Dirt"
    },
    {
      "x": 4,
      "y": 10,
      "z": -1,
      "name": "Empty"
    },
    {
      "x": 4,
      "y": 11,
      "z": -1,
      "name": "Empty"
    },
    {
      "x": 4,
      "y": 12,
      "z": -1,
      "name": "Empty"
    },
    {
      "x": 4,
      "y": 4,
      "z": 0,
      "name": "Soil_Dirt"
    },
    {
      "x": 4,
      "y": 5,
      "z": 0,
      "name": "Soil_Dirt"
    },
    {
      "x": 4,
      "y": 6,
      "z": 0,
      "name": "Soil_Dirt"
    },
    {
      "x": 4,
      "y": 7,
      "z": 0,
      "name": "Soil_Dirt"
    },
    {
      "x": 4,
      "y": 8,
      "z": 0,
      "name": "Soil_Dirt"
    },
    {
      "x": 4,
      "y": 9,
      "z": 0,
      "name": "Soil_Dirt"
    },
    {
      "x": 4,
      "y": 10,
      "z": 0,
      "name": "Empty"
    },
    {
      "x": 4,
      "y": 11,
      "z": 0,
      "name": "Empty"
    },
    {
      "x": 4,
      "y": 12,
      "z": 0,
      "name": "Empty"
    },
    {
      "x": 4,
      "y": 4,
      "z": 1,
      "name": "Soil_Dirt"
    },
    {
      "x": 4,
      "y": 5,
      "z": 1,
      "name": "Soil_Dirt"
    },
    {
      "x": 4,
      "y": 6,
      "z": 1,
      "name": "Soil_Dirt"
    },
    {
      "x": 4,
      "y": 7,
      "z": 1,
      "name": "Soil_Dirt"
    },
    {
      "x": 4,
      "y": 8,
      "z": 1,
      "name": "Soil_Dirt"
    },
    {
      "x": 4,
      "y": 9,
      "z": 1,
      "name": "Soil_Mud_Dry"
    },
    {
      "x": 4,
      "y": 10,
      "z": 1,
      "name": "Empty"
    },
    {
      "x": 4,
      "y": 11,
      "z": 1,
      "name": "Empty"
    },
    {
      "x": 4,
      "y": 12,
      "z": 1,
      "name": "Empty"
    },
    {
      "x": 4,
      "y": 4,
      "z": 2,
      "name": "Soil_Dirt"
    },
    {
      "x": 4,
      "y": 5,
      "z": 2,
      "name": "Soil_Dirt"
    },
    {
      "x": 4,
      "y": 6,
      "z": 2,
      "name": "Soil_Dirt"
    },
    {
      "x": 4,
      "y": 7,
      "z": 2,
      "name": "Soil_Dirt"
    },
    {
      "x": 4,
      "y": 8,
      "z": 2,
      "name": "Soil_Dirt"
    },
    {
      "x": 4,
      "y": 9,
      "z": 2,
      "name": "Soil_Mud_Dry"
    },
    {
      "x": 4,
      "y": 10,
      "z": 2,
      "name": "Empty"
    },
    {
      "x": 4,
      "y": 11,
      "z": 2,
      "name": "Empty"
    },
    {
      "x": 4,
      "y": 12,
      "z": 2,
      "name": "Empty"
    },
    {
      "x": 4,
      "y": 4,
      "z": 3,
      "name": "Soil_Dirt"
    },
    {
      "x": 4,
      "y": 5,
      "z": 3,
      "name": "Soil_Dirt"
    },
    {
      "x": 4,
      "y": 6,
      "z": 3,
      "name": "Soil_Dirt"
    },
    {
      "x": 4,
      "y": 7,
      "z": 3,
      "name": "Soil_Dirt"
    },
    {
      "x": 4,
      "y": 8,
      "z": 3,
      "name": "Soil_Dirt"
    },
    {
      "x": 4,
      "y": 9,
      "z": 3,
      "name": "Soil_Dirt_Tilled",
      "components": {
        "Components": {
          "TilledSoil": {
            "Version": 1,
            "DecayTime": "0001-01-02T20:21:38Z"
          }
        }
      }
    },
    {
      "x": 4,
      "y": 10,
      "z": 3,
      "name": "Empty"
    },
    {
      "x": 4,
      "y": 11,
      "z": 3,
      "name": "Empty"
    },
    {
      "x": 4,
      "y": 12,
      "z": 3,
      "name": "Empty"
    },
    {
      "x": 4,
      "y": 5,
      "z": 4,
      "name": "Soil_Dirt"
    },
    {
      "x": 4,
      "y": 6,
      "z": 4,
      "name": "Soil_Dirt"
    },
    {
      "x": 4,
      "y": 7,
      "z": 4,
      "name": "Soil_Dirt"
    },
    {
      "x": 4,
      "y": 8,
      "z": 4,
      "name": "Soil_Dirt"
    },
    {
      "x": 4,
      "y": 9,
      "z": 4,
      "name": "Soil_Dirt_Tilled",
      "components": {
        "Components": {
          "TilledSoil": {
            "Version": 1,
            "DecayTime": "0001-01-02T19:15:43Z"
          }
        }
      }
    },
    {
      "x": 4,
      "y": 10,
      "z": 4,
      "name": "*Plant_Crop_Carrot_Block_State_Definitions_StageFinal"
    },
    {
      "x": 4,
      "y": 11,
      "z": 4,
      "name": "Empty"
    },
    {
      "x": 4,
      "y": 12,
      "z": 4,
      "name": "Empty"
    },
    {
      "x": 4,
      "y": 5,
      "z": 5,
      "name": "Soil_Dirt"
    },
    {
      "x": 4,
      "y": 6,
      "z": 5,
      "name": "Soil_Dirt"
    },
    {
      "x": 4,
      "y": 7,
      "z": 5,
      "name": "Soil_Dirt"
    },
    {
      "x": 4,
      "y": 8,
      "z": 5,
      "name": "Soil_Dirt"
    },
    {
      "x": 4,
      "y": 9,
      "z": 5,
      "name": "Soil_Dirt_Tilled",
      "components": {
        "Components": {
          "TilledSoil": {
            "Version": 1,
            "DecayTime": "0001-01-02T23:41:52Z"
          }
        }
      }
    },
    {
      "x": 4,
      "y": 10,
      "z": 5,
      "name": "*Plant_Crop_Carrot_Block_State_Definitions_Stage1",
      "components": {
        "Components": {
          "FarmingBlock": {
            "GrowthProgress": 1.0,
            "LastTickGameTime": "0001-01-01T12:00:00Z"
          }
        }
      }
    },
    {
      "x": 4,
      "y": 11,
      "z": 5,
      "name": "Empty"
    },
    {
      "x": 4,
      "y": 12,
      "z": 5,
      "name": "Empty"
    },
    {
      "x": 4,
      "y": 6,
      "z": 6,
      "name": "Soil_Dirt"
    },
    {
      "x": 4,
      "y": 7,
      "z": 6,
      "name": "Soil_Dirt"
    },
    {
      "x": 4,
      "y": 8,
      "z": 6,
      "name": "Soil_Dirt"
    },
    {
      "x": 4,
      "y": 9,
      "z": 6,
      "name": "Soil_Dirt_Tilled",
      "components": {
        "Components": {
          "TilledSoil": {
            "Version": 1,
            "DecayTime": "0001-01-02T18:27:58Z"
          }
        }
      }
    },
    {
      "x": 4,
      "y": 10,
      "z": 6,
      "name": "Wood_Hardwood_Fence"
    },
    {
      "x": 4,
      "y": 11,
      "z": 6,
      "name": "Empty"
    },
    {
      "x": 4,
      "y": 12,
      "z": 6,
      "name": "Empty"
    },
    {
      "x": 5,
      "y": 6,
      "z": -4,
      "name": "Soil_Dirt"
    },
    {
      "x": 5,
      "y": 7,
      "z": -4,
      "name": "Soil_Dirt"
    },
    {
      "x": 5,
      "y": 8,
      "z": -4,
      "name": "Soil_Dirt"
    },
    {
      "x": 5,
      "y": 9,
      "z": -4,
      "name": "Soil_Dirt"
    },
    {
      "x": 5,
      "y": 10,
      "z": -4,
      "name": "Wood_Hardwood_Fence",
      "rotation": 2
    },
    {
      "x": 5,
      "y": 11,
      "z": -4,
      "name": "Empty"
    },
    {
      "x": 5,
      "y": 12,
      "z": -4,
      "name": "Empty"
    },
    {
      "x": 5,
      "y": 5,
      "z": -3,
      "name": "Soil_Dirt"
    },
    {
      "x": 5,
      "y": 6,
      "z": -3,
      "name": "Soil_Dirt"
    },
    {
      "x": 5,
      "y": 7,
      "z": -3,
      "name": "Soil_Dirt"
    },
    {
      "x": 5,
      "y": 8,
      "z": -3,
      "name": "Soil_Dirt"
    },
    {
      "x": 5,
      "y": 9,
      "z": -3,
      "name": "Soil_Dirt"
    },
    {
      "x": 5,
      "y": 10,
      "z": -3,
      "name": "Empty"
    },
    {
      "x": 5,
      "y": 11,
      "z": -3,
      "name": "Empty"
    },
    {
      "x": 5,
      "y": 12,
      "z": -3,
      "name": "Empty"
    },
    {
      "x": 5,
      "y": 5,
      "z": -2,
      "name": "Soil_Dirt"
    },
    {
      "x": 5,
      "y": 6,
      "z": -2,
      "name": "Soil_Dirt"
    },
    {
      "x": 5,
      "y": 7,
      "z": -2,
      "name": "Soil_Dirt"
    },
    {
      "x": 5,
      "y": 8,
      "z": -2,
      "name": "Soil_Dirt"
    },
    {
      "x": 5,
      "y": 9,
      "z": -2,
      "name": "Soil_Grass_Deep"
    },
    {
      "x": 5,
      "y": 10,
      "z": -2,
      "name": "Empty"
    },
    {
      "x": 5,
      "y": 11,
      "z": -2,
      "name": "Empty"
    },
    {
      "x": 5,
      "y": 12,
      "z": -2,
      "name": "Empty"
    },
    {
      "x": 5,
      "y": 5,
      "z": -1,
      "name": "Soil_Dirt"
    },
    {
      "x": 5,
      "y": 6,
      "z": -1,
      "name": "Soil_Dirt"
    },
    {
      "x": 5,
      "y": 7,
      "z": -1,
      "name": "Soil_Dirt"
    },
    {
      "x": 5,
      "y": 8,
      "z": -1,
      "name": "Soil_Dirt"
    },
    {
      "x": 5,
      "y": 9,
      "z": -1,
      "name": "Soil_Mud_Dry"
    },
    {
      "x": 5,
      "y": 10,
      "z": -1,
      "name": "Empty"
    },
    {
      "x": 5,
      "y": 11,
      "z": -1,
      "name": "Empty"
    },
    {
      "x": 5,
      "y": 12,
      "z": -1,
      "name": "Empty"
    },
    {
      "x": 5,
      "y": 5,
      "z": 0,
      "name": "Soil_Dirt"
    },
    {
      "x": 5,
      "y": 6,
      "z": 0,
      "name": "Soil_Dirt"
    },
    {
      "x": 5,
      "y": 7,
      "z": 0,
      "name": "Soil_Dirt"
    },
    {
      "x": 5,
      "y": 8,
      "z": 0,
      "name": "Soil_Dirt"
    },
    {
      "x": 5,
      "y": 9,
      "z": 0,
      "name": "Soil_Mud_Dry"
    },
    {
      "x": 5,
      "y": 10,
      "z": 0,
      "name": "Empty"
    },
    {
      "x": 5,
      "y": 11,
      "z": 0,
      "name": "Empty"
    },
    {
      "x": 5,
      "y": 12,
      "z": 0,
      "name": "Empty"
    },
    {
      "x": 5,
      "y": 5,
      "z": 1,
      "name": "Soil_Dirt"
    },
    {
      "x": 5,
      "y": 6,
      "z": 1,
      "name": "Soil_Dirt"
    },
    {
      "x": 5,
      "y": 7,
      "z": 1,
      "name": "Soil_Dirt"
    },
    {
      "x": 5,
      "y": 8,
      "z": 1,
      "name": "Soil_Dirt"
    },
    {
      "x": 5,
      "y": 9,
      "z": 1,
      "name": "Soil_Mud_Dry"
    },
    {
      "x": 5,
      "y": 10,
      "z": 1,
      "name": "Empty"
    },
    {
      "x": 5,
      "y": 11,
      "z": 1,
      "name": "Empty"
    },
    {
      "x": 5,
      "y": 12,
      "z": 1,
      "name": "Empty"
    },
    {
      "x": 5,
      "y": 5,
      "z": 2,
      "name": "Soil_Dirt"
    },
    {
      "x": 5,
      "y": 6,
      "z": 2,
      "name": "Soil_Dirt"
    },
    {
      "x": 5,
      "y": 7,
      "z": 2,
      "name": "Soil_Dirt"
    },
    {
      "x": 5,
      "y": 8,
      "z": 2,
      "name": "Soil_Dirt"
    },
    {
      "x": 5,
      "y": 9,
      "z": 2,
      "name": "Soil_Mud_Dry"
    },
    {
      "x": 5,
      "y": 10,
      "z": 2,
      "name": "Empty"
    },
    {
      "x": 5,
      "y": 11,
      "z": 2,
      "name": "Empty"
    },
    {
      "x": 5,
      "y": 12,
      "z": 2,
      "name": "Empty"
    },
    {
      "x": 5,
      "y": 5,
      "z": 3,
      "name": "Soil_Dirt"
    },
    {
      "x": 5,
      "y": 6,
      "z": 3,
      "name": "Soil_Dirt"
    },
    {
      "x": 5,
      "y": 7,
      "z": 3,
      "name": "Soil_Dirt"
    },
    {
      "x": 5,
      "y": 8,
      "z": 3,
      "name": "Soil_Dirt"
    },
    {
      "x": 5,
      "y": 9,
      "z": 3,
      "name": "Soil_Dirt_Tilled",
      "components": {
        "Components": {
          "TilledSoil": {
            "Version": 1,
            "DecayTime": "0001-01-02T19:59:39Z"
          }
        }
      }
    },
    {
      "x": 5,
      "y": 10,
      "z": 3,
      "name": "*Plant_Crop_Carrot_Block_State_Definitions_StageFinal"
    },
    {
      "x": 5,
      "y": 11,
      "z": 3,
      "name": "Empty"
    },
    {
      "x": 5,
      "y": 12,
      "z": 3,
      "name": "Empty"
    },
    {
      "x": 5,
      "y": 6,
      "z": 4,
      "name": "Soil_Dirt"
    },
    {
      "x": 5,
      "y": 7,
      "z": 4,
      "name": "Soil_Dirt"
    },
    {
      "x": 5,
      "y": 8,
      "z": 4,
      "name": "Soil_Dirt"
    },
    {
      "x": 5,
      "y": 9,
      "z": 4,
      "name": "Soil_Leaves"
    },
    {
      "x": 5,
      "y": 10,
      "z": 4,
      "name": "Plant_Grass_Sharp_Tall"
    },
    {
      "x": 5,
      "y": 11,
      "z": 4,
      "name": "Plant_Grass_Sharp_Tall",
      "filler": 1024
    },
    {
      "x": 5,
      "y": 12,
      "z": 4,
      "name": "Empty"
    },
    {
      "x": 5,
      "y": 5,
      "z": 5,
      "name": "Soil_Dirt"
    },
    {
      "x": 5,
      "y": 6,
      "z": 5,
      "name": "Soil_Dirt"
    },
    {
      "x": 5,
      "y": 7,
      "z": 5,
      "name": "Soil_Dirt"
    },
    {
      "x": 5,
      "y": 8,
      "z": 5,
      "name": "Soil_Dirt"
    },
    {
      "x": 5,
      "y": 9,
      "z": 5,
      "name": "Soil_Dirt_Tilled",
      "components": {
        "Components": {
          "TilledSoil": {
            "Version": 1,
            "DecayTime": "0001-01-02T20:13:36Z"
          }
        }
      }
    },
    {
      "x": 5,
      "y": 10,
      "z": 5,
      "name": "*Plant_Crop_Carrot_Block_State_Definitions_Stage2",
      "components": {
        "Components": {
          "FarmingBlock": {
            "GrowthProgress": 2.0,
            "LastTickGameTime": "0001-01-01T12:00:00Z"
          }
        }
      }
    },
    {
      "x": 5,
      "y": 11,
      "z": 5,
      "name": "Empty"
    },
    {
      "x": 5,
      "y": 12,
      "z": 5,
      "name": "Empty"
    },
    {
      "x": 5,
      "y": 8,
      "z": 6,
      "name": "Soil_Dirt"
    },
    {
      "x": 5,
      "y": 9,
      "z": 6,
      "name": "Soil_Grass_Deep"
    },
    {
      "x": 5,
      "y": 10,
      "z": 6,
      "name": "Wood_Hardwood_Fence"
    },
    {
      "x": 5,
      "y": 11,
      "z": 6,
