{
  "version": 8,
  "blockIdVersion": 11,
  "anchorX": 0,
  "anchorY": 1,
  "anchorZ": 0,
  "blocks": [
    {
      "x": -4,
      "y": 4,
      "z": -1,
      "name": "Plant_Leaves_Goldentree"
    },
    {
      "x": -4,
      "y": 4,
      "z": 0,
      "name": "Plant_Leaves_Goldentree"
    },
    {
      "x": -3,
      "y": 5,
      "z": -1,
      "name": "Plant_Leaves_Goldentree"
    },
    {
      "x": -3,
      "y": 4,
      "z": 0,
      "name": "Plant_Leaves_Goldentree"
    },
    {
      "x": -3,
      "y": 5,
      "z": 0,
      "name": "Plant_Leaves_Goldentree"
    },
    {
      "x": -3,
      "y": 4,
      "z": 1,
      "name": "Plant_Leaves_Goldentree"
    },
    {
      "x": -3,
      "y": 6,
      "z": 3,
      "name": "Plant_Leaves_Goldentree"
    },
    {
      "x": -2,
      "y": 4,
      "z": 0,
      "name": "Wood_Amber_Branch_Long",
      "rotation": 5
    },
    {
      "x": -2,
      "y": 5,
      "z": 0,
      "name": "Plant_Leaves_Goldentree"
    },
    {
      "x": -2,
      "y": 8,
      "z": 0,
      "name": "Plant_Leaves_Goldentree"
    },
    {
      "x": -2,
      "y": 4,
      "z": 1,
      "name": "Plant_Leaves_Goldentree"
    },
    {
      "x": -2,
      "y": 6,
      "z": 3,
      "name": "Plant_Leaves_Goldentree"
    },
    {
      "x": -2,
      "y": 5,
      "z": 4,
      "name": "Plant_Leaves_Goldentree"
    },
    {
      "x": -1,
      "y": 5,
      "z": -4,
      "name": "Plant_Leaves_Goldentree"
    },
    {
      "x": -1,
      "y": 5,
      "z": -3,
      "name": "Plant_Leaves_Goldentree"
    },
    {
      "x": -1,
      "y": 5,
      "z": -2,
      "name": "Plant_Leaves_Goldentree"
    },
    {
      "x": -1,
      "y": 8,
      "z": -1,
      "name": "Plant_Leaves_Goldentree"
    },
    {
      "x": -1,
      "y": 9,
      "z": -1,
      "name": "Plant_Leaves_Goldentree"
    },
    {
      "x": -1,
      "y": 4,
      "z": 0,
      "name": "Wood_Amber_Branch_Long",
      "rotation": 5
    },
    {
      "x": -1,
      "y": 5,
      "z": 0,
      "name": "Plant_Leaves_Goldentree"
    },
    {
      "x": -1,
      "y": 7,
      "z": 0,
      "name": "Plant_Leaves_Goldentree"
    },
    {
      "x": -1,
      "y": 8,
      "z": 0,
      "name": "Plant_Leaves_Goldentree"
    },
    {
      "x": -1,
      "y": 8,
      "z": 1,
      "name": "Plant_Leaves_Goldentree"
    },
    {
      "x": -1,
      "y": 5,
      "z": 2,
      "name": "Plant_Leaves_Goldentree"
    },
    {
      "x": -1,
      "y": 8,
      "z": 2,
      "name": "Plant_Leaves_Goldentree"
    },
    {
      "x": -1,
      "y": 6,
      "z": 3,
      "name": "Plant_Leaves_Goldentree"
    },
    {
      "x": -1,
      "y": 5,
      "z": 4,
      "name": "Plant_Leaves_Goldentree"
    },
    {
      "x": -1,
      "y": 6,
      "z": 4,
      "name": "Plant_Leaves_Goldentree"
    },
    {
      "x": 0,
      "y": 4,
      "z": -4,
      "name": "Plant_Leaves_Goldentree"
    },
    {
      "x": 0,
      "y": 5,
      "z": -4,
      "name": "Plant_Leaves_Goldentree"
    },
    {
      "x": 0,
      "y": 5,
      "z": -3,
      "name": "Plant_Leaves_Goldentree"
    },
    {
      "x": 0,
      "y": 6,
      "z": -3,
      "name": "Plant_Leaves_Goldentree"
    },
    {
      "x": 0,
      "y": 5,
      "z": -2,
      "name": "Wood_Amber_Branch_Corner",
      "rotation": 2
    },
    {
      "x": 0,
      "y": 6,
      "z": -2,
      "name": "Plant_Leaves_Goldentree"
    },
    {
      "x": 0,
      "y": 8,
      "z": -2,
      "name": "Plant_Leaves_Goldentree"
    },
    {
      "x": 0,
      "y": 5,
      "z": -1,
      "name": "Wood_Amber_Branch_Long",
      "rotation": 4
    },
    {
      "x": 0,
      "y": 6,
      "z": -1,
      "name": "Plant_Leaves_Goldentree"
    },
    {
      "x": 0,
      "y": 8,
      "z": -1,
      "name": "Plant_Leaves_Goldentree"
    },
    {
      "x": 0,
      "y": 1,
      "z": 0,
      "name": "Wood_Amber_Trunk"
    },
    {
      "x": 0,
      "y": 2,
      "z": 0,
      "name": "Wood_Amber_Trunk"
    },
    {
      "x": 0,
      "y": 3,
      "z": 0,
      "name": "Wood_Amber_Trunk"
    },
    {
      "x": 0,
      "y": 4,
      "z": 0,
      "name": "Wood_Amber_Trunk"
    },
    {
      "x": 0,
      "y": 5,
      "z": 0,
      "name": "Wood_Amber_Trunk"
    },
    {
      "x": 0,
      "y": 6,
      "z": 0,
      "name": "Wood_Amber_Trunk_Full"
    },
    {
      "x": 0,
      "y": 7,
      "z": 0,
      "name": "Wood_Amber_Branch_Long"
    },
    {
      "x": 0,
      "y": 8,
      "z": 0,
      "name": "Wood_Amber_Branch_Long"
    },
    {
      "x": 0,
      "y": 9,
      "z": 0,
      "name": "Plant_Leaves_Goldentree"
    },
    {
      "x": 0,
      "y": 0,
      "z": 1,
      "name": "Wood_Amber_Trunk"
    },
    {
      "x": 0,
      "y": 1,
      "z": 1,
      "name": "Wood_Amber_Trunk"
    },
    {
      "x": 0,
      "y": 2,
      "z": 1,
      "name": "Wood_Amber_Trunk_Full"
    },
    {
      "x": 0,
      "y": 5,
      "z": 1,
      "name": "Wood_Amber_Branch_Long",
      "rotation": 4
    },
    {
      "x": 0,
      "y": 6,
      "z": 1,
      "name": "Plant_Leaves_Goldentree"
    },
    {
      "x": 0,
      "y": 8,
      "z": 1,
      "name": "Plant_Leaves_Goldentree"
    },
    {
      "x": 0,
      "y": 9,
      "z": 1,
      "name": "Plant_Leaves_Goldentree"
    },
    {
      "x": 0,
      "y": 5,
      "z": 2,
      "name": "Wood_Amber_Branch_Long",
      "rotation": 4
    },
    {
      "x": 0,
      "y": 6,
      "z": 2,
      "name": "Plant_Leaves_Goldentree"
    },
    {
      "x": 0,
      "y": 8,
      "z": 2,
      "name": "Plant_Leaves_Goldentree"
    },
    {
      "x": 0,
      "y": 5,
      "z": 3,
      "name": "Plant_Leaves_Goldentree"
    },
    {
      "x": 0,
      "y": 6,
      "z": 3,
      "name": "Plant_Leaves_Goldentree"
    },
    {
      "x": 0,
      "y": 4,
      "z": 4,
      "name": "Plant_Leaves_Goldentree"
    },
    {
      "x": 0,
      "y": 5,
      "z": 4,
      "name": "Plant_Leaves_Goldentree"
    },
    {
      "x": 1,
      "y": 5,
      "z": -3,
      "name": "Plant_Leaves_Goldentree"
    },
    {
      "x": 1,
      "y": 5,
      "z": -2,
      "name": "Plant_Leaves_Goldentree"
    },
    {
      "x": 1,
      "y": 5,
      "z": -1,
      "name": "Plant_Leaves_Goldentree"
    },
    {
      "x": 1,
      "y": 4,
      "z": 0,
      "name": "Wood_Amber_Branch_Long",
      "rotation": 5
    },
    {
      "x": 1,
      "y": 5,
      "z": 0,
      "name": "Plant_Leaves_Goldentree"
    },
    {
      "x": 1,
      "y": 6,
      "z": 0,
      "name": "Wood_Amber_Branch_Long",
      "rotation": 5
    },
    {
      "x": 1,
      "y": 8,
      "z": 0,
      "name": "Plant_Leaves_Goldentree"
    },
    {
      "x": 1,
      "y": 9,
      "z": 0,
      "name": "Plant_Leaves_Goldentree"
    },
    {
      "x": 1,
      "y": 5,
      "z": 3,
      "name": "Plant_Leaves_Goldentree"
    },
    {
      "x": 1,
      "y": 6,
      "z": 3,
      "name": "Plant_Leaves_Goldentree"
    },
    {
      "x": 1,
      "y": 5,
      "z": 4,
      "name": "Plant_Leaves_Goldentree"
    },
    {
      "x": 2,
      "y": 5,
      "z": -3,
      "name": "Plant_Leaves_Goldentree"
    },
    {
      "x": 2,
      "y": 4,
      "z": -1,
      "name": "Plant_Leaves_Goldentree"
    },
    {
      "x": 2,
      "y": 7,
      "z": -1,
      "name": "Plant_Leaves_Goldentree"
    },
    {
      "x": 2,
      "y": 4,
      "z": 0,
      "name": "Plant_Leaves_Goldentree"
    },
    {
      "x": 2,
      "y": 6,
      "z": 0,
      "name": "Wood_Amber_Branch_Long",
      "rotation": 5
    },
    {
      "x": 2,
      "y": 7,
      "z": 0,
      "name": "Plant_Leaves_Goldentree"
    },
    {
      "x": 2,
      "y": 4,
      "z": 1,
      "name": "Plant_Leaves_Goldentree"
    },
    {
      "x": 2,
      "y": 6,
      "z": 1,
      "name": "Plant_Leaves_Goldentree"
    },
    {
      "x": 3,
      "y": 6,
      "z": -1,
      "name": "Plant_Leaves_Goldentree"
    },
    {
      "x": 3,
      "y": 6,
      "z": 0,
      "name": "Plant_Leaves_Goldentree"
    },
    {
      "x": 3,
      "y": 7,
      "z": 0,
      "name": "Plant_Leaves_Goldentree"
    },
    {
      "x": 3,
      "y": 6,
      "z": 1,
      "name": "Plant_Leaves_Goldentree"
    },
    {
      "x": 4,
      "y": 6,
      "z": -1,
      "name": "Plant_Leaves_Goldentree"
    },
    {
      "x": 4,
      "y": 6,
      "z": 0,
      "name": "Plant_Leaves_Goldentree"
    }
  ]
}