{
  "version": 8,
  "blockIdVersion": 11,
  "anchorX": 0,
  "anchorY": 0,
  "anchorZ": 0,
  "blocks": [
    {
      "x": -3,
      "y": 2,
      "z": 0,
      "name": "Plant_Leaves_Apple"
    },
    {
      "x": -3,
      "y": 3,
      "z": 0,
      "name": "Plant_Leaves_Apple"
    },
    {
      "x": -3,
      "y": 4,
      "z": 0,
      "name": "Plant_Leaves_Apple"
    },
    {
      "x": -3,
      "y": 3,
      "z": 1,
      "name": "Plant_Crop_Apple_Block_Wall"
    },
    {
      "x": -3,
      "y": 4,
      "z": 1,
      "name": "Plant_Leaves_Apple"
    },
    {
      "x": -2,
      "y": 3,
      "z": -2,
      "name": "Plant_Crop_Apple_Block_Wall",
      "rotation": 2
    },
    {
      "x": -2,
      "y": 4,
      "z": -2,
      "name": "Plant_Leaves_Apple"
    },
    {
      "x": -2,
      "y": 5,
      "z": -2,
      "name": "Plant_Leaves_Apple"
    },
    {
      "x": -2,
      "y": 3,
      "z": -1,
      "name": "Plant_Leaves_Apple"
    },
    {
      "x": -2,
      "y": 4,
      "z": -1,
      "name": "Plant_Leaves_Apple"
    },
    {
      "x": -2,
      "y": 5,
      "z": -1,
      "name": "Plant_Leaves_Apple"
    },
    {
      "x": -2,
      "y": 6,
      "z": -1,
      "name": "Plant_Leaves_Apple"
    },
    {
      "x": -2,
      "y": 7,
      "z": -1,
      "name": "Plant_Crop_Apple_Block_Wall",
      "rotation": 3
    },
    {
      "x": -2,
      "y": 3,
      "z": 0,
      "name": "Wood_Apple_Branch_Long",
      "rotation": 5
    },
    {
      "x": -2,
      "y": 4,
      "z": 0,
      "name": "Plant_Leaves_Apple"
    },
    {
      "x": -2,
      "y": 5,
      "z": 0,
      "name": "Plant_Leaves_Apple"
    },
    {
      "x": -2,
      "y": 5,
      "z": 1,
      "name": "Plant_Leaves_Apple"
    },
    {
      "x": -1,
      "y": 6,
      "z": -3,
      "name": "Plant_Crop_Apple_Block_Wall",
      "rotation": 2
    },
    {
      "x": -1,
      "y": 5,
      "z": -2,
      "name": "Plant_Leaves_Apple"
    },
    {
      "x": -1,
      "y": 6,
      "z": -2,
      "name": "Plant_Leaves_Apple"
    },
    {
      "x": -1,
      "y": 6,
      "z": -1,
      "name": "Plant_Leaves_Apple"
    },
    {
      "x": -1,
      "y": 7,
      "z": -1,
      "name": "Plant_Leaves_Apple"
    },
    {
      "x": -1,
      "y": 1,
      "z": 0,
      "name": "Wood_Apple_Branch_Short",
      "rotation": 3
    },
    {
      "x": -1,
      "y": 3,
      "z": 0,
      "name": "Wood_Apple_Branch_Long",
      "rotation": 5
    },
    {
      "x": -1,
      "y": 5,
      "z": 0,
      "name": "Plant_Leaves_Apple"
    },
    {
      "x": -1,
      "y": 6,
      "z": 0,
      "name": "Plant_Leaves_Apple"
    },
    {
      "x": -1,
      "y": 6,
      "z": 1,
      "name": "Plant_Crop_Apple_Block_Wall",
      "rotation": 3
    },
    {
      "x": -1,
      "y": 3,
      "z": 2,
      "name": "Plant_Leaves_Apple"
    },
    {
      "x": -1,
      "y": 4,
      "z": 2,
      "name": "Plant_Leaves_Apple"
    },
    {
      "x": -1,
      "y": 4,
      "z": 3,
      "name": "Plant_Leaves_Apple"
    },
    {
      "x": 0,
      "y": 3,
      "z": -3,
      "name": "Plant_Leaves_Apple"
    },
    {
      "x": 0,
      "y": 4,
      "z": -3,
      "name": "Plant_Leaves_Apple"
    },
    {
      "x": 0,
      "y": 5,
      "z": -3,
      "name": "Plant_Leaves_Apple"
    },
    {
      "x": 0,
      "y": 4,
      "z": -2,
      "name": "Wood_Apple_Branch_Long",
      "rotation": 4
    },
    {
      "x": 0,
      "y": 5,
      "z": -2,
      "name": "Plant_Leaves_Apple"
    },
    {
      "x": 0,
      "y": 6,
      "z": -2,
      "name": "Plant_Leaves_Apple"
    },
    {
      "x": 0,
      "y": 4,
      "z": -1,
      "name": "Wood_Apple_Branch_Long",
      "rotation": 4
    },
    {
      "x": 0,
      "y": 7,
      "z": -1,
      "name": "Plant_Leaves_Apple"
    },
    {
      "x": 0,
      "y": 0,
      "z": 0,
      "name": "Wood_Apple_Trunk"
    },
    {
      "x": 0,
      "y": 1,
      "z": 0,
      "name": "Wood_Apple_Trunk"
    },
    {
      "x": 0,
      "y": 2,
      "z": 0,
      "name": "Wood_Apple_Trunk"
    },
    {
      "x": 0,
      "y": 3,
      "z": 0,
      "name": "Wood_Apple_Trunk"
    },
    {
      "x": 0,
      "y": 4,
      "z": 0,
      "name": "Wood_Apple_Trunk"
    },
    {
      "x": 0,
      "y": 5,
      "z": 0,
      "name": "Wood_Apple_Branch_Long"
    },
    {
      "x": 0,
      "y": 6,
      "z": 0,
      "name": "Plant_Leaves_Apple"
    },
    {
      "x": 0,
      "y": 7,
      "z": 0,
      "name": "Plant_Leaves_Apple"
    },
    {
      "x": 0,
      "y": 3,
      "z": 1,
      "name": "Wood_Apple_Branch_Long",
      "rotation": 4
    },
    {
      "x": 0,
      "y": 5,
      "z": 1,
      "name": "Plant_Leaves_Apple"
    },
    {
      "x": 0,
      "y": 6,
      "z": 1,
      "name": "Plant_Leaves_Apple"
    },
    {
      "x": 0,
      "y": 3,
      "z": 2,
      "name": "Wood_Apple_Branch_Long",
      "rotation": 4
    },
    {
      "x": 0,
      "y": 4,
      "z": 2,
      "name": "Plant_Leaves_Apple"
    },
    {
      "x": 0,
      "y": 5,
      "z": 2,
      "name": "Plant_Leaves_Apple"
    },
    {
      "x": 0,
      "y": 6,
      "z": 2,
      "name": "Plant_Leaves_Apple"
    },
    {
      "x": 0,
      "y": 2,
      "z": 3,
      "name": "Plant_Leaves_Apple"
    },
    {
      "x": 0,
      "y": 3,
      "z": 3,
      "name": "Plant_Leaves_Apple"
    },
    {
      "x": 0,
      "y": 5,
      "z": 3,
      "name": "Plant_Crop_Apple_Block_Wall"
    },
    {
      "x": 1,
      "y": 5,
      "z": -2,
      "name": "Plant_Leaves_Apple"
    },
    {
      "x": 1,
      "y": 6,
      "z": -2,
      "name": "Plant_Leaves_Apple"
    },
    {
      "x": 1,
      "y": 6,
      "z": -1,
      "name": "Plant_Leaves_Apple"
    },
    {
      "x": 1,
      "y": 7,
      "z": -1,
      "name": "Plant_Leaves_Apple"
    },
    {
      "x": 1,
      "y": 2,
      "z": 0,
      "name": "Wood_Apple_Branch_Short",
      "rotation": 1
    },
    {
      "x": 1,
      "y": 3,
      "z": 0,
      "name": "Wood_Apple_Branch_Long",
      "rotation": 5
    },
    {
      "x": 1,
      "y": 6,
      "z": 0,
      "name": "Plant_Leaves_Apple"
    },
    {
      "x": 1,
      "y": 3,
      "z": 1,
      "name": "Plant_Leaves_Apple"
    },
    {
      "x": 1,
      "y": 5,
      "z": 1,
      "name": "Plant_Leaves_Apple"
    },
    {
      "x": 1,
      "y": 3,
      "z": 2,
      "name": "Plant_Leaves_Apple"
    },
    {
      "x": 1,
      "y": 4,
      "z": 2,
      "name": "Plant_Leaves_Apple"
    },
    {
      "x": 1,
      "y": 5,
      "z": 2,
      "name": "Plant_Leaves_Apple"
    },
    {
      "x": 1,
      "y": 2,
      "z": 3,
      "name": "Plant_Crop_Apple_Block_Wall",
      "rotation": 1
    },
    {
      "x": 1,
      "y": 4,
      "z": 3,
      "name": "Plant_Leaves_Apple"
    },
    {
      "x": 2,
      "y": 4,
      "z": -3,
      "name": "Plant_Leaves_Apple"
    },
    {
      "x": 2,
      "y": 2,
      "z": -2,
      "name": "Plant_Leaves_Apple"
    },
    {
      "x": 2,
      "y": 3,
      "z": -2,
      "name": "Plant_Leaves_Apple"
    },
    {
      "x": 2,
      "y": 4,
      "z": -2,
      "name": "Plant_Leaves_Apple"
    },
    {
      "x": 2,
      "y": 5,
      "z": -2,
      "name": "Plant_Leaves_Apple"
    },
    {
      "x": 2,
      "y": 6,
      "z": -2,
      "name": "Plant_Crop_Apple_Block_Wall",
      "components": {
        "Components": {
          "FarmingBlock": {
            "LastTickGameTime": "0001-01-01T12:00:00Z"
          },
          "PlacedByInteraction": {
            "WhoPlacedUuid": {
              "$binary": "kPed5NWhMb+aE2p8EA4Dog==",
              "$type": "04"
            }
          }
        }
      },
      "rotation": 1
    },
    {
      "x": 2,
      "y": 4,
      "z": -1,
      "name": "Plant_Leaves_Apple"
    },
    {
      "x": 2,
      "y": 5,
      "z": -1,
      "name": "Plant_Leaves_Apple"
    },
    {
      "x": 2,
      "y": 6,
      "z": -1,
      "name": "Plant_Leaves_Apple"
    },
    {
      "x": 2,
      "y": 3,
      "z": 0,
      "name": "Wood_Apple_Branch_Long",
      "rotation": 5
    },
    {
      "x": 2,
      "y": 4,
      "z": 0,
      "name": "Plant_Leaves_Apple"
    },
    {
      "x": 2,
      "y": 5,
      "z": 0,
      "name": "Plant_Leaves_Apple"
    },
    {
      "x": 2,
      "y": 6,
      "z": 0,
      "name": "Plant_Leaves_Apple"
    },
    {
      "x": 2,
      "y": 4,
      "z": 1,
      "name": "Plant_Leaves_Apple"
    },
    {
      "x": 2,
      "y": 5,
      "z": 1,
      "name": "Plant_Leaves_Apple"
    },
    {
      "x": 3,
      "y": 3,
      "z": -2,
      "name": "Plant_Crop_Apple_Block_Wall",
      "rotation": 1
    },
    {
      "x": 3,
      "y": 6,
      "z": -1,
      "name": "Plant_Leaves_Apple"
    },
    {
      "x": 3,
      "y": 2,
      "z": 0,
      "name": "Plant_Leaves_Apple"
    },
    {
      "x": 3,
      "y": 3,
      "z": 0,
      "name": "Plant_Leaves_Apple"
    },
    {
      "x": 3,
      "y": 4,
      "z": 0,
      "name": "Plant_Leaves_Apple"
    },
    {
      "x": 3,
      "y": 6,
      "z": 0,
      "name": "Plant_Crop_Apple_Block_Wall",
      "rotation": 1
    },
    {
      "x": 3,
      "y": 3,
      "z": 1,
      "name": "Plant_Crop_Apple_Block_Wall"
    },
    {
      "x": 3,
      "y": 4,
      "z": 1,
      "name": "Plant_Leaves_Apple"
    }
  ]
}