{
  "version": 8,
  "blockIdVersion": 11,
  "anchorX": 0,
  "anchorY": 4,
  "anchorZ": 0,
  "blocks": [
    {
      "x": -11,
      "y": 23,
      "z": -2,
      "name": "Plant_Leaves_Goldentree"
    },
    {
      "x": -11,
      "y": 24,
      "z": -2,
      "name": "Plant_Leaves_Goldentree"
    },
    {
      "x": -11,
      "y": 23,
      "z": -1,
      "name": "Plant_Leaves_Goldentree"
    },
    {
      "x": -11,
      "y": 24,
      "z": -1,
      "name": "Plant_Leaves_Goldentree"
    },
    {
      "x": -11,
      "y": 25,
      "z": -1,
      "name": "Plant_Leaves_Goldentree"
    },
    {
      "x": -11,
      "y": 24,
      "z": 0,
      "name": "Plant_Leaves_Goldentree"
    },
    {
      "x": -11,
      "y": 25,
      "z": 0,
      "name": "Plant_Leaves_Goldentree"
    },
    {
      "x": -11,
      "y": 23,
      "z": 1,
      "name": "Plant_Leaves_Goldentree"
    },
    {
      "x": -11,
      "y": 24,
      "z": 1,
      "name": "Plant_Leaves_Goldentree"
    },
    {
      "x": -10,
      "y": 25,
      "z": -8,
      "name": "Plant_Leaves_Goldentree"
    },
    {
      "x": -10,
      "y": 27,
      "z": -8,
      "name": "Plant_Leaves_Goldentree"
    },
    {
      "x": -10,
      "y": 26,
      "z": -7,
      "name": "Plant_Leaves_Goldentree"
    },
    {
      "x": -10,
      "y": 26,
      "z": -6,
      "name": "Plant_Leaves_Goldentree"
    },
    {
      "x": -10,
      "y": 15,
      "z": -4,
      "name": "Plant_Leaves_Goldentree"
    },
    {
      "x": -10,
      "y": 15,
      "z": -3,
      "name": "Plant_Leaves_Goldentree"
    },
    {
      "x": -10,
      "y": 23,
      "z": -3,
      "name": "Plant_Leaves_Goldentree"
    },
    {
      "x": -10,
      "y": 24,
      "z": -3,
      "name": "Plant_Leaves_Goldentree"
    },
    {
      "x": -10,
      "y": 15,
      "z": -2,
      "name": "Plant_Leaves_Goldentree"
    },
    {
      "x": -10,
      "y": 16,
      "z": -2,
      "name": "Plant_Leaves_Goldentree"
    },
    {
      "x": -10,
      "y": 24,
      "z": -2,
      "name": "Plant_Leaves_Goldentree"
    },
    {
      "x": -10,
      "y": 24,
      "z": -1,
      "name": "Wood_Amber_Branch_Long",
      "rotation": 5
    },
    {
      "x": -10,
      "y": 25,
      "z": -1,
      "name": "Plant_Leaves_Goldentree"
    },
    {
      "x": -10,
      "y": 26,
      "z": -1,
      "name": "Plant_Leaves_Goldentree"
    },
    {
      "x": -10,
      "y": 23,
      "z": 0,
      "name": "Plant_Leaves_Goldentree"
    },
    {
      "x": -10,
      "y": 24,
      "z": 0,
      "name": "Plant_Leaves_Goldentree"
    },
    {
      "x": -10,
      "y": 25,
      "z": 0,
      "name": "Plant_Leaves_Goldentree"
    },
    {
      "x": -10,
      "y": 22,
      "z": 1,
      "name": "Plant_Leaves_Goldentree"
    },
    {
      "x": -10,
      "y": 23,
      "z": 1,
      "name": "Plant_Leaves_Goldentree"
    },
    {
      "x": -10,
      "y": 24,
      "z": 1,
      "name": "Plant_Leaves_Goldentree"
    },
    {
      "x": -10,
      "y": 25,
      "z": 1,
      "name": "Plant_Leaves_Goldentree"
    },
    {
      "x": -10,
      "y": 24,
      "z": 2,
      "name": "Plant_Leaves_Goldentree"
    },
    {
      "x": -9,
      "y": 25,
      "z": -9,
      "name": "Plant_Leaves_Goldentree"
    },
    {
      "x": -9,
      "y": 26,
      "z": -9,
      "name": "Plant_Leaves_Goldentree"
    },
    {
      "x": -9,
      "y": 25,
      "z": -8,
      "name": "Plant_Leaves_Goldentree"
    },
    {
      "x": -9,
      "y": 26,
      "z": -8,
      "name": "Plant_Leaves_Goldentree"
    },
    {
      "x": -9,
      "y": 27,
      "z": -8,
      "name": "Plant_Leaves_Goldentree"
    },
    {
      "x": -9,
      "y": 26,
      "z": -7,
      "name": "Plant_Leaves_Goldentree"
    },
    {
      "x": -9,
      "y": 27,
      "z": -7,
      "name": "Plant_Leaves_Goldentree"
    },
    {
      "x": -9,
      "y": 25,
      "z": -6,
      "name": "Plant_Leaves_Goldentree"
    },
    {
      "x": -9,
      "y": 26,
      "z": -6,
      "name": "Plant_Leaves_Goldentree"
    },
    {
      "x": -9,
      "y": 14,
      "z": -5,
      "name": "Plant_Leaves_Goldentree"
    },
    {
      "x": -9,
      "y": 15,
      "z": -5,
      "name": "Plant_Leaves_Goldentree"
    },
    {
      "x": -9,
      "y": 16,
      "z": -5,
      "name": "Plant_Leaves_Goldentree"
    },
    {
      "x": -9,
      "y": 15,
      "z": -4,
      "name": "Plant_Leaves_Goldentree"
    },
    {
      "x": -9,
      "y": 16,
      "z": -4,
      "name": "Plant_Leaves_Goldentree"
    },
    {
      "x": -9,
      "y": 17,
      "z": -4,
      "name": "Plant_Leaves_Goldentree"
    },
    {
      "x": -9,
      "y": 23,
      "z": -4,
      "name": "Plant_Leaves_Goldentree"
    },
    {
      "x": -9,
      "y": 24,
      "z": -4,
      "name": "Plant_Leaves_Goldentree"
    },
    {
      "x": -9,
      "y": 14,
      "z": -3,
      "name": "Plant_Leaves_Goldentree"
    },
    {
      "x": -9,
      "y": 15,
      "z": -3,
      "name": "Plant_Leaves_Goldentree"
    },
    {
      "x": -9,
      "y": 16,
      "z": -3,
      "name": "Wood_Amber_Branch_Long",
      "rotation": 5
    },
    {
      "x": -9,
      "y": 17,
      "z": -3,
      "name": "Plant_Leaves_Goldentree"
    },
    {
      "x": -9,
      "y": 18,
      "z": -3,
      "name": "Plant_Leaves_Goldentree"
    },
    {
      "x": -9,
      "y": 23,
      "z": -3,
      "name": "Plant_Leaves_Goldentree"
    },
    {
      "x": -9,
      "y": 24,
      "z": -3,
      "name": "Plant_Leaves_Goldentree"
    },
    {
      "x": -9,
      "y": 25,
      "z": -3,
      "name": "Plant_Leaves_Goldentree"
    },
    {
      "x": -9,
      "y": 26,
      "z": -3,
      "name": "Plant_Leaves_Goldentree"
    },
    {
      "x": -9,
      "y": 14,
      "z": -2,
      "name": "Plant_Leaves_Goldentree"
    },
    {
      "x": -9,
      "y": 15,
      "z": -2,
      "name": "Plant_Leaves_Goldentree"
    },
    {
      "x": -9,
      "y": 17,
      "z": -2,
      "name": "Plant_Leaves_Goldentree"
    },
    {
      "x": -9,
      "y": 24,
      "z": -2,
      "name": "Plant_Leaves_Goldentree"
    },
    {
      "x": -9,
      "y": 25,
      "z": -2,
      "name": "Plant_Leaves_Goldentree"
    },
    {
      "x": -9,
      "y": 26,
      "z": -2,
      "name": "Plant_Leaves_Goldentree"
    },
    {
      "x": -9,
      "y": 15,
      "z": -1,
      "name": "Plant_Leaves_Goldentree"
    },
    {
      "x": -9,
      "y": 24,
      "z": -1,
      "name": "Wood_Amber_Branch_Long",
      "rotation": 5
    },
    {
      "x": -9,
      "y": 25,
      "z": -1,
      "name": "Plant_Leaves_Goldentree"
    },
    {
      "x": -9,
      "y": 26,
      "z": -1,
      "name": "Plant_Leaves_Goldentree"
    },
    {
      "x": -9,
      "y": 15,
      "z": 0,
      "name": "Plant_Leaves_Goldentree"
    },
    {
      "x": -9,
      "y": 16,
      "z": 0,
      "name": "Plant_Leaves_Goldentree"
    },
    {
      "x": -9,
      "y": 25,
      "z": 0,
      "name": "Plant_Leaves_Goldentree"
    },
    {
      "x": -9,
      "y": 26,
      "z": 0,
      "name": "Plant_Leaves_Goldentree"
    },
    {
      "x": -9,
      "y": 23,
      "z": 1,
      "name": "Plant_Leaves_Goldentree"
    },
    {
      "x": -9,
      "y": 24,
      "z": 1,
      "name": "Plant_Leaves_Goldentree"
    },
    {
      "x": -9,
      "y": 25,
      "z": 1,
      "name": "Plant_Leaves_Goldentree"
    },
    {
      "x": -9,
      "y": 26,
      "z": 1,
      "name": "Plant_Leaves_Goldentree"
    },
    {
      "x": -9,
      "y": 23,
      "z": 2,
      "name": "Plant_Leaves_Goldentree"
    },
    {
      "x": -9,
      "y": 24,
      "z": 2,
      "name": "Plant_Leaves_Goldentree"
    },
    {
      "x": -9,
      "y": 26,
      "z": 2,
      "name": "Plant_Leaves_Goldentree"
    },
    {
      "x": -9,
      "y": 23,
      "z": 3,
      "name": "Plant_Leaves_Goldentree"
    },
    {
      "x": -9,
      "y": 24,
      "z": 3,
      "name": "Plant_Leaves_Goldentree"
    },
    {
      "x": -8,
      "y": 26,
      "z": -10,
      "name": "Plant_Leaves_Goldentree"
    },
    {
      "x": -8,
      "y": 25,
      "z": -9,
      "name": "Plant_Leaves_Goldentree"
    },
    {
      "x": -8,
      "y": 26,
      "z": -9,
      "name": "Plant_Leaves_Goldentree"
    },
    {
      "x": -8,
      "y": 27,
      "z": -9,
      "name": "Plant_Leaves_Goldentree"
    },
    {
      "x": -8,
      "y": 27,
      "z": -8,
      "name": "Plant_Leaves_Goldentree"
    },
    {
      "x": -8,
      "y": 28,
      "z": -8,
      "name": "Plant_Leaves_Goldentree"
    },
    {
      "x": -8,
      "y": 26,
      "z": -7,
      "name": "Wood_Amber_Branch_Long",
      "rotation": 5
    },
    {
      "x": -8,
      "y": 27,
      "z": -7,
      "name": "Plant_Leaves_Goldentree"
    },
    {
      "x": -8,
      "y": 28,
      "z": -7,
      "name": "Plant_Leaves_Goldentree"
    },
    {
      "x": -8,
      "y": 16,
      "z": -6,
      "name": "Plant_Leaves_Goldentree"
    },
    {
      "x": -8,
      "y": 26,
      "z": -6,
      "name": "Plant_Leaves_Goldentree"
    },
    {
      "x": -8,
      "y": 27,
      "z": -6,
      "name": "Plant_Leaves_Goldentree"
    },
    {
      "x": -8,
      "y": 16,
      "z": -5,
      "name": "Plant_Leaves_Goldentree"
    },
    {
      "x": -8,
      "y": 17,
      "z": -5,
      "name": "Plant_Leaves_Goldentree"
    },
    {
      "x": -8,
      "y": 18,
      "z": -5,
      "name": "Plant_Leaves_Goldentree"
    },
    {
      "x": -8,
      "y": 26,
      "z": -5,
      "name": "Plant_Leaves_Goldentree"
    },
    {
      "x": -8,
      "y": 27,
      "z": -5,
      "name": "Plant_Leaves_Goldentree"
    },
    {
      "x": -8,
      "y": 17,
      "z": -4,
      "name": "Plant_Leaves_Goldentree"
    },
    {
      "x": -8,
      "y": 23,
      "z": -4,
      "name": "Plant_Leaves_Goldentree"
    },
    {
      "x": -8,
      "y": 16,
      "z": -3,
      "name": "Wood_Amber_Branch_Long",
      "rotation": 5
    },
    {
      "x": -8,
      "y": 17,
      "z": -3,
      "name": "Plant_Leaves_Goldentree"
    },
    {
      "x": -8,
      "y": 18,
      "z": -3,
      "name": "Plant_Leaves_Goldentree"
    },
    {
      "x": -8,
      "y": 24,
      "z": -3,
      "name": "Plant_Leaves_Goldentree"
    },
    {
      "x": -8,
      "y": 25,
      "z": -3,
      "name": "Plant_Leaves_Goldentree"
    },
    {
      "x": -8,
      "y": 17,
      "z": -2,
      "name": "Plant_Leaves_Goldentree"
    },
    {
      "x": -8,
      "y": 24,
      "z": -2,
      "name": "Wood_Amber_Branch_Long",
      "rotation": 4
    },
    {
      "x": -8,
      "y": 25,
      "z": -2,
      "name": "Plant_Leaves_Goldentree"
    },
    {
      "x": -8,
      "y": 26,
      "z": -2,
      "name": "Plant_Leaves_Goldentree"
    },
    {
      "x": -8,
      "y": 17,
      "z": -1,
      "name": "Plant_Leaves_Goldentree"
    },
    {
      "x": -8,
      "y": 24,
      "z": -1,
      "name": "Wood_Amber_Trunk_Full"
    },
    {
      "x": -8,
      "y": 25,
      "z": -1,
      "name": "Wood_Amber_Branch_Long"
    },
    {
      "x": -8,
      "y": 26,
      "z": -1,
      "name": "Plant_Leaves_Goldentree"
    },
    {
      "x": -8,
      "y": 27,
      "z": -1,
      "name": "Plant_Leaves_Goldentree"
    },
    {
      "x": -8,
      "y": 15,
      "z": 0,
      "name": "Plant_Leaves_Goldentree"
    },
    {
      "x": -8,
      "y": 16,
      "z": 0,
      "name": "Plant_Leaves_Goldentree"
    },
    {
      "x": -8,
      "y": 24,
      "z": 0,
      "name": "Wood_Amber_Branch_Long",
      "rotation": 4
    },
    {
      "x": -8,
      "y": 25,
      "z": 0,
      "name": "Plant_Leaves_Goldentree"
    },
    {
      "x": -8,
      "y": 24,
      "z": 1,
      "name": "Wood_Amber_Branch_Long",
      "rotation": 4
    },
    {
      "x": -8,
      "y": 25,
      "z": 1,
      "name": "Plant_Leaves_Goldentree"
    },
    {
      "x": -8,
      "y": 26,
      "z": 1,
      "name": "Plant_Leaves_Goldentree"
    },
    {
      "x": -8,
      "y": 23,
      "z": 2,
      "name": "Plant_Leaves_Goldentree"
    },
    {
      "x": -8,
      "y": 24,
      "z": 2,
      "name": "Plant_Leaves_Goldentree"
    },
    {
      "x": -7,
      "y": 24,
      "z": -10,
      "name": "Plant_Leaves_Goldentree"
    },
    {
      "x": -7,
      "y": 25,
      "z": -10,
      "name": "Plant_Leaves_Goldentree"
    },
    {
      "x": -7,
      "y": 26,
      "z": -10,
      "name": "Plant_Leaves_Goldentree"
    },
    {
      "x": -7,
      "y": 26,
      "z": -9,
      "name": "Wood_Amber_Branch_Long",
      "rotation": 4
    },
    {
      "x": -7,
      "y": 27,
      "z": -9,
      "name": "Plant_Leaves_Goldentree"
    },
    {
      "x": -7,
      "y": 28,
      "z": -9,
      "name": "Plant_Leaves_Goldentree"
    },
    {
      "x": -7,
      "y": 26,
      "z": -8,
      "name": "Wood_Amber_Branch_Long",
      "rotation": 4
    },
    {
      "x": -7,
      "y": 27,
      "z": -8,
      "name": "Plant_Leaves_Goldentree"
    },
    {
      "x": -7,
      "y": 25,
      "z": -7,
      "name": "Wood_Amber_Trunk_Full"
    },
    {
      "x": -7,
      "y": 26,
      "z": -7,
      "name": "Wood_Amber_Trunk_Full"
    },
    {
      "x": -7,
      "y": 27,
      "z": -7,
      "name": "Wood_Amber_Branch_Long"
    },
    {
      "x": -7,
      "y": 28,
      "z": -7,
      "name": "Plant_Leaves_Goldentree"
    },
    {
      "x": -7,
      "y": 16,
      "z": -6,
      "name": "Plant_Leaves_Goldentree"
    },
    {
      "x": -7,
      "y": 25,
      "z": -6,
      "name": "Plant_Leaves_Goldentree"
    },
    {
      "x": -7,
      "y": 26,
      "z": -6,
      "name": "Plant_Leaves_Goldentree"
    },
    {
      "x": -7,
      "y": 27,
      "z": -6,
      "name": "Plant_Leaves_Goldentree"
    },
    {
      "x": -7,
      "y": 16,
      "z": -5,
      "name": "Wood_Amber_Branch_Long",
      "rotation": 4
    },
    {
      "x": -7,
      "y": 17,
      "z": -5,
      "name": "Plant_Leaves_Goldentree"
    },
    {
      "x": -7,
      "y": 26,
      "z": -5,
      "name": "Plant_Leaves_Goldentree"
    },
    {
      "x": -7,
      "y": 16,
      "z": -4,
      "name": "Wood_Amber_Branch_Long",
      "rotation": 4
    },
    {
      "x": -7,
      "y": 17,
      "z": -4,
      "name": "Plant_Leaves_Goldentree"
    },
    {
      "x": -7,
      "y": 18,
      "z": -4,
      "name": "Plant_Leaves_Goldentree"
    },
    {
      "x": -7,
      "y": 16,
      "z": -3,
      "name": "Wood_Amber_Trunk_Full"
    },
    {
      "x": -7,
      "y": 17,
      "z": -3,
      "name": "Plant_Leaves_Goldentree"
    },
    {
      "x": -7,
      "y": 18,
      "z": -3,
      "name": "Plant_Leaves_Goldentree"
    },
    {
      "x": -7,
      "y": 25,
      "z": -3,
      "name": "Plant_Leaves_Goldentree"
    },
    {
      "x": -7,
      "y": 16,
      "z": -2,
      "name": "Wood_Amber_Branch_Long",
      "rotation": 4
    },
    {
      "x": -7,
      "y": 17,
      "z": -2,
      "name": "Plant_Leaves_Goldentree"
    },
    {
      "x": -7,
      "y": 24,
      "z": -2,
      "name": "Plant_Leaves_Goldentree"
    },
    {
      "x": -7,
      "y": 25,
      "z": -2,
      "name": "Plant_Leaves_Goldentree"
    },
    {
      "x": -7,
      "y": 26,
      "z": -2,
      "name": "Plant_Leaves_Goldentree"
    },
    {
      "x": -7,
      "y": 16,
      "z": -1,
      "name": "Wood_Amber_Branch_Long",
      "rotation": 4
    },
    {
      "x": -7,
      "y": 17,
      "z": -1,
      "name": "Plant_Leaves_Goldentree"
    },
    {
      "x": -7,
      "y": 18,
      "z": -1,
      "name": "Plant_Leaves_Goldentree"
    },
    {
      "x": -7,
      "y": 23,
      "z": -1,
      "name": "Wood_Amber_Trunk_Full"
    },
    {
      "x": -7,
      "y": 24,
      "z": -1,
      "name": "Wood_Amber_Trunk_Full"
    },
    {
      "x": -7,
      "y": 25,
      "z": -1,
      "name": "Plant_Leaves_Goldentree"
    },
    {
      "x": -7,
      "y": 16,
      "z": 0,
      "name": "Plant_Leaves_Goldentree"
    },
    {
      "x": -7,
      "y": 18,
      "z": 0,
      "name": "Plant_Leaves_Goldentree"
    },
    {
      "x": -7,
      "y": 25,
      "z": 0,
      "name": "Plant_Leaves_Goldentree"
    },
    {
      "x": -7,
      "y": 26,
      "z": 0,
      "name": "Plant_Leaves_Goldentree"
    },
    {
      "x": -7,
      "y": 24,
      "z": 1,
      "name": "Plant_Leaves_Goldentree"
    },
    {
      "x": -7,
      "y": 26,
      "z": 1,
      "name": "Plant_Leaves_Goldentree"
    },
    {
      "x": -7,
      "y": 22,
      "z": 4,
      "name": "Plant_Leaves_Goldentree"
    },
    {
      "x": -7,
      "y": 22,
      "z": 5,
      "name": "Plant_Leaves_Goldentree"
    },
    {
      "x": -7,
      "y": 23,
      "z": 5,
      "name": "Plant_Leaves_Goldentree"
    },
    {
      "x": -7,
      "y": 21,
      "z": 6,
      "name": "Plant_Leaves_Goldentree"
    },
    {
      "x": -7,
      "y": 22,
      "z": 6,
      "name": "Plant_Leaves_Goldentree"
    },
    {
      "x": -7,
      "y": 23,
      "z": 6,
      "name": "Plant_Leaves_Goldentree"
    },
    {
      "x": -7,
      "y": 24,
      "z": 6,
      "name": "Plant_Leaves_Goldentree"
    },
    {
      "x": -7,
      "y": 21,
      "z": 7,
      "name": "Plant_Leaves_Goldentree"
    },
    {
      "x": -7,
      "y": 22,
      "z": 7,
      "name": "Plant_Leaves_Goldentree"
    },
    {
      "x": -7,
      "y": 23,
      "z": 7,
      "name": "Plant_Leaves_Goldentree"
    },
    {
      "x": -6,
      "y": 26,
      "z": -10,
      "name": "Plant_Leaves_Goldentree"
    },
    {
      "x": -6,
      "y": 26,
      "z": -9,
      "name": "Plant_Leaves_Goldentree"
    },
    {
      "x": -6,
      "y": 27,
      "z": -9,
      "name": "Plant_Leaves_Goldentree"
    },
    {
      "x": -6,
      "y": 28,
      "z": -9,
      "name": "Plant_Leaves_Goldentree"
    },
    {
      "x": -6,
      "y": 26,
      "z": -8,
      "name": "Plant_Leaves_Goldentree"
    },
    {
      "x": -6,
      "y": 27,
      "z": -8,
      "name": "Plant_Leaves_Goldentree"
    },
    {
      "x": -6,
      "y": 28,
      "z": -8,
      "name": "Plant_Leaves_Goldentree"
    },
    {
      "x": -6,
      "y": 25,
      "z": -7,
      "name": "Wood_Amber_Trunk_Full"
    },
    {
      "x": -6,
      "y": 26,
      "z": -7,
      "name": "Plant_Leaves_Goldentree"
    },
    {
      "x": -6,
      "y": 27,
      "z": -7,
      "name": "Plant_Leaves_Goldentree"
    },
    {
      "x": -6,
      "y": 28,
      "z": -7,
      "name": "Plant_Leaves_Goldentree"
    },
    {
      "x": -6,
      "y": 25,
      "z": -6,
      "name": "Wood_Amber_Trunk_Full"
    },
    {
      "x": -6,
      "y": 26,
      "z": -6,
      "name": "Plant_Leaves_Goldentree"
    },
    {
      "x": -6,
      "y": 26,
      "z": -5,
      "name": "Plant_Leaves_Goldentree"
    },
    {
      "x": -6,
      "y": 18,
      "z": -4,
      "name": "Plant_Leaves_Goldentree"
    },
    {
      "x": -6,
      "y": 15,
      "z": -3,
      "name": "Wood_Amber_Trunk_Full"
    },
    {
      "x": -6,
      "y": 16,
      "z": -3,
      "name": "Wood_Amber_Branch_Long",
      "rotation": 5
    },
    {
      "x": -6,
      "y": 17,
      "z": -3,
      "name": "Plant_Leaves_Goldentree"
    },
    {
      "x": -6,
      "y": 18,
      "z": -3,
      "name": "Plant_Leaves_Goldentree"
    },
    {
      "x": -6,
      "y": 14,
      "z": -2,
      "name": "Wood_Amber_Trunk_Full"
    },
    {
      "x": -6,
      "y": 17,
      "z": -2,
      "name": "Plant_Leaves_Goldentree"
    },
    {
      "x": -6,
      "y": 18,
      "z": -2,
      "name": "Plant_Leaves_Goldentree"
    },
    {
      "x": -6,
      "y": 24,
      "z": -2,
      "name": "Plant_Leaves_Goldentree"
    },
    {
      "x": -6,
      "y": 26,
      "z": -2,
      "name": "Plant_Leaves_Goldentree"
    },
    {
      "x": -6,
      "y": 16,
      "z": -1,
      "name": "Plant_Leaves_Goldentree"
    },
    {
      "x": -6,
      "y": 23,
      "z": -1,
      "name": "Wood_Amber_Trunk_Full"
    },
    {
      "x": -6,
      "y": 24,
      "z": 0,
      "name": "Plant_Leaves_Goldentree"
    },
    {
      "x": -6,
      "y": 24,
      "z": 1,
      "name": "Plant_Leaves_Goldentree"
    },
    {
      "x": -6,
      "y": 21,
      "z": 4,
      "name": "Plant_Leaves_Goldentree"
    },
    {
      "x": -6,
      "y": 22,
      "z": 4,
      "name": "Plant_Leaves_Goldentree"
    },
    {
      "x": -6,
      "y": 22,
      "z": 5,
      "name": "Wood_Amber_Branch_Long",
      "rotation": 5
    },
    {
      "x": -6,
      "y": 23,
      "z": 5,
      "name": "Plant_Leaves_Goldentree"
    },
    {
      "x": -6,
      "y": 24,
      "z": 5,
      "name": "Plant_Leaves_Goldentree"
    },
    {
      "x": -6,
      "y": 20,
      "z": 6,
      "name": "Plant_Leaves_Goldentree"
    },
    {
      "x": -6,
      "y": 21,
      "z": 6,
      "name": "Plant_Leaves_Goldentree"
    },
    {
      "x": -6,
      "y": 23,
      "z": 6,
      "name": "Plant_Leaves_Goldentree"
    },
    {
      "x": -6,
      "y": 20,
      "z": 7,
      "name": "Plant_Leaves_Goldentree"
    },
    {
      "x": -6,
      "y": 22,
      "z": 7,
      "name": "Plant_Leaves_Goldentree"
    },
    {
      "x": -6,
      "y": 23,
      "z": 7,
      "name": "Plant_Leaves_Goldentree"
    },
    {
      "x": -6,
      "y": 24,
      "z": 7,
      "name": "Plant_Leaves_Goldentree"
    },
    {
      "x": -6,
      "y": 22,
      "z": 8,
      "name": "Plant_Leaves_Goldentree"
    },
    {
      "x": -5,
      "y": 23,
      "z": -10,
      "name": "Plant_Leaves_Goldentree"
    },
    {
      "x": -5,
      "y": 26,
      "z": -8,
      "name": "Plant_Leaves_Goldentree"
    },
    {
      "x": -5,
      "y": 24,
      "z": -6,
      "name": "Wood_Amber_Trunk_Full"
    },
    {
      "x": -5,
      "y": 25,
      "z": -6,
      "name": "Wood_Amber_Trunk_Full"
    },
    {
      "x": -5,
      "y": 17,
      "z": -5,
      "name": "Plant_Leaves_Goldentree"
    },
    {
      "x": -5,
      "y": 17,
      "z": -4,
      "name": "Plant_Leaves_Goldentree"
    },
    {
      "x": -5,
      "y": 18,
      "z": -4,
      "name": "Plant_Leaves_Goldentree"
    },
    {
      "x": -5,
      "y": 14,
      "z": -3,
      "name": "Wood_Amber_Trunk_Full"
    },
    {
      "x": -5,
      "y": 16,
      "z": -3,
      "name": "Wood_Amber_Branch_Long",
      "rotation": 5
    },
    {
      "x": -5,
      "y": 17,
      "z": -3,
      "name": "Plant_Leaves_Goldentree"
    },
    {
      "x": -5,
      "y": 14,
      "z": -2,
      "name": "Wood_Amber_Trunk_Full"
    },
    {
      "x": -5,
      "y": 16,
      "z": -2,
      "name": "Plant_Leaves_Goldentree"
    },
    {
      "x": -5,
      "y": 16,
      "z": -1,
      "name": "Plant_Leaves_Goldentree"
    },
    {
      "x": -5,
      "y": 22,
      "z": -1,
      "name": "Wood_Amber_Trunk_Full"
    },
    {
      "x": -5,
      "y": 23,
      "z": -1,
      "name": "Wood_Amber_Trunk_Full"
    },
    {
      "x": -5,
      "y": 22,
      "z": 3,
      "name": "Plant_Leaves_Goldentree"
    },
    {
      "x": -5,
      "y": 22,
      "z": 4,
      "name": "Plant_Leaves_Goldentree"
    },
    {
      "x": -5,
      "y": 23,
      "z": 4,
      "name": "Plant_Leaves_Goldentree"
    },
    {
      "x": -5,
      "y": 22,
      "z": 5,
      "name": "Wood_Amber_Branch_Long",
      "rotation": 5
    },
    {
      "x": -5,
      "y": 23,
      "z": 5,
      "name": "Plant_Leaves_Goldentree"
    },
    {
      "x": -5,
      "y": 24,
      "z": 5,
      "name": "Plant_Leaves_Goldentree"
    },
    {
      "x": -5,
      "y": 24,
      "z": 6,
      "name": "Plant_Leaves_Goldentree"
    },
    {
      "x": -5,
      "y": 25,
      "z": 6,
      "name": "Plant_Leaves_Goldentree"
    },
    {
      "x": -5,
      "y": 20,
      "z": 7,
      "name": "Plant_Leaves_Goldentree"
    },
    {
      "x": -5,
      "y": 21,
      "z": 7,
      "name": "Plant_Leaves_Goldentree"
    },
    {
      "x": -5,
      "y": 22,
      "z": 7,
      "name": "Plant_Leaves_Goldentree"
    },
    {
      "x": -5,
      "y": 23,
      "z": 7,
      "name": "Plant_Leaves_Goldentree"
    },
    {
      "x": -5,
      "y": 22,
      "z": 8,
      "name": "Plant_Leaves_Goldentree"
    },
    {
      "x": -4,
      "y": 22,
      "z": -12,
      "name": "Plant_Leaves_Goldentree"
    },
    {
      "x": -4,
      "y": 23,
      "z": -12,
      "name": "Plant_Leaves_Goldentree"
    },
    {
      "x": -4,
      "y": 24,
      "z": -12,
      "name": "Plant_Leaves_Goldentree"
    },
    {
      "x": -4,
      "y": 22,
      "z": -11,
      "name": "Plant_Leaves_Goldentree"
    },
    {
      "x": -4,
      "y": 23,
      "z": -11,
      "name": "Plant_Leaves_Goldentree"
    },
    {
      "x": -4,
      "y": 24,
      "z": -11,
      "name": "Plant_Leaves_Goldentree"
    },
    {
      "x": -4,
      "y": 16,
      "z": -10,
      "name": "Plant_Leaves_Goldentree"
    },
    {
      "x": -4,
      "y": 22,
      "z": -10,
      "name": "Plant_Leaves_Goldentree"
    },
    {
      "x": -4,
      "y": 23,
      "z": -10,
      "name": "Plant_Leaves_Goldentree"
    },
    {
      "x": -4,
      "y": 16,
      "z": -9,
      "name": "Plant_Leaves_Goldentree"
    },
    {
      "x": -4,
      "y": 23,
      "z": -9,
      "name": "Plant_Leaves_Goldentree"
    },
    {
      "x": -4,
      "y": 15,
      "z": -8,
      "name": "Plant_Leaves_Goldentree"
    },
    {
      "x": -4,
      "y": 16,
      "z": -8,
      "name": "Plant_Leaves_Goldentree"
    },
    {
      "x": -4,
      "y": 23,
      "z": -6,
      "name": "Wood_Amber_Trunk_Full"
    },
    {
      "x": -4,
      "y": 24,
      "z": -6,
      "name": "Wood_Amber_Trunk_Full"
    },
    {
      "x": -4,
      "y": 23,
      "z": -5,
      "name": "Wood_Amber_Trunk_Full"
    },
    {
      "x": -4,
      "y": 16,
      "z": -4,
      "name": "Plant_Leaves_Goldentree"
    },
    {
      "x": -4,
      "y": 16,
      "z": -3,
      "name": "Plant_Leaves_Goldentree"
    },
    {
      "x": -4,
      "y": 13,
      "z": -2,
      "name": "Wood_Amber_Trunk_Full"
    },
    {
      "x": -4,
      "y": 14,
      "z": -2,
      "name": "Wood_Amber_Trunk_Full"
    },
    {
      "x": -4,
      "y": 16,
      "z": -1,
      "name": "Plant_Leaves_Goldentree"
    },
    {
      "x": -4,
      "y": 22,
      "z": -1,
      "name": "Wood_Amber_Trunk_Full"
    },
    {
      "x": -4,
      "y": 21,
      "z": 2,
      "name": "Wood_Amber_Trunk_Full"
    },
    {
      "x": -4,
      "y": 21,
      "z": 3,
      "name": "Wood_Amber_Trunk_Full"
    },
    {
      "x": -4,
      "y": 22,
      "z": 3,
      "name": "Plant_Leaves_Goldentree"
    },
    {
      "x": -4,
      "y": 29,
      "z": 3,
      "name": "Plant_Leaves_Goldentree"
    },
    {
      "x": -4,
      "y": 21,
      "z": 4,
      "name": "Wood_Amber_Trunk_Full"
    },
    {
      "x": -4,
      "y": 22,
      "z": 4,
      "name": "Plant_Leaves_Goldentree"
    },
    {
      "x": -4,
      "y": 23,
      "z": 4,
      "name": "Plant_Leaves_Goldentree"
    },
    {
      "x": -4,
      "y": 21,
      "z": 5,
      "name": "Wood_Amber_Trunk_Full"
    },
    {
      "x": -4,
      "y": 22,
      "z": 5,
      "name": "Wood_Amber_Trunk_Full"
    },
    {
      "x": -4,
      "y": 23,
      "z": 5,
      "name": "Wood_Amber_Branch_Long"
    },
    {
      "x": -4,
      "y": 24,
      "z": 5,
      "name": "Plant_Leaves_Goldentree"
    },
    {
      "x": -4,
      "y": 29,
      "z": 5,
      "name": "Plant_Leaves_Goldentree"
    },
    {
      "x": -4,
      "y": 22,
      "z": 6,
      "name": "Wood_Amber_Branch_Long",
      "rotation": 4
    },
    {
      "x": -4,
      "y": 23,
      "z": 6,
      "name": "Plant_Leaves_Goldentree"
    },
    {
      "x": -4,
      "y": 29,
      "z": 6,
      "name": "Plant_Leaves_Goldentree"
    },
    {
      "x": -4,
      "y": 21,
      "z": 7,
      "name": "Plant_Leaves_Goldentree"
    },
    {
      "x": -4,
      "y": 22,
      "z": 7,
      "name": "Wood_Amber_Branch_Long",
      "rotation": 4
    },
    {
      "x": -4,
      "y": 23,
      "z": 7,
      "name": "Plant_Leaves_Goldentree"
    },
    {
      "x": -4,
      "y": 22,
      "z": 8,
      "name": "Plant_Leaves_Goldentree"
    },
    {
      "x": -3,
      "y": 22,
      "z": -13,
      "name": "Plant_Leaves_Goldentree"
    },
    {
      "x": -3,
      "y": 23,
      "z": -13,
      "name": "Plant_Leaves_Goldentree"
    },
    {
      "x": -3,
      "y": 21,
      "z": -12,
      "name": "Plant_Leaves_Goldentree"
    },
    {
      "x": -3,
      "y": 22,
      "z": -12,
      "name": "Plant_Leaves_Goldentree"
    },
    {
      "x": -3,
      "y": 23,
      "z": -12,
      "name": "Plant_Leaves_Goldentree"
    },
    {
      "x": -3,
      "y": 24,
      "z": -12,
      "name": "Plant_Leaves_Goldentree"
    },
    {
      "x": -3,
      "y": 15,
      "z": -11,
      "name": "Plant_Leaves_Goldentree"
    },
    {
      "x": -3,
      "y": 16,
      "z": -11,
      "name": "Plant_Leaves_Goldentree"
    },
    {
      "x": -3,
      "y": 21,
      "z": -11,
      "name": "Plant_Leaves_Goldentree"
    },
    {
      "x": -3,
      "y": 24,
      "z": -11,
      "name": "Plant_Leaves_Goldentree"
    },
    {
      "x": -3,
      "y": 15,
      "z": -10,
      "name": "Plant_Leaves_Goldentree"
    },
    {
      "x": -3,
      "y": 16,
      "z": -10,
      "name": "Plant_Leaves_Goldentree"
    },
    {
      "x": -3,
      "y": 17,
      "z": -10,
      "name": "Plant_Leaves_Goldentree"
    },
    {
      "x": -3,
      "y": 18,
      "z": -10,
      "name": "Plant_Leaves_Goldentree"
    },
    {
      "x": -3,
      "y": 23,
      "z": -10,
      "name": "Wood_Amber_Branch_Long",
      "rotation": 5
    },
    {
      "x": -3,
      "y": 24,
      "z": -10,
      "name": "Plant_Leaves_Goldentree"
    },
    {
      "x": -3,
      "y": 25,
      "z": -10,
      "name": "Plant_Leaves_Goldentree"
    },
    {
      "x": -3,
      "y": 17,
      "z": -9,
      "name": "Plant_Leaves_Goldentree"
    },
    {
      "x": -3,
      "y": 24,
      "z": -9,
      "name": "Plant_Leaves_Goldentree"
    },
    {
      "x": -3,
      "y": 16,
      "z": -8,
      "name": "Plant_Leaves_Goldentree"
    },
    {
      "x": -3,
      "y": 17,
      "z": -8,
      "name": "Plant_Leaves_Goldentree"
    },
    {
      "x": -3,
      "y": 23,
      "z": -8,
      "name": "Plant_Leaves_Goldentree"
    },
    {
      "x": -3,
      "y": 15,
      "z": -7,
      "name": "Plant_Leaves_Goldentree"
    },
    {
      "x": -3,
      "y": 16,
      "z": -7,
      "name": "Plant_Leaves_Goldentree"
    },
    {
      "x": -3,
      "y": 17,
      "z": -7,
      "name": "Plant_Leaves_Goldentree"
    },
    {
      "x": -3,
      "y": 27,
      "z": -7,
      "name": "Plant_Leaves_Goldentree"
    },
    {
      "x": -3,
      "y": 15,
      "z": -6,
      "name": "Plant_Leaves_Goldentree"
    },
    {
      "x": -3,
      "y": 27,
      "z": -6,
      "name": "Plant_Leaves_Goldentree"
    },
    {
      "x": -3,
      "y": 28,
      "z": -6,
      "name": "Plant_Leaves_Goldentree"
    },
    {
      "x": -3,
      "y": 22,
      "z": -5,
      "name": "Wood_Amber_Trunk_Full"
    },
    {
      "x": -3,
      "y": 23,
      "z": -5,
      "name": "Wood_Amber_Trunk_Full"
    },
    {
      "x": -3,
      "y": 13,
      "z": -2,
      "name": "Wood_Amber_Trunk_Full"
    },
    {
      "x": -3,
      "y": 14,
      "z": -2,
      "name": "Wood_Amber_Trunk_Full"
    },
    {
      "x": -3,
      "y": 13,
      "z": -1,
      "name": "Wood_Amber_Trunk_Full"
    },
    {
      "x": -3,
      "y": 14,
      "z": -1,
      "name": "Wood_Amber_Trunk_Full"
    },
    {
      "x": -3,
      "y": 22,
      "z": -1,
      "name": "Wood_Amber_Trunk_Full"
    },
    {
      "x": -3,
      "y": 22,
      "z": 0,
      "name": "Wood_Amber_Trunk_Full"
    },
    {
      "x": -3,
      "y": 20,
      "z": 1,
      "name": "Wood_Amber_Trunk_Full"
    },
    {
      "x": -3,
      "y": 0,
      "z": 2,
      "name": "Wood_Amber_Trunk"
    },
    {
      "x": -3,
      "y": 1,
      "z": 2,
      "name": "Wood_Amber_Trunk"
    },
    {
      "x": -3,
      "y": 2,
      "z": 2,
      "name": "Wood_Amber_Trunk_Full"
    },
    {
      "x": -3,
      "y": 20,
      "z": 2,
      "name": "Wood_Amber_Trunk_Full"
    },
    {
      "x": -3,
      "y": 21,
      "z": 2,
      "name": "Wood_Amber_Trunk_Full"
    },
    {
      "x": -3,
      "y": 29,
      "z": 2,
      "name": "Plant_Leaves_Goldentree"
    },
    {
      "x": -3,
      "y": 30,
      "z": 2,
      "name": "Plant_Leaves_Goldentree"
    },
    {
      "x": -3,
      "y": 0,
      "z": 3,
      "name": "Wood_Amber_Trunk"
    },
    {
      "x": -3,
      "y": 1,
      "z": 3,
      "name": "Wood_Amber_Trunk_Full"
    },
    {
      "x": -3,
      "y": 29,
      "z": 3,
      "name": "Wood_Amber_Branch_Long",
      "rotation": 5
    },
    {
      "x": -3,
      "y": 30,
      "z": 3,
      "name": "Plant_Leaves_Goldentree"
    },
    {
      "x": -3,
      "y": 22,
      "z": 4,
      "name": "Plant_Leaves_Goldentree"
    },
    {
      "x": -3,
      "y": 30,
      "z": 4,
      "name": "Plant_Leaves_Goldentree"
    },
    {
      "x": -3,
      "y": 31,
      "z": 4,
      "name": "Plant_Leaves_Goldentree"
    },
    {
      "x": -3,
      "y": 22,
      "z": 5,
      "name": "Wood_Amber_Branch_Long",
      "rotation": 5
    },
    {
      "x": -3,
      "y": 23,
      "z": 5,
      "name": "Plant_Leaves_Goldentree"
    },
    {
      "x": -3,
      "y": 24,
      "z": 5,
      "name": "Plant_Leaves_Goldentree"
    },
    {
      "x": -3,
      "y": 30,
      "z": 5,
      "name": "Plant_Leaves_Goldentree"
    },
    {
      "x": -3,
      "y": 23,
      "z": 6,
      "name": "Plant_Leaves_Goldentree"
    },
    {
      "x": -3,
      "y": 24,
      "z": 6,
      "name": "Plant_Leaves_Goldentree"
    },
    {
      "x": -3,
      "y": 28,
      "z": 6,
      "name": "Plant_Leaves_Goldentree"
    },
    {
      "x": -3,
      "y": 29,
      "z": 6,
      "name": "Plant_Leaves_Goldentree"
    },
    {
      "x": -3,
      "y": 30,
      "z": 6,
      "name": "Plant_Leaves_Goldentree"
    },
    {
      "x": -3,
      "y": 21,
      "z": 7,
      "name": "Plant_Leaves_Goldentree"
    },
    {
      "x": -3,
      "y": 22,
      "z": 7,
      "name": "Plant_Leaves_Goldentree"
    },
    {
      "x": -3,
      "y": 23,
      "z": 7,
      "name": "Plant_Leaves_Goldentree"
    },
    {
      "x": -2,
      "y": 21,
      "z": -13,
      "name": "Plant_Leaves_Goldentree"
    },
    {
      "x": -2,
      "y": 22,
      "z": -13,
      "name": "Plant_Leaves_Goldentree"
    },
    {
      "x": -2,
      "y": 23,
      "z": -13,
      "name": "Plant_Leaves_Goldentree"
    },
    {
      "x": -2,
      "y": 24,
      "z": -13,
      "name": "Plant_Leaves_Goldentree"
    },
    {
      "x": -2,
      "y": 22,
      "z": -12,
      "name": "Plant_Leaves_Goldentree"
    },
    {
      "x": -2,
      "y": 23,
      "z": -12,
      "name": "Wood_Amber_Branch_Long",
      "rotation": 4
    },
    {
      "x": -2,
      "y": 24,
      "z": -12,
      "name": "Plant_Leaves_Goldentree"
    },
    {
      "x": -2,
      "y": 15,
      "z": -11,
      "name": "Plant_Leaves_Goldentree"
    },
    {
      "x": -2,
      "y": 16,
      "z": -11,
      "name": "Plant_Leaves_Goldentree"
    },
    {
      "x": -2,
      "y": 23,
      "z": -11,
      "name": "Wood_Amber_Branch_Long",
      "rotation": 4
    },
    {
      "x": -2,
      "y": 24,
      "z": -11,
      "name": "Plant_Leaves_Goldentree"
    },
    {
      "x": -2,
      "y": 25,
      "z": -11,
      "name": "Plant_Leaves_Goldentree"
    },
    {
      "x": -2,
      "y": 15,
      "z": -10,
      "name": "Plant_Leaves_Goldentree"
    },
    {
      "x": -2,
      "y": 17,
      "z": -10,
      "name": "Plant_Leaves_Goldentree"
    },
    {
      "x": -2,
      "y": 22,
      "z": -10,
      "name": "Wood_Amber_Trunk_Full"
    },
    {
      "x": -2,
      "y": 23,
      "z": -10,
      "name": "Wood_Amber_Trunk_Full"
    },
    {
      "x": -2,
      "y": 24,
      "z": -10,
      "name": "Wood_Amber_Branch_Long"
    },
    {
      "x": -2,
      "y": 25,
      "z": -10,
      "name": "Plant_Leaves_Goldentree"
    },
    {
      "x": -2,
      "y": 17,
      "z": -9,
      "name": "Plant_Leaves_Goldentree"
    },
    {
      "x": -2,
      "y": 23,
      "z": -9,
      "name": "Wood_Amber_Branch_Long",
      "rotation": 4
    },
    {
      "x": -2,
      "y": 24,
      "z": -9,
      "name": "Plant_Leaves_Goldentree"
    },
    {
      "x": -2,
      "y": 16,
      "z": -8,
      "name": "Wood_Amber_Branch_Long",
      "rotation": 5
    },
    {
      "x": -2,
      "y": 17,
      "z": -8,
      "name": "Plant_Leaves_Goldentree"
    },
    {
      "x": -2,
      "y": 23,
      "z": -8,
      "name": "Plant_Leaves_Goldentree"
    },
    {
      "x": -2,
      "y": 26,
      "z": -8,
      "name": "Plant_Leaves_Goldentree"
    },
    {
      "x": -2,
      "y": 27,
      "z": -8,
      "name": "Plant_Leaves_Goldentree"
    },
    {
      "x": -2,
      "y": 28,
      "z": -8,
      "name": "Plant_Leaves_Goldentree"
    },
    {
      "x": -2,
      "y": 29,
      "z": -8,
      "name": "Plant_Leaves_Goldentree"
    },
    {
      "x": -2,
      "y": 15,
      "z": -7,
      "name": "Plant_Leaves_Goldentree"
    },
    {
      "x": -2,
      "y": 16,
      "z": -7,
      "name": "Plant_Leaves_Goldentree"
    },
    {
      "x": -2,
      "y": 17,
      "z": -7,
      "name": "Plant_Leaves_Goldentree"
    },
    {
      "x": -2,
      "y": 27,
      "z": -7,
      "name": "Plant_Leaves_Goldentree"
    },
    {
      "x": -2,
      "y": 28,
      "z": -7,
      "name": "Plant_Leaves_Goldentree"
    },
    {
      "x": -2,
      "y": 15,
      "z": -6,
      "name": "Plant_Leaves_Goldentree"
    },
    {
      "x": -2,
      "y": 16,
      "z": -6,
      "name": "Plant_Leaves_Goldentree"
    },
    {
      "x": -2,
      "y": 27,
      "z": -6,
      "name": "Wood_Amber_Branch_Long",
      "rotation": 5
    },
    {
      "x": -2,
      "y": 28,
      "z": -6,
      "name": "Plant_Leaves_Goldentree"
    },
    {
      "x": -2,
      "y": 29,
      "z": -6,
      "name": "Plant_Leaves_Goldentree"
    },
    {
      "x": -2,
      "y": 22,
      "z": -5,
      "name": "Wood_Amber_Trunk_Full"
    },
    {
      "x": -2,
      "y": 27,
      "z": -5,
      "name": "Plant_Leaves_Goldentree"
    },
    {
      "x": -2,
      "y": 0,
      "z": -3,
      "name": "Wood_Amber_Trunk"
    },
    {
      "x": -2,
      "y": 1,
      "z": -3,
      "name": "Wood_Amber_Trunk_Full",
      "rotation": 4
    },
    {
      "x": -2,
      "y": 0,
      "z": -2,
      "name": "Wood_Amber_Trunk"
    },
    {
      "x": -2,
      "y": 1,
      "z": -2,
      "name": "Wood_Amber_Trunk"
    },
    {
      "x": -2,
      "y": 2,
      "z": -2,
      "name": "Wood_Amber_Trunk_Full"
    },
    {
      "x": -2,
      "y": 12,
      "z": -1,
      "name": "Wood_Amber_Trunk_Full"
    },
    {
      "x": -2,
      "y": 13,
      "z": -1,
      "name": "Wood_Amber_Trunk_Full"
    },
    {
      "x": -2,
      "y": 14,
      "z": -1,
      "name": "Wood_Amber_Trunk_Full"
    },
    {
      "x": -2,
      "y": 19,
      "z": 0,
      "name": "Wood_Amber_Trunk_Full"
    },
    {
      "x": -2,
      "y": 20,
      "z": 0,
      "name": "Wood_Amber_Trunk_Full"
    },
    {
      "x": -2,
      "y": 21,
      "z": 0,
      "name": "Wood_Amber_Trunk_Full"
    },
    {
      "x": -2,
      "y": 22,
      "z": 0,
      "name": "Wood_Amber_Trunk_Full"
    },
    {
      "x": -2,
      "y": 2,
      "z": 1,
      "name": "Wood_Amber_Trunk"
    },
    {
      "x": -2,
      "y": 3,
      "z": 1,
      "name": "Wood_Amber_Trunk"
    },
    {
      "x": -2,
      "y": 4,
      "z": 1,
      "name": "Wood_Amber_Trunk_Full"
    },
    {
      "x": -2,
      "y": 20,
      "z": 1,
      "name": "Wood_Amber_Trunk_Full"
    },
    {
      "x": -2,
      "y": 29,
      "z": 1,
      "name": "Plant_Leaves_Goldentree"
    },
    {
      "x": -2,
      "y": 30,
      "z": 1,
      "name": "Plant_Leaves_Goldentree"
    },
    {
      "x": -2,
      "y": 0,
      "z": 2,
      "name": "Wood_Amber_Trunk"
    },
    {
      "x": -2,
      "y": 1,
      "z": 2,
      "name": "Wood_Amber_Trunk"
    },
    {
      "x": -2,
      "y": 2,
      "z": 2,
      "name": "Wood_Amber_Trunk"
    },
    {
      "x": -2,
      "y": 3,
      "z": 2,
      "name": "Wood_Amber_Trunk"
    },
    {
      "x": -2,
      "y": 4,
      "z": 2,
      "name": "Wood_Amber_Trunk"
    },
    {
      "x": -2,
      "y": 5,
      "z": 2,
      "name": "Wood_Amber_Trunk_Full"
    },
    {
      "x": -2,
      "y": 30,
      "z": 2,
      "name": "Plant_Leaves_Goldentree"
    },
    {
      "x": -2,
      "y": 31,
      "z": 2,
      "name": "Plant_Leaves_Goldentree"
    },
    {
      "x": -2,
      "y": 0,
      "z": 3,
      "name": "Wood_Amber_Trunk_Full"
    },
    {
      "x": -2,
      "y": 1,
      "z": 3,
      "name": "Wood_Amber_Trunk"
    },
    {
      "x": -2,
      "y": 2,
      "z": 3,
      "name": "Wood_Amber_Trunk"
    },
    {
      "x": -2,
      "y": 3,
      "z": 3,
      "name": "Wood_Amber_Trunk_Full"
    },
    {
      "x": -2,
      "y": 29,
      "z": 3,
      "name": "Wood_Amber_Branch_Long",
      "rotation": 5
    },
    {
      "x": -2,
      "y": 30,
      "z": 3,
      "name": "Plant_Leaves_Goldentree"
    },
    {
      "x": -2,
      "y": 31,
      "z": 3,
      "name": "Plant_Leaves_Goldentree"
    },
    {
      "x": -2,
      "y": 21,
      "z": 4,
      "name": "Plant_Leaves_Goldentree"
    },
    {
      "x": -2,
      "y": 22,
      "z": 4,
      "name": "Plant_Leaves_Goldentree"
    },
    {
      "x": -2,
      "y": 30,
      "z": 4,
      "name": "Plant_Leaves_Goldentree"
    },
    {
      "x": -2,
      "y": 21,
      "z": 5,
      "name": "Plant_Leaves_Goldentree"
    },
    {
      "x": -2,
      "y": 22,
      "z": 5,
      "name": "Plant_Leaves_Goldentree"
    },
    {
      "x": -2,
      "y": 23,
      "z": 5,
      "name": "Plant_Leaves_Goldentree"
    },
    {
      "x": -2,
      "y": 30,
      "z": 5,
      "name": "Plant_Leaves_Goldentree"
    },
    {
      "x": -2,
      "y": 31,
      "z": 5,
      "name": "Plant_Leaves_Goldentree"
    },
    {
      "x": -2,
      "y": 22,
      "z": 6,
      "name": "Plant_Leaves_Goldentree"
    },
    {
      "x": -2,
      "y": 29,
      "z": 6,
      "name": "Plant_Leaves_Goldentree"
    },
    {
      "x": -2,
      "y": 30,
      "z": 6,
      "name": "Plant_Leaves_Goldentree"
    },
    {
      "x": -2,
      "y": 31,
      "z": 6,
      "name": "Plant_Leaves_Goldentree"
    },
    {
      "x": -2,
      "y": 22,
      "z": 7,
      "name": "Plant_Leaves_Goldentree"
    },
    {
      "x": -1,
      "y": 22,
      "z": -13,
      "name": "Plant_Leaves_Goldentree"
    },
    {
      "x": -1,
      "y": 23,
      "z": -13,
      "name": "Plant_Leaves_Goldentree"
    },
    {
      "x": -1,
      "y": 22,
      "z": -12,
      "name": "Plant_Leaves_Goldentree"
    },
    {
      "x": -1,
      "y": 23,
      "z": -12,
      "name": "Plant_Leaves_Goldentree"
    },
    {
      "x": -1,
      "y": 24,
      "z": -12,
      "name": "Plant_Leaves_Goldentree"
    },
    {
      "x": -1,
      "y": 15,
      "z": -11,
      "name": "Plant_Leaves_Goldentree"
    },
    {
      "x": -1,
      "y": 16,
      "z": -11,
      "name": "Plant_Leaves_Goldentree"
    },
    {
      "x": -1,
      "y": 22,
      "z": -11,
      "name": "Plant_Leaves_Goldentree"
    },
    {
      "x": -1,
      "y": 23,
      "z": -11,
      "name": "Plant_Leaves_Goldentree"
    },
    {
      "x": -1,
      "y": 24,
      "z": -11,
      "name": "Plant_Leaves_Goldentree"
    },
    {
      "x": -1,
      "y": 25,
      "z": -11,
      "name": "Plant_Leaves_Goldentree"
    },
    {
      "x": -1,
      "y": 16,
      "z": -10,
      "name": "Wood_Amber_Branch_Long",
      "rotation": 4
    },
    {
      "x": -1,
      "y": 17,
      "z": -10,
      "name": "Plant_Leaves_Goldentree"
    },
    {
      "x": -1,
      "y": 18,
      "z": -10,
      "name": "Plant_Leaves_Goldentree"
    },
    {
      "x": -1,
      "y": 22,
      "z": -10,
      "name": "Wood_Amber_Trunk_Full"
    },
    {
      "x": -1,
      "y": 23,
      "z": -10,
      "name": "Wood_Amber_Branch_Long",
      "rotation": 5
    },
    {
      "x": -1,
      "y": 24,
      "z": -10,
      "name": "Plant_Leaves_Goldentree"
    },
    {
      "x": -1,
      "y": 16,
      "z": -9,
      "name": "Wood_Amber_Trunk_Full"
    },
    {
      "x": -1,
      "y": 17,
      "z": -9,
      "name": "Plant_Leaves_Goldentree"
    },
    {
      "x": -1,
      "y": 18,
      "z": -9,
      "name": "Plant_Leaves_Goldentree"
    },
    {
      "x": -1,
      "y": 22,
      "z": -9,
      "name": "Wood_Amber_Trunk_Full"
    },
    {
      "x": -1,
      "y": 24,
      "z": -9,
      "name": "Plant_Leaves_Goldentree"
    },
    {
      "x": -1,
      "y": 25,
      "z": -9,
      "name": "Plant_Leaves_Goldentree"
    },
    {
      "x": -1,
      "y": 16,
      "z": -8,
      "name": "Wood_Amber_Trunk_Full"
    },
    {
      "x": -1,
      "y": 17,
      "z": -8,
      "name": "Wood_Amber_Branch_Long"
    },
    {
      "x": -1,
      "y": 18,
      "z": -8,
      "name": "Plant_Leaves_Goldentree"
    },
    {
      "x": -1,
      "y": 19,
      "z": -8,
      "name": "Plant_Leaves_Goldentree"
    },
    {
      "x": -1,
      "y": 22,
      "z": -8,
      "name": "Wood_Amber_Trunk_Full"
    },
    {
      "x": -1,
      "y": 23,
      "z": -8,
      "name": "Plant_Leaves_Goldentree"
    },
    {
      "x": -1,
      "y": 27,
      "z": -8,
      "name": "Plant_Leaves_Goldentree"
    },
    {
      "x": -1,
      "y": 28,
      "z": -8,
      "name": "Plant_Leaves_Goldentree"
    },
    {
      "x": -1,
      "y": 29,
      "z": -8,
      "name": "Plant_Leaves_Goldentree"
    },
    {
      "x": -1,
      "y": 15,
      "z": -7,
      "name": "Wood_Amber_Trunk_Full"
    },
    {
      "x": -1,
      "y": 16,
      "z": -7,
      "name": "Wood_Amber_Trunk_Full"
    },
    {
      "x": -1,
      "y": 17,
      "z": -7,
      "name": "Plant_Leaves_Goldentree"
    },
    {
      "x": -1,
      "y": 18,
      "z": -7,
      "name": "Plant_Leaves_Goldentree"
    },
    {
      "x": -1,
      "y": 21,
      "z": -7,
      "name": "Wood_Amber_Trunk_Full"
    },
    {
      "x": -1,
      "y": 22,
      "z": -7,
      "name": "Wood_Amber_Trunk_Full"
    },
    {
      "x": -1,
      "y": 28,
      "z": -7,
      "name": "Plant_Leaves_Goldentree"
    },
    {
      "x": -1,
      "y": 29,
      "z": -7,
      "name": "Plant_Leaves_Goldentree"
    },
    {
      "x": -1,
      "y": 15,
      "z": -6,
      "name": "Wood_Amber_Trunk_Full"
    },
    {
      "x": -1,
      "y": 16,
      "z": -6,
      "name": "Plant_Leaves_Goldentree"
    },
    {
      "x": -1,
      "y": 17,
      "z": -6,
      "name": "Plant_Leaves_Goldentree"
    },
    {
      "x": -1,
      "y": 21,
      "z": -6,
      "name": "Wood_Amber_Trunk_Full"
    },
    {
      "x": -1,
      "y": 27,
      "z": -6,
      "name": "Wood_Amber_Branch_Long",
      "rotation": 5
    },
    {
      "x": -1,
      "y": 28,
      "z": -6,
      "name": "Plant_Leaves_Goldentree"
    },
    {
      "x": -1,
      "y": 14,
      "z": -5,
      "name": "Wood_Amber_Trunk_Full"
    },
    {
      "x": -1,
      "y": 15,
      "z": -5,
      "name": "Wood_Amber_Trunk_Full"
    },
    {
      "x": -1,
      "y": 20,
      "z": -5,
      "name": "Wood_Amber_Trunk_Full"
    },
    {
      "x": -1,
      "y": 21,
      "z": -5,
      "name": "Wood_Amber_Trunk_Full"
    },
    {
      "x": -1,
      "y": 22,
      "z": -5,
      "name": "Wood_Amber_Trunk_Full"
    },
    {
      "x": -1,
      "y": 28,
      "z": -5,
      "name": "Plant_Leaves_Goldentree"
    },
    {
      "x": -1,
      "y": 29,
      "z": -5,
      "name": "Plant_Leaves_Goldentree"
    },
    {
      "x": -1,
      "y": 13,
      "z": -4,
      "name": "Wood_Amber_Trunk_Full"
    },
    {
      "x": -1,
      "y": 14,
      "z": -4,
      "name": "Wood_Amber_Trunk_Full"
    },
    {
      "x": -1,
      "y": 15,
      "z": -4,
      "name": "Wood_Amber_Trunk_Full"
    },
    {
      "x": -1,
      "y": 20,
      "z": -4,
      "name": "Wood_Amber_Trunk_Full"
    },
    {
      "x": -1,
      "y": 21,
      "z": -4,
      "name": "Wood_Amber_Trunk_Full"
    },
    {
      "x": -1,
      "y": 0,
      "z": -3,
      "name": "Wood_Amber_Trunk"
    },
    {
      "x": -1,
      "y": 1,
      "z": -3,
      "name": "Wood_Amber_Trunk"
    },
    {
      "x": -1,
      "y": 2,
      "z": -3,
      "name": "Wood_Amber_Trunk_Full"
    },
    {
      "x": -1,
      "y": 13,
      "z": -3,
      "name": "Wood_Amber_Trunk_Full"
    },
    {
      "x": -1,
      "y": 14,
      "z": -3,
      "name": "Wood_Amber_Trunk_Full"
    },
    {
      "x": -1,
      "y": 0,
      "z": -2,
      "name": "Wood_Amber_Trunk"
    },
    {
      "x": -1,
      "y": 1,
      "z": -2,
      "name": "Wood_Amber_Trunk"
    },
    {
      "x": -1,
      "y": 2,
      "z": -2,
      "name": "Wood_Amber_Trunk"
    },
    {
      "x": -1,
      "y": 3,
      "z": -2,
      "name": "Wood_Amber_Trunk"
    },
    {
      "x": -1,
      "y": 4,
      "z": -2,
      "name": "Wood_Amber_Trunk"
    },
    {
      "x": -1,
      "y": 5,
      "z": -2,
      "name": "Wood_Amber_Trunk_Full"
    },
    {
      "x": -1,
      "y": 12,
      "z": -2,
      "name": "Wood_Amber_Trunk_Full"
    },
    {
      "x": -1,
      "y": 13,
      "z": -2,
      "name": "Wood_Amber_Trunk_Full"
    },
    {
      "x": -1,
      "y": 14,
      "z": -2,
      "name": "Wood_Amber_Trunk_Full"
    },
    {
      "x": -1,
      "y": 1,
      "z": -1,
      "name": "Wood_Amber_Trunk"
    },
    {
      "x": -1,
      "y": 2,
      "z": -1,
      "name": "Wood_Amber_Trunk"
    },
    {
      "x": -1,
      "y": 3,
      "z": -1,
      "name": "Wood_Amber_Trunk"
    },
    {
      "x": -1,
      "y": 4,
      "z": -1,
      "name": "Wood_Amber_Trunk"
    },
    {
      "x": -1,
      "y": 5,
      "z": -1,
      "name": "Wood_Amber_Trunk"
    },
    {
      "x": -1,
      "y": 6,
      "z": -1,
      "name": "Wood_Amber_Trunk"
    },
    {
      "x": -1,
      "y": 7,
      "z": -1,
      "name": "Wood_Amber_Trunk_Full"
    },
    {
      "x": -1,
      "y": 9,
      "z": -1,
      "name": "Wood_Amber_Trunk_Full"
    },
    {
      "x": -1,
      "y": 10,
      "z": -1,
      "name": "Wood_Amber_Trunk"
    },
    {
      "x": -1,
      "y": 11,
      "z": -1,
      "name": "Wood_Amber_Trunk"
    },
    {
      "x": -1,
      "y": 12,
      "z": -1,
      "name": "Wood_Amber_Trunk"
    },
    {
      "x": -1,
      "y": 13,
      "z": -1,
      "name": "Wood_Amber_Trunk"
    },
    {
      "x": -1,
      "y": 14,
      "z": -1,
      "name": "Wood_Amber_Trunk"
    },
    {
      "x": -1,
      "y": 15,
      "z": -1,
      "name": "Wood_Amber_Trunk"
    },
    {
      "x": -1,
      "y": 16,
      "z": -1,
      "name": "Wood_Amber_Trunk"
    },
    {
      "x": -1,
      "y": 17,
      "z": -1,
      "name": "Wood_Amber_Trunk"
    },
    {
      "x": -1,
      "y": 18,
      "z": -1,
      "name": "Wood_Amber_Trunk_Full"
    },
    {
      "x": -1,
      "y": 19,
      "z": -1,
      "name": "Wood_Amber_Trunk_Full"
    },
    {
      "x": -1,
      "y": 20,
      "z": -1,
      "name": "Wood_Amber_Trunk_Full"
    },
    {
      "x": -1,
      "y": 27,
      "z": -1,
      "name": "Wood_Amber_Trunk_Full"
    },
    {
      "x": -1,
      "y": 7,
      "z": 0,
      "name": "Wood_Amber_Trunk_Full"
    },
    {
      "x": -1,
      "y": 8,
      "z": 0,
      "name": "Wood_Amber_Trunk"
    },
    {
      "x": -1,
      "y": 9,
      "z": 0,
      "name": "Wood_Amber_Trunk"
    },
    {
      "x": -1,
      "y": 10,
      "z": 0,
      "name": "Wood_Amber_Trunk"
    },
    {
      "x": -1,
      "y": 11,
      "z": 0,
      "name": "Wood_Amber_Trunk"
    },
    {
      "x": -1,
      "y": 12,
      "z": 0,
      "name": "Wood_Amber_Trunk"
    },
    {
      "x": -1,
      "y": 13,
      "z": 0,
      "name": "Wood_Amber_Trunk"
    },
    {
      "x": -1,
      "y": 14,
      "z": 0,
      "name": "Wood_Amber_Trunk"
    },
    {
      "x": -1,
      "y": 15,
      "z": 0,
      "name": "Wood_Amber_Trunk_Full"
    },
    {
      "x": -1,
      "y": 19,
      "z": 0,
      "name": "Wood_Amber_Trunk_Full"
    },
    {
      "x": -1,
      "y": 20,
      "z": 0,
      "name": "Wood_Amber_Trunk_Full"
    },
    {
      "x": -1,
      "y": 27,
      "z": 0,
      "name": "Wood_Amber_Trunk_Full"
    },
    {
      "x": -1,
      "y": 2,
      "z": 1,
      "name": "Wood_Amber_Trunk"
    },
    {
      "x": -1,
      "y": 3,
      "z": 1,
      "name": "Wood_Amber_Trunk"
    },
    {
      "x": -1,
      "y": 4,
      "z": 1,
      "name": "Wood_Amber_Trunk"
    },
    {
      "x": -1,
      "y": 5,
      "z": 1,
      "name": "Wood_Amber_Trunk"
    },
    {
      "x": -1,
      "y": 6,
      "z": 1,
      "name": "Wood_Amber_Trunk"
    },
    {
      "x": -1,
      "y": 7,
      "z": 1,
      "name": "Wood_Amber_Trunk"
    },
    {
      "x": -1,
      "y": 8,
      "z": 1,
      "name": "Wood_Amber_Trunk"
    },
    {
      "x": -1,
      "y": 9,
      "z": 1,
      "name": "Wood_Amber_Trunk_Full"
    },
    {
      "x": -1,
      "y": 27,
      "z": 1,
      "name": "Wood_Amber_Trunk_Full"
    },
    {
      "x": -1,
      "y": 28,
      "z": 1,
      "name": "Wood_Amber_Trunk_Full"
    },
    {
      "x": -1,
      "y": 29,
      "z": 1,
      "name": "Plant_Leaves_Goldentree"
    },
    {
      "x": -1,
      "y": 30,
      "z": 1,
      "name": "Plant_Leaves_Goldentree"
    },
    {
      "x": -1,
      "y": 1,
      "z": 2,
      "name": "Wood_Amber_Trunk"
    },
    {
      "x": -1,
      "y": 2,
      "z": 2,
      "name": "Wood_Amber_Trunk"
    },
    {
      "x": -1,
      "y": 3,
      "z": 2,
      "name": "Wood_Amber_Trunk"
    },
    {
      "x": -1,
      "y": 4,
      "z": 2,
      "name": "Wood_Amber_Trunk"
    },
    {
      "x": -1,
      "y": 5,
      "z": 2,
      "name": "Wood_Amber_Trunk"
    },
    {
      "x": -1,
      "y": 6,
      "z": 2,
      "name": "Wood_Amber_Trunk"
    },
    {
      "x": -1,
      "y": 7,
      "z": 2,
      "name": "Wood_Amber_Trunk_Full"
    },
    {
      "x": -1,
      "y": 28,
      "z": 2,
      "name": "Wood_Amber_Trunk_Full"
    },
    {
      "x": -1,
      "y": 29,
      "z": 2,
      "name": "Plant_Leaves_Goldentree"
    },
    {
      "x": -1,
      "y": 30,
      "z": 2,
      "name": "Plant_Leaves_Goldentree"
    },
    {
      "x": -1,
      "y": 31,
      "z": 2,
      "name": "Plant_Leaves_Goldentree"
    },
    {
      "x": -1,
      "y": 28,
      "z": 3,
      "name": "Wood_Amber_Trunk_Full"
    },
    {
      "x": -1,
      "y": 29,
      "z": 3,
      "name": "Wood_Amber_Trunk_Full"
    },
    {
      "x": -1,
      "y": 30,
      "z": 3,
      "name": "Wood_Amber_Branch_Long"
    },
    {
      "x": -1,
      "y": 31,
      "z": 3,
      "name": "Plant_Leaves_Goldentree"
    },
    {
      "x": -1,
      "y": 29,
      "z": 4,
      "name": "Wood_Amber_Branch_Long",
      "rotation": 4
    },
    {
      "x": -1,
      "y": 31,
      "z": 4,
      "name": "Plant_Leaves_Goldentree"
    },
    {
      "x": -1,
      "y": 32,
      "z": 4,
      "name": "Plant_Leaves_Goldentree"
    },
    {
      "x": -1,
      "y": 29,
      "z": 5,
      "name": "Wood_Amber_Branch_Long",
      "rotation": 4
    },
    {
      "x": -1,
      "y": 30,
      "z": 5,
      "name": "Plant_Leaves_Goldentree"
    },
    {
      "x": -1,
      "y": 31,
      "z": 5,
      "name": "Plant_Leaves_Goldentree"
    },
    {
      "x": -1,
      "y": 29,
      "z": 6,
      "name": "Plant_Leaves_Goldentree"
    },
    {
      "x": -1,
      "y": 30,
      "z": 6,
      "name": "Plant_Leaves_Goldentree"
    },
    {
      "x": 0,
      "y": 22,
      "z": -12,
      "name": "Plant_Leaves_Goldentree"
    },
    {
      "x": 0,
      "y": 23,
      "z": -12,
      "name": "Plant_Leaves_Goldentree"
    },
    {
      "x": 0,
      "y": 15,
      "z": -11,
      "name": "Plant_Leaves_Goldentree"
    },
    {
      "x": 0,
      "y": 16,
      "z": -11,
      "name": "Plant_Leaves_Goldentree"
    },
    {
      "x": 0,
      "y": 24,
      "z": -11,
      "name": "Plant_Leaves_Goldentree"
    },
    {
      "x": 0,
      "y": 25,
      "z": -11,
      "name": "Plant_Leaves_Goldentree"
    },
    {
      "x": 0,
      "y": 14,
      "z": -10,
      "name": "Plant_Leaves_Goldentree"
    },
    {
      "x": 0,
      "y": 15,
      "z": -10,
      "name": "Plant_Leaves_Goldentree"
    },
    {
      "x": 0,
      "y": 16,
      "z": -10,
      "name": "Plant_Leaves_Goldentree"
    },
    {
      "x": 0,
      "y": 17,
      "z": -10,
      "name": "Plant_Leaves_Goldentree"
    },
    {
      "x": 0,
      "y": 22,
      "z": -10,
      "name": "Plant_Leaves_Goldentree"
    },
    {
      "x": 0,
      "y": 23,
      "z": -10,
      "name": "Wood_Amber_Branch_Long",
      "rotation": 5
    },
    {
      "x": 0,
      "y": 24,
      "z": -10,
      "name": "Plant_Leaves_Goldentree"
    },
    {
      "x": 0,
      "y": 25,
      "z": -10,
      "name": "Plant_Leaves_Goldentree"
    },
    {
      "x": 0,
      "y": 15,
      "z": -9,
      "name": "Plant_Leaves_Goldentree"
    },
    {
      "x": 0,
      "y": 17,
      "z": -9,
      "name": "Plant_Leaves_Goldentree"
    },
    {
      "x": 0,
      "y": 18,
      "z": -9,
      "name": "Plant_Leaves_Goldentree"
    },
    {
      "x": 0,
      "y": 23,
      "z": -9,
      "name": "Plant_Leaves_Goldentree"
    },
    {
      "x": 0,
      "y": 24,
      "z": -9,
      "name": "Plant_Leaves_Goldentree"
    },
    {
      "x": 0,
      "y": 27,
      "z": -9,
      "name": "Plant_Leaves_Goldentree"
    },
    {
      "x": 0,
      "y": 28,
      "z": -9,
      "name": "Plant_Leaves_Goldentree"
    },
    {
      "x": 0,
      "y": 16,
      "z": -8,
      "name": "Wood_Amber_Branch_Long",
      "rotation": 5
    },
    {
      "x": 0,
      "y": 17,
      "z": -8,
      "name": "Plant_Leaves_Goldentree"
    },
    {
      "x": 0,
      "y": 23,
      "z": -8,
      "name": "Plant_Leaves_Goldentree"
    },
    {
      "x": 0,
      "y": 27,
      "z": -8,
      "name": "Wood_Amber_Branch_Long",
      "rotation": 4
    },
    {
      "x": 0,
      "y": 28,
      "z": -8,
      "name": "Plant_Leaves_Goldentree"
    },
    {
      "x": 0,
      "y": 16,
      "z": -7,
      "name": "Plant_Leaves_Goldentree"
    },
    {
      "x": 0,
      "y": 17,
      "z": -7,
      "name": "Plant_Leaves_Goldentree"
    },
    {
      "x": 0,
      "y": 27,
      "z": -7,
      "name": "Wood_Amber_Branch_Long",
      "rotation": 4
    },
    {
      "x": 0,
      "y": 28,
      "z": -7,
      "name": "Plant_Leaves_Goldentree"
    },
    {
      "x": 0,
      "y": 16,
      "z": -6,
      "name": "Plant_Leaves_Goldentree"
    },
    {
      "x": 0,
      "y": 17,
      "z": -6,
      "name": "Plant_Leaves_Goldentree"
    },
    {
      "x": 0,
      "y": 18,
      "z": -6,
      "name": "Plant_Leaves_Goldentree"
    },
    {
      "x": 0,
      "y": 27,
      "z": -6,
      "name": "Wood_Amber_Trunk_Full"
    },
    {
      "x": 0,
      "y": 28,
      "z": -6,
      "name": "Wood_Amber_Branch_Long"
    },
    {
      "x": 0,
      "y": 29,
      "z": -6,
      "name": "Plant_Leaves_Goldentree"
    },
    {
      "x": 0,
      "y": 30,
      "z": -6,
      "name": "Plant_Leaves_Goldentree"
    },
    {
      "x": 0,
      "y": 27,
      "z": -5,
      "name": "Wood_Amber_Trunk_Full"
    },
    {
      "x": 0,
      "y": 28,
      "z": -5,
      "name": "Plant_Leaves_Goldentree"
    },
    {
      "x": 0,
      "y": 19,
      "z": -4,
      "name": "Wood_Amber_Trunk_Full"
    },
    {
      "x": 0,
      "y": 20,
      "z": -4,
      "name": "Wood_Amber_Trunk_Full"
    },
    {
      "x": 0,
      "y": 21,
      "z": -4,
      "name": "Wood_Amber_Trunk_Full"
    },
    {
      "x": 0,
      "y": 25,
      "z": -4,
      "name": "Wood_Amber_Trunk_Full"
    },
    {
      "x": 0,
      "y": 26,
      "z": -4,
      "name": "Wood_Amber_Trunk_Full"
    },
    {
      "x": 0,
      "y": 27,
      "z": -4,
      "name": "Wood_Amber_Trunk_Full"
    },
    {
      "x": 0,
      "y": 18,
      "z": -3,
      "name": "Wood_Amber_Trunk_Full"
    },
    {
      "x": 0,
      "y": 19,
      "z": -3,
      "name": "Wood_Amber_Trunk_Full"
    },
    {
      "x": 0,
      "y": 20,
      "z": -3,
      "name": "Wood_Amber_Trunk_Full"
    },
    {
      "x": 0,
      "y": 24,
      "z": -3,
      "name": "Wood_Amber_Trunk_Full"
    },
    {
      "x": 0,
      "y": 25,
      "z": -3,
      "name": "Wood_Amber_Trunk_Full"
    },
    {
      "x": 0,
      "y": 26,
      "z": -3,
      "name": "Wood_Amber_Trunk_Full"
    },
    {
      "x": 0,
      "y": 1,
      "z": -2,
      "name": "Wood_Amber_Trunk"
    },
    {
      "x": 0,
      "y": 2,
      "z": -2,
      "name": "Wood_Amber_Trunk"
    },
    {
      "x": 0,
      "y": 3,
      "z": -2,
      "name": "Wood_Amber_Trunk"
    },
    {
      "x": 0,
      "y": 4,
      "z": -2,
      "name": "Wood_Amber_Trunk_Full"
    },
    {
      "x": 0,
      "y": 11,
      "z": -2,
      "name": "Wood_Amber_Trunk_Full"
    },
    {
      "x": 0,
      "y": 12,
      "z": -2,
      "name": "Wood_Amber_Trunk"
    },
    {
      "x": 0,
      "y": 13,
      "z": -2,
      "name": "Wood_Amber_Trunk"
    },
    {
      "x": 0,
      "y": 14,
      "z": -2,
      "name": "Wood_Amber_Trunk"
    },
    {
      "x": 0,
      "y": 15,
      "z": -2,
      "name": "Wood_Amber_Trunk"
    },
    {
      "x": 0,
      "y": 16,
      "z": -2,
      "name": "Wood_Amber_Trunk"
    },
    {
      "x": 0,
      "y": 17,
      "z": -2,
      "name": "Wood_Amber_Trunk"
    },
    {
      "x": 0,
      "y": 18,
      "z": -2,
      "name": "Wood_Amber_Trunk"
    },
    {
      "x": 0,
      "y": 19,
      "z": -2,
      "name": "Wood_Amber_Trunk"
    },
    {
      "x": 0,
      "y": 20,
      "z": -2,
      "name": "Wood_Amber_Trunk_Full"
    },
    {
      "x": 0,
      "y": 21,
      "z": -2,
      "name": "Wood_Amber_Trunk"
    },
    {
      "x": 0,
      "y": 22,
      "z": -2,
      "name": "Wood_Amber_Trunk"
    },
    {
      "x": 0,
      "y": 23,
      "z": -2,
      "name": "Wood_Amber_Trunk"
    },
    {
      "x": 0,
      "y": 24,
      "z": -2,
      "name": "Wood_Amber_Trunk"
    },
    {
      "x": 0,
      "y": 25,
      "z": -2,
      "name": "Wood_Amber_Trunk_Full"
    },
    {
      "x": 0,
      "y": 2,
      "z": -1,
      "name": "Wood_Amber_Trunk"
    },
    {
      "x": 0,
      "y": 3,
      "z": -1,
      "name": "Wood_Amber_Trunk"
    },
    {
      "x": 0,
      "y": 4,
      "z": -1,
      "name": "Wood_Amber_Trunk"
    },
    {
      "x": 0,
      "y": 5,
      "z": -1,
      "name": "Wood_Amber_Trunk"
    },
    {
      "x": 0,
      "y": 6,
      "z": -1,
      "name": "Wood_Amber_Trunk"
    },
    {
      "x": 0,
      "y": 7,
      "z": -1,
      "name": "Wood_Amber_Trunk"
    },
    {
      "x": 0,
      "y": 8,
      "z": -1,
      "name": "Wood_Amber_Trunk"
    },
    {
      "x": 0,
      "y": 9,
      "z": -1,
      "name": "Wood_Amber_Trunk"
    },
    {
      "x": 0,
      "y": 10,
      "z": -1,
      "name": "Wood_Amber_Trunk"
    },
    {
      "x": 0,
      "y": 11,
      "z": -1,
      "name": "Wood_Amber_Trunk"
    },
    {
      "x": 0,
      "y": 12,
      "z": -1,
      "name": "Wood_Amber_Trunk"
    },
    {
      "x": 0,
      "y": 13,
      "z": -1,
      "name": "Wood_Amber_Trunk"
    },
    {
      "x": 0,
      "y": 14,
      "z": -1,
      "name": "Wood_Amber_Trunk"
    },
    {
      "x": 0,
      "y": 15,
      "z": -1,
      "name": "Wood_Amber_Trunk"
    },
    {
      "x": 0,
      "y": 16,
      "z": -1,
      "name": "Wood_Amber_Trunk"
    },
    {
      "x": 0,
      "y": 17,
      "z": -1,
      "name": "Wood_Amber_Trunk"
    },
    {
      "x": 0,
      "y": 18,
      "z": -1,
      "name": "Wood_Amber_Trunk"
    },
    {
      "x": 0,
      "y": 19,
      "z": -1,
      "name": "Wood_Amber_Trunk"
    },
    {
      "x": 0,
      "y": 20,
      "z": -1,
      "name": "Wood_Amber_Trunk_Full"
    },
    {
      "x": 0,
      "y": 25,
      "z": -1,
      "name": "Wood_Amber_Trunk_Full"
    },
    {
      "x": 0,
      "y": 26,
      "z": -1,
      "name": "Wood_Amber_Trunk_Full"
    },
    {
      "x": 0,
      "y": 27,
      "z": -1,
      "name": "Wood_Amber_Trunk_Full"
    },
    {
      "x": 0,
      "y": 4,
      "z": 0,
      "name": "Wood_Amber_Trunk"
    },
    {
      "x": 0,
      "y": 5,
      "z": 0,
      "name": "Wood_Amber_Trunk"
    },
    {
      "x": 0,
      "y": 6,
      "z": 0,
      "name": "Wood_Amber_Trunk"
    },
    {
      "x": 0,
      "y": 7,
      "z": 0,
      "name": "Wood_Amber_Trunk"
    },
    {
      "x": 0,
      "y": 8,
      "z": 0,
      "name": "Wood_Amber_Trunk"
    },
    {
      "x": 0,
      "y": 9,
      "z": 0,
      "name": "Wood_Amber_Trunk"
    },
    {
      "x": 0,
      "y": 10,
      "z": 0,
      "name": "Wood_Amber_Trunk"
    },
    {
      "x": 0,
      "y": 11,
      "z": 0,
      "name": "Wood_Amber_Trunk"
    },
    {
      "x": 0,
      "y": 12,
      "z": 0,
      "name": "Wood_Amber_Trunk"
    },
    {
      "x": 0,
      "y": 13,
      "z": 0,
      "name": "Wood_Amber_Trunk"
    },
    {
      "x": 0,
      "y": 14,
      "z": 0,
      "name": "Wood_Amber_Trunk"
    },
    {
      "x": 0,
      "y": 15,
      "z": 0,
      "name": "Wood_Amber_Trunk"
    },
    {
      "x": 0,
      "y": 16,
      "z": 0,
      "name": "Wood_Amber_Trunk"
    },
    {
      "x": 0,
      "y": 17,
      "z": 0,
      "name": "Wood_Amber_Trunk_Full"
    },
    {
      "x": 0,
      "y": 3,
      "z": 1,
      "name": "Wood_Amber_Trunk"
    },
    {
      "x": 0,
      "y": 4,
      "z": 1,
      "name": "Wood_Amber_Trunk"
    },
    {
      "x": 0,
      "y": 5,
      "z": 1,
      "name": "Wood_Amber_Trunk"
    },
    {
      "x": 0,
      "y": 6,
      "z": 1,
      "name": "Wood_Amber_Trunk"
    },
    {
      "x": 0,
      "y": 7,
      "z": 1,
      "name": "Wood_Amber_Trunk"
    },
    {
      "x": 0,
      "y": 8,
      "z": 1,
      "name": "Wood_Amber_Trunk"
    },
    {
      "x": 0,
      "y": 9,
      "z": 1,
      "name": "Wood_Amber_Trunk"
    },
    {
      "x": 0,
      "y": 10,
      "z": 1,
      "name": "Wood_Amber_Trunk"
    },
    {
      "x": 0,
      "y": 11,
      "z": 1,
      "name": "Wood_Amber_Trunk"
    },
    {
      "x": 0,
      "y": 12,
      "z": 1,
      "name": "Wood_Amber_Trunk"
    },
    {
      "x": 0,
      "y": 13,
      "z": 1,
      "name": "Wood_Amber_Trunk_Full"
    },
    {
      "x": 0,
      "y": 16,
      "z": 1,
      "name": "Wood_Amber_Trunk_Full"
    },
    {
      "x": 0,
      "y": 17,
      "z": 1,
      "name": "Wood_Amber_Trunk_Full"
    },
    {
      "x": 0,
      "y": 29,
      "z": 1,
      "name": "Plant_Leaves_Goldentree"
    },
    {
      "x": 0,
      "y": 30,
      "z": 1,
      "name": "Plant_Leaves_Goldentree"
    },
    {
      "x": 0,
      "y": 3,
      "z": 2,
      "name": "Wood_Amber_Trunk"
    },
    {
      "x": 0,
      "y": 4,
      "z": 2,
      "name": "Wood_Amber_Trunk"
    },
    {
      "x": 0,
      "y": 5,
      "z": 2,
      "name": "Wood_Amber_Trunk_Full"
    },
    {
      "x": 0,
      "y": 29,
      "z": 2,
      "name": "Plant_Leaves_Goldentree"
    },
    {
      "x": 0,
      "y": 30,
      "z": 2,
      "name": "Plant_Leaves_Goldentree"
    },
    {
      "x": 0,
      "y": 31,
      "z": 2,
      "name": "Plant_Leaves_Goldentree"
    },
    {
      "x": 0,
      "y": 29,
      "z": 3,
      "name": "Wood_Amber_Branch_Long",
      "rotation": 5
    },
    {
      "x": 0,
      "y": 30,
      "z": 3,
      "name": "Plant_Leaves_Goldentree"
    },
    {
      "x": 0,
      "y": 29,
      "z": 5,
      "name": "Plant_Leaves_Goldentree"
    },
    {
      "x": 0,
      "y": 30,
      "z": 5,
      "name": "Plant_Leaves_Goldentree"
    },
    {
      "x": 0,
      "y": 28,
      "z": 6,
      "name": "Plant_Leaves_Goldentree"
    },
    {
      "x": 0,
      "y": 29,
      "z": 6,
      "name": "Plant_Leaves_Goldentree"
    },
    {
      "x": 0,
      "y": 30,
      "z": 6,
      "name": "Plant_Leaves_Goldentree"
    },
    {
      "x": 0,
      "y": 19,
      "z": 9,
      "name": "Plant_Leaves_Goldentree"
    },
    {
      "x": 0,
      "y": 20,
      "z": 9,
      "name": "Plant_Leaves_Goldentree"
    },
    {
      "x": 0,
      "y": 19,
      "z": 10,
      "name": "Plant_Leaves_Goldentree"
    },
    {
      "x": 0,
      "y": 20,
      "z": 10,
      "name": "Plant_Leaves_Goldentree"
    },
    {
      "x": 1,
      "y": 22,
      "z": -11,
      "name": "Plant_Leaves_Goldentree"
    },
    {
      "x": 1,
      "y": 23,
      "z": -11,
      "name": "Plant_Leaves_Goldentree"
    },
    {
      "x": 1,
      "y": 16,
      "z": -10,
      "name": "Plant_Leaves_Goldentree"
    },
    {
      "x": 1,
      "y": 17,
      "z": -10,
      "name": "Plant_Leaves_Goldentree"
    },
    {
      "x": 1,
      "y": 22,
      "z": -10,
      "name": "Plant_Leaves_Goldentree"
    },
    {
      "x": 1,
      "y": 23,
      "z": -10,
      "name": "Plant_Leaves_Goldentree"
    },
    {
      "x": 1,
      "y": 15,
      "z": -9,
      "name": "Plant_Leaves_Goldentree"
    },
    {
      "x": 1,
      "y": 16,
      "z": -9,
      "name": "Plant_Leaves_Goldentree"
    },
    {
      "x": 1,
      "y": 17,
      "z": -9,
      "name": "Plant_Leaves_Goldentree"
    },
    {
      "x": 1,
      "y": 16,
      "z": -8,
      "name": "Wood_Amber_Branch_Long",
      "rotation": 5
    },
    {
      "x": 1,
      "y": 17,
      "z": -8,
      "name": "Plant_Leaves_Goldentree"
    },
    {
      "x": 1,
      "y": 27,
      "z": -8,
      "name": "Plant_Leaves_Goldentree"
    },
    {
      "x": 1,
      "y": 28,
      "z": -8,
      "name": "Plant_Leaves_Goldentree"
    },
    {
      "x": 1,
      "y": 16,
      "z": -7,
      "name": "Plant_Leaves_Goldentree"
    },
    {
      "x": 1,
      "y": 28,
      "z": -7,
      "name": "Plant_Leaves_Goldentree"
    },
    {
      "x": 1,
      "y": 28,
      "z": -6,
      "name": "Plant_Leaves_Goldentree"
    },
    {
      "x": 1,
      "y": 29,
      "z": -6,
      "name": "Plant_Leaves_Goldentree"
    },
    {
      "x": 1,
      "y": 28,
      "z": -5,
      "name": "Plant_Leaves_Goldentree"
    },
    {
      "x": 1,
      "y": 28,
      "z": -4,
      "name": "Plant_Leaves_Goldentree"
    },
    {
      "x": 1,
      "y": 15,
      "z": -3,
      "name": "Wood_Amber_Trunk_Full"
    },
    {
      "x": 1,
      "y": 16,
      "z": -3,
      "name": "Wood_Amber_Trunk_Full"
    },
    {
      "x": 1,
      "y": 14,
      "z": -2,
      "name": "Wood_Amber_Trunk_Full"
    },
    {
      "x": 1,
      "y": 15,
      "z": -2,
      "name": "Wood_Amber_Trunk_Full"
    },
    {
      "x": 1,
      "y": 16,
      "z": -2,
      "name": "Wood_Amber_Trunk_Full"
    },
    {
      "x": 1,
      "y": 30,
      "z": -2,
      "name": "Plant_Leaves_Goldentree"
    },
    {
      "x": 1,
      "y": 9,
      "z": -1,
      "name": "Wood_Amber_Trunk_Full"
    },
    {
      "x": 1,
      "y": 10,
      "z": -1,
      "name": "Wood_Amber_Trunk"
    },
    {
      "x": 1,
      "y": 11,
      "z": -1,
      "name": "Wood_Amber_Trunk"
    },
    {
      "x": 1,
      "y": 12,
      "z": -1,
      "name": "Wood_Amber_Trunk"
    },
    {
      "x": 1,
      "y": 13,
      "z": -1,
      "name": "Wood_Amber_Trunk"
    },
    {
      "x": 1,
      "y": 14,
      "z": -1,
      "name": "Wood_Amber_Trunk"
    },
    {
      "x": 1,
      "y": 15,
      "z": -1,
      "name": "Wood_Amber_Trunk"
    },
    {
      "x": 1,
      "y": 16,
      "z": -1,
      "name": "Wood_Amber_Trunk_Full"
    },
    {
      "x": 1,
      "y": 20,
      "z": -1,
      "name": "Wood_Amber_Trunk_Full"
    },
    {
      "x": 1,
      "y": 21,
      "z": -1,
      "name": "Wood_Amber_Trunk_Full"
    },
    {
      "x": 1,
      "y": 22,
      "z": -1,
      "name": "Wood_Amber_Trunk_Full"
    },
    {
      "x": 1,
      "y": 27,
      "z": -1,
      "name": "Wood_Amber_Trunk_Full"
    },
    {
      "x": 1,
      "y": 28,
      "z": -1,
      "name": "Wood_Amber_Trunk_Full"
    },
    {
      "x": 1,
      "y": 3,
      "z": 0,
      "name": "Wood_Amber_Trunk"
    },
    {
      "x": 1,
      "y": 4,
      "z": 0,
      "name": "Wood_Amber_Trunk"
    },
    {
      "x": 1,
      "y": 5,
      "z": 0,
      "name": "Wood_Amber_Trunk"
    },
    {
      "x": 1,
      "y": 6,
      "z": 0,
      "name": "Wood_Amber_Trunk"
    },
    {
      "x": 1,
      "y": 7,
      "z": 0,
      "name": "Wood_Amber_Trunk"
    },
    {
      "x": 1,
      "y": 8,
      "z": 0,
      "name": "Wood_Amber_Trunk"
    },
    {
      "x": 1,
      "y": 9,
      "z": 0,
      "name": "Wood_Amber_Trunk"
    },
    {
      "x": 1,
      "y": 10,
      "z": 0,
      "name": "Wood_Amber_Trunk"
    },
    {
      "x": 1,
      "y": 11,
      "z": 0,
      "name": "Wood_Amber_Trunk"
    },
    {
      "x": 1,
      "y": 12,
      "z": 0,
      "name": "Wood_Amber_Trunk"
    },
    {
      "x": 1,
      "y": 13,
      "z": 0,
      "name": "Wood_Amber_Trunk"
    },
    {
      "x": 1,
      "y": 14,
      "z": 0,
      "name": "Wood_Amber_Trunk_Full"
    },
    {
      "x": 1,
      "y": 4,
      "z": 1,
      "name": "Wood_Amber_Trunk"
    },
    {
      "x": 1,
      "y": 5,
      "z": 1,
      "name": "Wood_Amber_Trunk"
    },
    {
      "x": 1,
      "y": 6,
      "z": 1,
      "name": "Wood_Amber_Trunk"
    },
    {
      "x": 1,
      "y": 7,
      "z": 1,
      "name": "Wood_Amber_Trunk"
    },
    {
      "x": 1,
      "y": 8,
      "z": 1,
      "name": "Wood_Amber_Trunk"
    },
    {
      "x": 1,
      "y": 9,
      "z": 1,
      "name": "Wood_Amber_Trunk"
    },
    {
      "x": 1,
      "y": 10,
      "z": 1,
      "name": "Wood_Amber_Trunk_Full"
    },
    {
      "x": 1,
      "y": 16,
      "z": 1,
      "name": "Wood_Amber_Trunk_Full"
    },
    {
      "x": 1,
      "y": 17,
      "z": 1,
      "name": "Wood_Amber_Trunk_Full"
    },
    {
      "x": 1,
      "y": 18,
      "z": 1,
      "name": "Wood_Amber_Trunk_Full"
    },
    {
      "x": 1,
      "y": 29,
      "z": 1,
      "name": "Plant_Leaves_Goldentree"
    },
    {
      "x": 1,
      "y": 17,
      "z": 2,
      "name": "Wood_Amber_Trunk_Full"
    },
    {
      "x": 1,
      "y": 18,
      "z": 2,
      "name": "Wood_Amber_Trunk_Full"
    },
    {
      "x": 1,
      "y": 29,
      "z": 2,
      "name": "Plant_Leaves_Goldentree"
    },
    {
      "x": 1,
      "y": 30,
      "z": 2,
      "name": "Plant_Leaves_Goldentree"
    },
    {
      "x": 1,
      "y": 18,
      "z": 3,
      "name": "Wood_Amber_Trunk_Full"
    },
    {
      "x": 1,
      "y": 19,
      "z": 3,
      "name": "Wood_Amber_Trunk_Full"
    },
    {
      "x": 1,
      "y": 29,
      "z": 3,
      "name": "Wood_Amber_Branch_Long",
      "rotation": 5
    },
    {
      "x": 1,
      "y": 30,
      "z": 3,
      "name": "Plant_Leaves_Goldentree"
    },
    {
      "x": 1,
      "y": 30,
      "z": 4,
      "name": "Plant_Leaves_Goldentree"
    },
    {
      "x": 1,
      "y": 31,
      "z": 4,
      "name": "Plant_Leaves_Goldentree"
    },
    {
      "x": 1,
      "y": 29,
      "z": 5,
      "name": "Plant_Leaves_Goldentree"
    },
    {
      "x": 1,
      "y": 30,
      "z": 5,
      "name": "Plant_Leaves_Goldentree"
    },
    {
      "x": 1,
      "y": 31,
      "z": 5,
      "name": "Plant_Leaves_Goldentree"
    },
    {
      "x": 1,
      "y": 20,
      "z": 6,
      "name": "Plant_Leaves_Goldentree"
    },
    {
      "x": 1,
      "y": 28,
      "z": 6,
      "name": "Plant_Leaves_Goldentree"
    },
    {
      "x": 1,
      "y": 29,
      "z": 6,
      "name": "Plant_Leaves_Goldentree"
    },
    {
      "x": 1,
      "y": 21,
      "z": 7,
      "name": "Plant_Leaves_Goldentree"
    },
    {
      "x": 1,
      "y": 20,
      "z": 8,
      "name": "Plant_Leaves_Goldentree"
    },
    {
      "x": 1,
      "y": 21,
      "z": 8,
      "name": "Plant_Leaves_Goldentree"
    },
    {
      "x": 1,
      "y": 22,
      "z": 8,
      "name": "Plant_Leaves_Goldentree"
    },
    {
      "x": 1,
      "y": 21,
      "z": 9,
      "name": "Plant_Leaves_Goldentree"
    },
    {
      "x": 1,
      "y": 18,
      "z": 10,
      "name": "Plant_Leaves_Goldentree"
    },
    {
      "x": 1,
      "y": 19,
      "z": 10,
      "name": "Plant_Leaves_Goldentree"
    },
    {
      "x": 1,
      "y": 20,
      "z": 10,
      "name": "Plant_Leaves_Goldentree"
    },
    {
      "x": 1,
      "y": 21,
      "z": 10,
      "name": "Plant_Leaves_Goldentree"
    },
    {
      "x": 1,
      "y": 19,
      "z": 11,
      "name": "Plant_Leaves_Goldentree"
    },
    {
      "x": 1,
      "y": 20,
      "z": 11,
      "name": "Plant_Leaves_Goldentree"
    },
    {
      "x": 2,
      "y": 16,
      "z": -9,
      "name": "Plant_Leaves_Goldentree"
    },
    {
      "x": 2,
      "y": 15,
      "z": -8,
      "name": "Plant_Leaves_Goldentree"
    },
    {
      "x": 2,
      "y": 16,
      "z": -8,
      "name": "Plant_Leaves_Goldentree"
    },
    {
      "x": 2,
      "y": 28,
      "z": -7,
      "name": "Plant_Leaves_Goldentree"
    },
    {
      "x": 2,
      "y": 29,
      "z": -7,
      "name": "Plant_Leaves_Goldentree"
    },
    {
      "x": 2,
      "y": 28,
      "z": -6,
      "name": "Plant_Leaves_Goldentree"
    },
    {
      "x": 2,
      "y": 16,
      "z": -4,
      "name": "Wood_Amber_Trunk_Full"
    },
    {
      "x": 2,
      "y": 15,
      "z": -3,
      "name": "Wood_Amber_Trunk_Full"
    },
    {
      "x": 2,
      "y": 16,
      "z": -3,
      "name": "Wood_Amber_Trunk_Full"
    },
    {
      "x": 2,
      "y": 30,
      "z": -3,
      "name": "Plant_Leaves_Goldentree"
    },
    {
      "x": 2,
      "y": 29,
      "z": -2,
      "name": "Plant_Leaves_Goldentree"
    },
    {
      "x": 2,
      "y": 30,
      "z": -2,
      "name": "Plant_Leaves_Goldentree"
    },
    {
      "x": 2,
      "y": 21,
      "z": -1,
      "name": "Wood_Amber_Trunk_Full"
    },
    {
      "x": 2,
      "y": 22,
      "z": -1,
      "name": "Wood_Amber_Trunk_Full"
    },
    {
      "x": 2,
      "y": 23,
      "z": -1,
      "name": "Wood_Amber_Trunk_Full"
    },
    {
      "x": 2,
      "y": 28,
      "z": -1,
      "name": "Wood_Amber_Trunk_Full"
    },
    {
      "x": 2,
      "y": 30,
      "z": -1,
      "name": "Plant_Leaves_Goldentree"
    },
    {
      "x": 2,
      "y": 31,
      "z": -1,
      "name": "Plant_Leaves_Goldentree"
    },
    {
      "x": 2,
      "y": 32,
      "z": -1,
      "name": "Plant_Leaves_Goldentree"
    },
    {
      "x": 2,
      "y": 1,
      "z": 0,
      "name": "Wood_Amber_Trunk"
    },
    {
      "x": 2,
      "y": 2,
      "z": 0,
      "name": "Wood_Amber_Trunk"
    },
    {
      "x": 2,
      "y": 3,
      "z": 0,
      "name": "Wood_Amber_Trunk"
    },
    {
      "x": 2,
      "y": 4,
      "z": 0,
      "name": "Wood_Amber_Trunk"
    },
    {
      "x": 2,
      "y": 5,
      "z": 0,
      "name": "Wood_Amber_Trunk"
    },
    {
      "x": 2,
      "y": 6,
      "z": 0,
      "name": "Wood_Amber_Trunk"
    },
    {
      "x": 2,
      "y": 7,
      "z": 0,
      "name": "Wood_Amber_Trunk"
    },
    {
      "x": 2,
      "y": 8,
      "z": 0,
      "name": "Wood_Amber_Trunk_Full"
    },
    {
      "x": 2,
      "y": 9,
      "z": 0,
      "name": "Wood_Amber_Trunk_Full"
    },
    {
      "x": 2,
      "y": 10,
      "z": 0,
      "name": "Wood_Amber_Trunk_Full"
    },
    {
      "x": 2,
      "y": 29,
      "z": 0,
      "name": "Plant_Leaves_Goldentree"
    },
    {
      "x": 2,
      "y": 1,
      "z": 1,
      "name": "Wood_Amber_Trunk"
    },
    {
      "x": 2,
      "y": 2,
      "z": 1,
      "name": "Wood_Amber_Trunk"
    },
    {
      "x": 2,
      "y": 3,
      "z": 1,
      "name": "Wood_Amber_Trunk"
    },
    {
      "x": 2,
      "y": 4,
      "z": 1,
      "name": "Wood_Amber_Trunk"
    },
    {
      "x": 2,
      "y": 5,
      "z": 1,
      "name": "Wood_Amber_Trunk"
    },
    {
      "x": 2,
      "y": 6,
      "z": 1,
      "name": "Wood_Amber_Trunk_Full"
    },
    {
      "x": 2,
      "y": 16,
      "z": 1,
      "name": "Wood_Amber_Trunk_Full"
    },
    {
      "x": 2,
      "y": 17,
      "z": 1,
      "name": "Wood_Amber_Trunk_Full"
    },
    {
      "x": 2,
      "y": 18,
      "z": 1,
      "name": "Wood_Amber_Trunk_Full"
    },
    {
      "x": 2,
      "y": 29,
      "z": 2,
      "name": "Plant_Leaves_Goldentree"
    },
    {
      "x": 2,
      "y": 18,
      "z": 3,
      "name": "Wood_Amber_Trunk_Full"
    },
    {
      "x": 2,
      "y": 19,
      "z": 3,
      "name": "Wood_Amber_Trunk_Full"
    },
    {
      "x": 2,
      "y": 29,
      "z": 3,
      "name": "Plant_Leaves_Goldentree"
    },
    {
      "x": 2,
      "y": 18,
      "z": 4,
      "name": "Wood_Amber_Trunk_Full"
    },
    {
      "x": 2,
      "y": 19,
      "z": 4,
      "name": "Wood_Amber_Trunk_Full"
    },
    {
      "x": 2,
      "y": 19,
      "z": 5,
      "name": "Wood_Amber_Trunk_Full"
    },
    {
      "x": 2,
      "y": 28,
      "z": 5,
      "name": "Plant_Leaves_Goldentree"
    },
    {
      "x": 2,
      "y": 29,
      "z": 5,
      "name": "Plant_Leaves_Goldentree"
    },
    {
      "x": 2,
      "y": 19,
      "z": 6,
      "name": "Wood_Amber_Trunk_Full"
    },
    {
      "x": 2,
      "y": 20,
      "z": 6,
      "name": "Plant_Leaves_Goldentree"
    },
    {
      "x": 2,
      "y": 21,
      "z": 7,
      "name": "Plant_Leaves_Goldentree"
    },
    {
      "x": 2,
      "y": 20,
      "z": 8,
      "name": "Wood_Amber_Branch_Long",
      "rotation": 5
    },
    {
      "x": 2,
      "y": 21,
      "z": 8,
      "name": "Plant_Leaves_Goldentree"
    },
    {
      "x": 2,
      "y": 20,
      "z": 9,
      "name": "Plant_Leaves_Goldentree"
    },
    {
      "x": 2,
      "y": 21,
      "z": 9,
      "name": "Plant_Leaves_Goldentree"
    },
    {
      "x": 2,
      "y": 22,
      "z": 9,
      "name": "Plant_Leaves_Goldentree"
    },
    {
      "x": 2,
      "y": 21,
      "z": 10,
      "name": "Plant_Leaves_Goldentree"
    },
    {
      "x": 2,
      "y": 22,
      "z": 10,
      "name": "Plant_Leaves_Goldentree"
    },
    {
      "x": 2,
      "y": 20,
      "z": 11,
      "name": "Plant_Leaves_Goldentree"
    },
    {
      "x": 2,
      "y": 21,
      "z": 11,
      "name": "Plant_Leaves_Goldentree"
    },
    {
      "x": 3,
      "y": 17,
      "z": -5,
      "name": "Wood_Amber_Trunk_Full"
    },
    {
      "x": 3,
      "y": 16,
      "z": -4,
      "name": "Wood_Amber_Trunk_Full"
    },
    {
      "x": 3,
      "y": 17,
      "z": -4,
      "name": "Wood_Amber_Trunk_Full"
    },
    {
      "x": 3,
      "y": 23,
      "z": -3,
      "name": "Wood_Amber_Trunk_Full"
    },
    {
      "x": 3,
      "y": 28,
      "z": -3,
      "name": "Plant_Leaves_Goldentree"
    },
    {
      "x": 3,
      "y": 29,
      "z": -3,
      "name": "Plant_Leaves_Goldentree"
    },
    {
      "x": 3,
      "y": 30,
      "z": -3,
      "name": "Plant_Leaves_Goldentree"
    },
    {
      "x": 3,
      "y": 31,
      "z": -3,
      "name": "Plant_Leaves_Goldentree"
    },
    {
      "x": 3,
      "y": 23,
      "z": -2,
      "name": "Wood_Amber_Trunk_Full"
    },
    {
      "x": 3,
      "y": 30,
      "z": -2,
      "name": "Plant_Leaves_Goldentree"
    },
    {
      "x": 3,
      "y": 22,
      "z": -1,
      "name": "Wood_Amber_Trunk_Full"
    },
    {
      "x": 3,
      "y": 23,
      "z": -1,
      "name": "Wood_Amber_Trunk_Full"
    },
    {
      "x": 3,
      "y": 28,
      "z": -1,
      "name": "Wood_Amber_Trunk_Full"
    },
    {
      "x": 3,
      "y": 29,
      "z": -1,
      "name": "Wood_Amber_Trunk_Full"
    },
    {
      "x": 3,
      "y": 30,
      "z": -1,
      "name": "Plant_Leaves_Goldentree"
    },
    {
      "x": 3,
      "y": 31,
      "z": -1,
      "name": "Plant_Leaves_Goldentree"
    },
    {
      "x": 3,
      "y": 0,
      "z": 0,
      "name": "Wood_Amber_Trunk"
    },
    {
      "x": 3,
      "y": 1,
      "z": 0,
      "name": "Wood_Amber_Trunk"
    },
    {
      "x": 3,
      "y": 2,
      "z": 0,
      "name": "Wood_Amber_Trunk"
    },
    {
      "x": 3,
      "y": 3,
      "z": 0,
      "name": "Wood_Amber_Trunk_Full"
    },
    {
      "x": 3,
      "y": 9,
      "z": 0,
      "name": "Wood_Amber_Trunk_Full"
    },
    {
      "x": 3,
      "y": 10,
      "z": 0,
      "name": "Wood_Amber_Trunk_Full"
    },
    {
      "x": 3,
      "y": 23,
      "z": 0,
      "name": "Wood_Amber_Trunk_Full"
    },
    {
      "x": 3,
      "y": 29,
      "z": 0,
      "name": "Plant_Leaves_Goldentree"
    },
    {
      "x": 3,
      "y": 30,
      "z": 0,
      "name": "Plant_Leaves_Goldentree"
    },
    {
      "x": 3,
      "y": 31,
      "z": 0,
      "name": "Plant_Leaves_Goldentree"
    },
    {
      "x": 3,
      "y": 0,
      "z": 1,
      "name": "Wood_Amber_Trunk"
    },
    {
      "x": 3,
      "y": 1,
      "z": 1,
      "name": "Wood_Amber_Trunk"
    },
    {
      "x": 3,
      "y": 2,
      "z": 1,
      "name": "Wood_Amber_Trunk"
    },
    {
      "x": 3,
      "y": 3,
      "z": 1,
      "name": "Wood_Amber_Trunk"
    },
    {
      "x": 3,
      "y": 4,
      "z": 1,
      "name": "Wood_Amber_Trunk_Full"
    },
    {
      "x": 3,
      "y": 9,
      "z": 1,
      "name": "Wood_Amber_Trunk_Full"
    },
    {
      "x": 3,
      "y": 10,
      "z": 1,
      "name": "Wood_Amber_Trunk_Full"
    },
    {
      "x": 3,
      "y": 17,
      "z": 1,
      "name": "Wood_Amber_Trunk_Full"
    },
    {
      "x": 3,
      "y": 18,
      "z": 1,
      "name": "Wood_Amber_Trunk_Full"
    },
    {
      "x": 3,
      "y": 30,
      "z": 1,
      "name": "Plant_Leaves_Goldentree"
    },
    {
      "x": 3,
      "y": 31,
      "z": 1,
      "name": "Plant_Leaves_Goldentree"
    },
    {
      "x": 3,
      "y": 0,
      "z": 2,
      "name": "Wood_Amber_Trunk"
    },
    {
      "x": 3,
      "y": 1,
      "z": 2,
      "name": "Wood_Amber_Trunk_Full"
    },
    {
      "x": 3,
      "y": 20,
      "z": 5,
      "name": "Plant_Leaves_Goldentree"
    },
    {
      "x": 3,
      "y": 19,
      "z": 6,
      "name": "Wood_Amber_Trunk_Full"
    },
    {
      "x": 3,
      "y": 20,
      "z": 6,
      "name": "Plant_Leaves_Goldentree"
    },
    {
      "x": 3,
      "y": 21,
      "z": 6,
      "name": "Plant_Leaves_Goldentree"
    },
    {
      "x": 3,
      "y": 19,
      "z": 7,
      "name": "Wood_Amber_Trunk_Full"
    },
    {
      "x": 3,
      "y": 20,
      "z": 7,
      "name": "Wood_Amber_Trunk_Full"
    },
    {
      "x": 3,
      "y": 21,
      "z": 7,
      "name": "Plant_Leaves_Goldentree"
    },
    {
      "x": 3,
      "y": 22,
      "z": 7,
      "name": "Plant_Leaves_Goldentree"
    },
    {
      "x": 3,
      "y": 20,
      "z": 8,
      "name": "Wood_Amber_Trunk_Full"
    },
    {
      "x": 3,
      "y": 21,
      "z": 8,
      "name": "Wood_Amber_Branch_Long"
    },
    {
      "x": 3,
      "y": 22,
      "z": 8,
      "name": "Plant_Leaves_Goldentree"
    },
    {
      "x": 3,
      "y": 20,
      "z": 9,
      "name": "Wood_Amber_Branch_Long",
      "rotation": 4
    },
    {
      "x": 3,
      "y": 21,
      "z": 9,
      "name": "Plant_Leaves_Goldentree"
    },
    {
      "x": 3,
      "y": 22,
      "z": 9,
      "name": "Plant_Leaves_Goldentree"
    },
    {
      "x": 3,
      "y": 18,
      "z": 10,
      "name": "Plant_Leaves_Goldentree"
    },
    {
      "x": 3,
      "y": 19,
      "z": 10,
      "name": "Plant_Leaves_Goldentree"
    },
    {
      "x": 3,
      "y": 20,
      "z": 10,
      "name": "Wood_Amber_Branch_Long",
      "rotation": 4
    },
    {
      "x": 3,
      "y": 21,
      "z": 10,
      "name": "Plant_Leaves_Goldentree"
    },
    {
      "x": 3,
      "y": 18,
      "z": 11,
      "name": "Plant_Leaves_Goldentree"
    },
    {
      "x": 3,
      "y": 19,
      "z": 11,
      "name": "Plant_Leaves_Goldentree"
    },
    {
      "x": 3,
      "y": 20,
      "z": 11,
      "name": "Plant_Leaves_Goldentree"
    },
    {
      "x": 3,
      "y": 21,
      "z": 11,
      "name": "Plant_Leaves_Goldentree"
    },
    {
      "x": 4,
      "y": 19,
      "z": -7,
      "name": "Plant_Leaves_Goldentree"
    },
    {
      "x": 4,
      "y": 17,
      "z": -5,
      "name": "Wood_Amber_Trunk_Full"
    },
    {
      "x": 4,
      "y": 25,
      "z": -5,
      "name": "Plant_Leaves_Goldentree"
    },
    {
      "x": 4,
      "y": 24,
      "z": -4,
      "name": "Wood_Amber_Trunk_Full"
    },
    {
      "x": 4,
      "y": 28,
      "z": -4,
      "name": "Plant_Leaves_Goldentree"
    },
    {
      "x": 4,
      "y": 29,
      "z": -4,
      "name": "Plant_Leaves_Goldentree"
    },
    {
      "x": 4,
      "y": 30,
      "z": -4,
      "name": "Plant_Leaves_Goldentree"
    },
    {
      "x": 4,
      "y": 23,
      "z": -3,
      "name": "Wood_Amber_Trunk_Full"
    },
    {
      "x": 4,
      "y": 24,
      "z": -3,
      "name": "Wood_Amber_Trunk_Full"
    },
    {
      "x": 4,
      "y": 29,
      "z": -3,
      "name": "Wood_Amber_Branch_Long",
      "rotation": 4
    },
    {
      "x": 4,
      "y": 30,
      "z": -3,
      "name": "Plant_Leaves_Goldentree"
    },
    {
      "x": 4,
      "y": 31,
      "z": -3,
      "name": "Plant_Leaves_Goldentree"
    },
    {
      "x": 4,
      "y": 29,
      "z": -2,
      "name": "Wood_Amber_Branch_Long",
      "rotation": 4
    },
    {
      "x": 4,
      "y": 30,
      "z": -2,
      "name": "Plant_Leaves_Goldentree"
    },
    {
      "x": 4,
      "y": 31,
      "z": -2,
      "name": "Plant_Leaves_Goldentree"
    },
    {
      "x": 4,
      "y": 29,
      "z": -1,
      "name": "Wood_Amber_Trunk_Full"
    },
    {
      "x": 4,
      "y": 30,
      "z": -1,
      "name": "Wood_Amber_Branch_Long"
    },
    {
      "x": 4,
      "y": 31,
      "z": -1,
      "name": "Plant_Leaves_Goldentree"
    },
    {
      "x": 4,
      "y": 32,
      "z": -1,
      "name": "Plant_Leaves_Goldentree"
    },
    {
      "x": 4,
      "y": 0,
      "z": 0,
      "name": "Wood_Amber_Trunk"
    },
    {
      "x": 4,
      "y": 1,
      "z": 0,
      "name": "Wood_Amber_Trunk_Full"
    },
    {
      "x": 4,
      "y": 23,
      "z": 0,
      "name": "Wood_Amber_Trunk_Full"
    },
    {
      "x": 4,
      "y": 24,
      "z": 0,
      "name": "Wood_Amber_Trunk_Full"
    },
    {
      "x": 4,
      "y": 29,
      "z": 0,
      "name": "Wood_Amber_Branch_Long",
      "rotation": 4
    },
    {
      "x": 4,
      "y": 30,
      "z": 0,
      "name": "Plant_Leaves_Goldentree"
    },
    {
      "x": 4,
      "y": 31,
      "z": 0,
      "name": "Plant_Leaves_Goldentree"
    },
    {
      "x": 4,
      "y": 0,
      "z": 1,
      "name": "Wood_Amber_Trunk"
    },
    {
      "x": 4,
      "y": 1,
      "z": 1,
      "name": "Wood_Amber_Trunk"
    },
    {
      "x": 4,
      "y": 2,
      "z": 1,
      "name": "Wood_Amber_Trunk_Full"
    },
    {
      "x": 4,
      "y": 9,
      "z": 1,
      "name": "Wood_Amber_Trunk_Full"
    },
    {
      "x": 4,
      "y": 10,
      "z": 1,
      "name": "Wood_Amber_Trunk_Full"
    },
    {
      "x": 4,
      "y": 18,
      "z": 1,
      "name": "Wood_Amber_Trunk_Full"
    },
    {
      "x": 4,
      "y": 29,
      "z": 1,
      "name": "Plant_Leaves_Goldentree"
    },
    {
      "x": 4,
      "y": 30,
      "z": 1,
      "name": "Plant_Leaves_Goldentree"
    },
    {
      "x": 4,
      "y": 31,
      "z": 1,
      "name": "Plant_Leaves_Goldentree"
    },
    {
      "x": 4,
      "y": 20,
      "z": 6,
      "name": "Plant_Leaves_Goldentree"
    },
    {
      "x": 4,
      "y": 20,
      "z": 7,
      "name": "Wood_Amber_Branch_Long",
      "rotation": 5
    },
    {
      "x": 4,
      "y": 21,
      "z": 7,
      "name": "Plant_Leaves_Goldentree"
    },
    {
      "x": 4,
      "y": 22,
      "z": 7,
      "name": "Plant_Leaves_Goldentree"
    },
    {
      "x": 4,
      "y": 21,
      "z": 8,
      "name": "Plant_Leaves_Goldentree"
    },
    {
      "x": 4,
      "y": 22,
      "z": 8,
      "name": "Plant_Leaves_Goldentree"
    },
    {
      "x": 4,
      "y": 21,
      "z": 9,
      "name": "Plant_Leaves_Goldentree"
    },
    {
      "x": 4,
      "y": 18,
      "z": 10,
      "name": "Plant_Leaves_Goldentree"
    },
    {
      "x": 4,
      "y": 19,
      "z": 10,
      "name": "Plant_Leaves_Goldentree"
    },
    {
      "x": 4,
      "y": 20,
      "z": 10,
      "name": "Plant_Leaves_Goldentree"
    },
    {
      "x": 4,
      "y": 21,
      "z": 10,
      "name": "Plant_Leaves_Goldentree"
    },
    {
      "x": 4,
      "y": 22,
      "z": 10,
      "name": "Plant_Leaves_Goldentree"
    },
    {
      "x": 4,
      "y": 19,
      "z": 11,
      "name": "Plant_Leaves_Goldentree"
    },
    {
      "x": 4,
      "y": 20,
      "z": 11,
      "name": "Plant_Leaves_Goldentree"
    },
    {
      "x": 5,
      "y": 20,
      "z": -8,
      "name": "Plant_Leaves_Goldentree"
    },
    {
      "x": 5,
      "y": 19,
      "z": -7,
      "name": "Wood_Amber_Branch_Long",
      "rotation": 5
    },
    {
      "x": 5,
      "y": 20,
      "z": -7,
      "name": "Plant_Leaves_Goldentree"
    },
    {
      "x": 5,
      "y": 24,
      "z": -7,
      "name": "Plant_Leaves_Goldentree"
    },
    {
      "x": 5,
      "y": 25,
      "z": -7,
      "name": "Plant_Leaves_Goldentree"
    },
    {
      "x": 5,
      "y": 17,
      "z": -6,
      "name": "Wood_Amber_Trunk_Full"
    },
    {
      "x": 5,
      "y": 19,
      "z": -6,
      "name": "Plant_Leaves_Goldentree"
    },
    {
      "x": 5,
      "y": 20,
      "z": -6,
      "name": "Plant_Leaves_Goldentree"
    },
    {
      "x": 5,
      "y": 25,
      "z": -6,
      "name": "Plant_Leaves_Goldentree"
    },
    {
      "x": 5,
      "y": 17,
      "z": -5,
      "name": "Wood_Amber_Trunk_Full"
    },
    {
      "x": 5,
      "y": 25,
      "z": -5,
      "name": "Wood_Amber_Trunk_Full"
    },
    {
      "x": 5,
      "y": 24,
      "z": -4,
      "name": "Wood_Amber_Trunk_Full"
    },
    {
      "x": 5,
      "y": 25,
      "z": -4,
      "name": "Wood_Amber_Trunk_Full"
    },
    {
      "x": 5,
      "y": 28,
      "z": -4,
      "name": "Plant_Leaves_Goldentree"
    },
    {
      "x": 5,
      "y": 29,
      "z": -4,
      "name": "Plant_Leaves_Goldentree"
    },
    {
      "x": 5,
      "y": 30,
      "z": -4,
      "name": "Plant_Leaves_Goldentree"
    },
    {
      "x": 5,
      "y": 31,
      "z": -4,
      "name": "Plant_Leaves_Goldentree"
    },
    {
      "x": 5,
      "y": 30,
      "z": -3,
      "name": "Plant_Leaves_Goldentree"
    },
    {
      "x": 5,
      "y": 31,
      "z": -3,
      "name": "Plant_Leaves_Goldentree"
    },
    {
      "x": 5,
      "y": 30,
      "z": -2,
      "name": "Plant_Leaves_Goldentree"
    },
    {
      "x": 5,
      "y": 29,
      "z": -1,
      "name": "Wood_Amber_Branch_Long",
      "rotation": 5
    },
    {
      "x": 5,
      "y": 31,
      "z": -1,
      "name": "Plant_Leaves_Goldentree"
    },
    {
      "x": 5,
      "y": 24,
      "z": 0,
      "name": "Wood_Amber_Trunk_Full"
    },
    {
      "x": 5,
      "y": 30,
      "z": 0,
      "name": "Plant_Leaves_Goldentree"
    },
    {
      "x": 5,
      "y": 31,
      "z": 0,
      "name": "Plant_Leaves_Goldentree"
    },
    {
      "x": 5,
      "y": 10,
      "z": 1,
      "name": "Wood_Amber_Trunk_Full"
    },
    {
      "x": 5,
      "y": 11,
      "z": 1,
      "name": "Wood_Amber_Trunk_Full"
    },
    {
      "x": 5,
      "y": 18,
      "z": 1,
      "name": "Wood_Amber_Trunk_Full"
    },
    {
      "x": 5,
      "y": 19,
      "z": 1,
      "name": "Wood_Amber_Trunk_Full"
    },
    {
      "x": 5,
      "y": 29,
      "z": 1,
      "name": "Plant_Leaves_Goldentree"
    },
    {
      "x": 5,
      "y": 13,
      "z": 2,
      "name": "Plant_Leaves_Goldentree"
    },
    {
      "x": 5,
      "y": 20,
      "z": 6,
      "name": "Plant_Leaves_Goldentree"
    },
    {
      "x": 5,
      "y": 21,
      "z": 6,
      "name": "Plant_Leaves_Goldentree"
    },
    {
      "x": 5,
      "y": 20,
      "z": 7,
      "name": "Wood_Amber_Branch_Long",
      "rotation": 5
    },
    {
      "x": 5,
      "y": 21,
      "z": 7,
      "name": "Plant_Leaves_Goldentree"
    },
    {
      "x": 5,
      "y": 21,
      "z": 8,
      "name": "Plant_Leaves_Goldentree"
    },
    {
      "x": 5,
      "y": 22,
      "z": 8,
      "name": "Plant_Leaves_Goldentree"
    },
    {
      "x": 5,
      "y": 19,
      "z": 9,
      "name": "Plant_Leaves_Goldentree"
    },
    {
      "x": 5,
      "y": 20,
      "z": 9,
      "name": "Plant_Leaves_Goldentree"
    },
    {
      "x": 5,
      "y": 21,
      "z": 9,
      "name": "Plant_Leaves_Goldentree"
    },
    {
      "x": 5,
      "y": 19,
      "z": 10,
      "name": "Plant_Leaves_Goldentree"
    },
    {
      "x": 5,
      "y": 20,
      "z": 10,
      "name": "Plant_Leaves_Goldentree"
    },
    {
      "x": 5,
      "y": 21,
      "z": 10,
      "name": "Plant_Leaves_Goldentree"
    },
    {
      "x": 5,
      "y": 20,
      "z": 11,
      "name": "Plant_Leaves_Goldentree"
    },
    {
      "x": 6,
      "y": 19,
      "z": -10,
      "name": "Plant_Leaves_Goldentree"
    },
    {
      "x": 6,
      "y": 19,
      "z": -9,
      "name": "Plant_Leaves_Goldentree"
    },
    {
      "x": 6,
      "y": 21,
      "z": -8,
      "name": "Plant_Leaves_Goldentree"
    },
    {
      "x": 6,
      "y": 25,
      "z": -8,
      "name": "Plant_Leaves_Goldentree"
    },
    {
      "x": 6,
      "y": 18,
      "z": -7,
      "name": "Wood_Amber_Trunk_Full"
    },
    {
      "x": 6,
      "y": 19,
      "z": -7,
      "name": "Wood_Amber_Branch_Long",
      "rotation": 5
    },
    {
      "x": 6,
      "y": 20,
      "z": -7,
      "name": "Plant_Leaves_Goldentree"
    },
    {
      "x": 6,
      "y": 21,
      "z": -7,
      "name": "Plant_Leaves_Goldentree"
    },
    {
      "x": 6,
      "y": 25,
      "z": -7,
      "name": "Wood_Amber_Branch_Long",
      "rotation": 4
    },
    {
      "x": 6,
      "y": 26,
      "z": -7,
      "name": "Plant_Leaves_Goldentree"
    },
    {
      "x": 6,
      "y": 17,
      "z": -6,
      "name": "Wood_Amber_Trunk_Full"
    },
    {
      "x": 6,
      "y": 18,
      "z": -6,
      "name": "Wood_Amber_Trunk_Full"
    },
    {
      "x": 6,
      "y": 20,
      "z": -6,
      "name": "Plant_Leaves_Goldentree"
    },
    {
      "x": 6,
      "y": 21,
      "z": -6,
      "name": "Plant_Leaves_Goldentree"
    },
    {
      "x": 6,
      "y": 22,
      "z": -6,
      "name": "Plant_Leaves_Goldentree"
    },
    {
      "x": 6,
      "y": 25,
      "z": -6,
      "name": "Wood_Amber_Branch_Long",
      "rotation": 4
    },
    {
      "x": 6,
      "y": 26,
      "z": -6,
      "name": "Plant_Leaves_Goldentree"
    },
    {
      "x": 6,
      "y": 27,
      "z": -6,
      "name": "Plant_Leaves_Goldentree"
    },
    {
      "x": 6,
      "y": 19,
      "z": -5,
      "name": "Plant_Leaves_Goldentree"
    },
    {
