{
  "version": 8,
  "blockIdVersion": 11,
  "anchorX": 2,
  "anchorY": 7,
  "anchorZ": 3,
  "blocks": [
    {
      "x": -2,
      "y": 12,
      "z": 3,
      "name": "Plant_Leaves_Maple"
    },
    {
      "x": -1,
      "y": 12,
      "z": 1,
      "name": "Plant_Leaves_Maple"
    },
    {
      "x": -1,
      "y": 12,
      "z": 2,
      "name": "Plant_Leaves_Maple"
    },
    {
      "x": -1,
      "y": 12,
      "z": 3,
      "name": "Plant_Leaves_Maple"
    },
    {
      "x": -1,
      "y": 13,
      "z": 3,
      "name": "Plant_Leaves_Maple"
    },
    {
      "x": -1,
      "y": 12,
      "z": 4,
      "name": "Plant_Leaves_Maple"
    },
    {
      "x": 0,
      "y": 12,
      "z": 1,
      "name": "Plant_Leaves_Maple"
    },
    {
      "x": 0,
      "y": 12,
      "z": 2,
      "name": "Plant_Leaves_Maple"
    },
    {
      "x": 0,
      "y": 13,
      "z": 2,
      "name": "Plant_Leaves_Maple"
    },
    {
      "x": 0,
      "y": 12,
      "z": 3,
      "name": "Plant_Leaves_Maple"
    },
    {
      "x": 0,
      "y": 13,
      "z": 3,
      "name": "Plant_Leaves_Maple"
    },
    {
      "x": 0,
      "y": 14,
      "z": 3,
      "name": "Plant_Leaves_Maple"
    },
    {
      "x": 0,
      "y": 12,
      "z": 4,
      "name": "Plant_Leaves_Maple"
    },
    {
      "x": 0,
      "y": 13,
      "z": 4,
      "name": "Plant_Leaves_Maple"
    },
    {
      "x": 1,
      "y": 13,
      "z": 0,
      "name": "Plant_Leaves_Maple"
    },
    {
      "x": 1,
      "y": 13,
      "z": 1,
      "name": "Plant_Leaves_Maple"
    },
    {
      "x": 1,
      "y": 14,
      "z": 1,
      "name": "Plant_Leaves_Maple"
    },
    {
      "x": 1,
      "y": 6,
      "z": 3,
      "name": "Wood_Maple_Trunk_Full"
    },
    {
      "x": 1,
      "y": 7,
      "z": 3,
      "name": "Wood_Maple_Trunk_Full"
    },
    {
      "x": 1,
      "y": 10,
      "z": 3,
      "name": "Wood_Maple_Branch_Short",
      "rotation": 3
    },
    {
      "x": 1,
      "y": 12,
      "z": 3,
      "name": "Wood_Maple_Branch_Long",
      "rotation": 5
    },
    {
      "x": 1,
      "y": 14,
      "z": 3,
      "name": "Plant_Leaves_Maple"
    },
    {
      "x": 1,
      "y": 15,
      "z": 3,
      "name": "Plant_Leaves_Maple"
    },
    {
      "x": 1,
      "y": 12,
      "z": 5,
      "name": "Plant_Leaves_Maple"
    },
    {
      "x": 1,
      "y": 12,
      "z": 6,
      "name": "Plant_Leaves_Maple"
    },
    {
      "x": 2,
      "y": 13,
      "z": 0,
      "name": "Plant_Leaves_Maple"
    },
    {
      "x": 2,
      "y": 13,
      "z": 1,
      "name": "Plant_Leaves_Maple"
    },
    {
      "x": 2,
      "y": 14,
      "z": 1,
      "name": "Plant_Leaves_Maple"
    },
    {
      "x": 2,
      "y": 6,
      "z": 2,
      "name": "Wood_Maple_Trunk_Full"
    },
    {
      "x": 2,
      "y": 7,
      "z": 2,
      "name": "Wood_Maple_Trunk"
    },
    {
      "x": 2,
      "y": 8,
      "z": 2,
      "name": "Wood_Maple_Trunk_Full"
    },
    {
      "x": 2,
      "y": 11,
      "z": 2,
      "name": "Wood_Maple_Branch_Short",
      "rotation": 2
    },
    {
      "x": 2,
      "y": 12,
      "z": 2,
      "name": "Wood_Maple_Branch_Corner",
      "rotation": 2
    },
    {
      "x": 2,
      "y": 13,
      "z": 2,
      "name": "Plant_Leaves_Maple"
    },
    {
      "x": 2,
      "y": 14,
      "z": 2,
      "name": "Plant_Leaves_Maple"
    },
    {
      "x": 2,
      "y": 5,
      "z": 3,
      "name": "Wood_Maple_Trunk"
    },
    {
      "x": 2,
      "y": 6,
      "z": 3,
      "name": "Wood_Maple_Trunk"
    },
    {
      "x": 2,
      "y": 7,
      "z": 3,
      "name": "Wood_Maple_Trunk"
    },
    {
      "x": 2,
      "y": 8,
      "z": 3,
      "name": "Wood_Maple_Trunk"
    },
    {
      "x": 2,
      "y": 9,
      "z": 3,
      "name": "Wood_Maple_Trunk"
    },
    {
      "x": 2,
      "y": 10,
      "z": 3,
      "name": "Wood_Maple_Trunk"
    },
    {
      "x": 2,
      "y": 11,
      "z": 3,
      "name": "Wood_Maple_Trunk"
    },
    {
      "x": 2,
      "y": 12,
      "z": 3,
      "name": "Wood_Maple_Trunk_Full"
    },
    {
      "x": 2,
      "y": 13,
      "z": 3,
      "name": "Wood_Maple_Branch_Long"
    },
    {
      "x": 2,
      "y": 14,
      "z": 3,
      "name": "Plant_Leaves_Maple"
    },
    {
      "x": 2,
      "y": 15,
      "z": 3,
      "name": "Plant_Leaves_Maple"
    },
    {
      "x": 2,
      "y": 7,
      "z": 4,
      "name": "Wood_Maple_Trunk_Full"
    },
    {
      "x": 2,
      "y": 8,
      "z": 4,
      "name": "Wood_Maple_Trunk_Full"
    },
    {
      "x": 2,
      "y": 12,
      "z": 4,
      "name": "Wood_Maple_Branch_Long",
      "rotation": 4
    },
    {
      "x": 2,
      "y": 13,
      "z": 4,
      "name": "Plant_Leaves_Maple"
    },
    {
      "x": 2,
      "y": 14,
      "z": 4,
      "name": "Plant_Leaves_Maple"
    },
    {
      "x": 2,
      "y": 12,
      "z": 5,
      "name": "Plant_Leaves_Maple"
    },
    {
      "x": 2,
      "y": 13,
      "z": 5,
      "name": "Plant_Leaves_Maple"
    },
    {
      "x": 2,
      "y": 12,
      "z": 6,
      "name": "Plant_Leaves_Maple"
    },
    {
      "x": 3,
      "y": 13,
      "z": 1,
      "name": "Plant_Leaves_Maple"
    },
    {
      "x": 3,
      "y": 13,
      "z": 2,
      "name": "Plant_Leaves_Maple"
    },
    {
      "x": 3,
      "y": 14,
      "z": 2,
      "name": "Plant_Leaves_Maple"
    },
    {
      "x": 3,
      "y": 6,
      "z": 3,
      "name": "Wood_Maple_Trunk_Full"
    },
    {
      "x": 3,
      "y": 7,
      "z": 3,
      "name": "Wood_Maple_Trunk"
    },
    {
      "x": 3,
      "y": 8,
      "z": 3,
      "name": "Wood_Maple_Trunk"
    },
    {
      "x": 3,
      "y": 9,
      "z": 3,
      "name": "Wood_Maple_Trunk_Full"
    },
    {
      "x": 3,
      "y": 11,
      "z": 3,
      "name": "Wood_Maple_Branch_Long",
      "rotation": 5
    },
    {
      "x": 3,
      "y": 14,
      "z": 3,
      "name": "Plant_Leaves_Maple"
    },
    {
      "x": 3,
      "y": 15,
      "z": 3,
      "name": "Plant_Leaves_Maple"
    },
    {
      "x": 3,
      "y": 12,
      "z": 4,
      "name": "Plant_Leaves_Maple"
    },
    {
      "x": 3,
      "y": 13,
      "z": 4,
      "name": "Plant_Leaves_Maple"
    },
    {
      "x": 3,
      "y": 14,
      "z": 4,
      "name": "Plant_Leaves_Maple"
    },
    {
      "x": 3,
      "y": 12,
      "z": 5,
      "name": "Plant_Leaves_Maple"
    },
    {
      "x": 3,
      "y": 12,
      "z": 6,
      "name": "Plant_Leaves_Maple"
    },
    {
      "x": 4,
      "y": 12,
      "z": 2,
      "name": "Plant_Leaves_Maple"
    },
    {
      "x": 4,
      "y": 15,
      "z": 2,
      "name": "Plant_Leaves_Maple"
    },
    {
      "x": 4,
      "y": 11,
      "z": 3,
      "name": "Plant_Leaves_Maple"
    },
    {
      "x": 4,
      "y": 12,
      "z": 3,
      "name": "Plant_Leaves_Maple"
    },
    {
      "x": 4,
      "y": 14,
      "z": 3,
      "name": "Plant_Leaves_Maple"
    },
    {
      "x": 4,
      "y": 12,
      "z": 4,
      "name": "Plant_Leaves_Maple"
    },
    {
      "x": 4,
      "y": 14,
      "z": 4,
      "name": "Plant_Leaves_Maple"
    },
    {
      "x": 5,
      "y": 11,
      "z": 2,
      "name": "Plant_Leaves_Maple"
    },
    {
      "x": 5,
      "y": 11,
      "z": 3,
      "name": "Plant_Leaves_Maple"
    },
    {
      "x": 5,
      "y": 12,
      "z": 3,
      "name": "Plant_Leaves_Maple"
    }
  ]
}