{
  "version": 8,
  "blockIdVersion": 11,
  "anchorX": 1,
  "anchorY": 1,
  "anchorZ": 0,
  "blocks": [
    {
      "x": -1,
      "y": 4,
      "z": -1,
      "name": "Plant_Leaves_Camphor"
    },
    {
      "x": -1,
      "y": 4,
      "z": 0,
      "name": "Plant_Leaves_Camphor"
    },
    {
      "x": -1,
      "y": 5,
      "z": 1,
      "name": "Plant_Leaves_Camphor"
    },
    {
      "x": 0,
      "y": 4,
      "z": -2,
      "name": "Plant_Leaves_Camphor"
    },
    {
      "x": 0,
      "y": 3,
      "z": -1,
      "name": "Plant_Leaves_Camphor"
    },
    {
      "x": 0,
      "y": 4,
      "z": -1,
      "name": "Plant_Leaves_Camphor"
    },
    {
      "x": 0,
      "y": 4,
      "z": 0,
      "name": "Plant_Leaves_Camphor"
    },
    {
      "x": 0,
      "y": 5,
      "z": 0,
      "name": "Plant_Leaves_Camphor"
    },
    {
      "x": 0,
      "y": 4,
      "z": 1,
      "name": "Plant_Leaves_Camphor"
    },
    {
      "x": 0,
      "y": 4,
      "z": 2,
      "name": "Plant_Leaves_Camphor"
    },
    {
      "x": 1,
      "y": 3,
      "z": -3,
      "name": "Plant_Leaves_Camphor"
    },
    {
      "x": 1,
      "y": 4,
      "z": -3,
      "name": "Plant_Leaves_Camphor"
    },
    {
      "x": 1,
      "y": 4,
      "z": -2,
      "name": "Plant_Leaves_Camphor"
    },
    {
      "x": 1,
      "y": 4,
      "z": -1,
      "name": "Wood_Camphor_Branch_Corner",
      "rotation": 2
    },
    {
      "x": 1,
      "y": 5,
      "z": -1,
      "name": "Plant_Leaves_Camphor"
    },
    {
      "x": 1,
      "y": 1,
      "z": 0,
      "name": "Wood_Camphor_Branch_Long"
    },
    {
      "x": 1,
      "y": 2,
      "z": 0,
      "name": "Wood_Camphor_Branch_Long"
    },
    {
      "x": 1,
      "y": 3,
      "z": 0,
      "name": "Wood_Camphor_Branch_Long"
    },
    {
      "x": 1,
      "y": 4,
      "z": 0,
      "name": "Wood_Camphor_Branch_Corner",
      "rotation": 10
    },
    {
      "x": 1,
      "y": 5,
      "z": 0,
      "name": "Plant_Leaves_Camphor"
    },
    {
      "x": 1,
      "y": 4,
      "z": 1,
      "name": "Plant_Leaves_Camphor"
    },
    {
      "x": 1,
      "y": 5,
      "z": 1,
      "name": "Plant_Leaves_Camphor"
    },
    {
      "x": 1,
      "y": 4,
      "z": 2,
      "name": "Plant_Leaves_Camphor"
    },
    {
      "x": 1,
      "y": 5,
      "z": 2,
      "name": "Plant_Leaves_Camphor"
    },
    {
      "x": 1,
      "y": 3,
      "z": 3,
      "name": "Plant_Leaves_Camphor"
    },
    {
      "x": 1,
      "y": 4,
      "z": 3,
      "name": "Plant_Leaves_Camphor"
    },
    {
      "x": 2,
      "y": 4,
      "z": -2,
      "name": "Plant_Leaves_Camphor"
    },
    {
      "x": 2,
      "y": 5,
      "z": -2,
      "name": "Plant_Leaves_Camphor"
    },
    {
      "x": 2,
      "y": 5,
      "z": -1,
      "name": "Plant_Leaves_Camphor"
    },
    {
      "x": 2,
      "y": 4,
      "z": 0,
      "name": "Plant_Leaves_Camphor"
    },
    {
      "x": 2,
      "y": 5,
      "z": 0,
      "name": "Plant_Leaves_Camphor"
    },
    {
      "x": 2,
      "y": 3,
      "z": 1,
      "name": "Plant_Leaves_Camphor"
    },
    {
      "x": 2,
      "y": 4,
      "z": 1,
      "name": "Plant_Leaves_Camphor"
    },
    {
      "x": 2,
      "y": 5,
      "z": 1,
      "name": "Plant_Leaves_Camphor"
    },
    {
      "x": 2,
      "y": 5,
      "z": 2,
      "name": "Plant_Leaves_Camphor"
    },
    {
      "x": 3,
      "y": 3,
      "z": -2,
      "name": "Plant_Leaves_Camphor"
    },
    {
      "x": 3,
      "y": 4,
      "z": -2,
      "name": "Plant_Leaves_Camphor"
    },
    {
      "x": 3,
      "y": 4,
      "z": -1,
      "name": "Plant_Leaves_Camphor"
    },
    {
      "x": 3,
      "y": 4,
      "z": 0,
      "name": "Plant_Leaves_Camphor"
    }
  ]
}