{
  "version": 8,
  "blockIdVersion": 11,
  "anchorX": 1,
  "anchorY": 1,
  "anchorZ": 0,
  "blocks": [
    {
      "x": -8,
      "y": 5,
      "z": 0,
      "name": "Plant_Leaves_Camphor"
    },
    {
      "x": -7,
      "y": 5,
      "z": -3,
      "name": "Plant_Leaves_Camphor"
    },
    {
      "x": -7,
      "y": 6,
      "z": -3,
      "name": "Plant_Leaves_Camphor"
    },
    {
      "x": -7,
      "y": 4,
      "z": -2,
      "name": "Plant_Leaves_Camphor"
    },
    {
      "x": -7,
      "y": 5,
      "z": -2,
      "name": "Plant_Leaves_Camphor"
    },
    {
      "x": -7,
      "y": 4,
      "z": -1,
      "name": "Plant_Leaves_Camphor"
    },
    {
      "x": -7,
      "y": 5,
      "z": -1,
      "name": "Plant_Leaves_Camphor"
    },
    {
      "x": -7,
      "y": 6,
      "z": -1,
      "name": "Plant_Leaves_Camphor"
    },
    {
      "x": -7,
      "y": 5,
      "z": 0,
      "name": "Plant_Leaves_Camphor"
    },
    {
      "x": -6,
      "y": 5,
      "z": -3,
      "name": "Plant_Leaves_Camphor"
    },
    {
      "x": -6,
      "y": 6,
      "z": -3,
      "name": "Plant_Leaves_Camphor"
    },
    {
      "x": -6,
      "y": 9,
      "z": -3,
      "name": "Plant_Leaves_Camphor"
    },
    {
      "x": -6,
      "y": 5,
      "z": -2,
      "name": "Plant_Leaves_Camphor"
    },
    {
      "x": -6,
      "y": 9,
      "z": -2,
      "name": "Plant_Leaves_Camphor"
    },
    {
      "x": -6,
      "y": 5,
      "z": -1,
      "name": "Wood_Camphor_Branch_Long",
      "rotation": 5
    },
    {
      "x": -6,
      "y": 6,
      "z": -1,
      "name": "Plant_Leaves_Camphor"
    },
    {
      "x": -6,
      "y": 9,
      "z": -1,
      "name": "Plant_Leaves_Camphor"
    },
    {
      "x": -6,
      "y": 4,
      "z": 0,
      "name": "Plant_Leaves_Camphor"
    },
    {
      "x": -6,
      "y": 5,
      "z": 0,
      "name": "Plant_Leaves_Camphor"
    },
    {
      "x": -6,
      "y": 9,
      "z": 0,
      "name": "Plant_Leaves_Camphor"
    },
    {
      "x": -6,
      "y": 5,
      "z": 1,
      "name": "Plant_Leaves_Camphor"
    },
    {
      "x": -6,
      "y": 7,
      "z": 2,
      "name": "Plant_Leaves_Camphor"
    },
    {
      "x": -6,
      "y": 7,
      "z": 3,
      "name": "Plant_Leaves_Camphor"
    },
    {
      "x": -6,
      "y": 5,
      "z": 4,
      "name": "Plant_Leaves_Camphor"
    },
    {
      "x": -6,
      "y": 6,
      "z": 4,
      "name": "Plant_Leaves_Camphor"
    },
    {
      "x": -6,
      "y": 7,
      "z": 4,
      "name": "Plant_Leaves_Camphor"
    },
    {
      "x": -5,
      "y": 7,
      "z": -6,
      "name": "Plant_Leaves_Camphor"
    },
    {
      "x": -5,
      "y": 6,
      "z": -5,
      "name": "Plant_Leaves_Camphor"
    },
    {
      "x": -5,
      "y": 7,
      "z": -5,
      "name": "Plant_Leaves_Camphor"
    },
    {
      "x": -5,
      "y": 8,
      "z": -5,
      "name": "Plant_Leaves_Camphor"
    },
    {
      "x": -5,
      "y": 5,
      "z": -4,
      "name": "Plant_Leaves_Camphor"
    },
    {
      "x": -5,
      "y": 7,
      "z": -4,
      "name": "Plant_Leaves_Camphor"
    },
    {
      "x": -5,
      "y": 9,
      "z": -4,
      "name": "Plant_Leaves_Camphor"
    },
    {
      "x": -5,
      "y": 4,
      "z": -3,
      "name": "Plant_Leaves_Camphor"
    },
    {
      "x": -5,
      "y": 5,
      "z": -3,
      "name": "Plant_Leaves_Camphor"
    },
    {
      "x": -5,
      "y": 9,
      "z": -3,
      "name": "Plant_Leaves_Camphor"
    },
    {
      "x": -5,
      "y": 10,
      "z": -3,
      "name": "Plant_Leaves_Camphor"
    },
    {
      "x": -5,
      "y": 6,
      "z": -2,
      "name": "Plant_Leaves_Camphor"
    },
    {
      "x": -5,
      "y": 9,
      "z": -2,
      "name": "Wood_Camphor_Branch_Long",
      "rotation": 5
    },
    {
      "x": -5,
      "y": 10,
      "z": -2,
      "name": "Plant_Leaves_Camphor"
    },
    {
      "x": -5,
      "y": 5,
      "z": -1,
      "name": "Wood_Camphor_Branch_Long",
      "rotation": 5
    },
    {
      "x": -5,
      "y": 6,
      "z": -1,
      "name": "Plant_Leaves_Camphor"
    },
    {
      "x": -5,
      "y": 10,
      "z": -1,
      "name": "Plant_Leaves_Camphor"
    },
    {
      "x": -5,
      "y": 6,
      "z": 0,
      "name": "Plant_Leaves_Camphor"
    },
    {
      "x": -5,
      "y": 9,
      "z": 0,
      "name": "Plant_Leaves_Camphor"
    },
    {
      "x": -5,
      "y": 7,
      "z": 1,
      "name": "Plant_Leaves_Camphor"
    },
    {
      "x": -5,
      "y": 8,
      "z": 1,
      "name": "Plant_Leaves_Camphor"
    },
    {
      "x": -5,
      "y": 7,
      "z": 2,
      "name": "Wood_Camphor_Branch_Long",
      "rotation": 5
    },
    {
      "x": -5,
      "y": 8,
      "z": 2,
      "name": "Plant_Leaves_Camphor"
    },
    {
      "x": -5,
      "y": 12,
      "z": 2,
      "name": "Plant_Leaves_Camphor"
    },
    {
      "x": -5,
      "y": 7,
      "z": 3,
      "name": "Plant_Leaves_Camphor"
    },
    {
      "x": -5,
      "y": 8,
      "z": 3,
      "name": "Plant_Leaves_Camphor"
    },
    {
      "x": -5,
      "y": 9,
      "z": 3,
      "name": "Plant_Leaves_Camphor"
    },
    {
      "x": -5,
      "y": 7,
      "z": 4,
      "name": "Plant_Leaves_Camphor"
    },
    {
      "x": -5,
      "y": 8,
      "z": 4,
      "name": "Plant_Leaves_Camphor"
    },
    {
      "x": -4,
      "y": 6,
      "z": -7,
      "name": "Plant_Leaves_Camphor"
    },
    {
      "x": -4,
      "y": 7,
      "z": -7,
      "name": "Plant_Leaves_Camphor"
    },
    {
      "x": -4,
      "y": 7,
      "z": -6,
      "name": "Plant_Leaves_Camphor"
    },
    {
      "x": -4,
      "y": 7,
      "z": -5,
      "name": "Wood_Camphor_Branch_Long",
      "rotation": 5
    },
    {
      "x": -4,
      "y": 8,
      "z": -5,
      "name": "Plant_Leaves_Camphor"
    },
    {
      "x": -4,
      "y": 9,
      "z": -5,
      "name": "Plant_Leaves_Camphor"
    },
    {
      "x": -4,
      "y": 4,
      "z": -4,
      "name": "Plant_Leaves_Camphor"
    },
    {
      "x": -4,
      "y": 5,
      "z": -4,
      "name": "Plant_Leaves_Camphor"
    },
    {
      "x": -4,
      "y": 9,
      "z": -4,
      "name": "Plant_Leaves_Camphor"
    },
    {
      "x": -4,
      "y": 5,
      "z": -3,
      "name": "Wood_Camphor_Branch_Long",
      "rotation": 4
    },
    {
      "x": -4,
      "y": 6,
      "z": -3,
      "name": "Plant_Leaves_Camphor"
    },
    {
      "x": -4,
      "y": 10,
      "z": -3,
      "name": "Plant_Leaves_Camphor"
    },
    {
      "x": -4,
      "y": 5,
      "z": -2,
      "name": "Wood_Camphor_Branch_Long",
      "rotation": 4
    },
    {
      "x": -4,
      "y": 6,
      "z": -2,
      "name": "Plant_Leaves_Camphor"
    },
    {
      "x": -4,
      "y": 9,
      "z": -2,
      "name": "Wood_Camphor_Branch_Long",
      "rotation": 5
    },
    {
      "x": -4,
      "y": 10,
      "z": -2,
      "name": "Plant_Leaves_Camphor"
    },
    {
      "x": -4,
      "y": 12,
      "z": -2,
      "name": "Plant_Leaves_Camphor"
    },
    {
      "x": -4,
      "y": 5,
      "z": -1,
      "name": "Wood_Camphor_Trunk_Full"
    },
    {
      "x": -4,
      "y": 6,
      "z": -1,
      "name": "Plant_Leaves_Camphor"
    },
    {
      "x": -4,
      "y": 10,
      "z": -1,
      "name": "Plant_Leaves_Camphor"
    },
    {
      "x": -4,
      "y": 11,
      "z": -1,
      "name": "Plant_Leaves_Camphor"
    },
    {
      "x": -4,
      "y": 12,
      "z": -1,
      "name": "Plant_Leaves_Camphor"
    },
    {
      "x": -4,
      "y": 9,
      "z": 0,
      "name": "Plant_Leaves_Camphor"
    },
    {
      "x": -4,
      "y": 12,
      "z": 0,
      "name": "Plant_Leaves_Camphor"
    },
    {
      "x": -4,
      "y": 9,
      "z": 1,
      "name": "Plant_Leaves_Camphor"
    },
    {
      "x": -4,
      "y": 12,
      "z": 1,
      "name": "Plant_Leaves_Camphor"
    },
    {
      "x": -4,
      "y": 7,
      "z": 2,
      "name": "Wood_Camphor_Branch_Long",
      "rotation": 5
    },
    {
      "x": -4,
      "y": 8,
      "z": 2,
      "name": "Plant_Leaves_Camphor"
    },
    {
      "x": -4,
      "y": 11,
      "z": 2,
      "name": "Plant_Leaves_Camphor"
    },
    {
      "x": -4,
      "y": 12,
      "z": 2,
      "name": "Plant_Leaves_Camphor"
    },
    {
      "x": -4,
      "y": 7,
      "z": 4,
      "name": "Plant_Leaves_Camphor"
    },
    {
      "x": -4,
      "y": 8,
      "z": 4,
      "name": "Plant_Leaves_Camphor"
    },
    {
      "x": -4,
      "y": 7,
      "z": 5,
      "name": "Plant_Leaves_Camphor"
    },
    {
      "x": -3,
      "y": 5,
      "z": -7,
      "name": "Plant_Leaves_Camphor"
    },
    {
      "x": -3,
      "y": 6,
      "z": -7,
      "name": "Plant_Leaves_Camphor"
    },
    {
      "x": -3,
      "y": 7,
      "z": -7,
      "name": "Plant_Leaves_Camphor"
    },
    {
      "x": -3,
      "y": 8,
      "z": -6,
      "name": "Plant_Leaves_Camphor"
    },
    {
      "x": -3,
      "y": 7,
      "z": -5,
      "name": "Wood_Camphor_Branch_Long",
      "rotation": 5
    },
    {
      "x": -3,
      "y": 8,
      "z": -5,
      "name": "Plant_Leaves_Camphor"
    },
    {
      "x": -3,
      "y": 9,
      "z": -4,
      "name": "Plant_Leaves_Camphor"
    },
    {
      "x": -3,
      "y": 10,
      "z": -4,
      "name": "Plant_Leaves_Camphor"
    },
    {
      "x": -3,
      "y": 9,
      "z": -3,
      "name": "Wood_Camphor_Branch_Long",
      "rotation": 4
    },
    {
      "x": -3,
      "y": 10,
      "z": -3,
      "name": "Plant_Leaves_Camphor"
    },
    {
      "x": -3,
      "y": 12,
      "z": -3,
      "name": "Plant_Leaves_Camphor"
    },
    {
      "x": -3,
      "y": 9,
      "z": -2,
      "name": "Wood_Camphor_Trunk_Full"
    },
    {
      "x": -3,
      "y": 10,
      "z": -2,
      "name": "Plant_Leaves_Camphor"
    },
    {
      "x": -3,
      "y": 12,
      "z": -2,
      "name": "Plant_Leaves_Camphor"
    },
    {
      "x": -3,
      "y": 13,
      "z": -2,
      "name": "Plant_Leaves_Camphor"
    },
    {
      "x": -3,
      "y": 14,
      "z": -2,
      "name": "Plant_Leaves_Camphor"
    },
    {
      "x": -3,
      "y": 5,
      "z": -1,
      "name": "Wood_Camphor_Trunk_Full"
    },
    {
      "x": -3,
      "y": 9,
      "z": -1,
      "name": "Wood_Camphor_Branch_Long",
      "rotation": 4
    },
    {
      "x": -3,
      "y": 10,
      "z": -1,
      "name": "Plant_Leaves_Camphor"
    },
    {
      "x": -3,
      "y": 13,
      "z": -1,
      "name": "Plant_Leaves_Camphor"
    },
    {
      "x": -3,
      "y": 5,
      "z": 0,
      "name": "Wood_Camphor_Trunk_Full"
    },
    {
      "x": -3,
      "y": 9,
      "z": 0,
      "name": "Wood_Camphor_Branch_Long",
      "rotation": 4
    },
    {
      "x": -3,
      "y": 10,
      "z": 0,
      "name": "Plant_Leaves_Camphor"
    },
    {
      "x": -3,
      "y": 13,
      "z": 0,
      "name": "Plant_Leaves_Camphor"
    },
    {
      "x": -3,
      "y": 5,
      "z": 1,
      "name": "Wood_Camphor_Branch_Short"
    },
    {
      "x": -3,
      "y": 9,
      "z": 1,
      "name": "Plant_Leaves_Camphor"
    },
    {
      "x": -3,
      "y": 12,
      "z": 1,
      "name": "Wood_Camphor_Branch_Long",
      "rotation": 5
    },
    {
      "x": -3,
      "y": 13,
      "z": 1,
      "name": "Plant_Leaves_Camphor"
    },
    {
      "x": -3,
      "y": 14,
      "z": 1,
      "name": "Plant_Leaves_Camphor"
    },
    {
      "x": -3,
      "y": 7,
      "z": 2,
      "name": "Wood_Camphor_Trunk_Full"
    },
    {
      "x": -3,
      "y": 8,
      "z": 2,
      "name": "Plant_Leaves_Camphor"
    },
    {
      "x": -3,
      "y": 12,
      "z": 2,
      "name": "Plant_Leaves_Camphor"
    },
    {
      "x": -3,
      "y": 8,
      "z": 3,
      "name": "Plant_Leaves_Camphor"
    },
    {
      "x": -3,
      "y": 12,
      "z": 3,
      "name": "Plant_Leaves_Camphor"
    },
    {
      "x": -3,
      "y": 8,
      "z": 4,
      "name": "Plant_Leaves_Camphor"
    },
    {
      "x": -3,
      "y": 5,
      "z": 5,
      "name": "Plant_Leaves_Camphor"
    },
    {
      "x": -3,
      "y": 6,
      "z": 5,
      "name": "Plant_Leaves_Camphor"
    },
    {
      "x": -3,
      "y": 7,
      "z": 5,
      "name": "Plant_Leaves_Camphor"
    },
    {
      "x": -2,
      "y": 7,
      "z": -7,
      "name": "Plant_Leaves_Camphor"
    },
    {
      "x": -2,
      "y": 7,
      "z": -6,
      "name": "Wood_Camphor_Branch_Long",
      "rotation": 4
    },
    {
      "x": -2,
      "y": 8,
      "z": -6,
      "name": "Plant_Leaves_Camphor"
    },
    {
      "x": -2,
      "y": 7,
      "z": -5,
      "name": "Wood_Camphor_Trunk_Full"
    },
    {
      "x": -2,
      "y": 8,
      "z": -5,
      "name": "Plant_Leaves_Camphor"
    },
    {
      "x": -2,
      "y": 9,
      "z": -5,
      "name": "Plant_Leaves_Camphor"
    },
    {
      "x": -2,
      "y": 7,
      "z": -4,
      "name": "Wood_Camphor_Trunk_Full"
    },
    {
      "x": -2,
      "y": 12,
      "z": -3,
      "name": "Plant_Leaves_Camphor"
    },
    {
      "x": -2,
      "y": 9,
      "z": -2,
      "name": "Wood_Camphor_Trunk_Full"
    },
    {
      "x": -2,
      "y": 11,
      "z": -2,
      "name": "Plant_Leaves_Camphor"
    },
    {
      "x": -2,
      "y": 12,
      "z": -2,
      "name": "Plant_Leaves_Camphor"
    },
    {
      "x": -2,
      "y": 8,
      "z": -1,
      "name": "Wood_Camphor_Branch_Short",
      "rotation": 3
    },
    {
      "x": -2,
      "y": 9,
      "z": -1,
      "name": "Wood_Camphor_Trunk_Full"
    },
    {
      "x": -2,
      "y": 13,
      "z": -1,
      "name": "Plant_Leaves_Camphor"
    },
    {
      "x": -2,
      "y": 4,
      "z": 0,
      "name": "Wood_Camphor_Trunk_Full"
    },
    {
      "x": -2,
      "y": 5,
      "z": 0,
      "name": "Wood_Camphor_Trunk_Full"
    },
    {
      "x": -2,
      "y": 13,
      "z": 0,
      "name": "Plant_Leaves_Camphor"
    },
    {
      "x": -2,
      "y": 12,
      "z": 1,
      "name": "Wood_Camphor_Branch_Long",
      "rotation": 5
    },
    {
      "x": -2,
      "y": 13,
      "z": 1,
      "name": "Plant_Leaves_Camphor"
    },
    {
      "x": -2,
      "y": 7,
      "z": 2,
      "name": "Wood_Camphor_Trunk_Full"
    },
    {
      "x": -2,
      "y": 8,
      "z": 2,
      "name": "Plant_Leaves_Camphor"
    },
    {
      "x": -2,
      "y": 13,
      "z": 2,
      "name": "Plant_Leaves_Camphor"
    },
    {
      "x": -2,
      "y": 6,
      "z": 3,
      "name": "Wood_Camphor_Trunk_Full"
    },
    {
      "x": -2,
      "y": 7,
      "z": 3,
      "name": "Wood_Camphor_Trunk_Full"
    },
    {
      "x": -2,
      "y": 8,
      "z": 3,
      "name": "Plant_Leaves_Camphor"
    },
    {
      "x": -2,
      "y": 12,
      "z": 3,
      "name": "Plant_Leaves_Camphor"
    },
    {
      "x": -2,
      "y": 13,
      "z": 3,
      "name": "Plant_Leaves_Camphor"
    },
    {
      "x": -2,
      "y": 7,
      "z": 4,
      "name": "Wood_Camphor_Branch_Long",
      "rotation": 4
    },
    {
      "x": -2,
      "y": 8,
      "z": 4,
      "name": "Plant_Leaves_Camphor"
    },
    {
      "x": -2,
      "y": 11,
      "z": 4,
      "name": "Plant_Leaves_Camphor"
    },
    {
      "x": -2,
      "y": 12,
      "z": 4,
      "name": "Plant_Leaves_Camphor"
    },
    {
      "x": -2,
      "y": 7,
      "z": 5,
      "name": "Plant_Leaves_Camphor"
    },
    {
      "x": -2,
      "y": 12,
      "z": 5,
      "name": "Plant_Leaves_Camphor"
    },
    {
      "x": -2,
      "y": 6,
      "z": 6,
      "name": "Plant_Leaves_Camphor"
    },
    {
      "x": -2,
      "y": 6,
      "z": 7,
      "name": "Plant_Leaves_Camphor"
    },
    {
      "x": -1,
      "y": 7,
      "z": -8,
      "name": "Plant_Leaves_Camphor"
    },
    {
      "x": -1,
      "y": 6,
      "z": -5,
      "name": "Wood_Camphor_Branch_Short",
      "rotation": 2
    },
    {
      "x": -1,
      "y": 6,
      "z": -4,
      "name": "Wood_Camphor_Trunk_Full"
    },
    {
      "x": -1,
      "y": 7,
      "z": -4,
      "name": "Wood_Camphor_Trunk_Full"
    },
    {
      "x": -1,
      "y": 6,
      "z": -3,
      "name": "Wood_Camphor_Trunk_Full"
    },
    {
      "x": -1,
      "y": 12,
      "z": -3,
      "name": "Plant_Leaves_Camphor"
    },
    {
      "x": -1,
      "y": 13,
      "z": -3,
      "name": "Plant_Leaves_Camphor"
    },
    {
      "x": -1,
      "y": 12,
      "z": -2,
      "name": "Wood_Camphor_Branch_Long",
      "rotation": 4
    },
    {
      "x": -1,
      "y": 13,
      "z": -2,
      "name": "Plant_Leaves_Camphor"
    },
    {
      "x": -1,
      "y": 8,
      "z": -1,
      "name": "Wood_Camphor_Trunk_Full"
    },
    {
      "x": -1,
      "y": 9,
      "z": -1,
      "name": "Wood_Camphor_Trunk_Full"
    },
    {
      "x": -1,
      "y": 12,
      "z": -1,
      "name": "Wood_Camphor_Branch_Long",
      "rotation": 4
    },
    {
      "x": -1,
      "y": 13,
      "z": -1,
      "name": "Plant_Leaves_Camphor"
    },
    {
      "x": -1,
      "y": 15,
      "z": -1,
      "name": "Plant_Leaves_Camphor"
    },
    {
      "x": -1,
      "y": 1,
      "z": 0,
      "name": "Wood_Camphor_Trunk_Full"
    },
    {
      "x": -1,
      "y": 3,
      "z": 0,
      "name": "Wood_Camphor_Trunk"
    },
    {
      "x": -1,
      "y": 4,
      "z": 0,
      "name": "Wood_Camphor_Trunk_Full"
    },
    {
      "x": -1,
      "y": 9,
      "z": 0,
      "name": "Wood_Camphor_Branch_Long",
      "rotation": 4
    },
    {
      "x": -1,
      "y": 11,
      "z": 0,
      "name": "Wood_Camphor_Trunk_Full"
    },
    {
      "x": -1,
      "y": 12,
      "z": 0,
      "name": "Wood_Camphor_Trunk_Full"
    },
    {
      "x": -1,
      "y": 13,
      "z": 0,
      "name": "Plant_Leaves_Camphor"
    },
    {
      "x": -1,
      "y": 15,
      "z": 0,
      "name": "Plant_Leaves_Camphor"
    },
    {
      "x": -1,
      "y": 12,
      "z": 1,
      "name": "Wood_Camphor_Trunk_Full"
    },
    {
      "x": -1,
      "y": 13,
      "z": 1,
      "name": "Plant_Leaves_Camphor"
    },
    {
      "x": -1,
      "y": 15,
      "z": 1,
      "name": "Plant_Leaves_Camphor"
    },
    {
      "x": -1,
      "y": 12,
      "z": 2,
      "name": "Wood_Camphor_Branch_Long",
      "rotation": 4
    },
    {
      "x": -1,
      "y": 13,
      "z": 2,
      "name": "Plant_Leaves_Camphor"
    },
    {
      "x": -1,
      "y": 6,
      "z": 3,
      "name": "Wood_Camphor_Trunk_Full"
    },
    {
      "x": -1,
      "y": 7,
      "z": 3,
      "name": "Plant_Leaves_Camphor"
    },
    {
      "x": -1,
      "y": 12,
      "z": 3,
      "name": "Wood_Camphor_Branch_Long",
      "rotation": 4
    },
    {
      "x": -1,
      "y": 13,
      "z": 3,
      "name": "Plant_Leaves_Camphor"
    },
    {
      "x": -1,
      "y": 9,
      "z": 4,
      "name": "Plant_Leaves_Camphor"
    },
    {
      "x": -1,
      "y": 10,
      "z": 4,
      "name": "Plant_Leaves_Camphor"
    },
    {
      "x": -1,
      "y": 12,
      "z": 4,
      "name": "Plant_Leaves_Camphor"
    },
    {
      "x": -1,
      "y": 13,
      "z": 4,
      "name": "Plant_Leaves_Camphor"
    },
    {
      "x": -1,
      "y": 9,
      "z": 5,
      "name": "Plant_Leaves_Camphor"
    },
    {
      "x": -1,
      "y": 6,
      "z": 6,
      "name": "Wood_Camphor_Branch_Long",
      "rotation": 5
    },
    {
      "x": -1,
      "y": 7,
      "z": 6,
      "name": "Plant_Leaves_Camphor"
    },
    {
      "x": -1,
      "y": 9,
      "z": 6,
      "name": "Plant_Leaves_Camphor"
    },
    {
      "x": -1,
      "y": 5,
      "z": 7,
      "name": "Plant_Leaves_Camphor"
    },
    {
      "x": -1,
      "y": 6,
      "z": 7,
      "name": "Plant_Leaves_Camphor"
    },
    {
      "x": -1,
      "y": 6,
      "z": 8,
      "name": "Plant_Leaves_Camphor"
    },
    {
      "x": 0,
      "y": 7,
      "z": -9,
      "name": "Plant_Leaves_Camphor"
    },
    {
      "x": 0,
      "y": 6,
      "z": -8,
      "name": "Plant_Leaves_Camphor"
    },
    {
      "x": 0,
      "y": 7,
      "z": -8,
      "name": "Plant_Leaves_Camphor"
    },
    {
      "x": 0,
      "y": 8,
      "z": -8,
      "name": "Plant_Leaves_Camphor"
    },
    {
      "x": 0,
      "y": 8,
      "z": -7,
      "name": "Plant_Leaves_Camphor"
    },
    {
      "x": 0,
      "y": 11,
      "z": -6,
      "name": "Plant_Leaves_Camphor"
    },
    {
      "x": 0,
      "y": 10,
      "z": -5,
      "name": "Plant_Leaves_Camphor"
    },
    {
      "x": 0,
      "y": 11,
      "z": -5,
      "name": "Plant_Leaves_Camphor"
    },
    {
      "x": 0,
      "y": 12,
      "z": -4,
      "name": "Plant_Leaves_Camphor"
    },
    {
      "x": 0,
      "y": 6,
      "z": -3,
      "name": "Wood_Camphor_Trunk_Full"
    },
    {
      "x": 0,
      "y": 12,
      "z": -3,
      "name": "Plant_Leaves_Camphor"
    },
    {
      "x": 0,
      "y": 13,
      "z": -3,
      "name": "Plant_Leaves_Camphor"
    },
    {
      "x": 0,
      "y": 1,
      "z": -1,
      "name": "Wood_Camphor_Trunk"
    },
    {
      "x": 0,
      "y": 2,
      "z": -1,
      "name": "Wood_Camphor_Trunk"
    },
    {
      "x": 0,
      "y": 3,
      "z": -1,
      "name": "Wood_Camphor_Trunk_Full"
    },
    {
      "x": 0,
      "y": 8,
      "z": -1,
      "name": "Wood_Camphor_Trunk_Full"
    },
    {
      "x": 0,
      "y": 13,
      "z": -1,
      "name": "Plant_Leaves_Camphor"
    },
    {
      "x": 0,
      "y": 15,
      "z": -1,
      "name": "Plant_Leaves_Camphor"
    },
    {
      "x": 0,
      "y": 1,
      "z": 0,
      "name": "Wood_Camphor_Trunk_Full"
    },
    {
      "x": 0,
      "y": 2,
      "z": 0,
      "name": "Wood_Camphor_Trunk"
    },
    {
      "x": 0,
      "y": 3,
      "z": 0,
      "name": "Wood_Camphor_Trunk"
    },
    {
      "x": 0,
      "y": 4,
      "z": 0,
      "name": "Wood_Camphor_Trunk_Full"
    },
    {
      "x": 0,
      "y": 7,
      "z": 0,
      "name": "Wood_Camphor_Trunk_Full",
      "rotation": 5
    },
    {
      "x": 0,
      "y": 8,
      "z": 0,
      "name": "Wood_Camphor_Trunk_Full"
    },
    {
      "x": 0,
      "y": 11,
      "z": 0,
      "name": "Wood_Camphor_Trunk_Full"
    },
    {
      "x": 0,
      "y": 15,
      "z": 0,
      "name": "Plant_Leaves_Camphor"
    },
    {
      "x": 0,
      "y": 16,
      "z": 0,
      "name": "Plant_Leaves_Camphor"
    },
    {
      "x": 0,
      "y": 12,
      "z": 1,
      "name": "Plant_Leaves_Camphor"
    },
    {
      "x": 0,
      "y": 15,
      "z": 1,
      "name": "Plant_Leaves_Camphor"
    },
    {
      "x": 0,
      "y": 13,
      "z": 2,
      "name": "Plant_Leaves_Camphor"
    },
    {
      "x": 0,
      "y": 14,
      "z": 2,
      "name": "Plant_Leaves_Camphor"
    },
    {
      "x": 0,
      "y": 5,
      "z": 3,
      "name": "Wood_Camphor_Trunk_Full"
    },
    {
      "x": 0,
      "y": 6,
      "z": 3,
      "name": "Wood_Camphor_Trunk_Full"
    },
    {
      "x": 0,
      "y": 9,
      "z": 3,
      "name": "Wood_Camphor_Branch_Long",
      "rotation": 5
    },
    {
      "x": 0,
      "y": 12,
      "z": 3,
      "name": "Plant_Leaves_Camphor"
    },
    {
      "x": 0,
      "y": 13,
      "z": 3,
      "name": "Plant_Leaves_Camphor"
    },
    {
      "x": 0,
      "y": 6,
      "z": 4,
      "name": "Wood_Camphor_Trunk_Full"
    },
    {
      "x": 0,
      "y": 9,
      "z": 4,
      "name": "Wood_Camphor_Branch_Long",
      "rotation": 5
    },
    {
      "x": 0,
      "y": 10,
      "z": 4,
      "name": "Plant_Leaves_Camphor"
    },
    {
      "x": 0,
      "y": 12,
      "z": 4,
      "name": "Plant_Leaves_Camphor"
    },
    {
      "x": 0,
      "y": 6,
      "z": 5,
      "name": "Wood_Camphor_Trunk_Full"
    },
    {
      "x": 0,
      "y": 10,
      "z": 5,
      "name": "Plant_Leaves_Camphor"
    },
    {
      "x": 0,
      "y": 6,
      "z": 6,
      "name": "Wood_Camphor_Trunk_Full"
    },
    {
      "x": 0,
      "y": 7,
      "z": 6,
      "name": "Plant_Leaves_Camphor"
    },
    {
      "x": 0,
      "y": 9,
      "z": 6,
      "name": "Plant_Leaves_Camphor"
    },
    {
      "x": 0,
      "y": 6,
      "z": 7,
      "name": "Wood_Camphor_Branch_Long",
      "rotation": 4
    },
    {
      "x": 0,
      "y": 7,
      "z": 7,
      "name": "Plant_Leaves_Camphor"
    },
    {
      "x": 0,
      "y": 9,
      "z": 7,
      "name": "Plant_Leaves_Camphor"
    },
    {
      "x": 0,
      "y": 6,
      "z": 8,
      "name": "Plant_Leaves_Camphor"
    },
    {
      "x": 0,
      "y": 7,
      "z": 8,
      "name": "Plant_Leaves_Camphor"
    },
    {
      "x": 1,
      "y": 7,
      "z": -9,
      "name": "Plant_Leaves_Camphor"
    },
    {
      "x": 1,
      "y": 7,
      "z": -8,
      "name": "Wood_Camphor_Branch_Long",
      "rotation": 4
    },
    {
      "x": 1,
      "y": 8,
      "z": -8,
      "name": "Plant_Leaves_Camphor"
    },
    {
      "x": 1,
      "y": 7,
      "z": -7,
      "name": "Wood_Camphor_Branch_Long",
      "rotation": 4
    },
    {
      "x": 1,
      "y": 8,
      "z": -7,
      "name": "Plant_Leaves_Camphor"
    },
    {
      "x": 1,
      "y": 10,
      "z": -7,
      "name": "Plant_Leaves_Camphor"
    },
    {
      "x": 1,
      "y": 11,
      "z": -7,
      "name": "Plant_Leaves_Camphor"
    },
    {
      "x": 1,
      "y": 7,
      "z": -6,
      "name": "Wood_Camphor_Trunk_Full"
    },
    {
      "x": 1,
      "y": 8,
      "z": -6,
      "name": "Plant_Leaves_Camphor"
    },
    {
      "x": 1,
      "y": 11,
      "z": -6,
      "name": "Plant_Leaves_Camphor"
    },
    {
      "x": 1,
      "y": 7,
      "z": -5,
      "name": "Wood_Camphor_Trunk_Full"
    },
    {
      "x": 1,
      "y": 6,
      "z": -4,
      "name": "Wood_Camphor_Trunk_Full"
    },
    {
      "x": 1,
      "y": 7,
      "z": -4,
      "name": "Wood_Camphor_Trunk_Full"
    },
    {
      "x": 1,
      "y": 11,
      "z": -4,
      "name": "Plant_Leaves_Camphor"
    },
    {
      "x": 1,
      "y": 12,
      "z": -4,
      "name": "Plant_Leaves_Camphor"
    },
    {
      "x": 1,
      "y": 5,
      "z": -3,
      "name": "Wood_Camphor_Trunk_Full"
    },
    {
      "x": 1,
      "y": 6,
      "z": -3,
      "name": "Wood_Camphor_Trunk_Full"
    },
    {
      "x": 1,
      "y": 11,
      "z": -3,
      "name": "Wood_Camphor_Trunk_Full"
    },
    {
      "x": 1,
      "y": 12,
      "z": -3,
      "name": "Plant_Leaves_Camphor"
    },
    {
      "x": 1,
      "y": 15,
      "z": -3,
      "name": "Plant_Leaves_Camphor"
    },
    {
      "x": 1,
      "y": 1,
      "z": -2,
      "name": "Wood_Camphor_Trunk_Full"
    },
    {
      "x": 1,
      "y": 4,
      "z": -2,
      "name": "Wood_Camphor_Trunk_Full"
    },
    {
      "x": 1,
      "y": 5,
      "z": -2,
      "name": "Wood_Camphor_Trunk_Full"
    },
    {
      "x": 1,
      "y": 10,
      "z": -2,
      "name": "Wood_Camphor_Trunk_Full"
    },
    {
      "x": 1,
      "y": 11,
      "z": -2,
      "name": "Wood_Camphor_Trunk_Full"
    },
    {
      "x": 1,
      "y": 13,
      "z": -2,
      "name": "Plant_Leaves_Camphor"
    },
    {
      "x": 1,
      "y": 15,
      "z": -2,
      "name": "Plant_Leaves_Camphor"
    },
    {
      "x": 1,
      "y": 1,
      "z": -1,
      "name": "Wood_Camphor_Trunk"
    },
    {
      "x": 1,
      "y": 2,
      "z": -1,
      "name": "Wood_Camphor_Trunk"
    },
    {
      "x": 1,
      "y": 3,
      "z": -1,
      "name": "Wood_Camphor_Trunk"
    },
    {
      "x": 1,
      "y": 4,
      "z": -1,
      "name": "Wood_Camphor_Trunk_Full"
    },
    {
      "x": 1,
      "y": 10,
      "z": -1,
      "name": "Wood_Camphor_Trunk_Full"
    },
    {
      "x": 1,
      "y": 13,
      "z": -1,
      "name": "Plant_Leaves_Camphor"
    },
    {
      "x": 1,
      "y": 15,
      "z": -1,
      "name": "Plant_Leaves_Camphor"
    },
    {
      "x": 1,
      "y": 16,
      "z": -1,
      "name": "Plant_Leaves_Camphor"
    },
    {
      "x": 1,
      "y": 1,
      "z": 0,
      "name": "Wood_Camphor_Trunk"
    },
    {
      "x": 1,
      "y": 2,
      "z": 0,
      "name": "Wood_Camphor_Trunk"
    },
    {
      "x": 1,
      "y": 3,
      "z": 0,
      "name": "Wood_Camphor_Trunk"
    },
    {
      "x": 1,
      "y": 4,
      "z": 0,
      "name": "Wood_Camphor_Trunk"
    },
    {
      "x": 1,
      "y": 5,
      "z": 0,
      "name": "Wood_Camphor_Trunk"
    },
    {
      "x": 1,
      "y": 6,
      "z": 0,
      "name": "Wood_Camphor_Trunk"
    },
    {
      "x": 1,
      "y": 7,
      "z": 0,
      "name": "Wood_Camphor_Trunk"
    },
    {
      "x": 1,
      "y": 8,
      "z": 0,
      "name": "Wood_Camphor_Trunk"
    },
    {
      "x": 1,
      "y": 9,
      "z": 0,
      "name": "Wood_Camphor_Trunk"
    },
    {
      "x": 1,
      "y": 10,
      "z": 0,
      "name": "Wood_Camphor_Trunk"
    },
    {
      "x": 1,
      "y": 11,
      "z": 0,
      "name": "Wood_Camphor_Trunk"
    },
    {
      "x": 1,
      "y": 12,
      "z": 0,
      "name": "Wood_Camphor_Trunk"
    },
    {
      "x": 1,
      "y": 13,
      "z": 0,
      "name": "Wood_Camphor_Trunk_Full"
    },
    {
      "x": 1,
      "y": 14,
      "z": 0,
      "name": "Wood_Camphor_Branch_Long"
    },
    {
      "x": 1,
      "y": 15,
      "z": 0,
      "name": "Wood_Camphor_Branch_Long"
    },
    {
      "x": 1,
      "y": 16,
      "z": 0,
      "name": "Plant_Leaves_Camphor"
    },
    {
      "x": 1,
      "y": 1,
      "z": 1,
      "name": "Wood_Camphor_Trunk_Full"
    },
    {
      "x": 1,
      "y": 2,
      "z": 1,
      "name": "Wood_Camphor_Trunk_Full"
    },
    {
      "x": 1,
      "y": 4,
      "z": 1,
      "name": "Wood_Camphor_Trunk_Full"
    },
    {
      "x": 1,
      "y": 5,
      "z": 1,
      "name": "Wood_Camphor_Trunk_Full"
    },
    {
      "x": 1,
      "y": 8,
      "z": 1,
      "name": "Wood_Camphor_Trunk_Full"
    },
    {
      "x": 1,
      "y": 11,
      "z": 1,
      "name": "Wood_Camphor_Branch_Short"
    },
    {
      "x": 1,
      "y": 13,
      "z": 1,
      "name": "Wood_Camphor_Branch_Long",
      "rotation": 4
    },
    {
      "x": 1,
      "y": 15,
      "z": 1,
      "name": "Plant_Leaves_Camphor"
    },
    {
      "x": 1,
      "y": 5,
      "z": 2,
      "name": "Wood_Camphor_Trunk_Full"
    },
    {
      "x": 1,
      "y": 8,
      "z": 2,
      "name": "Wood_Camphor_Trunk_Full"
    },
    {
      "x": 1,
      "y": 9,
      "z": 2,
      "name": "Wood_Camphor_Trunk_Full"
    },
    {
      "x": 1,
      "y": 13,
      "z": 2,
      "name": "Plant_Leaves_Camphor"
    },
    {
      "x": 1,
      "y": 15,
      "z": 2,
      "name": "Plant_Leaves_Camphor"
    },
    {
      "x": 1,
      "y": 5,
      "z": 3,
      "name": "Wood_Camphor_Trunk_Full"
    },
    {
      "x": 1,
      "y": 9,
      "z": 3,
      "name": "Wood_Camphor_Trunk_Full"
    },
    {
      "x": 1,
      "y": 13,
      "z": 3,
      "name": "Plant_Leaves_Camphor"
    },
    {
      "x": 1,
      "y": 15,
      "z": 3,
      "name": "Plant_Leaves_Camphor"
    },
    {
      "x": 1,
      "y": 9,
      "z": 4,
      "name": "Wood_Camphor_Trunk_Full"
    },
    {
      "x": 1,
      "y": 6,
      "z": 5,
      "name": "Plant_Leaves_Camphor"
    },
    {
      "x": 1,
      "y": 9,
      "z": 5,
      "name": "Wood_Camphor_Branch_Long",
      "rotation": 4
    },
    {
      "x": 1,
      "y": 10,
      "z": 5,
      "name": "Plant_Leaves_Camphor"
    },
    {
      "x": 1,
      "y": 9,
      "z": 6,
      "name": "Wood_Camphor_Branch_Long",
      "rotation": 4
    },
    {
      "x": 1,
      "y": 10,
      "z": 6,
      "name": "Plant_Leaves_Camphor"
    },
    {
      "x": 1,
      "y": 7,
      "z": 7,
      "name": "Plant_Leaves_Camphor"
    },
    {
      "x": 1,
      "y": 9,
      "z": 7,
      "name": "Plant_Leaves_Camphor"
    },
    {
      "x": 1,
      "y": 10,
      "z": 7,
      "name": "Plant_Leaves_Camphor"
    },
    {
      "x": 1,
      "y": 5,
      "z": 8,
      "name": "Plant_Leaves_Camphor"
    },
    {
      "x": 1,
      "y": 6,
      "z": 8,
      "name": "Plant_Leaves_Camphor"
    },
    {
      "x": 2,
      "y": 7,
      "z": -9,
      "name": "Plant_Leaves_Camphor"
    },
    {
      "x": 2,
      "y": 7,
      "z": -8,
      "name": "Plant_Leaves_Camphor"
    },
    {
      "x": 2,
      "y": 8,
      "z": -7,
      "name": "Plant_Leaves_Camphor"
    },
    {
      "x": 2,
      "y": 10,
      "z": -7,
      "name": "Plant_Leaves_Camphor"
    },
    {
      "x": 2,
      "y": 11,
      "z": -7,
      "name": "Plant_Leaves_Camphor"
    },
    {
      "x": 2,
      "y": 7,
      "z": -6,
      "name": "Wood_Camphor_Branch_Long",
      "rotation": 5
    },
    {
      "x": 2,
      "y": 8,
      "z": -6,
      "name": "Plant_Leaves_Camphor"
    },
    {
      "x": 2,
      "y": 11,
      "z": -6,
      "name": "Wood_Camphor_Branch_Long",
      "rotation": 4
    },
    {
      "x": 2,
      "y": 12,
      "z": -6,
      "name": "Plant_Leaves_Camphor"
    },
    {
      "x": 2,
      "y": 11,
      "z": -5,
      "name": "Wood_Camphor_Branch_Long",
      "rotation": 4
    },
    {
      "x": 2,
      "y": 12,
      "z": -5,
      "name": "Plant_Leaves_Camphor"
    },
    {
      "x": 2,
      "y": 11,
      "z": -4,
      "name": "Wood_Camphor_Trunk_Full"
    },
    {
      "x": 2,
      "y": 12,
      "z": -4,
      "name": "Plant_Leaves_Camphor"
    },
    {
      "x": 2,
      "y": 11,
      "z": -3,
      "name": "Wood_Camphor_Trunk_Full"
    },
    {
      "x": 2,
      "y": 12,
      "z": -3,
      "name": "Plant_Leaves_Camphor"
    },
    {
      "x": 2,
      "y": 13,
      "z": -3,
      "name": "Plant_Leaves_Camphor"
    },
    {
      "x": 2,
      "y": 11,
      "z": -2,
      "name": "Plant_Leaves_Camphor"
    },
    {
      "x": 2,
      "y": 13,
      "z": -2,
      "name": "Plant_Leaves_Camphor"
    },
    {
      "x": 2,
      "y": 14,
      "z": -2,
      "name": "Plant_Leaves_Camphor"
    },
    {
      "x": 2,
      "y": 3,
      "z": -1,
      "name": "Wood_Camphor_Trunk_Full"
    },
    {
      "x": 2,
      "y": 4,
      "z": -1,
      "name": "Wood_Camphor_Trunk_Full"
    },
    {
      "x": 2,
      "y": 14,
      "z": -1,
      "name": "Plant_Leaves_Camphor"
    },
    {
      "x": 2,
      "y": 15,
      "z": -1,
      "name": "Plant_Leaves_Camphor"
    },
    {
      "x": 2,
      "y": 16,
      "z": -1,
      "name": "Plant_Leaves_Camphor"
    },
    {
      "x": 2,
      "y": 1,
      "z": 0,
      "name": "Wood_Camphor_Trunk_Full"
    },
    {
      "x": 2,
      "y": 7,
      "z": 0,
      "name": "Wood_Camphor_Trunk_Full"
    },
    {
      "x": 2,
      "y": 10,
      "z": 0,
      "name": "Wood_Camphor_Trunk_Full"
    },
    {
      "x": 2,
      "y": 13,
      "z": 0,
      "name": "Wood_Camphor_Branch_Long",
      "rotation": 5
    },
    {
      "x": 2,
      "y": 14,
      "z": 0,
      "name": "Plant_Leaves_Camphor"
    },
    {
      "x": 2,
      "y": 15,
      "z": 0,
      "name": "Plant_Leaves_Camphor"
    },
    {
      "x": 2,
      "y": 16,
      "z": 0,
      "name": "Plant_Leaves_Camphor"
    },
    {
      "x": 2,
      "y": 13,
      "z": 1,
      "name": "Plant_Leaves_Camphor"
    },
    {
      "x": 2,
      "y": 14,
      "z": 1,
      "name": "Plant_Leaves_Camphor"
    },
    {
      "x": 2,
      "y": 15,
      "z": 1,
      "name": "Plant_Leaves_Camphor"
    },
    {
      "x": 2,
      "y": 16,
      "z": 1,
      "name": "Plant_Leaves_Camphor"
    },
    {
      "x": 2,
      "y": 5,
      "z": 2,
      "name": "Wood_Camphor_Trunk_Full"
    },
    {
      "x": 2,
      "y": 13,
      "z": 2,
      "name": "Plant_Leaves_Camphor"
    },
    {
      "x": 2,
      "y": 15,
      "z": 2,
      "name": "Plant_Leaves_Camphor"
    },
    {
      "x": 2,
      "y": 12,
      "z": 3,
      "name": "Plant_Leaves_Camphor"
    },
    {
      "x": 2,
      "y": 9,
      "z": 4,
      "name": "Wood_Camphor_Branch_Long",
      "rotation": 5
    },
    {
      "x": 2,
      "y": 10,
      "z": 4,
      "name": "Plant_Leaves_Camphor"
    },
    {
      "x": 2,
      "y": 6,
      "z": 5,
      "name": "Wood_Camphor_Branch_Long",
      "rotation": 5
    },
    {
      "x": 2,
      "y": 7,
      "z": 5,
      "name": "Plant_Leaves_Camphor"
    },
    {
      "x": 2,
      "y": 10,
      "z": 5,
      "name": "Plant_Leaves_Camphor"
    },
    {
      "x": 2,
      "y": 6,
      "z": 6,
      "name": "Plant_Leaves_Camphor"
    },
    {
      "x": 2,
      "y": 10,
      "z": 6,
      "name": "Plant_Leaves_Camphor"
    },
    {
      "x": 2,
      "y": 5,
      "z": 7,
      "name": "Plant_Leaves_Camphor"
    },
    {
      "x": 2,
      "y": 6,
      "z": 7,
      "name": "Plant_Leaves_Camphor"
    },
    {
      "x": 2,
      "y": 9,
      "z": 7,
      "name": "Plant_Leaves_Camphor"
    },
    {
      "x": 3,
      "y": 6,
      "z": -8,
      "name": "Plant_Leaves_Camphor"
    },
    {
      "x": 3,
      "y": 7,
      "z": -8,
      "name": "Plant_Leaves_Camphor"
    },
    {
      "x": 3,
      "y": 7,
      "z": -7,
      "name": "Plant_Leaves_Camphor"
    },
    {
      "x": 3,
      "y": 8,
      "z": -7,
      "name": "Plant_Leaves_Camphor"
    },
    {
      "x": 3,
      "y": 11,
      "z": -7,
      "name": "Plant_Leaves_Camphor"
    },
    {
      "x": 3,
      "y": 3,
      "z": -6,
      "name": "Plant_Leaves_Camphor"
    },
    {
      "x": 3,
      "y": 4,
      "z": -6,
      "name": "Plant_Leaves_Camphor"
    },
    {
      "x": 3,
      "y": 7,
      "z": -6,
      "name": "Wood_Camphor_Branch_Long",
      "rotation": 5
    },
    {
      "x": 3,
      "y": 8,
      "z": -6,
      "name": "Plant_Leaves_Camphor"
    },
    {
      "x": 3,
      "y": 12,
      "z": -6,
      "name": "Plant_Leaves_Camphor"
    },
    {
      "x": 3,
      "y": 4,
      "z": -5,
      "name": "Plant_Leaves_Camphor"
    },
    {
      "x": 3,
      "y": 12,
      "z": -5,
      "name": "Plant_Leaves_Camphor"
    },
    {
      "x": 3,
      "y": 11,
      "z": -4,
      "name": "Wood_Camphor_Branch_Long",
      "rotation": 5
    },
    {
      "x": 3,
      "y": 12,
      "z": -4,
      "name": "Plant_Leaves_Camphor"
    },
    {
      "x": 3,
      "y": 11,
      "z": -3,
      "name": "Plant_Leaves_Camphor"
    },
    {
      "x": 3,
      "y": 4,
      "z": -2,
      "name": "Wood_Camphor_Trunk_Full"
    },
    {
      "x": 3,
      "y": 11,
      "z": -2,
      "name": "Plant_Leaves_Camphor"
    },
    {
      "x": 3,
      "y": 12,
      "z": -2,
      "name": "Plant_Leaves_Camphor"
    },
    {
      "x": 3,
      "y": 13,
      "z": -2,
      "name": "Plant_Leaves_Camphor"
    },
    {
      "x": 3,
      "y": 14,
      "z": -2,
      "name": "Plant_Leaves_Camphor"
    },
    {
      "x": 3,
      "y": 4,
      "z": -1,
      "name": "Wood_Camphor_Trunk_Full"
    },
    {
      "x": 3,
      "y": 11,
      "z": -1,
      "name": "Wood_Camphor_Branch_Long",
      "rotation": 4
    },
    {
      "x": 3,
      "y": 13,
      "z": -1,
      "name": "Plant_Leaves_Camphor"
    },
    {
      "x": 3,
      "y": 7,
      "z": 0,
      "name": "Wood_Camphor_Trunk_Full"
    },
    {
      "x": 3,
      "y": 10,
      "z": 0,
      "name": "Wood_Camphor_Trunk_Full"
    },
    {
      "x": 3,
      "y": 11,
      "z": 0,
      "name": "Wood_Camphor_Trunk_Full"
    },
    {
      "x": 3,
      "y": 13,
      "z": 0,
      "name": "Wood_Camphor_Branch_Long",
      "rotation": 5
    },
    {
      "x": 3,
      "y": 14,
      "z": 0,
      "name": "Plant_Leaves_Camphor"
    },
    {
      "x": 3,
      "y": 15,
      "z": 0,
      "name": "Plant_Leaves_Camphor"
    },
    {
      "x": 3,
      "y": 11,
      "z": 1,
      "name": "Wood_Camphor_Trunk_Full"
    },
    {
      "x": 3,
      "y": 12,
      "z": 1,
      "name": "Plant_Leaves_Camphor"
    },
    {
      "x": 3,
      "y": 13,
      "z": 1,
      "name": "Plant_Leaves_Camphor"
    },
    {
      "x": 3,
      "y": 5,
      "z": 2,
      "name": "Wood_Camphor_Trunk_Full"
    },
    {
      "x": 3,
      "y": 11,
      "z": 2,
      "name": "Plant_Leaves_Camphor"
    },
    {
      "x": 3,
      "y": 12,
      "z": 2,
      "name": "Plant_Leaves_Camphor"
    },
    {
      "x": 3,
      "y": 15,
      "z": 2,
      "name": "Plant_Leaves_Camphor"
    },
    {
      "x": 3,
      "y": 5,
      "z": 3,
      "name": "Wood_Camphor_Trunk_Full"
    },
    {
      "x": 3,
      "y": 6,
      "z": 3,
      "name": "Wood_Camphor_Trunk_Full"
    },
    {
      "x": 3,
      "y": 12,
      "z": 3,
      "name": "Plant_Leaves_Camphor"
    },
    {
      "x": 3,
      "y": 15,
      "z": 3,
      "name": "Plant_Leaves_Camphor"
    },
    {
      "x": 3,
      "y": 6,
      "z": 4,
      "name": "Wood_Camphor_Trunk_Full"
    },
    {
      "x": 3,
      "y": 9,
      "z": 4,
      "name": "Wood_Camphor_Branch_Long",
      "rotation": 5
    },
    {
      "x": 3,
      "y": 10,
      "z": 4,
      "name": "Plant_Leaves_Camphor"
    },
    {
      "x": 3,
      "y": 6,
      "z": 5,
      "name": "Wood_Camphor_Trunk_Full"
    },
    {
      "x": 3,
      "y": 7,
      "z": 5,
      "name": "Plant_Leaves_Camphor"
    },
    {
      "x": 3,
      "y": 6,
      "z": 6,
      "name": "Wood_Camphor_Branch_Long",
      "rotation": 4
    },
    {
      "x": 3,
      "y": 7,
      "z": 6,
      "name": "Plant_Leaves_Camphor"
    },
    {
      "x": 3,
      "y": 9,
      "z": 6,
      "name": "Plant_Leaves_Camphor"
    },
    {
      "x": 3,
      "y": 10,
      "z": 6,
      "name": "Plant_Leaves_Camphor"
    },
    {
      "x": 3,
      "y": 6,
      "z": 7,
      "name": "Wood_Camphor_Branch_Long",
      "rotation": 4
    },
    {
      "x": 3,
      "y": 7,
      "z": 7,
      "name": "Plant_Leaves_Camphor"
    },
    {
      "x": 3,
      "y": 9,
      "z": 7,
      "name": "Plant_Leaves_Camphor"
    },
    {
      "x": 3,
      "y": 6,
      "z": 8,
      "name": "Plant_Leaves_Camphor"
    },
    {
      "x": 4,
      "y": 7,
      "z": -7,
      "name": "Plant_Leaves_Camphor"
    },
    {
      "x": 4,
      "y": 8,
      "z": -7,
      "name": "Plant_Leaves_Camphor"
    },
    {
      "x": 4,
      "y": 10,
      "z": -7,
      "name": "Plant_Leaves_Camphor"
    },
    {
      "x": 4,
      "y": 11,
      "z": -7,
      "name": "Plant_Leaves_Camphor"
    },
    {
      "x": 4,
      "y": 4,
      "z": -6,
      "name": "Plant_Leaves_Camphor"
    },
    {
      "x": 4,
      "y": 7,
      "z": -6,
      "name": "Plant_Leaves_Camphor"
    },
    {
      "x": 4,
      "y": 10,
      "z": -6,
      "name": "Plant_Leaves_Camphor"
    },
    {
      "x": 4,
      "y": 11,
      "z": -6,
      "name": "Plant_Leaves_Camphor"
    },
    {
      "x": 4,
      "y": 12,
      "z": -6,
      "name": "Plant_Leaves_Camphor"
    },
    {
      "x": 4,
      "y": 4,
      "z": -5,
      "name": "Wood_Camphor_Branch_Long",
      "rotation": 4
    },
    {
      "x": 4,
      "y": 5,
      "z": -5,
      "name": "Plant_Leaves_Camphor"
    },
    {
      "x": 4,
      "y": 7,
      "z": -5,
      "name": "Plant_Leaves_Camphor"
    },
    {
      "x": 4,
      "y": 12,
      "z": -5,
      "name": "Plant_Leaves_Camphor"
    },
    {
      "x": 4,
      "y": 13,
      "z": -5,
      "name": "Plant_Leaves_Camphor"
    },
    {
      "x": 4,
      "y": 4,
      "z": -4,
      "name": "Wood_Camphor_Trunk_Full"
    },
    {
      "x": 4,
      "y": 11,
      "z": -4,
      "name": "Wood_Camphor_Branch_Long",
      "rotation": 5
    },
    {
      "x": 4,
      "y": 12,
      "z": -4,
      "name": "Plant_Leaves_Camphor"
    },
    {
      "x": 4,
      "y": 4,
      "z": -3,
      "name": "Wood_Camphor_Trunk_Full"
    },
    {
      "x": 4,
      "y": 8,
      "z": -3,
      "name": "Plant_Leaves_Camphor"
    },
    {
      "x": 4,
      "y": 11,
      "z": -3,
      "name": "Plant_Leaves_Camphor"
    },
    {
      "x": 4,
      "y": 4,
      "z": -2,
      "name": "Wood_Camphor_Trunk_Full"
    },
    {
      "x": 4,
      "y": 5,
      "z": -2,
      "name": "Wood_Camphor_Trunk_Full"
    },
    {
      "x": 4,
      "y": 8,
      "z": -2,
      "name": "Plant_Leaves_Camphor"
    },
    {
      "x": 4,
      "y": 8,
      "z": -1,
      "name": "Wood_Camphor_Trunk_Full"
    },
    {
      "x": 4,
      "y": 13,
      "z": -1,
      "name": "Plant_Leaves_Camphor"
    },
    {
      "x": 4,
      "y": 7,
      "z": 0,
      "name": "Wood_Camphor_Trunk_Full"
    },
    {
      "x": 4,
      "y": 8,
      "z": 0,
      "name": "Wood_Camphor_Trunk_Full"
    },
    {
      "x": 4,
      "y": 11,
      "z": 0,
      "name": "Wood_Camphor_Branch_Long",
      "rotation": 5
    },
    {
      "x": 4,
      "y": 12,
      "z": 0,
      "name": "Plant_Leaves_Camphor"
    },
    {
      "x": 4,
      "y": 13,
      "z": 0,
      "name": "Plant_Leaves_Camphor"
    },
    {
      "x": 4,
      "y": 11,
      "z": 1,
      "name": "Wood_Camphor_Trunk_Full"
    },
    {
      "x": 4,
      "y": 12,
      "z": 1,
      "name": "Plant_Leaves_Camphor"
    },
    {
      "x": 4,
      "y": 13,
      "z": 1,
      "name": "Plant_Leaves_Camphor"
    },
    {
      "x": 4,
      "y": 11,
      "z": 2,
      "name": "Wood_Camphor_Branch_Long",
      "rotation": 4
    },
    {
      "x": 4,
      "y": 12,
      "z": 2,
      "name": "Plant_Leaves_Camphor"
    },
    {
      "x": 4,
      "y": 6,
      "z": 3,
      "name": "Wood_Camphor_Trunk_Full"
    },
    {
      "x": 4,
      "y": 11,
      "z": 3,
      "name": "Plant_Leaves_Camphor"
    },
    {
      "x": 4,
      "y": 12,
      "z": 3,
      "name": "Plant_Leaves_Camphor"
    },
    {
      "x": 4,
      "y": 9,
      "z": 4,
      "name": "Plant_Leaves_Camphor"
    },
    {
      "x": 4,
      "y": 9,
      "z": 5,
      "name": "Plant_Leaves_Camphor"
    },
    {
      "x": 4,
      "y": 7,
      "z": 6,
      "name": "Plant_Leaves_Camphor"
    },
    {
      "x": 4,
      "y": 9,
      "z": 6,
      "name": "Plant_Leaves_Camphor"
    },
    {
      "x": 4,
      "y": 5,
      "z": 7,
      "name": "Plant_Leaves_Camphor"
    },
    {
      "x": 4,
      "y": 6,
      "z": 7,
      "name": "Plant_Leaves_Camphor"
    },
    {
      "x": 4,
      "y": 7,
      "z": 7,
      "name": "Plant_Leaves_Camphor"
    },
    {
      "x": 4,
      "y": 6,
      "z": 8,
      "name": "Plant_Leaves_Camphor"
    },
    {
      "x": 4,
      "y": 7,
      "z": 8,
      "name": "Plant_Leaves_Camphor"
    },
    {
      "x": 5,
      "y": 4,
      "z": -6,
      "name": "Plant_Leaves_Camphor"
    },
    {
      "x": 5,
      "y": 11,
      "z": -6,
      "name": "Plant_Leaves_Camphor"
    },
    {
      "x": 5,
      "y": 5,
      "z": -5,
      "name": "Plant_Leaves_Camphor"
    },
    {
      "x": 5,
      "y": 10,
      "z": -5,
      "name": "Plant_Leaves_Camphor"
    },
    {
      "x": 5,
      "y": 11,
      "z": -5,
      "name": "Plant_Leaves_Camphor"
    },
    {
      "x": 5,
      "y": 4,
      "z": -4,
      "name": "Wood_Camphor_Branch_Long",
      "rotation": 5
    },
    {
      "x": 5,
      "y": 10,
      "z": -4,
      "name": "Plant_Leaves_Camphor"
    },
    {
      "x": 5,
      "y": 11,
      "z": -4,
      "name": "Plant_Leaves_Camphor"
    },
    {
      "x": 5,
      "y": 8,
      "z": -3,
      "name": "Plant_Leaves_Camphor"
    },
    {
      "x": 5,
      "y": 11,
      "z": -3,
      "name": "Plant_Leaves_Camphor"
    },
    {
      "x": 5,
      "y": 5,
      "z": -2,
      "name": "Wood_Camphor_Trunk_Full"
    },
    {
      "x": 5,
      "y": 8,
      "z": -2,
      "name": "Wood_Camphor_Branch_Long",
      "rotation": 4
    },
    {
      "x": 5,
      "y": 9,
      "z": -2,
      "name": "Plant_Leaves_Camphor"
    },
    {
      "x": 5,
      "y": 8,
      "z": -1,
      "name": "Wood_Camphor_Trunk_Full"
    },
    {
      "x": 5,
      "y": 9,
      "z": -1,
      "name": "Plant_Leaves_Camphor"
    },
    {
      "x": 5,
      "y": 12,
      "z": -1,
      "name": "Plant_Leaves_Camphor"
    },
    {
      "x": 5,
      "y": 8,
      "z": 0,
      "name": "Wood_Camphor_Branch_Long",
      "rotation": 5
    },
    {
      "x": 5,
      "y": 9,
      "z": 0,
      "name": "Plant_Leaves_Camphor"
    },
    {
      "x": 5,
      "y": 12,
      "z": 0,
      "name": "Plant_Leaves_Camphor"
    },
    {
      "x": 5,
      "y": 11,
      "z": 1,
      "name": "Wood_Camphor_Branch_Long",
      "rotation": 5
    },
    {
      "x": 5,
      "y": 12,
      "z": 1,
      "name": "Plant_Leaves_Camphor"
    },
    {
      "x": 5,
      "y": 12,
      "z": 2,
      "name": "Plant_Leaves_Camphor"
    },
    {
      "x": 5,
      "y": 6,
      "z": 3,
      "name": "Wood_Camphor_Trunk_Full"
    },
    {
      "x": 5,
      "y": 11,
      "z": 3,
      "name": "Plant_Leaves_Camphor"
    },
    {
      "x": 5,
      "y": 6,
      "z": 4,
      "name": "Wood_Camphor_Trunk_Full"
    },
    {
      "x": 5,
      "y": 7,
      "z": 4,
      "name": "Wood_Camphor_Trunk_Full"
    },
    {
      "x": 5,
      "y": 5,
      "z": 6,
      "name": "Plant_Leaves_Camphor"
    },
    {
      "x": 5,
      "y": 6,
      "z": 6,
      "name": "Plant_Leaves_Camphor"
    },
    {
      "x": 5,
      "y": 7,
      "z": 6,
      "name": "Plant_Leaves_Camphor"
    },
    {
      "x": 5,
      "y": 6,
      "z": 7,
      "name": "Plant_Leaves_Camphor"
    },
    {
      "x": 6,
      "y": 4,
      "z": -6,
      "name": "Plant_Leaves_Camphor"
    },
    {
      "x": 6,
      "y": 5,
      "z": -6,
      "name": "Plant_Leaves_Camphor"
    },
    {
      "x": 6,
      "y": 4,
      "z": -5,
      "name": "Plant_Leaves_Camphor"
    },
    {
      "x": 6,
      "y": 5,
      "z": -5,
      "name": "Plant_Leaves_Camphor"
    },
    {
      "x": 6,
      "y": 3,
      "z": -4,
      "name": "Plant_Leaves_Camphor"
    },
    {
      "x": 6,
      "y": 4,
      "z": -4,
      "name": "Plant_Leaves_Camphor"
    },
    {
      "x": 6,
      "y": 5,
      "z": -4,
      "name": "Plant_Leaves_Camphor"
    },
    {
      "x": 6,
      "y": 6,
      "z": -4,
      "name": "Plant_Leaves_Camphor"
    },
    {
      "x": 6,
      "y": 5,
      "z": -3,
      "name": "Wood_Camphor_Branch_Long",
      "rotation": 4
    },
    {
      "x": 6,
      "y": 6,
      "z": -3,
      "name": "Plant_Leaves_Camphor"
    },
    {
      "x": 6,
      "y": 8,
      "z": -3,
      "name": "Plant_Leaves_Camphor"
    },
    {
      "x": 6,
      "y": 5,
      "z": -2,
      "name": "Wood_Camphor_Trunk_Full"
    },
    {
      "x": 6,
      "y": 9,
      "z": -2,
      "name": "Plant_Leaves_Camphor"
    },
    {
      "x": 6,
      "y": 5,
      "z": -1,
      "name": "Wood_Camphor_Branch_Short"
    },
    {
      "x": 6,
      "y": 8,
      "z": -1,
      "name": "Wood_Camphor_Branch_Long",
      "rotation": 5
    },
    {
      "x": 6,
      "y": 9,
      "z": -1,
      "name": "Plant_Leaves_Camphor"
    },
    {
      "x": 6,
      "y": 10,
      "z": -1,
      "name": "Plant_Leaves_Camphor"
    },
    {
      "x": 6,
      "y": 11,
      "z": -1,
      "name": "Plant_Leaves_Camphor"
    },
    {
      "x": 6,
      "y": 9,
      "z": 0,
      "name": "Plant_Leaves_Camphor"
    },
    {
      "x": 6,
      "y": 11,
      "z": 0,
      "name": "Plant_Leaves_Camphor"
    },
    {
      "x": 6,
      "y": 6,
      "z": 1,
      "name": "Plant_Leaves_Camphor"
    },
    {
      "x": 6,
      "y": 7,
      "z": 1,
      "name": "Plant_Leaves_Camphor"
    },
    {
      "x": 6,
      "y": 8,
      "z": 1,
      "name": "Plant_Leaves_Camphor"
    },
    {
      "x": 6,
      "y": 11,
      "z": 1,
      "name": "Wood_Camphor_Branch_Long",
      "rotation": 5
    },
    {
      "x": 6,
      "y": 12,
      "z": 1,
      "name": "Plant_Leaves_Camphor"
    },
    {
      "x": 6,
      "y": 11,
      "z": 2,
      "name": "Plant_Leaves_Camphor"
    },
    {
      "x": 6,
      "y": 12,
      "z": 2,
      "name": "Plant_Leaves_Camphor"
    },
    {
      "x": 6,
      "y": 6,
      "z": 3,
      "name": "Wood_Camphor_Branch_Short",
      "rotation": 1
    },
    {
      "x": 6,
      "y": 10,
      "z": 3,
      "name": "Plant_Leaves_Camphor"
    },
    {
      "x": 6,
      "y": 11,
      "z": 3,
      "name": "Plant_Leaves_Camphor"
    },
    {
      "x": 6,
      "y": 7,
      "z": 4,
      "name": "Wood_Camphor_Trunk_Full"
    },
    {
      "x": 6,
      "y": 8,
      "z": 4,
      "name": "Plant_Leaves_Camphor"
    },
    {
      "x": 6,
      "y": 7,
      "z": 5,
      "name": "Wood_Camphor_Branch_Long",
      "rotation": 4
    },
    {
      "x": 6,
      "y": 8,
      "z": 5,
      "name": "Plant_Leaves_Camphor"
    },
    {
      "x": 6,
      "y": 7,
      "z": 6,
      "name": "Wood_Camphor_Branch_Long",
      "rotation": 4
    },
    {
      "x": 6,
      "y": 8,
      "z": 6,
      "name": "Plant_Leaves_Camphor"
    },
    {
      "x": 6,
      "y": 6,
      "z": 7,
      "name": "Plant_Leaves_Camphor"
    },
    {
      "x": 6,
      "y": 7,
      "z": 7,
      "name": "Plant_Leaves_Camphor"
    },
    {
      "x": 7,
      "y": 5,
      "z": -4,
      "name": "Plant_Leaves_Camphor"
    },
    {
      "x": 7,
      "y": 6,
      "z": -3,
      "name": "Plant_Leaves_Camphor"
    },
    {
      "x": 7,
      "y": 8,
      "z": -3,
      "name": "Plant_Leaves_Camphor"
    },
    {
      "x": 7,
      "y": 5,
      "z": -2,
      "name": "Wood_Camphor_Branch_Long",
      "rotation": 5
    },
    {
      "x": 7,
      "y": 6,
      "z": -2,
      "name": "Plant_Leaves_Camphor"
    },
    {
      "x": 7,
      "y": 8,
      "z": -2,
      "name": "Plant_Leaves_Camphor"
    },
    {
      "x": 7,
      "y": 9,
      "z": -2,
      "name": "Plant_Leaves_Camphor"
    },
    {
      "x": 7,
      "y": 6,
      "z": -1,
      "name": "Plant_Leaves_Camphor"
    },
    {
      "x": 7,
      "y": 8,
      "z": -1,
      "name": "Wood_Camphor_Branch_Long",
      "rotation": 5
    },
    {
      "x": 7,
      "y": 9,
      "z": -1,
      "name": "Plant_Leaves_Camphor"
    },
    {
      "x": 7,
      "y": 6,
      "z": 0,
      "name": "Plant_Leaves_Camphor"
    },
    {
      "x": 7,
      "y": 9,
      "z": 0,
      "name": "Plant_Leaves_Camphor"
    },
    {
      "x": 7,
      "y": 11,
      "z": 0,
      "name": "Plant_Leaves_Camphor"
    },
    {
      "x": 7,
      "y": 7,
      "z": 1,
      "name": "Plant_Leaves_Camphor"
    },
    {
      "x": 7,
      "y": 8,
      "z": 1,
      "name": "Plant_Leaves_Camphor"
    },
    {
      "x": 7,
      "y": 9,
      "z": 1,
      "name": "Plant_Leaves_Camphor"
    },
    {
      "x": 7,
      "y": 11,
      "z": 1,
      "name": "Plant_Leaves_Camphor"
    },
    {
      "x": 7,
      "y": 12,
      "z": 1,
      "name": "Plant_Leaves_Camphor"
    },
    {
      "x": 7,
      "y": 10,
      "z": 2,
      "name": "Plant_Leaves_Camphor"
    },
    {
      "x": 7,
      "y": 11,
      "z": 2,
      "name": "Plant_Leaves_Camphor"
    },
    {
      "x": 7,
      "y": 7,
      "z": 3,
      "name": "Plant_Leaves_Camphor"
    },
    {
      "x": 7,
      "y": 8,
      "z": 3,
      "name": "Plant_Leaves_Camphor"
    },
    {
      "x": 7,
      "y": 7,
      "z": 4,
      "name": "Wood_Camphor_Branch_Long",
      "rotation": 5
    },
    {
      "x": 7,
      "y": 8,
      "z": 4,
      "name": "Plant_Leaves_Camphor"
    },
    {
      "x": 7,
      "y": 9,
      "z": 4,
      "name": "Plant_Leaves_Camphor"
    },
    {
      "x": 7,
      "y": 8,
      "z": 5,
      "name": "Plant_Leaves_Camphor"
    },
    {
      "x": 7,
      "y": 6,
      "z": 7,
      "name": "Plant_Leaves_Camphor"
    },
    {
      "x": 7,
      "y": 7,
      "z": 7,
      "name": "Plant_Leaves_Camphor"
    },
    {
      "x": 8,
      "y": 5,
      "z": -4,
      "name": "Plant_Leaves_Camphor"
    },
    {
      "x": 8,
      "y": 4,
      "z": -3,
      "name": "Plant_Leaves_Camphor"
    },
    {
      "x": 8,
      "y": 5,
      "z": -3,
      "name": "Plant_Leaves_Camphor"
    },
    {
      "x": 8,
      "y": 6,
      "z": -3,
      "name": "Plant_Leaves_Camphor"
    },
    {
      "x": 8,
      "y": 5,
      "z": -2,
      "name": "Wood_Camphor_Branch_Long",
      "rotation": 5
    },
    {
      "x": 8,
      "y": 6,
      "z": -2,
      "name": "Plant_Leaves_Camphor"
    },
    {
      "x": 8,
      "y": 8,
      "z": -2,
      "name": "Plant_Leaves_Camphor"
    },
    {
      "x": 8,
      "y": 4,
      "z": -1,
      "name": "Plant_Leaves_Camphor"
    },
    {
      "x": 8,
      "y": 5,
      "z": -1,
      "name": "Plant_Leaves_Camphor"
    },
    {
      "x": 8,
      "y": 6,
      "z": -1,
      "name": "Plant_Leaves_Camphor"
    },
    {
      "x": 8,
      "y": 8,
      "z": -1,
      "name": "Plant_Leaves_Camphor"
    },
    {
      "x": 8,
      "y": 9,
      "z": -1,
      "name": "Plant_Leaves_Camphor"
    },
    {
      "x": 8,
      "y": 8,
      "z": 0,
      "name": "Plant_Leaves_Camphor"
    },
    {
      "x": 8,
      "y": 8,
      "z": 1,
      "name": "Plant_Leaves_Camphor"
    },
    {
      "x": 8,
      "y": 7,
      "z": 2,
      "name": "Plant_Leaves_Camphor"
    },
    {
      "x": 8,
      "y": 8,
      "z": 3,
      "name": "Plant_Leaves_Camphor"
    },
    {
      "x": 8,
      "y": 7,
      "z": 4,
      "name": "Wood_Camphor_Branch_Long",
      "rotation": 5
    },
    {
      "x": 8,
      "y": 8,
      "z": 4,
      "name": "Plant_Leaves_Camphor"
    },
    {
      "x": 8,
      "y": 6,
      "z": 5,
      "name": "Plant_Leaves_Camphor"
    },
    {
      "x": 8,
      "y": 7,
      "z": 5,
      "name": "Plant_Leaves_Camphor"
    },
    {
      "x": 8,
      "y": 8,
      "z": 5,
      "name": "Plant_Leaves_Camphor"
    },
    {
      "x": 8,
      "y": 7,
      "z": 6,
      "name": "Plant_Leaves_Camphor"
    },
    {
      "x": 9,
      "y": 5,
      "z": -3,
      "name": "Plant_Leaves_Camphor"
    },
    {
      "x": 9,
      "y": 6,
      "z": -3,
      "name": "Plant_Leaves_Camphor"
    },
    {
      "x": 9,
      "y": 5,
      "z": -2,
      "name": "Plant_Leaves_Camphor"
    },
    {
      "x": 9,
      "y": 6,
      "z": 3,
      "name": "Plant_Leaves_Camphor"
    },
    {
      "x": 9,
      "y": 7,
      "z": 3,
      "name": "Plant_Leaves_Camphor"
    },
    {
      "x": 9,
      "y": 7,
      "z": 4,
      "name": "Plant_Leaves_Camphor"
    },
    {
      "x": 9,
      "y": 7,
      "z": 5,
      "name": "Plant_Leaves_Camphor"
    }
  ]
}