{
  "version": 8,
  "blockIdVersion": 11,
  "anchorX": 1,
  "anchorY": 1,
  "anchorZ": -3,
  "blocks": [
    {
      "x": -3,
      "y": 3,
      "z": -3,
      "name": "Plant_Leaves_Camphor"
    },
    {
      "x": -3,
      "y": 4,
      "z": -3,
      "name": "Plant_Leaves_Camphor"
    },
    {
      "x": -2,
      "y": 5,
      "z": -5,
      "name": "Plant_Leaves_Camphor"
    },
    {
      "x": -2,
      "y": 5,
      "z": -4,
      "name": "Plant_Leaves_Camphor"
    },
    {
      "x": -2,
      "y": 3,
      "z": -3,
      "name": "Plant_Leaves_Camphor"
    },
    {
      "x": -2,
      "y": 4,
      "z": -3,
      "name": "Plant_Leaves_Camphor"
    },
    {
      "x": -2,
      "y": 5,
      "z": -3,
      "name": "Plant_Leaves_Camphor"
    },
    {
      "x": -1,
      "y": 5,
      "z": -6,
      "name": "Plant_Leaves_Camphor"
    },
    {
      "x": -1,
      "y": 6,
      "z": -5,
      "name": "Plant_Leaves_Camphor"
    },
    {
      "x": -1,
      "y": 6,
      "z": -4,
      "name": "Plant_Leaves_Camphor"
    },
    {
      "x": -1,
      "y": 4,
      "z": -3,
      "name": "Wood_Camphor_Branch_Long",
      "rotation": 5
    },
    {
      "x": -1,
      "y": 6,
      "z": -3,
      "name": "Plant_Leaves_Camphor"
    },
    {
      "x": -1,
      "y": 4,
      "z": -2,
      "name": "Plant_Leaves_Camphor"
    },
    {
      "x": -1,
      "y": 5,
      "z": -2,
      "name": "Plant_Leaves_Camphor"
    },
    {
      "x": 0,
      "y": 5,
      "z": -6,
      "name": "Plant_Leaves_Camphor"
    },
    {
      "x": 0,
      "y": 6,
      "z": -5,
      "name": "Plant_Leaves_Camphor"
    },
    {
      "x": 0,
      "y": 2,
      "z": -3,
      "name": "Wood_Camphor_Branch_Long",
      "rotation": 5
    },
    {
      "x": 0,
      "y": 3,
      "z": -3,
      "name": "Wood_Camphor_Branch_Corner",
      "rotation": 3
    },
    {
      "x": 0,
      "y": 4,
      "z": -3,
      "name": "Wood_Camphor_Branch_Corner",
      "rotation": 11
    },
    {
      "x": 0,
      "y": 7,
      "z": -3,
      "name": "Plant_Leaves_Camphor"
    },
    {
      "x": 0,
      "y": 4,
      "z": -2,
      "name": "Plant_Leaves_Camphor"
    },
    {
      "x": 0,
      "y": 6,
      "z": -2,
      "name": "Plant_Leaves_Camphor"
    },
    {
      "x": 0,
      "y": 7,
      "z": -2,
      "name": "Plant_Leaves_Camphor"
    },
    {
      "x": 0,
      "y": 4,
      "z": -1,
      "name": "Plant_Leaves_Camphor"
    },
    {
      "x": 0,
      "y": 6,
      "z": -1,
      "name": "Plant_Leaves_Camphor"
    },
    {
      "x": 0,
      "y": 4,
      "z": 0,
      "name": "Plant_Leaves_Camphor"
    },
    {
      "x": 0,
      "y": 3,
      "z": 1,
      "name": "Plant_Leaves_Camphor"
    },
    {
      "x": 0,
      "y": 4,
      "z": 1,
      "name": "Plant_Leaves_Camphor"
    },
    {
      "x": 1,
      "y": 3,
      "z": -7,
      "name": "Plant_Leaves_Camphor"
    },
    {
      "x": 1,
      "y": 4,
      "z": -7,
      "name": "Plant_Leaves_Camphor"
    },
    {
      "x": 1,
      "y": 3,
      "z": -6,
      "name": "Plant_Leaves_Camphor"
    },
    {
      "x": 1,
      "y": 4,
      "z": -6,
      "name": "Plant_Leaves_Camphor"
    },
    {
      "x": 1,
      "y": 4,
      "z": -5,
      "name": "Wood_Camphor_Branch_Long",
      "rotation": 4
    },
    {
      "x": 1,
      "y": 5,
      "z": -5,
      "name": "Plant_Leaves_Camphor"
    },
    {
      "x": 1,
      "y": 2,
      "z": -4,
      "name": "Wood_Camphor_Branch_Long",
      "rotation": 4
    },
    {
      "x": 1,
      "y": 3,
      "z": -4,
      "name": "Wood_Camphor_Branch_Corner",
      "rotation": 2
    },
    {
      "x": 1,
      "y": 4,
      "z": -4,
      "name": "Wood_Camphor_Branch_Corner",
      "rotation": 10
    },
    {
      "x": 1,
      "y": 5,
      "z": -4,
      "name": "Plant_Leaves_Camphor"
    },
    {
      "x": 1,
      "y": 6,
      "z": -4,
      "name": "Plant_Leaves_Camphor"
    },
    {
      "x": 1,
      "y": 7,
      "z": -4,
      "name": "Plant_Leaves_Camphor"
    },
    {
      "x": 1,
      "y": 1,
      "z": -3,
      "name": "Wood_Camphor_Trunk_Full"
    },
    {
      "x": 1,
      "y": 2,
      "z": -3,
      "name": "Wood_Camphor_Trunk"
    },
    {
      "x": 1,
      "y": 3,
      "z": -3,
      "name": "Wood_Camphor_Trunk_Full"
    },
    {
      "x": 1,
      "y": 4,
      "z": -3,
      "name": "Wood_Camphor_Branch_Long"
    },
    {
      "x": 1,
      "y": 5,
      "z": -3,
      "name": "Wood_Camphor_Branch_Long"
    },
    {
      "x": 1,
      "y": 6,
      "z": -3,
      "name": "Wood_Camphor_Branch_Long"
    },
    {
      "x": 1,
      "y": 7,
      "z": -3,
      "name": "Plant_Leaves_Camphor"
    },
    {
      "x": 1,
      "y": 2,
      "z": -2,
      "name": "Wood_Camphor_Branch_Short"
    },
    {
      "x": 1,
      "y": 3,
      "z": -2,
      "name": "Wood_Camphor_Branch_Corner"
    },
    {
      "x": 1,
      "y": 4,
      "z": -2,
      "name": "Wood_Camphor_Branch_Corner",
      "rotation": 8
    },
    {
      "x": 1,
      "y": 5,
      "z": -2,
      "name": "Plant_Leaves_Camphor"
    },
    {
      "x": 1,
      "y": 7,
      "z": -2,
      "name": "Plant_Leaves_Camphor"
    },
    {
      "x": 1,
      "y": 4,
      "z": -1,
      "name": "Wood_Camphor_Branch_Long",
      "rotation": 4
    },
    {
      "x": 1,
      "y": 5,
      "z": -1,
      "name": "Plant_Leaves_Camphor"
    },
    {
      "x": 1,
      "y": 6,
      "z": -1,
      "name": "Plant_Leaves_Camphor"
    },
    {
      "x": 1,
      "y": 3,
      "z": 0,
      "name": "Plant_Leaves_Camphor"
    },
    {
      "x": 1,
      "y": 4,
      "z": 0,
      "name": "Plant_Leaves_Camphor"
    },
    {
      "x": 1,
      "y": 6,
      "z": 0,
      "name": "Plant_Leaves_Camphor"
    },
    {
      "x": 2,
      "y": 4,
      "z": -5,
      "name": "Plant_Leaves_Camphor"
    },
    {
      "x": 2,
      "y": 3,
      "z": -4,
      "name": "Plant_Leaves_Camphor"
    },
    {
      "x": 2,
      "y": 4,
      "z": -4,
      "name": "Plant_Leaves_Camphor"
    },
    {
      "x": 2,
      "y": 5,
      "z": -4,
      "name": "Plant_Leaves_Camphor"
    },
    {
      "x": 2,
      "y": 3,
      "z": -3,
      "name": "Wood_Camphor_Branch_Long",
      "rotation": 5
    },
    {
      "x": 2,
      "y": 4,
      "z": -3,
      "name": "Plant_Leaves_Camphor"
    },
    {
      "x": 2,
      "y": 6,
      "z": -3,
      "name": "Plant_Leaves_Camphor"
    },
    {
      "x": 2,
      "y": 7,
      "z": -3,
      "name": "Plant_Leaves_Camphor"
    },
    {
      "x": 2,
      "y": 3,
      "z": -2,
      "name": "Plant_Leaves_Camphor"
    },
    {
      "x": 2,
      "y": 4,
      "z": -2,
      "name": "Plant_Leaves_Camphor"
    },
    {
      "x": 2,
      "y": 5,
      "z": -2,
      "name": "Plant_Leaves_Camphor"
    },
    {
      "x": 2,
      "y": 7,
      "z": -2,
      "name": "Plant_Leaves_Camphor"
    },
    {
      "x": 2,
      "y": 4,
      "z": -1,
      "name": "Plant_Leaves_Camphor"
    },
    {
      "x": 2,
      "y": 6,
      "z": -1,
      "name": "Plant_Leaves_Camphor"
    },
    {
      "x": 2,
      "y": 7,
      "z": -1,
      "name": "Plant_Leaves_Camphor"
    },
    {
      "x": 3,
      "y": 3,
      "z": -4,
      "name": "Plant_Leaves_Camphor"
    },
    {
      "x": 3,
      "y": 6,
      "z": -4,
      "name": "Plant_Leaves_Camphor"
    },
    {
      "x": 3,
      "y": 3,
      "z": -3,
      "name": "Wood_Camphor_Branch_Corner",
      "rotation": 1
    },
    {
      "x": 3,
      "y": 4,
      "z": -3,
      "name": "Plant_Leaves_Camphor"
    },
    {
      "x": 3,
      "y": 7,
      "z": -3,
      "name": "Plant_Leaves_Camphor"
    },
    {
      "x": 3,
      "y": 3,
      "z": -2,
      "name": "Plant_Leaves_Camphor"
    },
    {
      "x": 3,
      "y": 6,
      "z": -2,
      "name": "Plant_Leaves_Camphor"
    },
    {
      "x": 3,
      "y": 6,
      "z": -1,
      "name": "Plant_Leaves_Camphor"
    },
    {
      "x": 4,
      "y": 3,
      "z": -3,
      "name": "Plant_Leaves_Camphor"
    },
    {
      "x": 4,
      "y": 6,
      "z": -3,
      "name": "Plant_Leaves_Camphor"
    },
    {
      "x": 4,
      "y": 6,
      "z": -2,
      "name": "Plant_Leaves_Camphor"
    },
    {
      "x": 4,
      "y": 7,
      "z": -2,
      "name": "Plant_Leaves_Camphor"
    },
    {
      "x": 4,
      "y": 6,
      "z": -1,
      "name": "Plant_Leaves_Camphor"
    }
  ]
}