{
  "version": 8,
  "blockIdVersion": 11,
  "anchorX": 2,
  "anchorY": 3,
  "anchorZ": -1,
  "blocks": [
    {
      "x": -21,
      "y": 4,
      "z": 10,
      "name": "Wood_Softwood_Fence"
    },
    {
      "x": -20,
      "y": 4,
      "z": 10,
      "name": "Wood_Softwood_Fence"
    },
    {
      "x": -16,
      "y": 4,
      "z": 10,
      "name": "Wood_Softwood_Fence"
    },
    {
      "x": -15,
      "y": 4,
      "z": 10,
      "name": "Wood_Softwood_Fence"
    },
    {
      "x": -14,
      "y": 4,
      "z": -11,
      "name": "Wood_Softwood_Fence",
      "rotation": 3
    },
    {
      "x": -14,
      "y": 4,
      "z": -8,
      "name": "Wood_Softwood_Fence",
      "rotation": 3
    },
    {
      "x": -14,
      "y": 4,
      "z": -7,
      "name": "Wood_Softwood_Fence",
      "rotation": 3
    },
    {
      "x": -14,
      "y": 4,
      "z": -6,
      "name": "Wood_Softwood_Fence",
      "rotation": 3
    },
    {
      "x": -14,
      "y": 4,
      "z": -2,
      "name": "Wood_Softwood_Fence",
      "rotation": 3
    },
    {
      "x": -14,
      "y": 4,
      "z": -1,
      "name": "Wood_Softwood_Fence",
      "rotation": 3
    },
    {
      "x": -14,
      "y": 4,
      "z": 4,
      "name": "Wood_Softwood_Fence",
      "rotation": 3
    },
    {
      "x": -14,
      "y": 4,
      "z": 5,
      "name": "Wood_Softwood_Fence",
      "rotation": 3
    },
    {
      "x": -14,
      "y": 4,
      "z": 6,
      "name": "Wood_Softwood_Fence",
      "rotation": 3
    },
    {
      "x": -14,
      "y": 4,
      "z": 8,
      "name": "Wood_Softwood_Fence",
      "rotation": 3
    },
    {
      "x": -14,
      "y": 4,
      "z": 9,
      "name": "Wood_Softwood_Fence",
      "rotation": 3
    },
    {
      "x": -14,
      "y": 4,
      "z": 10,
      "name": "Wood_Softwood_Fence"
    },
    {
      "x": -13,
      "y": 3,
      "z": -2,
      "name": "Soil_Dirt_Tilled",
      "components": {
        "Components": {
          "TilledSoil": {
            "Version": 1,
            "DecayTime": "0001-01-02T22:22:32Z"
          }
        }
      }
    },
    {
      "x": -13,
      "y": 4,
      "z": -2,
      "name": "*Plant_Crop_Wheat_Block_State_Definitions_StageFinal"
    },
    {
      "x": -13,
      "y": 5,
      "z": -2,
      "name": "*Plant_Crop_Wheat_Block_State_Definitions_StageFinal",
      "filler": 1024
    },
    {
      "x": -13,
      "y": 3,
      "z": -1,
      "name": "Soil_Dirt_Tilled",
      "components": {
        "Components": {
          "TilledSoil": {
            "Version": 1,
            "DecayTime": "0001-01-02T23:51:32Z"
          }
        }
      }
    },
    {
      "x": -13,
      "y": 4,
      "z": -1,
      "name": "*Plant_Crop_Wheat_Block_State_Definitions_StageFinal"
    },
    {
      "x": -13,
      "y": 5,
      "z": -1,
      "name": "*Plant_Crop_Wheat_Block_State_Definitions_StageFinal",
      "filler": 1024
    },
    {
      "x": -13,
      "y": 3,
      "z": 0,
      "name": "Soil_Dirt_Tilled",
      "components": {
        "Components": {
          "TilledSoil": {
            "Version": 1,
            "DecayTime": "0001-01-02T17:23:06Z"
          }
        }
      }
    },
    {
      "x": -13,
      "y": 4,
      "z": 0,
      "name": "*Plant_Crop_Wheat_Block_State_Definitions_StageFinal"
    },
    {
      "x": -13,
      "y": 5,
      "z": 0,
      "name": "*Plant_Crop_Wheat_Block_State_Definitions_StageFinal",
      "filler": 1024
    },
    {
      "x": -13,
      "y": 3,
      "z": 1,
      "name": "Soil_Dirt_Tilled",
      "components": {
        "Components": {
          "TilledSoil": {
            "Version": 1,
            "DecayTime": "0001-01-02T22:27:36Z"
          }
        }
      }
    },
    {
      "x": -13,
      "y": 3,
      "z": 2,
      "name": "Soil_Dirt_Tilled",
      "components": {
        "Components": {
          "TilledSoil": {
            "Version": 1,
            "DecayTime": "0001-01-02T18:36:15Z"
          }
        }
      }
    },
    {
      "x": -13,
      "y": 3,
      "z": 4,
      "name": "Soil_Dirt_Tilled",
      "components": {
        "Components": {
          "TilledSoil": {
            "Version": 1,
            "DecayTime": "0001-01-02T19:45:53Z"
          }
        }
      }
    },
    {
      "x": -13,
      "y": 4,
      "z": 4,
      "name": "*Plant_Crop_Wheat_Block_State_Definitions_StageFinal"
    },
    {
      "x": -13,
      "y": 5,
      "z": 4,
      "name": "*Plant_Crop_Wheat_Block_State_Definitions_StageFinal",
      "filler": 1024
    },
    {
      "x": -13,
      "y": 3,
      "z": 5,
      "name": "Soil_Dirt_Tilled",
      "components": {
        "Components": {
          "TilledSoil": {
            "Version": 1,
            "DecayTime": "0001-01-02T17:55:18Z"
          }
        }
      }
    },
    {
      "x": -13,
      "y": 4,
      "z": 5,
      "name": "*Plant_Crop_Wheat_Block_State_Definitions_StageFinal"
    },
    {
      "x": -13,
      "y": 5,
      "z": 5,
      "name": "*Plant_Crop_Wheat_Block_State_Definitions_StageFinal",
      "filler": 1024
    },
    {
      "x": -13,
      "y": 3,
      "z": 6,
      "name": "Soil_Dirt_Tilled",
      "components": {
        "Components": {
          "TilledSoil": {
            "Version": 1,
            "DecayTime": "0001-01-02T22:06:09Z"
          }
        }
      }
    },
    {
      "x": -13,
      "y": 4,
      "z": 6,
      "name": "*Plant_Crop_Wheat_Block_State_Definitions_StageFinal"
    },
    {
      "x": -13,
      "y": 5,
      "z": 6,
      "name": "*Plant_Crop_Wheat_Block_State_Definitions_StageFinal",
      "filler": 1024
    },
    {
      "x": -13,
      "y": 3,
      "z": 7,
      "name": "Soil_Dirt_Tilled",
      "components": {
        "Components": {
          "TilledSoil": {
            "Version": 1,
            "DecayTime": "0001-01-02T18:39:13Z"
          }
        }
      }
    },
    {
      "x": -13,
      "y": 3,
      "z": 8,
      "name": "Soil_Dirt_Tilled",
      "components": {
        "Components": {
          "TilledSoil": {
            "Version": 1,
            "DecayTime": "0001-01-02T18:22:14Z"
          }
        }
      }
    },
    {
      "x": -12,
      "y": 4,
      "z": -10,
      "name": "Wood_Softwood_Fence",
      "rotation": 2
    },
    {
      "x": -12,
      "y": 3,
      "z": -3,
      "name": "Soil_Dirt_Tilled",
      "components": {
        "Components": {
          "TilledSoil": {
            "Version": 1,
            "DecayTime": "0001-01-02T20:52:08Z"
          }
        }
      }
    },
    {
      "x": -12,
      "y": 4,
      "z": -3,
      "name": "*Plant_Crop_Wheat_Block_State_Definitions_StageFinal"
    },
    {
      "x": -12,
      "y": 5,
      "z": -3,
      "name": "*Plant_Crop_Wheat_Block_State_Definitions_StageFinal",
      "filler": 1024
    },
    {
      "x": -12,
      "y": 3,
      "z": -2,
      "name": "Soil_Dirt_Tilled",
      "components": {
        "Components": {
          "TilledSoil": {
            "Version": 1,
            "DecayTime": "0001-01-02T19:43:21Z"
          }
        }
      }
    },
    {
      "x": -12,
      "y": 4,
      "z": -2,
      "name": "*Plant_Crop_Wheat_Block_State_Definitions_StageFinal"
    },
    {
      "x": -12,
      "y": 5,
      "z": -2,
      "name": "*Plant_Crop_Wheat_Block_State_Definitions_StageFinal",
      "filler": 1024
    },
    {
      "x": -12,
      "y": 3,
      "z": -1,
      "name": "Soil_Dirt_Tilled",
      "components": {
        "Components": {
          "TilledSoil": {
            "Version": 1,
            "DecayTime": "0001-01-02T18:55:27Z"
          }
        }
      }
    },
    {
      "x": -12,
      "y": 3,
      "z": 0,
      "name": "Soil_Dirt_Tilled",
      "components": {
        "Components": {
          "TilledSoil": {
            "Version": 1,
            "DecayTime": "0001-01-02T19:38:16Z"
          }
        }
      }
    },
    {
      "x": -12,
      "y": 4,
      "z": 0,
      "name": "*Plant_Crop_Wheat_Block_State_Definitions_StageFinal"
    },
    {
      "x": -12,
      "y": 5,
      "z": 0,
      "name": "*Plant_Crop_Wheat_Block_State_Definitions_StageFinal",
      "filler": 1024
    },
    {
      "x": -12,
      "y": 3,
      "z": 1,
      "name": "Soil_Dirt_Tilled",
      "components": {
        "Components": {
          "TilledSoil": {
            "Version": 1,
            "DecayTime": "0001-01-02T23:49:55Z"
          }
        }
      }
    },
    {
      "x": -12,
      "y": 4,
      "z": 1,
      "name": "*Plant_Crop_Wheat_Block_State_Definitions_StageFinal"
    },
    {
      "x": -12,
      "y": 5,
      "z": 1,
      "name": "*Plant_Crop_Wheat_Block_State_Definitions_StageFinal",
      "filler": 1024
    },
    {
      "x": -12,
      "y": 3,
      "z": 2,
      "name": "Soil_Dirt_Tilled",
      "components": {
        "Components": {
          "TilledSoil": {
            "Version": 1,
            "DecayTime": "0001-01-02T18:38:08Z"
          }
        }
      }
    },
    {
      "x": -12,
      "y": 3,
      "z": 3,
      "name": "Soil_Dirt_Tilled",
      "components": {
        "Components": {
          "TilledSoil": {
            "Version": 1,
            "DecayTime": "0001-01-02T22:10:20Z"
          }
        }
      }
    },
    {
      "x": -12,
      "y": 3,
      "z": 5,
      "name": "Soil_Dirt_Tilled",
      "components": {
        "Components": {
          "TilledSoil": {
            "Version": 1,
            "DecayTime": "0001-01-02T22:00:24Z"
          }
        }
      }
    },
    {
      "x": -12,
      "y": 4,
      "z": 5,
      "name": "*Plant_Crop_Wheat_Block_State_Definitions_StageFinal"
    },
    {
      "x": -12,
      "y": 5,
      "z": 5,
      "name": "*Plant_Crop_Wheat_Block_State_Definitions_StageFinal",
      "filler": 1024
    },
    {
      "x": -12,
      "y": 3,
      "z": 6,
      "name": "Soil_Dirt_Tilled",
      "components": {
        "Components": {
          "TilledSoil": {
            "Version": 1,
            "DecayTime": "0001-01-02T23:51:14Z"
          }
        }
      }
    },
    {
      "x": -12,
      "y": 3,
      "z": 7,
      "name": "Soil_Dirt_Tilled",
      "components": {
        "Components": {
          "TilledSoil": {
            "Version": 1,
            "DecayTime": "0001-01-02T17:51:11Z"
          }
        }
      }
    },
    {
      "x": -12,
      "y": 4,
      "z": 7,
      "name": "*Plant_Crop_Wheat_Block_State_Definitions_StageFinal"
    },
    {
      "x": -12,
      "y": 5,
      "z": 7,
      "name": "*Plant_Crop_Wheat_Block_State_Definitions_StageFinal",
      "filler": 1024
    },
    {
      "x": -12,
      "y": 3,
      "z": 8,
      "name": "Soil_Dirt_Tilled",
      "components": {
        "Components": {
          "TilledSoil": {
            "Version": 1,
            "DecayTime": "0001-01-02T18:59:40Z"
          }
        }
      }
    },
    {
      "x": -12,
      "y": 4,
      "z": 10,
      "name": "Wood_Softwood_Fence"
    },
    {
      "x": -10,
      "y": 4,
      "z": -10,
      "name": "Wood_Softwood_Fence",
      "rotation": 2
    },
    {
      "x": -10,
      "y": 4,
      "z": 10,
      "name": "Wood_Softwood_Fence"
    },
    {
      "x": -9,
      "y": 4,
      "z": -10,
      "name": "Wood_Softwood_Fence",
      "rotation": 2
    },
    {
      "x": -9,
      "y": 4,
      "z": 10,
      "name": "Wood_Softwood_Fence"
    },
    {
      "x": -8,
      "y": 4,
      "z": -10,
      "name": "Wood_Softwood_Fence",
      "rotation": 2
    },
    {
      "x": -8,
      "y": 4,
      "z": 10,
      "name": "Wood_Softwood_Fence"
    },
    {
      "x": -7,
      "y": 4,
      "z": 10,
      "name": "Wood_Softwood_Fence"
    },
    {
      "x": -6,
      "y": 3,
      "z": -9,
      "name": "Soil_Dirt_Tilled",
      "components": {
        "Components": {
          "TilledSoil": {
            "Version": 1,
            "DecayTime": "0001-01-02T21:29:47Z"
          }
        }
      }
    },
    {
      "x": -6,
      "y": 3,
      "z": -8,
      "name": "Soil_Dirt_Tilled",
      "components": {
        "Components": {
          "TilledSoil": {
            "Version": 1,
            "DecayTime": "0001-01-02T17:48:56Z"
          }
        }
      }
    },
    {
      "x": -6,
      "y": 3,
      "z": -7,
      "name": "Soil_Dirt_Tilled",
      "components": {
        "Components": {
          "TilledSoil": {
            "Version": 1,
            "DecayTime": "0001-01-02T17:40:09Z"
          }
        }
      }
    },
    {
      "x": -6,
      "y": 3,
      "z": -6,
      "name": "Soil_Dirt_Tilled",
      "components": {
        "Components": {
          "TilledSoil": {
            "Version": 1,
            "DecayTime": "0001-01-02T18:27:33Z"
          }
        }
      }
    },
    {
      "x": -6,
      "y": 4,
      "z": -6,
      "name": "*Plant_Crop_Wheat_Block_State_Definitions_StageFinal"
    },
    {
      "x": -6,
      "y": 5,
      "z": -6,
      "name": "*Plant_Crop_Wheat_Block_State_Definitions_StageFinal",
      "filler": 1024
    },
    {
      "x": -6,
      "y": 3,
      "z": -5,
      "name": "Soil_Dirt_Tilled",
      "components": {
        "Components": {
          "TilledSoil": {
            "Version": 1,
            "DecayTime": "0001-01-02T21:44:33Z"
          }
        }
      }
    },
    {
      "x": -6,
      "y": 3,
      "z": -4,
      "name": "Soil_Dirt_Tilled",
      "components": {
        "Components": {
          "TilledSoil": {
            "Version": 1,
            "DecayTime": "0001-01-02T18:52:25Z"
          }
        }
      }
    },
    {
      "x": -6,
      "y": 4,
      "z": -4,
      "name": "*Plant_Crop_Wheat_Block_State_Definitions_StageFinal"
    },
    {
      "x": -6,
      "y": 5,
      "z": -4,
      "name": "*Plant_Crop_Wheat_Block_State_Definitions_StageFinal",
      "filler": 1024
    },
    {
      "x": -6,
      "y": 3,
      "z": 1,
      "name": "Soil_Dirt_Tilled",
      "components": {
        "Components": {
          "TilledSoil": {
            "Version": 1,
            "DecayTime": "0001-01-02T22:36:25Z"
          }
        }
      }
    },
    {
      "x": -6,
      "y": 4,
      "z": 1,
      "name": "*Plant_Crop_Wheat_Block_State_Definitions_StageFinal"
    },
    {
      "x": -6,
      "y": 5,
      "z": 1,
      "name": "*Plant_Crop_Wheat_Block_State_Definitions_StageFinal",
      "filler": 1024
    },
    {
      "x": -6,
      "y": 3,
      "z": 2,
      "name": "Soil_Dirt_Tilled",
      "components": {
        "Components": {
          "TilledSoil": {
            "Version": 1,
            "DecayTime": "0001-01-02T21:10:09Z"
          }
        }
      }
    },
    {
      "x": -6,
      "y": 3,
      "z": 3,
      "name": "Soil_Dirt_Tilled",
      "components": {
        "Components": {
          "TilledSoil": {
            "Version": 1,
            "DecayTime": "0001-01-02T18:52:17Z"
          }
        }
      }
    },
    {
      "x": -6,
      "y": 4,
      "z": 3,
      "name": "*Plant_Crop_Wheat_Block_State_Definitions_StageFinal"
    },
    {
      "x": -6,
      "y": 5,
      "z": 3,
      "name": "*Plant_Crop_Wheat_Block_State_Definitions_StageFinal",
      "filler": 1024
    },
    {
      "x": -6,
      "y": 3,
      "z": 4,
      "name": "Soil_Dirt_Tilled",
      "components": {
        "Components": {
          "TilledSoil": {
            "Version": 1,
            "DecayTime": "0001-01-02T20:32:29Z"
          }
        }
      }
    },
    {
      "x": -6,
      "y": 4,
      "z": 4,
      "name": "*Plant_Crop_Wheat_Block_State_Definitions_StageFinal"
    },
    {
      "x": -6,
      "y": 5,
      "z": 4,
      "name": "*Plant_Crop_Wheat_Block_State_Definitions_StageFinal",
      "filler": 1024
    },
    {
      "x": -6,
      "y": 3,
      "z": 5,
      "name": "Soil_Dirt_Tilled",
      "components": {
        "Components": {
          "TilledSoil": {
            "Version": 1,
            "DecayTime": "0001-01-02T17:47:45Z"
          }
        }
      }
    },
    {
      "x": -6,
      "y": 4,
      "z": 10,
      "name": "Wood_Softwood_Fence"
    },
    {
      "x": -5,
      "y": 4,
      "z": -10,
      "name": "Wood_Softwood_Fence",
      "rotation": 2
    },
    {
      "x": -5,
      "y": 3,
      "z": -9,
      "name": "Soil_Dirt_Tilled",
      "components": {
        "Components": {
          "TilledSoil": {
            "Version": 1,
            "DecayTime": "0001-01-02T23:18:36Z"
          }
        }
      }
    },
    {
      "x": -5,
      "y": 4,
      "z": -9,
      "name": "*Plant_Crop_Wheat_Block_State_Definitions_StageFinal"
    },
    {
      "x": -5,
      "y": 5,
      "z": -9,
      "name": "*Plant_Crop_Wheat_Block_State_Definitions_StageFinal",
      "filler": 1024
    },
    {
      "x": -5,
      "y": 3,
      "z": -8,
      "name": "Soil_Dirt_Tilled",
      "components": {
        "Components": {
          "TilledSoil": {
            "Version": 1,
            "DecayTime": "0001-01-02T17:32:43Z"
          }
        }
      }
    },
    {
      "x": -5,
      "y": 3,
      "z": -5,
      "name": "Soil_Dirt_Tilled",
      "components": {
        "Components": {
          "TilledSoil": {
            "Version": 1,
            "DecayTime": "0001-01-02T20:41:39Z"
          }
        }
      }
    },
    {
      "x": -5,
      "y": 4,
      "z": -5,
      "name": "*Plant_Crop_Wheat_Block_State_Definitions_StageFinal"
    },
    {
      "x": -5,
      "y": 5,
      "z": -5,
      "name": "*Plant_Crop_Wheat_Block_State_Definitions_StageFinal",
      "filler": 1024
    },
    {
      "x": -5,
      "y": 3,
      "z": -4,
      "name": "Soil_Dirt_Tilled",
      "components": {
        "Components": {
          "TilledSoil": {
            "Version": 1,
            "DecayTime": "0001-01-02T22:33:59Z"
          }
        }
      }
    },
    {
      "x": -5,
      "y": 4,
      "z": -4,
      "name": "*Plant_Crop_Wheat_Block_State_Definitions_StageFinal"
    },
    {
      "x": -5,
      "y": 5,
      "z": -4,
      "name": "*Plant_Crop_Wheat_Block_State_Definitions_StageFinal",
      "filler": 1024
    },
    {
      "x": -5,
      "y": 3,
      "z": -3,
      "name": "Soil_Dirt_Tilled",
      "components": {
        "Components": {
          "TilledSoil": {
            "Version": 1,
            "DecayTime": "0001-01-02T21:02:56Z"
          }
        }
      }
    },
    {
      "x": -5,
      "y": 3,
      "z": -2,
      "name": "Soil_Dirt_Tilled",
      "components": {
        "Components": {
          "TilledSoil": {
            "Version": 1,
            "DecayTime": "0001-01-02T17:59:12Z"
          }
        }
      }
    },
    {
      "x": -5,
      "y": 4,
      "z": -2,
      "name": "*Plant_Crop_Wheat_Block_State_Definitions_StageFinal"
    },
    {
      "x": -5,
      "y": 5,
      "z": -2,
      "name": "*Plant_Crop_Wheat_Block_State_Definitions_StageFinal",
      "filler": 1024
    },
    {
      "x": -5,
      "y": 3,
      "z": 0,
      "name": "Soil_Dirt_Tilled",
      "components": {
        "Components": {
          "TilledSoil": {
            "Version": 1,
            "DecayTime": "0001-01-02T20:16:51Z"
          }
        }
      }
    },
    {
      "x": -5,
      "y": 3,
      "z": 2,
      "name": "Soil_Dirt_Tilled",
      "components": {
        "Components": {
          "TilledSoil": {
            "Version": 1,
            "DecayTime": "0001-01-02T19:30:31Z"
          }
        }
      }
    },
    {
      "x": -5,
      "y": 4,
      "z": 2,
      "name": "*Plant_Crop_Wheat_Block_State_Definitions_StageFinal"
    },
    {
      "x": -5,
      "y": 5,
      "z": 2,
      "name": "*Plant_Crop_Wheat_Block_State_Definitions_StageFinal",
      "filler": 1024
    },
    {
      "x": -5,
      "y": 3,
      "z": 3,
      "name": "Soil_Dirt_Tilled",
      "components": {
        "Components": {
          "TilledSoil": {
            "Version": 1,
            "DecayTime": "0001-01-02T19:39:52Z"
          }
        }
      }
    },
    {
      "x": -5,
      "y": 3,
      "z": 4,
      "name": "Soil_Dirt_Tilled",
      "components": {
        "Components": {
          "TilledSoil": {
            "Version": 1,
            "DecayTime": "0001-01-02T20:39:23Z"
          }
        }
      }
    },
    {
      "x": -5,
      "y": 3,
      "z": 5,
      "name": "Soil_Dirt_Tilled",
      "components": {
        "Components": {
          "TilledSoil": {
            "Version": 1,
            "DecayTime": "0001-01-02T17:02:58Z"
          }
        }
      }
    },
    {
      "x": -5,
      "y": 4,
      "z": 5,
      "name": "*Plant_Crop_Wheat_Block_State_Definitions_StageFinal"
    },
    {
      "x": -5,
      "y": 5,
      "z": 5,
      "name": "*Plant_Crop_Wheat_Block_State_Definitions_StageFinal",
      "filler": 1024
    },
    {
      "x": -5,
      "y": 3,
      "z": 6,
      "name": "Soil_Dirt_Tilled",
      "components": {
        "Components": {
          "TilledSoil": {
            "Version": 1,
            "DecayTime": "0001-01-02T20:25:05Z"
          }
        }
      }
    },
    {
      "x": -5,
      "y": 4,
      "z": 6,
      "name": "*Plant_Crop_Wheat_Block_State_Definitions_StageFinal"
    },
    {
      "x": -5,
      "y": 5,
      "z": 6,
      "name": "*Plant_Crop_Wheat_Block_State_Definitions_StageFinal",
      "filler": 1024
    },
    {
      "x": -5,
      "y": 4,
      "z": 10,
      "name": "Wood_Softwood_Fence"
    },
    {
      "x": -4,
      "y": 4,
      "z": 10,
      "name": "Wood_Softwood_Fence"
    },
    {
      "x": -3,
      "y": 4,
      "z": 3,
      "name": "Rock_Stone_Cobble_Wall",
      "rotation": 1
    },
    {
      "x": -3,
      "y": 4,
      "z": 4,
      "name": "Rock_Stone_Cobble_Wall",
      "rotation": 1
    },
    {
      "x": -3,
      "y": 4,
      "z": 5,
      "name": "Rock_Stone_Cobble_Wall",
      "rotation": 1
    },
    {
      "x": -3,
      "y": 4,
      "z": 6,
      "name": "Rock_Stone_Cobble_Wall",
      "rotation": 1
    },
    {
      "x": -3,
      "y": 4,
      "z": 9,
      "name": "Wood_Softwood_Fence",
      "rotation": 1
    },
    {
      "x": -3,
      "y": 4,
      "z": 10,
      "name": "*Wood_Softwood_Fence_State_Definitions_Corner",
      "rotation": 3
    },
    {
      "x": -2,
      "y": 4,
      "z": -10,
      "name": "Wood_Softwood_Fence",
      "rotation": 2
    },
    {
      "x": -1,
      "y": 4,
      "z": -10,
      "name": "Wood_Softwood_Fence",
      "rotation": 2
    },
    {
      "x": 1,
      "y": 4,
      "z": -10,
      "name": "Wood_Softwood_Fence",
      "rotation": 2
    },
    {
      "x": 2,
      "y": 4,
      "z": -10,
      "name": "*Wood_Softwood_Fence_State_Definitions_Corner"
    },
    {
      "x": 2,
      "y": 4,
      "z": -9,
      "name": "Wood_Softwood_Fence",
      "rotation": 1
    },
    {
      "x": 2,
      "y": 4,
      "z": -8,
      "name": "Wood_Softwood_Fence",
      "rotation": 1
    },
    {
      "x": 6,
      "y": 4,
      "z": -13,
      "name": "*Wood_Softwood_Fence_State_Definitions_Corner",
      "rotation": 1
    },
    {
      "x": 6,
      "y": 4,
      "z": -12,
      "name": "Wood_Softwood_Fence",
      "rotation": 3
    },
    {
      "x": 6,
      "y": 4,
      "z": -11,
      "name": "Wood_Softwood_Fence",
      "rotation": 3
    },
    {
      "x": 6,
      "y": 4,
      "z": -9,
      "name": "Wood_Softwood_Fence",
      "rotation": 3
    },
    {
      "x": 6,
      "y": 4,
      "z": -8,
      "name": "Wood_Softwood_Fence",
      "rotation": 3
    },
    {
      "x": 6,
      "y": 4,
      "z": -7,
      "name": "Wood_Softwood_Fence",
      "rotation": 3
    },
    {
      "x": 7,
      "y": 4,
      "z": -13,
      "name": "Wood_Softwood_Fence",
      "rotation": 2
    },
    {
      "x": 7,
      "y": 4,
      "z": -2,
      "name": "Wood_Softwood_Fence"
    },
    {
      "x": 9,
      "y": 3,
      "z": -4,
      "name": "Soil_Dirt_Tilled",
      "components": {
        "Components": {
          "TilledSoil": {
            "Version": 1,
            "DecayTime": "0001-01-02T20:33:09Z"
          }
        }
      }
    },
    {
      "x": 9,
      "y": 4,
      "z": -4,
      "name": "*Plant_Crop_Wheat_Block_State_Definitions_StageFinal"
    },
    {
      "x": 9,
      "y": 5,
      "z": -4,
      "name": "*Plant_Crop_Wheat_Block_State_Definitions_StageFinal",
      "filler": 1024
    },
    {
      "x": 9,
      "y": 3,
      "z": -3,
      "name": "Soil_Dirt_Tilled",
      "components": {
        "Components": {
          "TilledSoil": {
            "Version": 1,
            "DecayTime": "0001-01-02T21:55:52Z"
          }
        }
      }
    },
    {
      "x": 9,
      "y": 4,
      "z": -3,
      "name": "*Plant_Crop_Wheat_Block_State_Definitions_StageFinal"
    },
    {
      "x": 9,
      "y": 5,
      "z": -3,
      "name": "*Plant_Crop_Wheat_Block_State_Definitions_StageFinal",
      "filler": 1024
    },
    {
      "x": 9,
      "y": 4,
      "z": -2,
      "name": "Wood_Softwood_Fence"
    },
    {
      "x": 10,
      "y": 3,
      "z": -4,
      "name": "Soil_Dirt_Tilled",
      "components": {
        "Components": {
          "TilledSoil": {
            "Version": 1,
            "DecayTime": "0001-01-02T23:10:18Z"
          }
        }
      }
    },
    {
      "x": 10,
      "y": 3,
      "z": -3,
      "name": "Soil_Dirt_Tilled",
      "components": {
        "Components": {
          "TilledSoil": {
            "Version": 1,
            "DecayTime": "0001-01-02T20:36:03Z"
          }
        }
      }
    },
    {
      "x": 10,
      "y": 4,
      "z": -2,
      "name": "*Wood_Softwood_Fence_State_Definitions_Corner"
    },
    {
      "x": 10,
      "y": 4,
      "z": -1,
      "name": "Wood_Softwood_Fence",
      "rotation": 3
    },
    {
      "x": 10,
      "y": 4,
      "z": 2,
      "name": "Wood_Softwood_Fence",
      "rotation": 3
    },
    {
      "x": 10,
      "y": 4,
      "z": 3,
      "name": "Wood_Softwood_Fence",
      "rotation": 3
    },
    {
      "x": 10,
      "y": 4,
      "z": 7,
      "name": "Wood_Softwood_Fence",
      "rotation": 3
    },
    {
      "x": 11,
      "y": 4,
      "z": -13,
      "name": "Wood_Softwood_Fence",
      "rotation": 2
    },
    {
      "x": 11,
      "y": 4,
      "z": -2,
      "name": "Wood_Softwood_Fence"
    },
    {
      "x": 12,
      "y": 4,
      "z": -13,
      "name": "Wood_Softwood_Fence",
      "rotation": 2
    },
    {
      "x": 12,
      "y": 3,
      "z": -4,
      "name": "Soil_Dirt_Tilled",
      "components": {
        "Components": {
          "TilledSoil": {
            "Version": 1,
            "DecayTime": "0001-01-02T18:57:49Z"
          }
        }
      }
    },
    {
      "x": 12,
      "y": 4,
      "z": -4,
      "name": "*Plant_Crop_Wheat_Block_State_Definitions_StageFinal"
    },
    {
      "x": 12,
      "y": 5,
      "z": -4,
      "name": "*Plant_Crop_Wheat_Block_State_Definitions_StageFinal",
      "filler": 1024
    },
    {
      "x": 12,
      "y": 3,
      "z": -3,
      "name": "Soil_Dirt_Tilled",
      "components": {
        "Components": {
          "TilledSoil": {
            "Version": 1,
            "DecayTime": "0001-01-02T22:31:11Z"
          }
        }
      }
    },
    {
      "x": 12,
      "y": 4,
      "z": -2,
      "name": "Wood_Softwood_Fence"
    },
    {
      "x": 13,
      "y": 3,
      "z": -4,
      "name": "Soil_Dirt_Tilled",
      "components": {
        "Components": {
          "TilledSoil": {
            "Version": 1,
            "DecayTime": "0001-01-02T23:35:19Z"
          }
        }
      }
    },
    {
      "x": 13,
      "y": 3,
      "z": -3,
      "name": "Soil_Dirt_Tilled",
      "components": {
        "Components": {
          "TilledSoil": {
            "Version": 1,
            "DecayTime": "0001-01-02T17:39:25Z"
          }
        }
      }
    },
    {
      "x": 13,
      "y": 4,
      "z": -3,
      "name": "*Plant_Crop_Wheat_Block_State_Definitions_StageFinal"
    },
    {
      "x": 13,
      "y": 5,
      "z": -3,
      "name": "*Plant_Crop_Wheat_Block_State_Definitions_StageFinal",
      "filler": 1024
    },
    {
      "x": 14,
      "y": 4,
      "z": -13,
      "name": "Wood_Softwood_Fence",
      "rotation": 2
    },
    {
      "x": 14,
      "y": 3,
      "z": -4,
      "name": "Soil_Dirt_Tilled",
      "components": {
        "Components": {
          "TilledSoil": {
            "Version": 1,
            "DecayTime": "0001-01-02T19:05:10Z"
          }
        }
      }
    },
    {
      "x": 14,
      "y": 3,
      "z": -3,
      "name": "Soil_Dirt_Tilled",
      "components": {
        "Components": {
          "TilledSoil": {
            "Version": 1,
            "DecayTime": "0001-01-02T19:28:35Z"
          }
        }
      }
    },
    {
      "x": 14,
      "y": 4,
      "z": -3,
      "name": "*Plant_Crop_Wheat_Block_State_Definitions_StageFinal"
    },
    {
      "x": 14,
      "y": 5,
      "z": -3,
      "name": "*Plant_Crop_Wheat_Block_State_Definitions_StageFinal",
      "filler": 1024
    },
    {
      "x": 15,
      "y": 3,
      "z": -3,
      "name": "Soil_Dirt_Tilled",
      "components": {
        "Components": {
          "TilledSoil": {
            "Version": 1,
            "DecayTime": "0001-01-02T21:58:59Z"
          }
        }
      }
    },
    {
      "x": 15,
      "y": 4,
      "z": -2,
      "name": "Wood_Softwood_Fence"
    },
    {
      "x": 16,
      "y": 4,
      "z": -2,
      "name": "Wood_Softwood_Fence"
    },
    {
      "x": 17,
      "y": 4,
      "z": -2,
      "name": "Wood_Softwood_Fence"
    },
    {
      "x": 18,
      "y": 4,
      "z": -13,
      "name": "Wood_Softwood_Fence",
      "rotation": 2
    },
    {
      "x": 18,
      "y": 3,
      "z": -11,
      "name": "Soil_Dirt_Tilled",
      "components": {
        "Components": {
          "TilledSoil": {
            "Version": 1,
            "DecayTime": "0001-01-02T23:00:17Z"
          }
        }
      }
    },
    {
      "x": 18,
      "y": 4,
      "z": -11,
      "name": "*Plant_Crop_Wheat_Block_State_Definitions_StageFinal"
    },
    {
      "x": 18,
      "y": 5,
      "z": -11,
      "name": "*Plant_Crop_Wheat_Block_State_Definitions_StageFinal",
      "filler": 1024
    },
    {
      "x": 18,
      "y": 3,
      "z": -10,
      "name": "Soil_Dirt_Tilled",
      "components": {
        "Components": {
          "TilledSoil": {
            "Version": 1,
            "DecayTime": "0001-01-02T21:23:00Z"
          }
        }
      }
    },
    {
      "x": 18,
      "y": 3,
      "z": -9,
      "name": "Soil_Dirt_Tilled",
      "components": {
        "Components": {
          "TilledSoil": {
            "Version": 1,
            "DecayTime": "0001-01-02T18:49:45Z"
          }
        }
      }
    },
    {
      "x": 19,
      "y": 4,
      "z": -13,
      "name": "Wood_Softwood_Fence",
      "rotation": 2
    },
    {
      "x": 19,
      "y": 3,
      "z": -12,
      "name": "Soil_Dirt_Tilled",
      "components": {
        "Components": {
          "TilledSoil": {
            "Version": 1,
            "DecayTime": "0001-01-02T17:11:32Z"
          }
        }
      }
    },
    {
      "x": 19,
      "y": 4,
      "z": -12,
      "name": "*Plant_Crop_Wheat_Block_State_Definitions_StageFinal"
    },
    {
      "x": 19,
      "y": 5,
      "z": -12,
      "name": "*Plant_Crop_Wheat_Block_State_Definitions_StageFinal",
      "filler": 1024
    },
    {
      "x": 19,
      "y": 3,
      "z": -11,
      "name": "Soil_Dirt_Tilled",
      "components": {
        "Components": {
          "TilledSoil": {
            "Version": 1,
            "DecayTime": "0001-01-02T18:49:25Z"
          }
        }
      }
    },
    {
      "x": 19,
      "y": 3,
      "z": -10,
      "name": "Soil_Dirt_Tilled",
      "components": {
        "Components": {
          "TilledSoil": {
            "Version": 1,
            "DecayTime": "0001-01-02T23:52:36Z"
          }
        }
      }
    },
    {
      "x": 19,
      "y": 3,
      "z": -9,
      "name": "Soil_Dirt_Tilled",
      "components": {
        "Components": {
          "TilledSoil": {
            "Version": 1,
            "DecayTime": "0001-01-02T18:21:42Z"
          }
        }
      }
    },
    {
      "x": 20,
      "y": 3,
      "z": -12,
      "name": "Soil_Dirt_Tilled",
      "components": {
        "Components": {
          "TilledSoil": {
            "Version": 1,
            "DecayTime": "0001-01-02T21:39:53Z"
          }
        }
      }
    },
    {
      "x": 20,
      "y": 3,
      "z": -11,
      "name": "Soil_Dirt_Tilled",
      "components": {
        "Components": {
          "TilledSoil": {
            "Version": 1,
            "DecayTime": "0001-01-02T22:25:32Z"
          }
        }
      }
    },
    {
      "x": 20,
      "y": 4,
      "z": -2,
      "name": "Wood_Softwood_Fence"
    },
    {
      "x": 21,
      "y": 4,
      "z": -13,
      "name": "Wood_Softwood_Fence",
      "rotation": 2
    },
    {
      "x": 21,
      "y": 3,
      "z": -12,
      "name": "Soil_Dirt_Tilled",
      "components": {
        "Components": {
          "TilledSoil": {
            "Version": 1,
            "DecayTime": "0001-01-02T18:47:50Z"
          }
        }
      }
    },
    {
      "x": 21,
      "y": 3,
      "z": -11,
      "name": "Soil_Dirt_Tilled",
      "components": {
        "Components": {
          "TilledSoil": {
            "Version": 1,
            "DecayTime": "0001-01-02T19:41:50Z"
          }
        }
      }
    },
    {
      "x": 21,
      "y": 3,
      "z": -10,
      "name": "Soil_Dirt_Tilled",
      "components": {
        "Components": {
          "TilledSoil": {
            "Version": 1,
            "DecayTime": "0001-01-02T19:51:08Z"
          }
        }
      }
    },
    {
      "x": 21,
      "y": 4,
      "z": -10,
      "name": "*Plant_Crop_Wheat_Block_State_Definitions_StageFinal"
    },
    {
      "x": 21,
      "y": 5,
      "z": -10,
      "name": "*Plant_Crop_Wheat_Block_State_Definitions_StageFinal",
      "filler": 1024
    },
    {
      "x": 22,
      "y": 4,
      "z": -13,
      "name": "*Wood_Softwood_Fence_State_Definitions_Corner"
    },
    {
      "x": 22,
      "y": 4,
      "z": -12,
      "name": "Wood_Softwood_Fence",
      "rotation": 1
    },
    {
      "x": 22,
      "y": 4,
      "z": -7,
      "name": "Wood_Softwood_Fence",
      "rotation": 1
    },
    {
      "x": 22,
      "y": 4,
      "z": -5,
      "name": "Wood_Softwood_Fence",
      "rotation": 1
    },
    {
      "x": 22,
      "y": 4,
      "z": -2,
      "name": "Wood_Softwood_Fence",
      "rotation": 1
    },
    {
      "x": 22,
      "y": 4,
      "z": -1,
      "name": "Wood_Softwood_Fence",
      "rotation": 1
    }
  ]
}