{
  "version": 8,
  "blockIdVersion": 11,
  "anchorX": 1,
  "anchorY": 0,
  "anchorZ": 1,
  "blocks": [
    {
      "x": -3,
      "y": 3,
      "z": 1,
      "name": "Plant_Leaves_Palo"
    },
    {
      "x": -2,
      "y": 3,
      "z": 0,
      "name": "Plant_Leaves_Palo"
    },
    {
      "x": -2,
      "y": 3,
      "z": 1,
      "name": "Plant_Leaves_Palo"
    },
    {
      "x": -2,
      "y": 3,
      "z": 2,
      "name": "Plant_Leaves_Palo"
    },
    {
      "x": -1,
      "y": 4,
      "z": -2,
      "name": "Plant_Leaves_Palo"
    },
    {
      "x": -1,
      "y": 6,
      "z": -1,
      "name": "Plant_Leaves_Palo"
    },
    {
      "x": -1,
      "y": 3,
      "z": 0,
      "name": "Plant_Leaves_Palo"
    },
    {
      "x": -1,
      "y": 4,
      "z": 0,
      "name": "Plant_Leaves_Palo"
    },
    {
      "x": -1,
      "y": 6,
      "z": 0,
      "name": "Plant_Leaves_Palo"
    },
    {
      "x": -1,
      "y": 3,
      "z": 1,
      "name": "Wood_Palo_Branch_Long",
      "rotation": 5
    },
    {
      "x": -1,
      "y": 4,
      "z": 1,
      "name": "Plant_Leaves_Palo"
    },
    {
      "x": -1,
      "y": 3,
      "z": 2,
      "name": "Plant_Leaves_Palo"
    },
    {
      "x": -1,
      "y": 6,
      "z": 2,
      "name": "Plant_Leaves_Palo"
    },
    {
      "x": -1,
      "y": 4,
      "z": 3,
      "name": "Plant_Leaves_Palo"
    },
    {
      "x": -1,
      "y": 6,
      "z": 3,
      "name": "Plant_Leaves_Palo"
    },
    {
      "x": 0,
      "y": 4,
      "z": -2,
      "name": "Plant_Leaves_Palo"
    },
    {
      "x": 0,
      "y": 4,
      "z": -1,
      "name": "Plant_Leaves_Palo"
    },
    {
      "x": 0,
      "y": 5,
      "z": -1,
      "name": "Plant_Leaves_Palo"
    },
    {
      "x": 0,
      "y": 3,
      "z": 0,
      "name": "Plant_Leaves_Palo"
    },
    {
      "x": 0,
      "y": 6,
      "z": 0,
      "name": "Plant_Leaves_Palo"
    },
    {
      "x": 0,
      "y": 3,
      "z": 1,
      "name": "Wood_Palo_Branch_Long",
      "rotation": 5
    },
    {
      "x": 0,
      "y": 5,
      "z": 1,
      "name": "Plant_Leaves_Palo"
    },
    {
      "x": 0,
      "y": 6,
      "z": 1,
      "name": "Plant_Leaves_Palo"
    },
    {
      "x": 0,
      "y": 4,
      "z": 2,
      "name": "Plant_Leaves_Palo"
    },
    {
      "x": 0,
      "y": 6,
      "z": 2,
      "name": "Plant_Leaves_Palo"
    },
    {
      "x": 0,
      "y": 4,
      "z": 3,
      "name": "Plant_Leaves_Palo"
    },
    {
      "x": 0,
      "y": 4,
      "z": 4,
      "name": "Plant_Leaves_Palo"
    },
    {
      "x": 1,
      "y": 4,
      "z": -3,
      "name": "Plant_Leaves_Palo"
    },
    {
      "x": 1,
      "y": 4,
      "z": -2,
      "name": "Wood_Palo_Branch_Long",
      "rotation": 4
    },
    {
      "x": 1,
      "y": 5,
      "z": -2,
      "name": "Plant_Leaves_Palo"
    },
    {
      "x": 1,
      "y": 4,
      "z": -1,
      "name": "Wood_Palo_Branch_Long",
      "rotation": 4
    },
    {
      "x": 1,
      "y": 5,
      "z": -1,
      "name": "Plant_Leaves_Palo"
    },
    {
      "x": 1,
      "y": 4,
      "z": 0,
      "name": "Wood_Palo_Branch_Long",
      "rotation": 4
    },
    {
      "x": 1,
      "y": 6,
      "z": 0,
      "name": "Plant_Leaves_Palo"
    },
    {
      "x": 1,
      "y": 0,
      "z": 1,
      "name": "Wood_Palo_Trunk_Full"
    },
    {
      "x": 1,
      "y": 1,
      "z": 1,
      "name": "Wood_Palo_Trunk"
    },
    {
      "x": 1,
      "y": 2,
      "z": 1,
      "name": "Wood_Palo_Trunk"
    },
    {
      "x": 1,
      "y": 3,
      "z": 1,
      "name": "Wood_Palo_Trunk"
    },
    {
      "x": 1,
      "y": 4,
      "z": 1,
      "name": "Wood_Palo_Trunk_Full"
    },
    {
      "x": 1,
      "y": 5,
      "z": 1,
      "name": "Wood_Palo_Branch_Long"
    },
    {
      "x": 1,
      "y": 6,
      "z": 1,
      "name": "Wood_Palo_Branch_Long"
    },
    {
      "x": 1,
      "y": 7,
      "z": 1,
      "name": "Plant_Leaves_Palo"
    },
    {
      "x": 1,
      "y": 4,
      "z": 2,
      "name": "Wood_Palo_Branch_Long",
      "rotation": 4
    },
    {
      "x": 1,
      "y": 5,
      "z": 2,
      "name": "Plant_Leaves_Palo"
    },
    {
      "x": 1,
      "y": 6,
      "z": 2,
      "name": "Plant_Leaves_Palo"
    },
    {
      "x": 1,
      "y": 7,
      "z": 2,
      "name": "Plant_Leaves_Palo"
    },
    {
      "x": 1,
      "y": 4,
      "z": 3,
      "name": "Wood_Palo_Branch_Long",
      "rotation": 4
    },
    {
      "x": 1,
      "y": 5,
      "z": 3,
      "name": "Plant_Leaves_Palo"
    },
    {
      "x": 1,
      "y": 4,
      "z": 4,
      "name": "Plant_Leaves_Palo"
    },
    {
      "x": 1,
      "y": 5,
      "z": 4,
      "name": "Plant_Leaves_Palo"
    },
    {
      "x": 1,
      "y": 4,
      "z": 5,
      "name": "Plant_Leaves_Palo"
    },
    {
      "x": 2,
      "y": 4,
      "z": -2,
      "name": "Plant_Leaves_Palo"
    },
    {
      "x": 2,
      "y": 4,
      "z": -1,
      "name": "Plant_Leaves_Palo"
    },
    {
      "x": 2,
      "y": 4,
      "z": 0,
      "name": "Plant_Leaves_Palo"
    },
    {
      "x": 2,
      "y": 6,
      "z": 0,
      "name": "Plant_Leaves_Palo"
    },
    {
      "x": 2,
      "y": 4,
      "z": 1,
      "name": "Wood_Palo_Branch_Long",
      "rotation": 5
    },
    {
      "x": 2,
      "y": 5,
      "z": 1,
      "name": "Plant_Leaves_Palo"
    },
    {
      "x": 2,
      "y": 6,
      "z": 1,
      "name": "Plant_Leaves_Palo"
    },
    {
      "x": 2,
      "y": 7,
      "z": 1,
      "name": "Plant_Leaves_Palo"
    },
    {
      "x": 2,
      "y": 4,
      "z": 3,
      "name": "Plant_Leaves_Palo"
    },
    {
      "x": 2,
      "y": 5,
      "z": 3,
      "name": "Plant_Leaves_Palo"
    },
    {
      "x": 3,
      "y": 4,
      "z": -1,
      "name": "Plant_Leaves_Palo"
    },
    {
      "x": 3,
      "y": 6,
      "z": -1,
      "name": "Plant_Leaves_Palo"
    },
    {
      "x": 3,
      "y": 4,
      "z": 0,
      "name": "Plant_Leaves_Palo"
    },
    {
      "x": 3,
      "y": 6,
      "z": 0,
      "name": "Plant_Leaves_Palo"
    },
    {
      "x": 3,
      "y": 4,
      "z": 1,
      "name": "Wood_Palo_Branch_Long",
      "rotation": 5
    },
    {
      "x": 3,
      "y": 5,
      "z": 1,
      "name": "Plant_Leaves_Palo"
    },
    {
      "x": 3,
      "y": 4,
      "z": 2,
      "name": "Plant_Leaves_Palo"
    },
    {
      "x": 4,
      "y": 4,
      "z": 0,
      "name": "Plant_Leaves_Palo"
    },
    {
      "x": 4,
      "y": 4,
      "z": 1,
      "name": "Plant_Leaves_Palo"
    },
    {
      "x": 4,
      "y": 4,
      "z": 2,
      "name": "Plant_Leaves_Palo"
    },
    {
      "x": 4,
      "y": 4,
      "z": 3,
      "name": "Plant_Leaves_Palo"
    },
    {
      "x": 5,
      "y": 4,
      "z": 0,
      "name": "Plant_Leaves_Palo"
    },
    {
      "x": 5,
      "y": 4,
      "z": 1,
      "name": "Plant_Leaves_Palo"
    }
  ]
}