{
  "version": 8,
  "blockIdVersion": 11,
  "anchorX": 1,
  "anchorY": 0,
  "anchorZ": 1,
  "blocks": [
    {
      "x": -6,
      "y": 6,
      "z": -1,
      "name": "Plant_Leaves_Palo"
    },
    {
      "x": -6,
      "y": 6,
      "z": 1,
      "name": "Plant_Leaves_Palo"
    },
    {
      "x": -6,
      "y": 6,
      "z": 2,
      "name": "Plant_Leaves_Palo"
    },
    {
      "x": -5,
      "y": 6,
      "z": -1,
      "name": "Plant_Leaves_Palo"
    },
    {
      "x": -5,
      "y": 6,
      "z": 0,
      "name": "Plant_Leaves_Palo"
    },
    {
      "x": -5,
      "y": 6,
      "z": 1,
      "name": "Plant_Leaves_Palo"
    },
    {
      "x": -5,
      "y": 6,
      "z": 2,
      "name": "Plant_Leaves_Palo"
    },
    {
      "x": -5,
      "y": 7,
      "z": 2,
      "name": "Plant_Leaves_Palo"
    },
    {
      "x": -5,
      "y": 6,
      "z": 3,
      "name": "Plant_Leaves_Palo"
    },
    {
      "x": -5,
      "y": 6,
      "z": 4,
      "name": "Plant_Leaves_Palo"
    },
    {
      "x": -4,
      "y": 6,
      "z": -1,
      "name": "Plant_Leaves_Palo"
    },
    {
      "x": -4,
      "y": 6,
      "z": 0,
      "name": "Plant_Leaves_Palo"
    },
    {
      "x": -4,
      "y": 7,
      "z": 0,
      "name": "Plant_Leaves_Palo"
    },
    {
      "x": -4,
      "y": 6,
      "z": 1,
      "name": "Wood_Palo_Branch_Long",
      "rotation": 5
    },
    {
      "x": -4,
      "y": 7,
      "z": 1,
      "name": "Plant_Leaves_Palo"
    },
    {
      "x": -4,
      "y": 6,
      "z": 2,
      "name": "Plant_Leaves_Palo"
    },
    {
      "x": -4,
      "y": 7,
      "z": 2,
      "name": "Plant_Leaves_Palo"
    },
    {
      "x": -4,
      "y": 6,
      "z": 3,
      "name": "Plant_Leaves_Palo"
    },
    {
      "x": -4,
      "y": 7,
      "z": 3,
      "name": "Plant_Leaves_Palo"
    },
    {
      "x": -4,
      "y": 6,
      "z": 4,
      "name": "Plant_Leaves_Palo"
    },
    {
      "x": -3,
      "y": 6,
      "z": -1,
      "name": "Plant_Leaves_Palo"
    },
    {
      "x": -3,
      "y": 6,
      "z": 0,
      "name": "Plant_Leaves_Palo"
    },
    {
      "x": -3,
      "y": 7,
      "z": 0,
      "name": "Plant_Leaves_Palo"
    },
    {
      "x": -3,
      "y": 6,
      "z": 1,
      "name": "Wood_Palo_Trunk_Full"
    },
    {
      "x": -3,
      "y": 7,
      "z": 1,
      "name": "Plant_Leaves_Palo"
    },
    {
      "x": -3,
      "y": 6,
      "z": 2,
      "name": "Plant_Leaves_Palo"
    },
    {
      "x": -3,
      "y": 7,
      "z": 2,
      "name": "Plant_Leaves_Palo"
    },
    {
      "x": -3,
      "y": 6,
      "z": 3,
      "name": "Plant_Leaves_Palo"
    },
    {
      "x": -2,
      "y": 7,
      "z": -4,
      "name": "Plant_Leaves_Palo"
    },
    {
      "x": -2,
      "y": 4,
      "z": -3,
      "name": "Plant_Leaves_Palo"
    },
    {
      "x": -2,
      "y": 7,
      "z": -3,
      "name": "Plant_Leaves_Palo"
    },
    {
      "x": -2,
      "y": 6,
      "z": 0,
      "name": "Plant_Leaves_Palo"
    },
    {
      "x": -2,
      "y": 5,
      "z": 1,
      "name": "Wood_Palo_Trunk_Full"
    },
    {
      "x": -2,
      "y": 6,
      "z": 1,
      "name": "Wood_Palo_Trunk_Full"
    },
    {
      "x": -2,
      "y": 6,
      "z": 2,
      "name": "Plant_Leaves_Palo"
    },
    {
      "x": -2,
      "y": 8,
      "z": 2,
      "name": "Plant_Leaves_Palo"
    },
    {
      "x": -2,
      "y": 6,
      "z": 6,
      "name": "Plant_Leaves_Palo"
    },
    {
      "x": -1,
      "y": 7,
      "z": -5,
      "name": "Plant_Leaves_Palo"
    },
    {
      "x": -1,
      "y": 7,
      "z": -4,
      "name": "Plant_Leaves_Palo"
    },
    {
      "x": -1,
      "y": 4,
      "z": -3,
      "name": "Plant_Leaves_Palo"
    },
    {
      "x": -1,
      "y": 5,
      "z": -3,
      "name": "Plant_Leaves_Palo"
    },
    {
      "x": -1,
      "y": 7,
      "z": -3,
      "name": "Plant_Leaves_Palo"
    },
    {
      "x": -1,
      "y": 4,
      "z": -2,
      "name": "Plant_Leaves_Palo"
    },
    {
      "x": -1,
      "y": 8,
      "z": -2,
      "name": "Plant_Leaves_Palo"
    },
    {
      "x": -1,
      "y": 9,
      "z": -2,
      "name": "Plant_Leaves_Palo"
    },
    {
      "x": -1,
      "y": 4,
      "z": -1,
      "name": "Plant_Leaves_Palo"
    },
    {
      "x": -1,
      "y": 9,
      "z": -1,
      "name": "Plant_Leaves_Palo"
    },
    {
      "x": -1,
      "y": 5,
      "z": 1,
      "name": "Wood_Palo_Trunk_Full"
    },
    {
      "x": -1,
      "y": 8,
      "z": 1,
      "name": "Plant_Leaves_Palo"
    },
    {
      "x": -1,
      "y": 8,
      "z": 2,
      "name": "Wood_Palo_Branch_Long",
      "rotation": 5
    },
    {
      "x": -1,
      "y": 9,
      "z": 2,
      "name": "Plant_Leaves_Palo"
    },
    {
      "x": -1,
      "y": 8,
      "z": 3,
      "name": "Plant_Leaves_Palo"
    },
    {
      "x": -1,
      "y": 8,
      "z": 4,
      "name": "Plant_Leaves_Palo"
    },
    {
      "x": -1,
      "y": 6,
      "z": 5,
      "name": "Plant_Leaves_Palo"
    },
    {
      "x": -1,
      "y": 6,
      "z": 6,
      "name": "Wood_Palo_Branch_Long",
      "rotation": 5
    },
    {
      "x": -1,
      "y": 7,
      "z": 6,
      "name": "Plant_Leaves_Palo"
    },
    {
      "x": -1,
      "y": 6,
      "z": 7,
      "name": "Plant_Leaves_Palo"
    },
    {
      "x": 0,
      "y": 7,
      "z": -5,
      "name": "Plant_Leaves_Palo"
    },
    {
      "x": 0,
      "y": 4,
      "z": -4,
      "name": "Plant_Leaves_Palo"
    },
    {
      "x": 0,
      "y": 7,
      "z": -4,
      "name": "Plant_Leaves_Palo"
    },
    {
      "x": 0,
      "y": 4,
      "z": -3,
      "name": "Plant_Leaves_Palo"
    },
    {
      "x": 0,
      "y": 7,
      "z": -3,
      "name": "Wood_Palo_Branch_Long",
      "rotation": 5
    },
    {
      "x": 0,
      "y": 8,
      "z": -3,
      "name": "Plant_Leaves_Palo"
    },
    {
      "x": 0,
      "y": 9,
      "z": -3,
      "name": "Plant_Leaves_Palo"
    },
    {
      "x": 0,
      "y": 10,
      "z": -3,
      "name": "Plant_Leaves_Palo"
    },
    {
      "x": 0,
      "y": 4,
      "z": -2,
      "name": "Plant_Leaves_Palo"
    },
    {
      "x": 0,
      "y": 5,
      "z": -2,
      "name": "Plant_Leaves_Palo"
    },
    {
      "x": 0,
      "y": 7,
      "z": -2,
      "name": "Plant_Leaves_Palo"
    },
    {
      "x": 0,
      "y": 8,
      "z": -2,
      "name": "Plant_Leaves_Palo"
    },
    {
      "x": 0,
      "y": 9,
      "z": -2,
      "name": "Plant_Leaves_Palo"
    },
    {
      "x": 0,
      "y": 4,
      "z": -1,
      "name": "Plant_Leaves_Palo"
    },
    {
      "x": 0,
      "y": 9,
      "z": -1,
      "name": "Plant_Leaves_Palo"
    },
    {
      "x": 0,
      "y": 8,
      "z": 0,
      "name": "Plant_Leaves_Palo"
    },
    {
      "x": 0,
      "y": 9,
      "z": 0,
      "name": "Plant_Leaves_Palo"
    },
    {
      "x": 0,
      "y": 0,
      "z": 1,
      "name": "Wood_Palo_Trunk_Full"
    },
    {
      "x": 0,
      "y": 1,
      "z": 1,
      "name": "Wood_Palo_Trunk_Full"
    },
    {
      "x": 0,
      "y": 4,
      "z": 1,
      "name": "Wood_Palo_Trunk_Full"
    },
    {
      "x": 0,
      "y": 5,
      "z": 1,
      "name": "Wood_Palo_Trunk_Full"
    },
    {
      "x": 0,
      "y": 8,
      "z": 1,
      "name": "Plant_Leaves_Palo"
    },
    {
      "x": 0,
      "y": 9,
      "z": 1,
      "name": "Plant_Leaves_Palo"
    },
    {
      "x": 0,
      "y": 8,
      "z": 2,
      "name": "Wood_Palo_Branch_Long",
      "rotation": 5
    },
    {
      "x": 0,
      "y": 9,
      "z": 2,
      "name": "Plant_Leaves_Palo"
    },
    {
      "x": 0,
      "y": 8,
      "z": 3,
      "name": "Plant_Leaves_Palo"
    },
    {
      "x": 0,
      "y": 9,
      "z": 3,
      "name": "Plant_Leaves_Palo"
    },
    {
      "x": 0,
      "y": 8,
      "z": 4,
      "name": "Plant_Leaves_Palo"
    },
    {
      "x": 0,
      "y": 6,
      "z": 5,
      "name": "Plant_Leaves_Palo"
    },
    {
      "x": 0,
      "y": 6,
      "z": 6,
      "name": "Wood_Palo_Branch_Long",
      "rotation": 5
    },
    {
      "x": 0,
      "y": 7,
      "z": 6,
      "name": "Plant_Leaves_Palo"
    },
    {
      "x": 0,
      "y": 6,
      "z": 7,
      "name": "Plant_Leaves_Palo"
    },
    {
      "x": 0,
      "y": 7,
      "z": 7,
      "name": "Plant_Leaves_Palo"
    },
    {
      "x": 0,
      "y": 6,
      "z": 8,
      "name": "Plant_Leaves_Palo"
    },
    {
      "x": 1,
      "y": 7,
      "z": -5,
      "name": "Plant_Leaves_Palo"
    },
    {
      "x": 1,
      "y": 8,
      "z": -5,
      "name": "Plant_Leaves_Palo"
    },
    {
      "x": 1,
      "y": 4,
      "z": -4,
      "name": "Plant_Leaves_Palo"
    },
    {
      "x": 1,
      "y": 5,
      "z": -4,
      "name": "Plant_Leaves_Palo"
    },
    {
      "x": 1,
      "y": 7,
      "z": -4,
      "name": "Wood_Palo_Branch_Long",
      "rotation": 4
    },
    {
      "x": 1,
      "y": 8,
      "z": -4,
      "name": "Plant_Leaves_Palo"
    },
    {
      "x": 1,
      "y": 4,
      "z": -3,
      "name": "Plant_Leaves_Palo"
    },
    {
      "x": 1,
      "y": 5,
      "z": -3,
      "name": "Plant_Leaves_Palo"
    },
    {
      "x": 1,
      "y": 7,
      "z": -3,
      "name": "Wood_Palo_Trunk_Full"
    },
    {
      "x": 1,
      "y": 8,
      "z": -3,
      "name": "Plant_Leaves_Palo"
    },
    {
      "x": 1,
      "y": 9,
      "z": -3,
      "name": "Plant_Leaves_Palo"
    },
    {
      "x": 1,
      "y": 4,
      "z": -2,
      "name": "Wood_Palo_Branch_Long",
      "rotation": 4
    },
    {
      "x": 1,
      "y": 5,
      "z": -2,
      "name": "Plant_Leaves_Palo"
    },
    {
      "x": 1,
      "y": 6,
      "z": -2,
      "name": "Wood_Palo_Trunk_Full"
    },
    {
      "x": 1,
      "y": 7,
      "z": -2,
      "name": "Wood_Palo_Trunk_Full"
    },
    {
      "x": 1,
      "y": 8,
      "z": -2,
      "name": "Wood_Palo_Branch_Long"
    },
    {
      "x": 1,
      "y": 9,
      "z": -2,
      "name": "Wood_Palo_Branch_Long"
    },
    {
      "x": 1,
      "y": 10,
      "z": -2,
      "name": "Plant_Leaves_Palo"
    },
    {
      "x": 1,
      "y": 4,
      "z": -1,
      "name": "Wood_Palo_Branch_Long",
      "rotation": 4
    },
    {
      "x": 1,
      "y": 6,
      "z": -1,
      "name": "Wood_Palo_Trunk_Full"
    },
    {
      "x": 1,
      "y": 8,
      "z": -1,
      "name": "Plant_Leaves_Palo"
    },
    {
      "x": 1,
      "y": 9,
      "z": -1,
      "name": "Plant_Leaves_Palo"
    },
    {
      "x": 1,
      "y": 0,
      "z": 0,
      "name": "Wood_Palo_Trunk_Full"
    },
    {
      "x": 1,
      "y": 1,
      "z": 0,
      "name": "Wood_Palo_Trunk_Full"
    },
    {
      "x": 1,
      "y": 4,
      "z": 0,
      "name": "Wood_Palo_Branch_Long",
      "rotation": 4
    },
    {
      "x": 1,
      "y": 6,
      "z": 0,
      "name": "Wood_Palo_Trunk_Full"
    },
    {
      "x": 1,
      "y": 8,
      "z": 0,
      "name": "Plant_Leaves_Palo"
    },
    {
      "x": 1,
      "y": 0,
      "z": 1,
      "name": "Wood_Palo_Trunk_Full"
    },
    {
      "x": 1,
      "y": 1,
      "z": 1,
      "name": "Wood_Palo_Trunk"
    },
    {
      "x": 1,
      "y": 2,
      "z": 1,
      "name": "Wood_Palo_Trunk"
    },
    {
      "x": 1,
      "y": 3,
      "z": 1,
      "name": "Wood_Palo_Trunk"
    },
    {
      "x": 1,
      "y": 4,
      "z": 1,
      "name": "Wood_Palo_Trunk"
    },
    {
      "x": 1,
      "y": 5,
      "z": 1,
      "name": "Wood_Palo_Trunk"
    },
    {
      "x": 1,
      "y": 6,
      "z": 1,
      "name": "Wood_Palo_Trunk"
    },
    {
      "x": 1,
      "y": 7,
      "z": 1,
      "name": "Wood_Palo_Trunk_Full"
    },
    {
      "x": 1,
      "y": 8,
      "z": 1,
      "name": "Wood_Palo_Branch_Long"
    },
    {
      "x": 1,
      "y": 9,
      "z": 1,
      "name": "Plant_Leaves_Palo"
    },
    {
      "x": 1,
      "y": 0,
      "z": 2,
      "name": "Wood_Palo_Trunk_Full"
    },
    {
      "x": 1,
      "y": 5,
      "z": 2,
      "name": "Wood_Palo_Trunk_Full"
    },
    {
      "x": 1,
      "y": 7,
      "z": 2,
      "name": "Wood_Palo_Trunk_Full"
    },
    {
      "x": 1,
      "y": 8,
      "z": 2,
      "name": "Wood_Palo_Trunk_Full"
    },
    {
      "x": 1,
      "y": 9,
      "z": 2,
      "name": "Wood_Palo_Branch_Long"
    },
    {
      "x": 1,
      "y": 10,
      "z": 2,
      "name": "Plant_Leaves_Palo"
    },
    {
      "x": 1,
      "y": 5,
      "z": 3,
      "name": "Wood_Palo_Trunk_Full"
    },
    {
      "x": 1,
      "y": 8,
      "z": 3,
      "name": "Wood_Palo_Branch_Long",
      "rotation": 4
    },
    {
      "x": 1,
      "y": 9,
      "z": 3,
      "name": "Plant_Leaves_Palo"
    },
    {
      "x": 1,
      "y": 5,
      "z": 4,
      "name": "Wood_Palo_Trunk_Full"
    },
    {
      "x": 1,
      "y": 6,
      "z": 4,
      "name": "Wood_Palo_Trunk_Full"
    },
    {
      "x": 1,
      "y": 8,
      "z": 4,
      "name": "Plant_Leaves_Palo"
    },
    {
      "x": 1,
      "y": 9,
      "z": 4,
      "name": "Plant_Leaves_Palo"
    },
    {
      "x": 1,
      "y": 6,
      "z": 5,
      "name": "Wood_Palo_Trunk_Full"
    },
    {
      "x": 1,
      "y": 8,
      "z": 5,
      "name": "Plant_Leaves_Palo"
    },
    {
      "x": 1,
      "y": 6,
      "z": 6,
      "name": "Wood_Palo_Trunk_Full"
    },
    {
      "x": 1,
      "y": 7,
      "z": 6,
      "name": "Plant_Leaves_Palo"
    },
    {
      "x": 1,
      "y": 6,
      "z": 7,
      "name": "Wood_Palo_Branch_Long",
      "rotation": 4
    },
    {
      "x": 1,
      "y": 6,
      "z": 8,
      "name": "Plant_Leaves_Palo"
    },
    {
      "x": 2,
      "y": 7,
      "z": -6,
      "name": "Plant_Leaves_Palo"
    },
    {
      "x": 2,
      "y": 4,
      "z": -5,
      "name": "Plant_Leaves_Palo"
    },
    {
      "x": 2,
      "y": 7,
      "z": -5,
      "name": "Plant_Leaves_Palo"
    },
    {
      "x": 2,
      "y": 4,
      "z": -4,
      "name": "Plant_Leaves_Palo"
    },
    {
      "x": 2,
      "y": 7,
      "z": -4,
      "name": "Plant_Leaves_Palo"
    },
    {
      "x": 2,
      "y": 8,
      "z": -4,
      "name": "Plant_Leaves_Palo"
    },
    {
      "x": 2,
      "y": 4,
      "z": -3,
      "name": "Plant_Leaves_Palo"
    },
    {
      "x": 2,
      "y": 7,
      "z": -3,
      "name": "Plant_Leaves_Palo"
    },
    {
      "x": 2,
      "y": 9,
      "z": -3,
      "name": "Plant_Leaves_Palo"
    },
    {
      "x": 2,
      "y": 4,
      "z": -2,
      "name": "Plant_Leaves_Palo"
    },
    {
      "x": 2,
      "y": 5,
      "z": -2,
      "name": "Plant_Leaves_Palo"
    },
    {
      "x": 2,
      "y": 7,
      "z": -2,
      "name": "Plant_Leaves_Palo"
    },
    {
      "x": 2,
      "y": 9,
      "z": -2,
      "name": "Plant_Leaves_Palo"
    },
    {
      "x": 2,
      "y": 10,
      "z": -2,
      "name": "Plant_Leaves_Palo"
    },
    {
      "x": 2,
      "y": 4,
      "z": -1,
      "name": "Plant_Leaves_Palo"
    },
    {
      "x": 2,
      "y": 9,
      "z": -1,
      "name": "Plant_Leaves_Palo"
    },
    {
      "x": 2,
      "y": 8,
      "z": 0,
      "name": "Plant_Leaves_Palo"
    },
    {
      "x": 2,
      "y": 0,
      "z": 1,
      "name": "Wood_Palo_Trunk_Full"
    },
    {
      "x": 2,
      "y": 1,
      "z": 1,
      "name": "Wood_Palo_Trunk"
    },
    {
      "x": 2,
      "y": 2,
      "z": 1,
      "name": "Wood_Palo_Trunk_Full"
    },
    {
      "x": 2,
      "y": 5,
      "z": 1,
      "name": "Wood_Palo_Trunk_Full"
    },
    {
      "x": 2,
      "y": 8,
      "z": 1,
      "name": "Plant_Leaves_Palo"
    },
    {
      "x": 2,
      "y": 9,
      "z": 1,
      "name": "Plant_Leaves_Palo"
    },
    {
      "x": 2,
      "y": 8,
      "z": 2,
      "name": "Wood_Palo_Branch_Long",
      "rotation": 5
    },
    {
      "x": 2,
      "y": 9,
      "z": 2,
      "name": "Plant_Leaves_Palo"
    },
    {
      "x": 2,
      "y": 8,
      "z": 3,
      "name": "Plant_Leaves_Palo"
    },
    {
      "x": 2,
      "y": 9,
      "z": 3,
      "name": "Plant_Leaves_Palo"
    },
    {
      "x": 2,
      "y": 6,
      "z": 4,
      "name": "Plant_Leaves_Palo"
    },
    {
      "x": 2,
      "y": 8,
      "z": 4,
      "name": "Plant_Leaves_Palo"
    },
    {
      "x": 2,
      "y": 6,
      "z": 5,
      "name": "Plant_Leaves_Palo"
    },
    {
      "x": 2,
      "y": 6,
      "z": 6,
      "name": "Wood_Palo_Branch_Long",
      "rotation": 5
    },
    {
      "x": 2,
      "y": 7,
      "z": 6,
      "name": "Plant_Leaves_Palo"
    },
    {
      "x": 2,
      "y": 6,
      "z": 7,
      "name": "Plant_Leaves_Palo"
    },
    {
      "x": 2,
      "y": 7,
      "z": 7,
      "name": "Plant_Leaves_Palo"
    },
    {
      "x": 2,
      "y": 6,
      "z": 8,
      "name": "Plant_Leaves_Palo"
    },
    {
      "x": 3,
      "y": 7,
      "z": -6,
      "name": "Plant_Leaves_Palo"
    },
    {
      "x": 3,
      "y": 7,
      "z": -5,
      "name": "Plant_Leaves_Palo"
    },
    {
      "x": 3,
      "y": 4,
      "z": -4,
      "name": "Plant_Leaves_Palo"
    },
    {
      "x": 3,
      "y": 7,
      "z": -4,
      "name": "Plant_Leaves_Palo"
    },
    {
      "x": 3,
      "y": 9,
      "z": -4,
      "name": "Plant_Leaves_Palo"
    },
    {
      "x": 3,
      "y": 4,
      "z": -3,
      "name": "Plant_Leaves_Palo"
    },
    {
      "x": 3,
      "y": 5,
      "z": -3,
      "name": "Plant_Leaves_Palo"
    },
    {
      "x": 3,
      "y": 7,
      "z": -3,
      "name": "Plant_Leaves_Palo"
    },
    {
      "x": 3,
      "y": 9,
      "z": -3,
      "name": "Plant_Leaves_Palo"
    },
    {
      "x": 3,
      "y": 4,
      "z": -2,
      "name": "Plant_Leaves_Palo"
    },
    {
      "x": 3,
      "y": 9,
      "z": -2,
      "name": "Plant_Leaves_Palo"
    },
    {
      "x": 3,
      "y": 9,
      "z": -1,
      "name": "Plant_Leaves_Palo"
    },
    {
      "x": 3,
      "y": 5,
      "z": 1,
      "name": "Wood_Palo_Trunk_Full"
    },
    {
      "x": 3,
      "y": 8,
      "z": 1,
      "name": "Plant_Leaves_Palo"
    },
    {
      "x": 3,
      "y": 9,
      "z": 1,
      "name": "Plant_Leaves_Palo"
    },
    {
      "x": 3,
      "y": 8,
      "z": 2,
      "name": "Wood_Palo_Branch_Long",
      "rotation": 5
    },
    {
      "x": 3,
      "y": 9,
      "z": 2,
      "name": "Plant_Leaves_Palo"
    },
    {
      "x": 3,
      "y": 8,
      "z": 3,
      "name": "Plant_Leaves_Palo"
    },
    {
      "x": 3,
      "y": 6,
      "z": 5,
      "name": "Plant_Leaves_Palo"
    },
    {
      "x": 3,
      "y": 6,
      "z": 6,
      "name": "Plant_Leaves_Palo"
    },
    {
      "x": 3,
      "y": 7,
      "z": 6,
      "name": "Plant_Leaves_Palo"
    },
    {
      "x": 3,
      "y": 6,
      "z": 7,
      "name": "Plant_Leaves_Palo"
    },
    {
      "x": 4,
      "y": 4,
      "z": -3,
      "name": "Plant_Leaves_Palo"
    },
    {
      "x": 4,
      "y": 7,
      "z": -3,
      "name": "Plant_Leaves_Palo"
    },
    {
      "x": 4,
      "y": 9,
      "z": -2,
      "name": "Plant_Leaves_Palo"
    },
    {
      "x": 4,
      "y": 5,
      "z": 1,
      "name": "Wood_Palo_Trunk_Full"
    },
    {
      "x": 4,
      "y": 6,
      "z": 1,
      "name": "Wood_Palo_Trunk_Full"
    },
    {
      "x": 4,
      "y": 7,
      "z": 1,
      "name": "Plant_Leaves_Palo"
    },
    {
      "x": 4,
      "y": 6,
      "z": 2,
      "name": "Plant_Leaves_Palo"
    },
    {
      "x": 4,
      "y": 8,
      "z": 2,
      "name": "Plant_Leaves_Palo"
    },
    {
      "x": 4,
      "y": 6,
      "z": 5,
      "name": "Plant_Leaves_Palo"
    },
    {
      "x": 4,
      "y": 6,
      "z": 6,
      "name": "Plant_Leaves_Palo"
    },
    {
      "x": 4,
      "y": 6,
      "z": 7,
      "name": "Plant_Leaves_Palo"
    },
    {
      "x": 5,
      "y": 6,
      "z": -1,
      "name": "Plant_Leaves_Palo"
    },
    {
      "x": 5,
      "y": 6,
      "z": 0,
      "name": "Plant_Leaves_Palo"
    },
    {
      "x": 5,
      "y": 6,
      "z": 1,
      "name": "Wood_Palo_Trunk_Full"
    },
    {
      "x": 5,
      "y": 7,
      "z": 1,
      "name": "Plant_Leaves_Palo"
    },
    {
      "x": 5,
      "y": 6,
      "z": 2,
      "name": "Wood_Palo_Branch_Long",
      "rotation": 4
    },
    {
      "x": 5,
      "y": 7,
      "z": 2,
      "name": "Plant_Leaves_Palo"
    },
    {
      "x": 5,
      "y": 6,
      "z": 3,
      "name": "Plant_Leaves_Palo"
    },
    {
      "x": 6,
      "y": 6,
      "z": -2,
      "name": "Plant_Leaves_Palo"
    },
    {
      "x": 6,
      "y": 6,
      "z": -1,
      "name": "Wood_Palo_Branch_Long",
      "rotation": 4
    },
    {
      "x": 6,
      "y": 7,
      "z": -1,
      "name": "Plant_Leaves_Palo"
    },
    {
      "x": 6,
      "y": 6,
      "z": 0,
      "name": "Wood_Palo_Branch_Long",
      "rotation": 4
    },
    {
      "x": 6,
      "y": 7,
      "z": 0,
      "name": "Plant_Leaves_Palo"
    },
    {
      "x": 6,
      "y": 6,
      "z": 1,
      "name": "Wood_Palo_Trunk_Full"
    },
    {
      "x": 6,
      "y": 7,
      "z": 1,
      "name": "Plant_Leaves_Palo"
    },
    {
      "x": 6,
      "y": 6,
      "z": 2,
      "name": "Plant_Leaves_Palo"
    },
    {
      "x": 6,
      "y": 6,
      "z": 3,
      "name": "Plant_Leaves_Palo"
    },
    {
      "x": 7,
      "y": 6,
      "z": -1,
      "name": "Plant_Leaves_Palo"
    },
    {
      "x": 7,
      "y": 6,
      "z": 0,
      "name": "Plant_Leaves_Palo"
    },
    {
      "x": 7,
      "y": 7,
      "z": 0,
      "name": "Plant_Leaves_Palo"
    },
    {
      "x": 7,
      "y": 6,
      "z": 1,
      "name": "Wood_Palo_Branch_Long",
      "rotation": 5
    },
    {
      "x": 7,
      "y": 7,
      "z": 1,
      "name": "Plant_Leaves_Palo"
    },
    {
      "x": 7,
      "y": 6,
      "z": 2,
      "name": "Plant_Leaves_Palo"
    },
    {
      "x": 8,
      "y": 6,
      "z": 0,
      "name": "Plant_Leaves_Palo"
    },
    {
      "x": 8,
      "y": 6,
      "z": 1,
      "name": "Plant_Leaves_Palo"
    }
  ]
}