{
  "version": 8,
  "blockIdVersion": 11,
  "anchorX": 13,
  "anchorY": 9,
  "anchorZ": 15,
  "blocks": [
    {
      "x": 6,
      "y": 16,
      "z": 16,
      "name": "Plant_Leaves_Windwillow"
    },
    {
      "x": 6,
      "y": 17,
      "z": 16,
      "name": "Plant_Leaves_Windwillow"
    },
    {
      "x": 6,
      "y": 18,
      "z": 16,
      "name": "Plant_Leaves_Windwillow"
    },
    {
      "x": 7,
      "y": 18,
      "z": 14,
      "name": "Plant_Leaves_Windwillow"
    },
    {
      "x": 7,
      "y": 16,
      "z": 15,
      "name": "Plant_Leaves_Windwillow"
    },
    {
      "x": 7,
      "y": 17,
      "z": 15,
      "name": "Plant_Leaves_Windwillow"
    },
    {
      "x": 7,
      "y": 18,
      "z": 15,
      "name": "Plant_Leaves_Windwillow"
    },
    {
      "x": 7,
      "y": 17,
      "z": 16,
      "name": "Plant_Leaves_Windwillow"
    },
    {
      "x": 7,
      "y": 18,
      "z": 16,
      "name": "Wood_Windwillow_Branch_Long",
      "rotation": 5
    },
    {
      "x": 7,
      "y": 19,
      "z": 16,
      "name": "Plant_Leaves_Windwillow"
    },
    {
      "x": 7,
      "y": 17,
      "z": 17,
      "name": "Plant_Leaves_Windwillow"
    },
    {
      "x": 7,
      "y": 18,
      "z": 17,
      "name": "Plant_Leaves_Windwillow"
    },
    {
      "x": 8,
      "y": 16,
      "z": 14,
      "name": "Plant_Leaves_Windwillow"
    },
    {
      "x": 8,
      "y": 17,
      "z": 14,
      "name": "Plant_Leaves_Windwillow"
    },
    {
      "x": 8,
      "y": 18,
      "z": 14,
      "name": "Plant_Leaves_Windwillow"
    },
    {
      "x": 8,
      "y": 18,
      "z": 15,
      "name": "Plant_Leaves_Windwillow"
    },
    {
      "x": 8,
      "y": 19,
      "z": 15,
      "name": "Plant_Leaves_Windwillow"
    },
    {
      "x": 8,
      "y": 18,
      "z": 16,
      "name": "Wood_Windwillow_Trunk_Full"
    },
    {
      "x": 8,
      "y": 19,
      "z": 16,
      "name": "Plant_Leaves_Windwillow"
    },
    {
      "x": 8,
      "y": 18,
      "z": 17,
      "name": "Wood_Windwillow_Branch_Long",
      "rotation": 4
    },
    {
      "x": 8,
      "y": 19,
      "z": 17,
      "name": "Plant_Leaves_Windwillow"
    },
    {
      "x": 8,
      "y": 17,
      "z": 18,
      "name": "Plant_Leaves_Windwillow"
    },
    {
      "x": 8,
      "y": 18,
      "z": 18,
      "name": "Plant_Leaves_Windwillow"
    },
    {
      "x": 9,
      "y": 17,
      "z": 13,
      "name": "Plant_Leaves_Windwillow"
    },
    {
      "x": 9,
      "y": 18,
      "z": 13,
      "name": "Plant_Leaves_Windwillow"
    },
    {
      "x": 9,
      "y": 18,
      "z": 14,
      "name": "Wood_Windwillow_Branch_Long",
      "rotation": 4
    },
    {
      "x": 9,
      "y": 19,
      "z": 14,
      "name": "Plant_Leaves_Windwillow"
    },
    {
      "x": 9,
      "y": 18,
      "z": 15,
      "name": "Wood_Windwillow_Branch_Long",
      "rotation": 4
    },
    {
      "x": 9,
      "y": 19,
      "z": 15,
      "name": "Plant_Leaves_Windwillow"
    },
    {
      "x": 9,
      "y": 17,
      "z": 16,
      "name": "Plant_Leaves_Windwillow"
    },
    {
      "x": 9,
      "y": 18,
      "z": 16,
      "name": "Wood_Windwillow_Trunk_Full"
    },
    {
      "x": 9,
      "y": 19,
      "z": 16,
      "name": "Plant_Leaves_Windwillow"
    },
    {
      "x": 9,
      "y": 17,
      "z": 17,
      "name": "Plant_Leaves_Windwillow"
    },
    {
      "x": 9,
      "y": 18,
      "z": 17,
      "name": "Plant_Leaves_Windwillow"
    },
    {
      "x": 10,
      "y": 16,
      "z": 14,
      "name": "Plant_Leaves_Windwillow"
    },
    {
      "x": 10,
      "y": 17,
      "z": 14,
      "name": "Plant_Leaves_Windwillow"
    },
    {
      "x": 10,
      "y": 18,
      "z": 14,
      "name": "Plant_Leaves_Windwillow"
    },
    {
      "x": 10,
      "y": 21,
      "z": 14,
      "name": "Plant_Leaves_Windwillow"
    },
    {
      "x": 10,
      "y": 18,
      "z": 15,
      "name": "Plant_Leaves_Windwillow"
    },
    {
      "x": 10,
      "y": 20,
      "z": 15,
      "name": "Plant_Leaves_Windwillow"
    },
    {
      "x": 10,
      "y": 21,
      "z": 15,
      "name": "Plant_Leaves_Windwillow"
    },
    {
      "x": 10,
      "y": 17,
      "z": 16,
      "name": "Wood_Windwillow_Trunk_Full"
    },
    {
      "x": 10,
      "y": 18,
      "z": 16,
      "name": "Wood_Windwillow_Trunk_Full"
    },
    {
      "x": 10,
      "y": 21,
      "z": 16,
      "name": "Plant_Leaves_Windwillow"
    },
    {
      "x": 10,
      "y": 17,
      "z": 17,
      "name": "Plant_Leaves_Windwillow"
    },
    {
      "x": 10,
      "y": 18,
      "z": 17,
      "name": "Plant_Leaves_Windwillow"
    },
    {
      "x": 10,
      "y": 21,
      "z": 17,
      "name": "Plant_Leaves_Windwillow"
    },
    {
      "x": 11,
      "y": 16,
      "z": 10,
      "name": "Plant_Leaves_Windwillow"
    },
    {
      "x": 11,
      "y": 17,
      "z": 10,
      "name": "Plant_Leaves_Windwillow"
    },
    {
      "x": 11,
      "y": 16,
      "z": 11,
      "name": "Plant_Leaves_Windwillow"
    },
    {
      "x": 11,
      "y": 17,
      "z": 11,
      "name": "Plant_Leaves_Windwillow"
    },
    {
      "x": 11,
      "y": 18,
      "z": 15,
      "name": "Plant_Leaves_Windwillow"
    },
    {
      "x": 11,
      "y": 20,
      "z": 15,
      "name": "Plant_Leaves_Windwillow"
    },
    {
      "x": 11,
      "y": 21,
      "z": 15,
      "name": "Plant_Leaves_Windwillow"
    },
    {
      "x": 11,
      "y": 17,
      "z": 16,
      "name": "Wood_Windwillow_Trunk_Full"
    },
    {
      "x": 11,
      "y": 20,
      "z": 16,
      "name": "Wood_Windwillow_Branch_Corner",
      "rotation": 3
    },
    {
      "x": 11,
      "y": 21,
      "z": 16,
      "name": "Wood_Windwillow_Branch_Long"
    },
    {
      "x": 11,
      "y": 22,
      "z": 16,
      "name": "Plant_Leaves_Windwillow"
    },
    {
      "x": 11,
      "y": 21,
      "z": 17,
      "name": "Plant_Leaves_Windwillow"
    },
    {
      "x": 11,
      "y": 20,
      "z": 18,
      "name": "Plant_Leaves_Windwillow"
    },
    {
      "x": 11,
      "y": 21,
      "z": 18,
      "name": "Plant_Leaves_Windwillow"
    },
    {
      "x": 11,
      "y": 14,
      "z": 19,
      "name": "Plant_Leaves_Windwillow"
    },
    {
      "x": 11,
      "y": 15,
      "z": 19,
      "name": "Plant_Leaves_Windwillow"
    },
    {
      "x": 11,
      "y": 20,
      "z": 19,
      "name": "Plant_Leaves_Windwillow"
    },
    {
      "x": 11,
      "y": 14,
      "z": 20,
      "name": "Plant_Leaves_Windwillow"
    },
    {
      "x": 11,
      "y": 15,
      "z": 20,
      "name": "Plant_Leaves_Windwillow"
    },
    {
      "x": 11,
      "y": 21,
      "z": 20,
      "name": "Plant_Leaves_Windwillow"
    },
    {
      "x": 11,
      "y": 14,
      "z": 21,
      "name": "Plant_Leaves_Windwillow"
    },
    {
      "x": 11,
      "y": 15,
      "z": 21,
      "name": "Plant_Leaves_Windwillow"
    },
    {
      "x": 11,
      "y": 19,
      "z": 21,
      "name": "Plant_Leaves_Windwillow"
    },
    {
      "x": 11,
      "y": 20,
      "z": 21,
      "name": "Plant_Leaves_Windwillow"
    },
    {
      "x": 11,
      "y": 15,
      "z": 22,
      "name": "Plant_Leaves_Windwillow"
    },
    {
      "x": 12,
      "y": 15,
      "z": 9,
      "name": "Plant_Leaves_Windwillow"
    },
    {
      "x": 12,
      "y": 16,
      "z": 9,
      "name": "Plant_Leaves_Windwillow"
    },
    {
      "x": 12,
      "y": 17,
      "z": 9,
      "name": "Plant_Leaves_Windwillow"
    },
    {
      "x": 12,
      "y": 17,
      "z": 10,
      "name": "Plant_Leaves_Windwillow"
    },
    {
      "x": 12,
      "y": 21,
      "z": 10,
      "name": "Plant_Leaves_Windwillow"
    },
    {
      "x": 12,
      "y": 16,
      "z": 11,
      "name": "Plant_Leaves_Windwillow"
    },
    {
      "x": 12,
      "y": 17,
      "z": 11,
      "name": "Plant_Leaves_Windwillow"
    },
    {
      "x": 12,
      "y": 20,
      "z": 11,
      "name": "Plant_Leaves_Windwillow"
    },
    {
      "x": 12,
      "y": 21,
      "z": 11,
      "name": "Plant_Leaves_Windwillow"
    },
    {
      "x": 12,
      "y": 21,
      "z": 12,
      "name": "Plant_Leaves_Windwillow"
    },
    {
      "x": 12,
      "y": 22,
      "z": 12,
      "name": "Plant_Leaves_Windwillow"
    },
    {
      "x": 12,
      "y": 6,
      "z": 13,
      "name": "Wood_Windwillow_Trunk_Full"
    },
    {
      "x": 12,
      "y": 7,
      "z": 13,
      "name": "Wood_Windwillow_Trunk"
    },
    {
      "x": 12,
      "y": 8,
      "z": 13,
      "name": "Wood_Windwillow_Trunk_Full"
    },
    {
      "x": 12,
      "y": 20,
      "z": 13,
      "name": "Plant_Leaves_Windwillow"
    },
    {
      "x": 12,
      "y": 7,
      "z": 14,
      "name": "Wood_Windwillow_Trunk_Full"
    },
    {
      "x": 12,
      "y": 8,
      "z": 14,
      "name": "Wood_Windwillow_Trunk"
    },
    {
      "x": 12,
      "y": 9,
      "z": 14,
      "name": "Wood_Windwillow_Trunk_Full"
    },
    {
      "x": 12,
      "y": 20,
      "z": 14,
      "name": "Plant_Leaves_Windwillow"
    },
    {
      "x": 12,
      "y": 8,
      "z": 15,
      "name": "Wood_Windwillow_Trunk_Full"
    },
    {
      "x": 12,
      "y": 9,
      "z": 15,
      "name": "Wood_Windwillow_Trunk"
    },
    {
      "x": 12,
      "y": 10,
      "z": 15,
      "name": "Wood_Windwillow_Trunk"
    },
    {
      "x": 12,
      "y": 11,
      "z": 15,
      "name": "Wood_Windwillow_Trunk"
    },
    {
      "x": 12,
      "y": 12,
      "z": 15,
      "name": "Wood_Windwillow_Trunk_Full"
    },
    {
      "x": 12,
      "y": 20,
      "z": 15,
      "name": "Plant_Leaves_Windwillow"
    },
    {
      "x": 12,
      "y": 21,
      "z": 15,
      "name": "Plant_Leaves_Windwillow"
    },
    {
      "x": 12,
      "y": 17,
      "z": 16,
      "name": "Wood_Windwillow_Trunk_Full"
    },
    {
      "x": 12,
      "y": 20,
      "z": 16,
      "name": "Wood_Windwillow_Branch_Long",
      "rotation": 5
    },
    {
      "x": 12,
      "y": 21,
      "z": 16,
      "name": "Plant_Leaves_Windwillow"
    },
    {
      "x": 12,
      "y": 20,
      "z": 17,
      "name": "Plant_Leaves_Windwillow"
    },
    {
      "x": 12,
      "y": 21,
      "z": 17,
      "name": "Plant_Leaves_Windwillow"
    },
    {
      "x": 12,
      "y": 15,
      "z": 18,
      "name": "Plant_Leaves_Windwillow"
    },
    {
      "x": 12,
      "y": 19,
      "z": 18,
      "name": "Plant_Leaves_Windwillow"
    },
    {
      "x": 12,
      "y": 20,
      "z": 18,
      "name": "Plant_Leaves_Windwillow"
    },
    {
      "x": 12,
      "y": 21,
      "z": 18,
      "name": "Plant_Leaves_Windwillow"
    },
    {
      "x": 12,
      "y": 15,
      "z": 19,
      "name": "Plant_Leaves_Windwillow"
    },
    {
      "x": 12,
      "y": 20,
      "z": 19,
      "name": "Plant_Leaves_Windwillow"
    },
    {
      "x": 12,
      "y": 21,
      "z": 19,
      "name": "Plant_Leaves_Windwillow"
    },
    {
      "x": 12,
      "y": 15,
      "z": 20,
      "name": "Wood_Windwillow_Branch_Long",
      "rotation": 5
    },
    {
      "x": 12,
      "y": 16,
      "z": 20,
      "name": "Plant_Leaves_Windwillow"
    },
    {
      "x": 12,
      "y": 21,
      "z": 20,
      "name": "Wood_Windwillow_Branch_Long",
      "rotation": 5
    },
    {
      "x": 12,
      "y": 22,
      "z": 20,
      "name": "Plant_Leaves_Windwillow"
    },
    {
      "x": 12,
      "y": 15,
      "z": 21,
      "name": "Plant_Leaves_Windwillow"
    },
    {
      "x": 12,
      "y": 16,
      "z": 21,
      "name": "Plant_Leaves_Windwillow"
    },
    {
      "x": 12,
      "y": 19,
      "z": 21,
      "name": "Plant_Leaves_Windwillow"
    },
    {
      "x": 12,
      "y": 20,
      "z": 21,
      "name": "Plant_Leaves_Windwillow"
    },
    {
      "x": 12,
      "y": 21,
      "z": 21,
      "name": "Plant_Leaves_Windwillow"
    },
    {
      "x": 12,
      "y": 13,
      "z": 22,
      "name": "Plant_Leaves_Windwillow"
    },
    {
      "x": 12,
      "y": 14,
      "z": 22,
      "name": "Plant_Leaves_Windwillow"
    },
    {
      "x": 12,
      "y": 15,
      "z": 22,
      "name": "Plant_Leaves_Windwillow"
    },
    {
      "x": 12,
      "y": 16,
      "z": 22,
      "name": "Plant_Leaves_Windwillow"
    },
    {
      "x": 12,
      "y": 20,
      "z": 22,
      "name": "Plant_Leaves_Windwillow"
    },
    {
      "x": 12,
      "y": 13,
      "z": 23,
      "name": "Plant_Leaves_Windwillow"
    },
    {
      "x": 12,
      "y": 14,
      "z": 23,
      "name": "Plant_Leaves_Windwillow"
    },
    {
      "x": 12,
      "y": 15,
      "z": 23,
      "name": "Plant_Leaves_Windwillow"
    },
    {
      "x": 13,
      "y": 16,
      "z": 8,
      "name": "Plant_Leaves_Windwillow"
    },
    {
      "x": 13,
      "y": 17,
      "z": 8,
      "name": "Plant_Leaves_Windwillow"
    },
    {
      "x": 13,
      "y": 16,
      "z": 9,
      "name": "Plant_Leaves_Windwillow"
    },
    {
      "x": 13,
      "y": 17,
      "z": 9,
      "name": "Plant_Leaves_Windwillow"
    },
    {
      "x": 13,
      "y": 16,
      "z": 10,
      "name": "Plant_Leaves_Windwillow"
    },
    {
      "x": 13,
      "y": 17,
      "z": 10,
      "name": "Plant_Leaves_Windwillow"
    },
    {
      "x": 13,
      "y": 21,
      "z": 10,
      "name": "Plant_Leaves_Windwillow"
    },
    {
      "x": 13,
      "y": 22,
      "z": 10,
      "name": "Plant_Leaves_Windwillow"
    },
    {
      "x": 13,
      "y": 17,
      "z": 11,
      "name": "Wood_Windwillow_Branch_Long",
      "rotation": 5
    },
    {
      "x": 13,
      "y": 18,
      "z": 11,
      "name": "Plant_Leaves_Windwillow"
    },
    {
      "x": 13,
      "y": 21,
      "z": 11,
      "name": "Plant_Leaves_Windwillow"
    },
    {
      "x": 13,
      "y": 22,
      "z": 11,
      "name": "Plant_Leaves_Windwillow"
    },
    {
      "x": 13,
      "y": 17,
      "z": 12,
      "name": "Plant_Leaves_Windwillow"
    },
    {
      "x": 13,
      "y": 21,
      "z": 12,
      "name": "Plant_Leaves_Windwillow"
    },
    {
      "x": 13,
      "y": 22,
      "z": 12,
      "name": "Wood_Windwillow_Branch_Long",
      "rotation": 5
    },
    {
      "x": 13,
      "y": 23,
      "z": 12,
      "name": "Plant_Leaves_Windwillow"
    },
    {
      "x": 13,
      "y": 22,
      "z": 13,
      "name": "Plant_Leaves_Windwillow"
    },
    {
      "x": 13,
      "y": 8,
      "z": 14,
      "name": "Wood_Windwillow_Trunk_Full"
    },
    {
      "x": 13,
      "y": 9,
      "z": 14,
      "name": "Wood_Windwillow_Trunk"
    },
    {
      "x": 13,
      "y": 10,
      "z": 14,
      "name": "Wood_Windwillow_Trunk"
    },
    {
      "x": 13,
      "y": 11,
      "z": 14,
      "name": "Wood_Windwillow_Trunk"
    },
    {
      "x": 13,
      "y": 12,
      "z": 14,
      "name": "Wood_Windwillow_Trunk"
    },
    {
      "x": 13,
      "y": 13,
      "z": 14,
      "name": "Wood_Windwillow_Trunk"
    },
    {
      "x": 13,
      "y": 14,
      "z": 14,
      "name": "Wood_Windwillow_Trunk_Full"
    },
    {
      "x": 13,
      "y": 7,
      "z": 15,
      "name": "Wood_Windwillow_Trunk"
    },
    {
      "x": 13,
      "y": 8,
      "z": 15,
      "name": "Wood_Windwillow_Trunk"
    },
    {
      "x": 13,
      "y": 9,
      "z": 15,
      "name": "Wood_Windwillow_Trunk"
    },
    {
      "x": 13,
      "y": 10,
      "z": 15,
      "name": "Wood_Windwillow_Trunk"
    },
    {
      "x": 13,
      "y": 11,
      "z": 15,
      "name": "Wood_Windwillow_Trunk"
    },
    {
      "x": 13,
      "y": 12,
      "z": 15,
      "name": "Wood_Windwillow_Trunk"
    },
    {
      "x": 13,
      "y": 13,
      "z": 15,
      "name": "Wood_Windwillow_Trunk"
    },
    {
      "x": 13,
      "y": 14,
      "z": 15,
      "name": "Wood_Windwillow_Trunk"
    },
    {
      "x": 13,
      "y": 15,
      "z": 15,
      "name": "Wood_Windwillow_Trunk_Full"
    },
    {
      "x": 13,
      "y": 19,
      "z": 15,
      "name": "Plant_Leaves_Windwillow"
    },
    {
      "x": 13,
      "y": 20,
      "z": 15,
      "name": "Plant_Leaves_Windwillow"
    },
    {
      "x": 13,
      "y": 21,
      "z": 15,
      "name": "Plant_Leaves_Windwillow"
    },
    {
      "x": 13,
      "y": 6,
      "z": 16,
      "name": "Wood_Windwillow_Trunk_Full"
    },
    {
      "x": 13,
      "y": 7,
      "z": 16,
      "name": "Wood_Windwillow_Trunk_Full"
    },
    {
      "x": 13,
      "y": 12,
      "z": 16,
      "name": "Wood_Windwillow_Trunk_Full"
    },
    {
      "x": 13,
      "y": 13,
      "z": 16,
      "name": "Wood_Windwillow_Trunk"
    },
    {
      "x": 13,
      "y": 14,
      "z": 16,
      "name": "Wood_Windwillow_Trunk"
    },
    {
      "x": 13,
      "y": 15,
      "z": 16,
      "name": "Wood_Windwillow_Trunk"
    },
    {
      "x": 13,
      "y": 16,
      "z": 16,
      "name": "Wood_Windwillow_Trunk"
    },
    {
      "x": 13,
      "y": 17,
      "z": 16,
      "name": "Wood_Windwillow_Trunk"
    },
    {
      "x": 13,
      "y": 18,
      "z": 16,
      "name": "Wood_Windwillow_Trunk"
    },
    {
      "x": 13,
      "y": 19,
      "z": 16,
      "name": "Wood_Windwillow_Trunk"
    },
    {
      "x": 13,
      "y": 20,
      "z": 16,
      "name": "Wood_Windwillow_Trunk_Full"
    },
    {
      "x": 13,
      "y": 24,
      "z": 16,
      "name": "Plant_Leaves_Windwillow"
    },
    {
      "x": 13,
      "y": 14,
      "z": 17,
      "name": "Wood_Windwillow_Trunk_Full"
    },
    {
      "x": 13,
      "y": 19,
      "z": 17,
      "name": "Plant_Leaves_Windwillow"
    },
    {
      "x": 13,
      "y": 20,
      "z": 17,
      "name": "Plant_Leaves_Windwillow"
    },
    {
      "x": 13,
      "y": 22,
      "z": 17,
      "name": "Plant_Leaves_Windwillow"
    },
    {
      "x": 13,
      "y": 23,
      "z": 17,
      "name": "Plant_Leaves_Windwillow"
    },
    {
      "x": 13,
      "y": 24,
      "z": 17,
      "name": "Plant_Leaves_Windwillow"
    },
    {
      "x": 13,
      "y": 14,
      "z": 18,
      "name": "Wood_Windwillow_Trunk_Full"
    },
    {
      "x": 13,
      "y": 15,
      "z": 18,
      "name": "Plant_Leaves_Windwillow"
    },
    {
      "x": 13,
      "y": 14,
      "z": 19,
      "name": "Wood_Windwillow_Trunk_Full"
    },
    {
      "x": 13,
      "y": 15,
      "z": 19,
      "name": "Wood_Windwillow_Trunk_Full"
    },
    {
      "x": 13,
      "y": 16,
      "z": 19,
      "name": "Plant_Leaves_Windwillow"
    },
    {
      "x": 13,
      "y": 21,
      "z": 19,
      "name": "Plant_Leaves_Windwillow"
    },
    {
      "x": 13,
      "y": 15,
      "z": 20,
      "name": "Wood_Windwillow_Trunk_Full"
    },
    {
      "x": 13,
      "y": 16,
      "z": 20,
      "name": "Plant_Leaves_Windwillow"
    },
    {
      "x": 13,
      "y": 21,
      "z": 20,
      "name": "Wood_Windwillow_Branch_Long",
      "rotation": 5
    },
    {
      "x": 13,
      "y": 22,
      "z": 20,
      "name": "Plant_Leaves_Windwillow"
    },
    {
      "x": 13,
      "y": 14,
      "z": 21,
      "name": "Plant_Leaves_Windwillow"
    },
    {
      "x": 13,
      "y": 15,
      "z": 21,
      "name": "Wood_Windwillow_Branch_Long",
      "rotation": 4
    },
    {
      "x": 13,
      "y": 16,
      "z": 21,
      "name": "Plant_Leaves_Windwillow"
    },
    {
      "x": 13,
      "y": 21,
      "z": 21,
      "name": "Plant_Leaves_Windwillow"
    },
    {
      "x": 13,
      "y": 15,
      "z": 22,
      "name": "Wood_Windwillow_Branch_Long",
      "rotation": 4
    },
    {
      "x": 13,
      "y": 16,
      "z": 22,
      "name": "Plant_Leaves_Windwillow"
    },
    {
      "x": 13,
      "y": 20,
      "z": 22,
      "name": "Plant_Leaves_Windwillow"
    },
    {
      "x": 13,
      "y": 21,
      "z": 22,
      "name": "Plant_Leaves_Windwillow"
    },
    {
      "x": 13,
      "y": 22,
      "z": 22,
      "name": "Plant_Leaves_Windwillow"
    },
    {
      "x": 13,
      "y": 15,
      "z": 23,
      "name": "Plant_Leaves_Windwillow"
    },
    {
      "x": 13,
      "y": 16,
      "z": 23,
      "name": "Plant_Leaves_Windwillow"
    },
    {
      "x": 14,
      "y": 17,
      "z": 7,
      "name": "Plant_Leaves_Windwillow"
    },
    {
      "x": 14,
      "y": 16,
      "z": 8,
      "name": "Plant_Leaves_Windwillow"
    },
    {
      "x": 14,
      "y": 17,
      "z": 8,
      "name": "Wood_Windwillow_Branch_Long",
      "rotation": 4
    },
    {
      "x": 14,
      "y": 18,
      "z": 8,
      "name": "Plant_Leaves_Windwillow"
    },
    {
      "x": 14,
      "y": 17,
      "z": 9,
      "name": "Wood_Windwillow_Branch_Long",
      "rotation": 4
    },
    {
      "x": 14,
      "y": 18,
      "z": 9,
      "name": "Plant_Leaves_Windwillow"
    },
    {
      "x": 14,
      "y": 21,
      "z": 9,
      "name": "Plant_Leaves_Windwillow"
    },
    {
      "x": 14,
      "y": 22,
      "z": 9,
      "name": "Plant_Leaves_Windwillow"
    },
    {
      "x": 14,
      "y": 17,
      "z": 10,
      "name": "Wood_Windwillow_Trunk_Full"
    },
    {
      "x": 14,
      "y": 18,
      "z": 10,
      "name": "Plant_Leaves_Windwillow"
    },
    {
      "x": 14,
      "y": 22,
      "z": 10,
      "name": "Wood_Windwillow_Branch_Long",
      "rotation": 4
    },
    {
      "x": 14,
      "y": 23,
      "z": 10,
      "name": "Plant_Leaves_Windwillow"
    },
    {
      "x": 14,
      "y": 17,
      "z": 11,
      "name": "Wood_Windwillow_Trunk_Full"
    },
    {
      "x": 14,
      "y": 18,
      "z": 11,
      "name": "Plant_Leaves_Windwillow"
    },
    {
      "x": 14,
      "y": 22,
      "z": 11,
      "name": "Wood_Windwillow_Branch_Long",
      "rotation": 4
    },
    {
      "x": 14,
      "y": 23,
      "z": 11,
      "name": "Plant_Leaves_Windwillow"
    },
    {
      "x": 14,
      "y": 16,
      "z": 12,
      "name": "Wood_Windwillow_Trunk_Full"
    },
    {
      "x": 14,
      "y": 17,
      "z": 12,
      "name": "Wood_Windwillow_Trunk_Full"
    },
    {
      "x": 14,
      "y": 22,
      "z": 12,
      "name": "Wood_Windwillow_Trunk_Full"
    },
    {
      "x": 14,
      "y": 16,
      "z": 13,
      "name": "Wood_Windwillow_Trunk_Full"
    },
    {
      "x": 14,
      "y": 21,
      "z": 13,
      "name": "Wood_Windwillow_Trunk_Full"
    },
    {
      "x": 14,
      "y": 22,
      "z": 13,
      "name": "Wood_Windwillow_Trunk_Full"
    },
    {
      "x": 14,
      "y": 6,
      "z": 14,
      "name": "Wood_Windwillow_Trunk_Full"
    },
    {
      "x": 14,
      "y": 7,
      "z": 14,
      "name": "Wood_Windwillow_Trunk"
    },
    {
      "x": 14,
      "y": 8,
      "z": 14,
      "name": "Wood_Windwillow_Trunk_Full"
    },
    {
      "x": 14,
      "y": 16,
      "z": 14,
      "name": "Wood_Windwillow_Trunk_Full"
    },
    {
      "x": 14,
      "y": 21,
      "z": 14,
      "name": "Wood_Windwillow_Trunk_Full"
    },
    {
      "x": 14,
      "y": 11,
      "z": 15,
      "name": "Wood_Windwillow_Trunk_Full"
    },
    {
      "x": 14,
      "y": 12,
      "z": 15,
      "name": "Wood_Windwillow_Trunk"
    },
    {
      "x": 14,
      "y": 13,
      "z": 15,
      "name": "Wood_Windwillow_Trunk"
    },
    {
      "x": 14,
      "y": 14,
      "z": 15,
      "name": "Wood_Windwillow_Trunk"
    },
    {
      "x": 14,
      "y": 15,
      "z": 15,
      "name": "Wood_Windwillow_Trunk"
    },
    {
      "x": 14,
      "y": 16,
      "z": 15,
      "name": "Wood_Windwillow_Trunk"
    },
    {
      "x": 14,
      "y": 17,
      "z": 15,
      "name": "Wood_Windwillow_Trunk_Full"
    },
    {
      "x": 14,
      "y": 21,
      "z": 15,
      "name": "Wood_Windwillow_Trunk_Full"
    },
    {
      "x": 14,
      "y": 24,
      "z": 15,
      "name": "Plant_Leaves_Windwillow"
    },
    {
      "x": 14,
      "y": 17,
      "z": 16,
      "name": "Wood_Windwillow_Trunk_Full"
    },
    {
      "x": 14,
      "y": 18,
      "z": 16,
      "name": "Wood_Windwillow_Trunk"
    },
    {
      "x": 14,
      "y": 19,
      "z": 16,
      "name": "Wood_Windwillow_Trunk"
    },
    {
      "x": 14,
      "y": 20,
      "z": 16,
      "name": "Wood_Windwillow_Trunk"
    },
    {
      "x": 14,
      "y": 21,
      "z": 16,
      "name": "Wood_Windwillow_Trunk_Full"
    },
    {
      "x": 14,
      "y": 23,
      "z": 16,
      "name": "Plant_Leaves_Windwillow"
    },
    {
      "x": 14,
      "y": 24,
      "z": 16,
      "name": "Plant_Leaves_Windwillow"
    },
    {
      "x": 14,
      "y": 15,
      "z": 17,
      "name": "Plant_Leaves_Windwillow"
    },
    {
      "x": 14,
      "y": 19,
      "z": 17,
      "name": "Wood_Windwillow_Trunk_Full"
    },
    {
      "x": 14,
      "y": 20,
      "z": 17,
      "name": "Wood_Windwillow_Trunk_Full"
    },
    {
      "x": 14,
      "y": 22,
      "z": 17,
      "name": "Plant_Leaves_Windwillow"
    },
    {
      "x": 14,
      "y": 23,
      "z": 17,
      "name": "Plant_Leaves_Windwillow"
    },
    {
      "x": 14,
      "y": 24,
      "z": 17,
      "name": "Plant_Leaves_Windwillow"
    },
    {
      "x": 14,
      "y": 15,
      "z": 18,
      "name": "Plant_Leaves_Windwillow"
    },
    {
      "x": 14,
      "y": 16,
      "z": 18,
      "name": "Plant_Leaves_Windwillow"
    },
    {
      "x": 14,
      "y": 20,
      "z": 18,
      "name": "Wood_Windwillow_Trunk_Full"
    },
    {
      "x": 14,
      "y": 21,
      "z": 18,
      "name": "Wood_Windwillow_Trunk_Full"
    },
    {
      "x": 14,
      "y": 15,
      "z": 19,
      "name": "Wood_Windwillow_Branch_Long",
      "rotation": 5
    },
    {
      "x": 14,
      "y": 16,
      "z": 19,
      "name": "Plant_Leaves_Windwillow"
    },
    {
      "x": 14,
      "y": 21,
      "z": 19,
      "name": "Wood_Windwillow_Trunk_Full"
    },
    {
      "x": 14,
      "y": 14,
      "z": 20,
      "name": "Plant_Leaves_Windwillow"
    },
    {
      "x": 14,
      "y": 15,
      "z": 20,
      "name": "Plant_Leaves_Windwillow"
    },
    {
      "x": 14,
      "y": 21,
      "z": 20,
      "name": "Wood_Windwillow_Trunk_Full"
    },
    {
      "x": 14,
      "y": 22,
      "z": 20,
      "name": "Plant_Leaves_Windwillow"
    },
    {
      "x": 14,
      "y": 15,
      "z": 21,
      "name": "Plant_Leaves_Windwillow"
    },
    {
      "x": 14,
      "y": 16,
      "z": 21,
      "name": "Plant_Leaves_Windwillow"
    },
    {
      "x": 14,
      "y": 21,
      "z": 21,
      "name": "Wood_Windwillow_Trunk_Full"
    },
    {
      "x": 14,
      "y": 22,
      "z": 21,
      "name": "Plant_Leaves_Windwillow"
    },
    {
      "x": 14,
      "y": 13,
      "z": 22,
      "name": "Plant_Leaves_Windwillow"
    },
    {
      "x": 14,
      "y": 14,
      "z": 22,
      "name": "Plant_Leaves_Windwillow"
    },
    {
      "x": 14,
      "y": 15,
      "z": 22,
      "name": "Plant_Leaves_Windwillow"
    },
    {
      "x": 14,
      "y": 21,
      "z": 22,
      "name": "Wood_Windwillow_Branch_Long",
      "rotation": 4
    },
    {
      "x": 14,
      "y": 22,
      "z": 22,
      "name": "Plant_Leaves_Windwillow"
    },
    {
      "x": 14,
      "y": 15,
      "z": 23,
      "name": "Plant_Leaves_Windwillow"
    },
    {
      "x": 14,
      "y": 20,
      "z": 23,
      "name": "Plant_Leaves_Windwillow"
    },
    {
      "x": 14,
      "y": 21,
      "z": 23,
      "name": "Plant_Leaves_Windwillow"
    },
    {
      "x": 15,
      "y": 16,
      "z": 7,
      "name": "Plant_Leaves_Windwillow"
    },
    {
      "x": 15,
      "y": 17,
      "z": 7,
      "name": "Plant_Leaves_Windwillow"
    },
    {
      "x": 15,
      "y": 17,
      "z": 8,
      "name": "Plant_Leaves_Windwillow"
    },
    {
      "x": 15,
      "y": 16,
      "z": 9,
      "name": "Plant_Leaves_Windwillow"
    },
    {
      "x": 15,
      "y": 17,
      "z": 9,
      "name": "Plant_Leaves_Windwillow"
    },
    {
      "x": 15,
      "y": 17,
      "z": 10,
      "name": "Wood_Windwillow_Branch_Long",
      "rotation": 5
    },
    {
      "x": 15,
      "y": 18,
      "z": 10,
      "name": "Plant_Leaves_Windwillow"
    },
    {
      "x": 15,
      "y": 22,
      "z": 10,
      "name": "Plant_Leaves_Windwillow"
    },
    {
      "x": 15,
      "y": 17,
      "z": 11,
      "name": "Plant_Leaves_Windwillow"
    },
    {
      "x": 15,
      "y": 21,
      "z": 11,
      "name": "Plant_Leaves_Windwillow"
    },
    {
      "x": 15,
      "y": 22,
      "z": 11,
      "name": "Plant_Leaves_Windwillow"
    },
    {
      "x": 15,
      "y": 16,
      "z": 12,
      "name": "Plant_Leaves_Windwillow"
    },
    {
      "x": 15,
      "y": 17,
      "z": 12,
      "name": "Plant_Leaves_Windwillow"
    },
    {
      "x": 15,
      "y": 21,
      "z": 12,
      "name": "Plant_Leaves_Windwillow"
    },
    {
      "x": 15,
      "y": 22,
      "z": 12,
      "name": "Plant_Leaves_Windwillow"
    },
    {
      "x": 15,
      "y": 21,
      "z": 13,
      "name": "Plant_Leaves_Windwillow"
    },
    {
      "x": 15,
      "y": 22,
      "z": 13,
      "name": "Wood_Windwillow_Branch_Long",
      "rotation": 5
    },
    {
      "x": 15,
      "y": 23,
      "z": 13,
      "name": "Plant_Leaves_Windwillow"
    },
    {
      "x": 15,
      "y": 22,
      "z": 14,
      "name": "Plant_Leaves_Windwillow"
    },
    {
      "x": 15,
      "y": 24,
      "z": 14,
      "name": "Plant_Leaves_Windwillow"
    },
    {
      "x": 15,
      "y": 15,
      "z": 15,
      "name": "Wood_Windwillow_Trunk_Full"
    },
    {
      "x": 15,
      "y": 23,
      "z": 15,
      "name": "Plant_Leaves_Windwillow"
    },
    {
      "x": 15,
      "y": 24,
      "z": 15,
      "name": "Plant_Leaves_Windwillow"
    },
    {
      "x": 15,
      "y": 21,
      "z": 16,
      "name": "Wood_Windwillow_Trunk_Full"
    },
    {
      "x": 15,
      "y": 22,
      "z": 16,
      "name": "Wood_Windwillow_Trunk_Full"
    },
    {
      "x": 15,
      "y": 23,
      "z": 16,
      "name": "Wood_Windwillow_Trunk_Full"
    },
    {
      "x": 15,
      "y": 24,
      "z": 16,
      "name": "Wood_Windwillow_Branch_Long"
    },
    {
      "x": 15,
      "y": 25,
      "z": 16,
      "name": "Plant_Leaves_Windwillow"
    },
    {
      "x": 15,
      "y": 19,
      "z": 17,
      "name": "Wood_Windwillow_Branch_Long",
      "rotation": 5
    },
    {
      "x": 15,
      "y": 22,
      "z": 17,
      "name": "Plant_Leaves_Windwillow"
    },
    {
      "x": 15,
      "y": 23,
      "z": 17,
      "name": "Wood_Windwillow_Branch_Long",
      "rotation": 4
    },
    {
      "x": 15,
      "y": 24,
      "z": 17,
      "name": "Plant_Leaves_Windwillow"
    },
    {
      "x": 15,
      "y": 15,
      "z": 18,
      "name": "Plant_Leaves_Windwillow"
    },
    {
      "x": 15,
      "y": 22,
      "z": 18,
      "name": "Plant_Leaves_Windwillow"
    },
    {
      "x": 15,
      "y": 23,
      "z": 18,
      "name": "Plant_Leaves_Windwillow"
    },
    {
      "x": 15,
      "y": 24,
      "z": 18,
      "name": "Plant_Leaves_Windwillow"
    },
    {
      "x": 15,
      "y": 14,
      "z": 19,
      "name": "Plant_Leaves_Windwillow"
    },
    {
      "x": 15,
      "y": 15,
      "z": 19,
      "name": "Wood_Windwillow_Branch_Long",
      "rotation": 5
    },
    {
      "x": 15,
      "y": 16,
      "z": 19,
      "name": "Plant_Leaves_Windwillow"
    },
    {
      "x": 15,
      "y": 21,
      "z": 19,
      "name": "Plant_Leaves_Windwillow"
    },
    {
      "x": 15,
      "y": 15,
      "z": 20,
      "name": "Plant_Leaves_Windwillow"
    },
    {
      "x": 15,
      "y": 16,
      "z": 20,
      "name": "Plant_Leaves_Windwillow"
    },
    {
      "x": 15,
      "y": 21,
      "z": 20,
      "name": "Plant_Leaves_Windwillow"
    },
    {
      "x": 15,
      "y": 13,
      "z": 21,
      "name": "Plant_Leaves_Windwillow"
    },
    {
      "x": 15,
      "y": 14,
      "z": 21,
      "name": "Plant_Leaves_Windwillow"
    },
    {
      "x": 15,
      "y": 15,
      "z": 21,
      "name": "Plant_Leaves_Windwillow"
    },
    {
      "x": 15,
      "y": 20,
      "z": 21,
      "name": "Plant_Leaves_Windwillow"
    },
    {
      "x": 15,
      "y": 21,
      "z": 21,
      "name": "Wood_Windwillow_Branch_Long",
      "rotation": 5
    },
    {
      "x": 15,
      "y": 22,
      "z": 21,
      "name": "Plant_Leaves_Windwillow"
    },
    {
      "x": 15,
      "y": 15,
      "z": 22,
      "name": "Plant_Leaves_Windwillow"
    },
    {
      "x": 15,
      "y": 20,
      "z": 22,
      "name": "Plant_Leaves_Windwillow"
    },
    {
      "x": 15,
      "y": 21,
      "z": 22,
      "name": "Plant_Leaves_Windwillow"
    },
    {
      "x": 16,
      "y": 16,
      "z": 8,
      "name": "Plant_Leaves_Windwillow"
    },
    {
      "x": 16,
      "y": 17,
      "z": 8,
      "name": "Plant_Leaves_Windwillow"
    },
    {
      "x": 16,
      "y": 16,
      "z": 9,
      "name": "Plant_Leaves_Windwillow"
    },
    {
      "x": 16,
      "y": 17,
      "z": 9,
      "name": "Plant_Leaves_Windwillow"
    },
    {
      "x": 16,
      "y": 15,
      "z": 10,
      "name": "Plant_Leaves_Windwillow"
    },
    {
      "x": 16,
      "y": 16,
      "z": 10,
      "name": "Plant_Leaves_Windwillow"
    },
    {
      "x": 16,
      "y": 17,
      "z": 10,
      "name": "Plant_Leaves_Windwillow"
    },
    {
      "x": 16,
      "y": 20,
      "z": 10,
      "name": "Plant_Leaves_Windwillow"
    },
    {
      "x": 16,
      "y": 21,
      "z": 10,
      "name": "Plant_Leaves_Windwillow"
    },
    {
      "x": 16,
      "y": 16,
      "z": 11,
      "name": "Plant_Leaves_Windwillow"
    },
    {
      "x": 16,
      "y": 17,
      "z": 11,
      "name": "Plant_Leaves_Windwillow"
    },
    {
      "x": 16,
      "y": 21,
      "z": 11,
      "name": "Plant_Leaves_Windwillow"
    },
    {
      "x": 16,
      "y": 22,
      "z": 11,
      "name": "Plant_Leaves_Windwillow"
    },
    {
      "x": 16,
      "y": 22,
      "z": 13,
      "name": "Plant_Leaves_Windwillow"
    },
    {
      "x": 16,
      "y": 14,
      "z": 14,
      "name": "Plant_Leaves_Windwillow"
    },
    {
      "x": 16,
      "y": 15,
      "z": 15,
      "name": "Wood_Windwillow_Trunk_Full"
    },
    {
      "x": 16,
      "y": 16,
      "z": 15,
      "name": "Plant_Leaves_Windwillow"
    },
    {
      "x": 16,
      "y": 23,
      "z": 15,
      "name": "Plant_Leaves_Windwillow"
    },
    {
      "x": 16,
      "y": 23,
      "z": 16,
      "name": "Wood_Windwillow_Branch_Long",
      "rotation": 5
    },
    {
      "x": 16,
      "y": 24,
      "z": 16,
      "name": "Plant_Leaves_Windwillow"
    },
    {
      "x": 16,
      "y": 25,
      "z": 16,
      "name": "Plant_Leaves_Windwillow"
    },
    {
      "x": 16,
      "y": 19,
      "z": 17,
      "name": "Wood_Windwillow_Branch_Long",
      "rotation": 5
    },
    {
      "x": 16,
      "y": 23,
      "z": 17,
      "name": "Plant_Leaves_Windwillow"
    },
    {
      "x": 16,
      "y": 25,
      "z": 17,
      "name": "Plant_Leaves_Windwillow"
    },
    {
      "x": 16,
      "y": 22,
      "z": 18,
      "name": "Plant_Leaves_Windwillow"
    },
    {
      "x": 16,
      "y": 23,
      "z": 18,
      "name": "Plant_Leaves_Windwillow"
    },
    {
      "x": 16,
      "y": 24,
      "z": 18,
      "name": "Plant_Leaves_Windwillow"
    },
    {
      "x": 16,
      "y": 15,
      "z": 19,
      "name": "Plant_Leaves_Windwillow"
    },
    {
      "x": 16,
      "y": 21,
      "z": 19,
      "name": "Plant_Leaves_Windwillow"
    },
    {
      "x": 16,
      "y": 23,
      "z": 19,
      "name": "Plant_Leaves_Windwillow"
    },
    {
      "x": 16,
      "y": 15,
      "z": 20,
      "name": "Plant_Leaves_Windwillow"
    },
    {
      "x": 16,
      "y": 19,
      "z": 20,
      "name": "Plant_Leaves_Windwillow"
    },
    {
      "x": 16,
      "y": 20,
      "z": 20,
      "name": "Plant_Leaves_Windwillow"
    },
    {
      "x": 16,
      "y": 21,
      "z": 20,
      "name": "Plant_Leaves_Windwillow"
    },
    {
      "x": 16,
      "y": 15,
      "z": 21,
      "name": "Plant_Leaves_Windwillow"
    },
    {
      "x": 16,
      "y": 20,
      "z": 21,
      "name": "Plant_Leaves_Windwillow"
    },
    {
      "x": 16,
      "y": 21,
      "z": 21,
      "name": "Plant_Leaves_Windwillow"
    },
    {
      "x": 17,
      "y": 17,
      "z": 9,
      "name": "Plant_Leaves_Windwillow"
    },
    {
      "x": 17,
      "y": 14,
      "z": 14,
      "name": "Plant_Leaves_Windwillow"
    },
    {
      "x": 17,
      "y": 15,
      "z": 14,
      "name": "Plant_Leaves_Windwillow"
    },
    {
      "x": 17,
      "y": 16,
      "z": 14,
      "name": "Plant_Leaves_Windwillow"
    },
    {
      "x": 17,
      "y": 23,
      "z": 14,
      "name": "Plant_Leaves_Windwillow"
    },
    {
      "x": 17,
      "y": 15,
      "z": 15,
      "name": "Wood_Windwillow_Trunk_Full"
    },
    {
      "x": 17,
      "y": 16,
      "z": 15,
      "name": "Wood_Windwillow_Trunk_Full"
    },
    {
      "x": 17,
      "y": 17,
      "z": 15,
      "name": "Plant_Leaves_Windwillow"
    },
    {
      "x": 17,
      "y": 19,
      "z": 15,
      "name": "Plant_Leaves_Windwillow"
    },
    {
      "x": 17,
      "y": 23,
      "z": 15,
      "name": "Plant_Leaves_Windwillow"
    },
    {
      "x": 17,
      "y": 24,
      "z": 15,
      "name": "Plant_Leaves_Windwillow"
    },
    {
      "x": 17,
      "y": 15,
      "z": 16,
      "name": "Plant_Leaves_Windwillow"
    },
    {
      "x": 17,
      "y": 16,
      "z": 16,
      "name": "Plant_Leaves_Windwillow"
    },
    {
      "x": 17,
      "y": 19,
      "z": 16,
      "name": "Plant_Leaves_Windwillow"
    },
    {
      "x": 17,
      "y": 20,
      "z": 16,
      "name": "Plant_Leaves_Windwillow"
    },
    {
      "x": 17,
      "y": 23,
      "z": 16,
      "name": "Wood_Windwillow_Branch_Long",
      "rotation": 5
    },
    {
      "x": 17,
      "y": 24,
      "z": 16,
      "name": "Plant_Leaves_Windwillow"
    },
    {
      "x": 17,
      "y": 16,
      "z": 17,
      "name": "Plant_Leaves_Windwillow"
    },
    {
      "x": 17,
      "y": 19,
      "z": 17,
      "name": "Wood_Windwillow_Branch_Corner",
      "rotation": 1
    },
    {
      "x": 17,
      "y": 20,
      "z": 17,
      "name": "Plant_Leaves_Windwillow"
    },
    {
      "x": 17,
      "y": 23,
      "z": 17,
      "name": "Plant_Leaves_Windwillow"
    },
    {
      "x": 17,
      "y": 18,
      "z": 18,
      "name": "Plant_Leaves_Windwillow"
    },
    {
      "x": 17,
      "y": 19,
      "z": 18,
      "name": "Plant_Leaves_Windwillow"
    },
    {
      "x": 17,
      "y": 20,
      "z": 18,
      "name": "Plant_Leaves_Windwillow"
    },
    {
      "x": 17,
      "y": 23,
      "z": 18,
      "name": "Plant_Leaves_Windwillow"
    },
    {
      "x": 17,
      "y": 24,
      "z": 18,
      "name": "Plant_Leaves_Windwillow"
    },
    {
      "x": 17,
      "y": 19,
      "z": 19,
      "name": "Plant_Leaves_Windwillow"
    },
    {
      "x": 17,
      "y": 19,
      "z": 20,
      "name": "Plant_Leaves_Windwillow"
    },
    {
      "x": 18,
      "y": 15,
      "z": 13,
      "name": "Plant_Leaves_Windwillow"
    },
    {
      "x": 18,
      "y": 16,
      "z": 13,
      "name": "Plant_Leaves_Windwillow"
    },
    {
      "x": 18,
      "y": 16,
      "z": 14,
      "name": "Plant_Leaves_Windwillow"
    },
    {
      "x": 18,
      "y": 16,
      "z": 15,
      "name": "Wood_Windwillow_Trunk_Full"
    },
    {
      "x": 18,
      "y": 17,
      "z": 15,
      "name": "Plant_Leaves_Windwillow"
    },
    {
      "x": 18,
      "y": 18,
      "z": 15,
      "name": "Plant_Leaves_Windwillow"
    },
    {
      "x": 18,
      "y": 19,
      "z": 15,
      "name": "Plant_Leaves_Windwillow"
    },
    {
      "x": 18,
      "y": 22,
      "z": 15,
      "name": "Plant_Leaves_Windwillow"
    },
    {
      "x": 18,
      "y": 23,
      "z": 15,
      "name": "Plant_Leaves_Windwillow"
    },
    {
      "x": 18,
      "y": 16,
      "z": 16,
      "name": "Plant_Leaves_Windwillow"
    },
    {
      "x": 18,
      "y": 17,
      "z": 16,
      "name": "Plant_Leaves_Windwillow"
    },
    {
      "x": 18,
      "y": 19,
      "z": 16,
      "name": "Plant_Leaves_Windwillow"
    },
    {
      "x": 18,
      "y": 20,
      "z": 16,
      "name": "Plant_Leaves_Windwillow"
    },
    {
      "x": 18,
      "y": 23,
      "z": 16,
      "name": "Plant_Leaves_Windwillow"
    },
    {
      "x": 18,
      "y": 14,
      "z": 17,
      "name": "Plant_Leaves_Windwillow"
    },
    {
      "x": 18,
      "y": 15,
      "z": 17,
      "name": "Plant_Leaves_Windwillow"
    },
    {
      "x": 18,
      "y": 16,
      "z": 17,
      "name": "Plant_Leaves_Windwillow"
    },
    {
      "x": 18,
      "y": 20,
      "z": 17,
      "name": "Plant_Leaves_Windwillow"
    },
    {
      "x": 18,
      "y": 16,
      "z": 18,
      "name": "Plant_Leaves_Windwillow"
    },
    {
      "x": 18,
      "y": 19,
      "z": 18,
      "name": "Plant_Leaves_Windwillow"
    },
    {
      "x": 18,
      "y": 20,
      "z": 18,
      "name": "Plant_Leaves_Windwillow"
    },
    {
      "x": 19,
      "y": 14,
      "z": 13,
      "name": "Plant_Leaves_Windwillow"
    },
    {
      "x": 19,
      "y": 15,
      "z": 13,
      "name": "Plant_Leaves_Windwillow"
    },
    {
      "x": 19,
      "y": 16,
      "z": 13,
      "name": "Plant_Leaves_Windwillow"
    },
    {
      "x": 19,
      "y": 16,
      "z": 14,
      "name": "Wood_Windwillow_Branch_Long",
      "rotation": 4
    },
    {
      "x": 19,
      "y": 17,
      "z": 14,
      "name": "Plant_Leaves_Windwillow"
    },
    {
      "x": 19,
      "y": 16,
      "z": 15,
      "name": "Wood_Windwillow_Trunk_Full"
    },
    {
      "x": 19,
      "y": 17,
      "z": 15,
      "name": "Plant_Leaves_Windwillow"
    },
    {
      "x": 19,
      "y": 14,
      "z": 16,
      "name": "Plant_Leaves_Windwillow"
    },
    {
      "x": 19,
      "y": 15,
      "z": 16,
      "name": "Plant_Leaves_Windwillow"
    },
    {
      "x": 19,
      "y": 16,
      "z": 16,
      "name": "Wood_Windwillow_Branch_Long",
      "rotation": 4
    },
    {
      "x": 19,
      "y": 17,
      "z": 16,
      "name": "Plant_Leaves_Windwillow"
    },
    {
      "x": 19,
      "y": 19,
      "z": 16,
      "name": "Plant_Leaves_Windwillow"
    },
    {
      "x": 19,
      "y": 15,
      "z": 17,
      "name": "Plant_Leaves_Windwillow"
    },
    {
      "x": 19,
      "y": 16,
      "z": 17,
      "name": "Wood_Windwillow_Branch_Long",
      "rotation": 4
    },
    {
      "x": 19,
      "y": 17,
      "z": 17,
      "name": "Plant_Leaves_Windwillow"
    },
    {
      "x": 19,
      "y": 19,
      "z": 17,
      "name": "Plant_Leaves_Windwillow"
    },
    {
      "x": 19,
      "y": 20,
      "z": 17,
      "name": "Plant_Leaves_Windwillow"
    },
    {
      "x": 19,
      "y": 15,
      "z": 18,
      "name": "Plant_Leaves_Windwillow"
    },
    {
      "x": 19,
      "y": 16,
      "z": 18,
      "name": "Plant_Leaves_Windwillow"
    },
    {
      "x": 19,
      "y": 19,
      "z": 18,
      "name": "Plant_Leaves_Windwillow"
    },
    {
      "x": 20,
      "y": 16,
      "z": 13,
      "name": "Plant_Leaves_Windwillow"
    },
    {
      "x": 20,
      "y": 15,
      "z": 14,
      "name": "Plant_Leaves_Windwillow"
    },
    {
      "x": 20,
      "y": 16,
      "z": 14,
      "name": "Plant_Leaves_Windwillow"
    },
    {
      "x": 20,
      "y": 16,
      "z": 15,
      "name": "Wood_Windwillow_Branch_Long",
      "rotation": 5
    },
    {
      "x": 20,
      "y": 17,
      "z": 15,
      "name": "Plant_Leaves_Windwillow"
    },
    {
      "x": 20,
      "y": 14,
      "z": 16,
      "name": "Plant_Leaves_Windwillow"
    },
    {
      "x": 20,
      "y": 15,
      "z": 16,
      "name": "Plant_Leaves_Windwillow"
    },
    {
      "x": 20,
      "y": 16,
      "z": 16,
      "name": "Plant_Leaves_Windwillow"
    },
    {
      "x": 20,
      "y": 17,
      "z": 16,
      "name": "Plant_Leaves_Windwillow"
    },
    {
      "x": 20,
      "y": 15,
      "z": 17,
      "name": "Plant_Leaves_Windwillow"
    },
    {
      "x": 20,
      "y": 16,
      "z": 17,
      "name": "Plant_Leaves_Windwillow"
    },
    {
      "x": 21,
      "y": 15,
      "z": 15,
      "name": "Plant_Leaves_Windwillow"
    },
    {
      "x": 21,
      "y": 16,
      "z": 15,
      "name": "Plant_Leaves_Windwillow"
    },
    {
      "x": 21,
      "y": 16,
      "z": 16,
      "name": "Plant_Leaves_Windwillow"
    }
  ]
}