{
  "version": 8,
  "blockIdVersion": 11,
  "anchorX": 1,
  "anchorY": 1,
  "anchorZ": 0,
  "blocks": [
    {
      "x": -4,
      "y": 10,
      "z": -1,
      "name": "Plant_Leaves_Spiral"
    },
    {
      "x": -3,
      "y": 8,
      "z": -2,
      "name": "Wood_Spiral_Branch_Corner",
      "rotation": 3
    },
    {
      "x": -3,
      "y": 9,
      "z": -2,
      "name": "Wood_Spiral_Branch_Corner",
      "rotation": 8
    },
    {
      "x": -3,
      "y": 10,
      "z": -2,
      "name": "Plant_Leaves_Spiral"
    },
    {
      "x": -3,
      "y": 9,
      "z": -1,
      "name": "Wood_Spiral_Branch_Corner"
    },
    {
      "x": -3,
      "y": 10,
      "z": -1,
      "name": "Wood_Spiral_Branch_Corner",
      "rotation": 9
    },
    {
      "x": -3,
      "y": 11,
      "z": -1,
      "name": "Plant_Leaves_Spiral"
    },
    {
      "x": -3,
      "y": 5,
      "z": 0,
      "name": "Plant_Leaves_Spiral"
    },
    {
      "x": -3,
      "y": 10,
      "z": 0,
      "name": "Plant_Leaves_Spiral"
    },
    {
      "x": -3,
      "y": 7,
      "z": 3,
      "name": "Plant_Leaves_Spiral"
    },
    {
      "x": -2,
      "y": 7,
      "z": -2,
      "name": "Wood_Spiral_Branch_Corner",
      "rotation": 3
    },
    {
      "x": -2,
      "y": 8,
      "z": -2,
      "name": "Wood_Spiral_Branch_Corner",
      "rotation": 11
    },
    {
      "x": -2,
      "y": 10,
      "z": -2,
      "name": "Plant_Leaves_Spiral"
    },
    {
      "x": -2,
      "y": 5,
      "z": -1,
      "name": "Plant_Leaves_Spiral"
    },
    {
      "x": -2,
      "y": 10,
      "z": -1,
      "name": "Wood_Spiral_Branch_Corner",
      "rotation": 1
    },
    {
      "x": -2,
      "y": 11,
      "z": -1,
      "name": "Plant_Leaves_Spiral"
    },
    {
      "x": -2,
      "y": 5,
      "z": 0,
      "name": "Wood_Spiral_Branch_Long",
      "rotation": 5
    },
    {
      "x": -2,
      "y": 6,
      "z": 0,
      "name": "Plant_Leaves_Spiral"
    },
    {
      "x": -2,
      "y": 10,
      "z": 0,
      "name": "Plant_Leaves_Spiral"
    },
    {
      "x": -2,
      "y": 5,
      "z": 1,
      "name": "Plant_Leaves_Spiral"
    },
    {
      "x": -2,
      "y": 5,
      "z": 2,
      "name": "Wood_Spiral_Branch_Corner",
      "rotation": 3
    },
    {
      "x": -2,
      "y": 6,
      "z": 2,
      "name": "Wood_Spiral_Branch_Corner",
      "rotation": 8
    },
    {
      "x": -2,
      "y": 7,
      "z": 2,
      "name": "Plant_Leaves_Spiral"
    },
    {
      "x": -2,
      "y": 6,
      "z": 3,
      "name": "Wood_Spiral_Branch_Corner"
    },
    {
      "x": -2,
      "y": 7,
      "z": 3,
      "name": "Wood_Spiral_Branch_Corner",
      "rotation": 9
    },
    {
      "x": -2,
      "y": 8,
      "z": 3,
      "name": "Plant_Leaves_Spiral"
    },
    {
      "x": -2,
      "y": 7,
      "z": 4,
      "name": "Plant_Leaves_Spiral"
    },
    {
      "x": -1,
      "y": 3,
      "z": -3,
      "name": "Wood_Spiral_Branch_Corner",
      "rotation": 2
    },
    {
      "x": -1,
      "y": 4,
      "z": -3,
      "name": "Wood_Spiral_Branch_Corner",
      "rotation": 8
    },
    {
      "x": -1,
      "y": 3,
      "z": -2,
      "name": "Wood_Spiral_Branch_Corner"
    },
    {
      "x": -1,
      "y": 4,
      "z": -2,
      "name": "Wood_Spiral_Branch_Corner"
    },
    {
      "x": -1,
      "y": 5,
      "z": -2,
      "name": "Wood_Spiral_Branch_Corner",
      "rotation": 8
    },
    {
      "x": -1,
      "y": 6,
      "z": -2,
      "name": "Wood_Spiral_Branch_Corner",
      "rotation": 2
    },
    {
      "x": -1,
      "y": 7,
      "z": -2,
      "name": "Wood_Spiral_Branch_Corner",
      "rotation": 11
    },
    {
      "x": -1,
      "y": 4,
      "z": -1,
      "name": "Wood_Spiral_Trunk_Full"
    },
    {
      "x": -1,
      "y": 5,
      "z": -1,
      "name": "Wood_Spiral_Trunk_Full"
    },
    {
      "x": -1,
      "y": 6,
      "z": -1,
      "name": "Wood_Spiral_Trunk_Full"
    },
    {
      "x": -1,
      "y": 10,
      "z": -1,
      "name": "Plant_Leaves_Spiral"
    },
    {
      "x": -1,
      "y": 3,
      "z": 0,
      "name": "Wood_Spiral_Trunk_Full"
    },
    {
      "x": -1,
      "y": 4,
      "z": 0,
      "name": "Wood_Spiral_Trunk_Full"
    },
    {
      "x": -1,
      "y": 5,
      "z": 0,
      "name": "Wood_Spiral_Trunk_Full"
    },
    {
      "x": -1,
      "y": 7,
      "z": 0,
      "name": "Plant_Leaves_Spiral"
    },
    {
      "x": -1,
      "y": 2,
      "z": 1,
      "name": "Wood_Spiral_Trunk_Full"
    },
    {
      "x": -1,
      "y": 3,
      "z": 1,
      "name": "Wood_Spiral_Trunk_Full"
    },
    {
      "x": -1,
      "y": 4,
      "z": 1,
      "name": "Wood_Spiral_Trunk_Full"
    },
    {
      "x": -1,
      "y": 4,
      "z": 2,
      "name": "Wood_Spiral_Branch_Corner"
    },
    {
      "x": -1,
      "y": 5,
      "z": 2,
      "name": "Wood_Spiral_Branch_Corner",
      "rotation": 11
    },
    {
      "x": -1,
      "y": 7,
      "z": 2,
      "name": "Plant_Leaves_Spiral"
    },
    {
      "x": -1,
      "y": 7,
      "z": 3,
      "name": "Wood_Spiral_Branch_Corner",
      "rotation": 1
    },
    {
      "x": -1,
      "y": 8,
      "z": 3,
      "name": "Plant_Leaves_Spiral"
    },
    {
      "x": -1,
      "y": 7,
      "z": 4,
      "name": "Plant_Leaves_Spiral"
    },
    {
      "x": 0,
      "y": 7,
      "z": -3,
      "name": "Plant_Leaves_Spiral"
    },
    {
      "x": 0,
      "y": 7,
      "z": -2,
      "name": "Wood_Spiral_Branch_Long",
      "rotation": 4
    },
    {
      "x": 0,
      "y": 8,
      "z": -2,
      "name": "Plant_Leaves_Spiral"
    },
    {
      "x": 0,
      "y": 4,
      "z": -1,
      "name": "Plant_Leaves_Spiral"
    },
    {
      "x": 0,
      "y": 5,
      "z": -1,
      "name": "Wood_Spiral_Trunk_Full"
    },
    {
      "x": 0,
      "y": 6,
      "z": -1,
      "name": "Wood_Spiral_Trunk_Full"
    },
    {
      "x": 0,
      "y": 7,
      "z": -1,
      "name": "Wood_Spiral_Trunk_Full"
    },
    {
      "x": 0,
      "y": 4,
      "z": 0,
      "name": "Wood_Spiral_Branch_Long",
      "rotation": 5
    },
    {
      "x": 0,
      "y": 5,
      "z": 0,
      "name": "Plant_Leaves_Spiral"
    },
    {
      "x": 0,
      "y": 7,
      "z": 0,
      "name": "Wood_Spiral_Branch_Long",
      "rotation": 4
    },
    {
      "x": 0,
      "y": 8,
      "z": 0,
      "name": "Plant_Leaves_Spiral"
    },
    {
      "x": 0,
      "y": 1,
      "z": 1,
      "name": "Wood_Spiral_Trunk_Full"
    },
    {
      "x": 0,
      "y": 2,
      "z": 1,
      "name": "Wood_Spiral_Trunk_Full"
    },
    {
      "x": 0,
      "y": 3,
      "z": 1,
      "name": "Wood_Spiral_Trunk_Full"
    },
    {
      "x": 0,
      "y": 4,
      "z": 1,
      "name": "Plant_Leaves_Spiral"
    },
    {
      "x": 0,
      "y": 5,
      "z": 1,
      "name": "Plant_Leaves_Spiral"
    },
    {
      "x": 0,
      "y": 7,
      "z": 1,
      "name": "Plant_Leaves_Spiral"
    },
    {
      "x": 0,
      "y": 1,
      "z": 2,
      "name": "Wood_Spiral_Trunk_Full"
    },
    {
      "x": 0,
      "y": 2,
      "z": 2,
      "name": "Wood_Spiral_Trunk_Full"
    },
    {
      "x": 0,
      "y": 4,
      "z": 2,
      "name": "Plant_Leaves_Spiral"
    },
    {
      "x": 0,
      "y": 2,
      "z": 3,
      "name": "Wood_Spiral_Branch_Corner"
    },
    {
      "x": 0,
      "y": 3,
      "z": 3,
      "name": "Wood_Spiral_Branch_Corner",
      "rotation": 10
    },
    {
      "x": 0,
      "y": 7,
      "z": 3,
      "name": "Plant_Leaves_Spiral"
    },
    {
      "x": 1,
      "y": 7,
      "z": -2,
      "name": "Plant_Leaves_Spiral"
    },
    {
      "x": 1,
      "y": 7,
      "z": -1,
      "name": "Wood_Spiral_Trunk_Full"
    },
    {
      "x": 1,
      "y": 8,
      "z": -1,
      "name": "Wood_Spiral_Trunk_Full"
    },
    {
      "x": 1,
      "y": 1,
      "z": 0,
      "name": "Wood_Spiral_Trunk_Full"
    },
    {
      "x": 1,
      "y": 4,
      "z": 0,
      "name": "Plant_Leaves_Spiral"
    },
    {
      "x": 1,
      "y": 10,
      "z": 0,
      "name": "Plant_Leaves_Spiral"
    },
    {
      "x": 1,
      "y": 1,
      "z": 1,
      "name": "Wood_Spiral_Trunk_Full"
    },
    {
      "x": 1,
      "y": 2,
      "z": 1,
      "name": "Wood_Spiral_Trunk_Full"
    },
    {
      "x": 1,
      "y": 7,
      "z": 1,
      "name": "Plant_Leaves_Spiral"
    },
    {
      "x": 1,
      "y": 10,
      "z": 1,
      "name": "Plant_Leaves_Spiral"
    },
    {
      "x": 1,
      "y": 1,
      "z": 2,
      "name": "Wood_Spiral_Trunk_Full"
    },
    {
      "x": 2,
      "y": 8,
      "z": -1,
      "name": "Wood_Spiral_Branch_Corner",
      "rotation": 1
    },
    {
      "x": 2,
      "y": 9,
      "z": -1,
      "name": "Wood_Spiral_Branch_Corner",
      "rotation": 8
    },
    {
      "x": 2,
      "y": 10,
      "z": -1,
      "name": "Plant_Leaves_Spiral"
    },
    {
      "x": 2,
      "y": 9,
      "z": 0,
      "name": "Wood_Spiral_Branch_Corner"
    },
    {
      "x": 2,
      "y": 10,
      "z": 0,
      "name": "Wood_Spiral_Branch_Corner",
      "rotation": 8
    },
    {
      "x": 2,
      "y": 11,
      "z": 0,
      "name": "Plant_Leaves_Spiral"
    },
    {
      "x": 2,
      "y": 1,
      "z": 1,
      "name": "Wood_Spiral_Trunk_Full"
    },
    {
      "x": 2,
      "y": 10,
      "z": 1,
      "name": "Plant_Leaves_Spiral"
    },
    {
      "x": 2,
      "y": 11,
      "z": 1,
      "name": "Plant_Leaves_Spiral"
    },
    {
      "x": 2,
      "y": 10,
      "z": 2,
      "name": "Plant_Leaves_Spiral"
    },
    {
      "x": 3,
      "y": 10,
      "z": 0,
      "name": "Plant_Leaves_Spiral"
    },
    {
      "x": 3,
      "y": 10,
      "z": 1,
      "name": "Plant_Leaves_Spiral"
    }
  ]
}