{
  "version": 8,
  "blockIdVersion": 11,
  "anchorX": 0,
  "anchorY": 5,
  "anchorZ": 0,
  "blocks": [
    {
      "x": -5,
      "y": 12,
      "z": 0,
      "name": "Plant_Leaves_Dry"
    },
    {
      "x": -5,
      "y": 12,
      "z": 1,
      "name": "Plant_Leaves_Dry"
    },
    {
      "x": -5,
      "y": 12,
      "z": 2,
      "name": "Plant_Leaves_Dry"
    },
    {
      "x": -4,
      "y": 12,
      "z": -1,
      "name": "Plant_Leaves_Dry"
    },
    {
      "x": -4,
      "y": 12,
      "z": 0,
      "name": "Plant_Leaves_Dry"
    },
    {
      "x": -4,
      "y": 12,
      "z": 1,
      "name": "Plant_Leaves_Dry"
    },
    {
      "x": -4,
      "y": 12,
      "z": 2,
      "name": "Plant_Leaves_Dry"
    },
    {
      "x": -4,
      "y": 12,
      "z": 3,
      "name": "Plant_Leaves_Dry"
    },
    {
      "x": -3,
      "y": 12,
      "z": -1,
      "name": "Plant_Leaves_Dry"
    },
    {
      "x": -3,
      "y": 9,
      "z": 0,
      "name": "Plant_Leaves_Dry"
    },
    {
      "x": -3,
      "y": 12,
      "z": 0,
      "name": "Plant_Leaves_Dry"
    },
    {
      "x": -3,
      "y": 13,
      "z": 0,
      "name": "Plant_Leaves_Dry"
    },
    {
      "x": -3,
      "y": 9,
      "z": 1,
      "name": "Plant_Leaves_Dry"
    },
    {
      "x": -3,
      "y": 12,
      "z": 1,
      "name": "Wood_Dry_Branch_Long",
      "rotation": 5
    },
    {
      "x": -3,
      "y": 13,
      "z": 1,
      "name": "Plant_Leaves_Dry"
    },
    {
      "x": -3,
      "y": 12,
      "z": 2,
      "name": "Plant_Leaves_Dry"
    },
    {
      "x": -3,
      "y": 13,
      "z": 2,
      "name": "Plant_Leaves_Dry"
    },
    {
      "x": -3,
      "y": 12,
      "z": 3,
      "name": "Plant_Leaves_Dry"
    },
    {
      "x": -3,
      "y": 12,
      "z": 4,
      "name": "Plant_Leaves_Dry"
    },
    {
      "x": -2,
      "y": 9,
      "z": -1,
      "name": "Plant_Leaves_Dry"
    },
    {
      "x": -2,
      "y": 13,
      "z": -1,
      "name": "Plant_Leaves_Dry"
    },
    {
      "x": -2,
      "y": 9,
      "z": 0,
      "name": "Plant_Leaves_Dry"
    },
    {
      "x": -2,
      "y": 13,
      "z": 0,
      "name": "Plant_Leaves_Dry"
    },
    {
      "x": -2,
      "y": 9,
      "z": 1,
      "name": "Wood_Dry_Branch_Corner",
      "rotation": 3
    },
    {
      "x": -2,
      "y": 10,
      "z": 1,
      "name": "Wood_Dry_Branch_Long"
    },
    {
      "x": -2,
      "y": 11,
      "z": 1,
      "name": "Wood_Dry_Branch_Long"
    },
    {
      "x": -2,
      "y": 12,
      "z": 1,
      "name": "Wood_Dry_Branch_Corner",
      "rotation": 11
    },
    {
      "x": -2,
      "y": 13,
      "z": 1,
      "name": "Plant_Leaves_Dry"
    },
    {
      "x": -1,
      "y": 9,
      "z": 0,
      "name": "Plant_Leaves_Dry"
    },
    {
      "x": -1,
      "y": 6,
      "z": 1,
      "name": "Wood_Dry_Branch_Corner",
      "rotation": 3
    },
    {
      "x": -1,
      "y": 7,
      "z": 1,
      "name": "Wood_Dry_Branch_Long"
    },
    {
      "x": -1,
      "y": 8,
      "z": 1,
      "name": "Wood_Dry_Branch_Long"
    },
    {
      "x": -1,
      "y": 9,
      "z": 1,
      "name": "Wood_Dry_Branch_Corner",
      "rotation": 11
    },
    {
      "x": -1,
      "y": 13,
      "z": 1,
      "name": "Plant_Leaves_Dry"
    },
    {
      "x": 0,
      "y": 12,
      "z": -3,
      "name": "Plant_Leaves_Dry"
    },
    {
      "x": 0,
      "y": 12,
      "z": -2,
      "name": "Plant_Leaves_Dry"
    },
    {
      "x": 0,
      "y": 5,
      "z": 1,
      "name": "Wood_Dry_Branch_Long"
    },
    {
      "x": 0,
      "y": 6,
      "z": 1,
      "name": "Wood_Dry_Branch_Corner",
      "rotation": 11
    },
    {
      "x": 0,
      "y": 11,
      "z": 3,
      "name": "Plant_Leaves_Dry"
    },
    {
      "x": 1,
      "y": 12,
      "z": -4,
      "name": "Plant_Leaves_Dry"
    },
    {
      "x": 1,
      "y": 12,
      "z": -3,
      "name": "Plant_Leaves_Dry"
    },
    {
      "x": 1,
      "y": 12,
      "z": -2,
      "name": "Plant_Leaves_Dry"
    },
    {
      "x": 1,
      "y": 13,
      "z": -2,
      "name": "Plant_Leaves_Dry"
    },
    {
      "x": 1,
      "y": 7,
      "z": -1,
      "name": "Wood_Dry_Branch_Corner",
      "rotation": 2
    },
    {
      "x": 1,
      "y": 8,
      "z": -1,
      "name": "Wood_Dry_Branch_Long"
    },
    {
      "x": 1,
      "y": 9,
      "z": -1,
      "name": "Wood_Dry_Branch_Corner",
      "rotation": 9
    },
    {
      "x": 1,
      "y": 12,
      "z": -1,
      "name": "Plant_Leaves_Dry"
    },
    {
      "x": 1,
      "y": 13,
      "z": -1,
      "name": "Plant_Leaves_Dry"
    },
    {
      "x": 1,
      "y": 5,
      "z": 0,
      "name": "Wood_Dry_Branch_Long"
    },
    {
      "x": 1,
      "y": 6,
      "z": 0,
      "name": "Wood_Dry_Branch_Long"
    },
    {
      "x": 1,
      "y": 7,
      "z": 0,
      "name": "Wood_Dry_Branch_Corner",
      "rotation": 10
    },
    {
      "x": 1,
      "y": 5,
      "z": 1,
      "name": "Wood_Dry_Branch_Long"
    },
    {
      "x": 1,
      "y": 6,
      "z": 1,
      "name": "Wood_Dry_Branch_Long"
    },
    {
      "x": 1,
      "y": 7,
      "z": 1,
      "name": "Wood_Dry_Branch_Long"
    },
    {
      "x": 1,
      "y": 8,
      "z": 1,
      "name": "Wood_Dry_Branch_Long"
    },
    {
      "x": 1,
      "y": 9,
      "z": 1,
      "name": "Wood_Dry_Branch_Corner",
      "rotation": 9
    },
    {
      "x": 1,
      "y": 12,
      "z": 2,
      "name": "Plant_Leaves_Dry"
    },
    {
      "x": 1,
      "y": 13,
      "z": 2,
      "name": "Plant_Leaves_Dry"
    },
    {
      "x": 1,
      "y": 11,
      "z": 3,
      "name": "Plant_Leaves_Dry"
    },
    {
      "x": 1,
      "y": 11,
      "z": 4,
      "name": "Plant_Leaves_Dry"
    },
    {
      "x": 2,
      "y": 12,
      "z": -5,
      "name": "Plant_Leaves_Dry"
    },
    {
      "x": 2,
      "y": 12,
      "z": -4,
      "name": "Plant_Leaves_Dry"
    },
    {
      "x": 2,
      "y": 12,
      "z": -3,
      "name": "Plant_Leaves_Dry"
    },
    {
      "x": 2,
      "y": 12,
      "z": -2,
      "name": "Wood_Dry_Branch_Long",
      "rotation": 4
    },
    {
      "x": 2,
      "y": 13,
      "z": -2,
      "name": "Plant_Leaves_Dry"
    },
    {
      "x": 2,
      "y": 9,
      "z": -1,
      "name": "Wood_Dry_Branch_Corner",
      "rotation": 1
    },
    {
      "x": 2,
      "y": 10,
      "z": -1,
      "name": "Wood_Dry_Branch_Long"
    },
    {
      "x": 2,
      "y": 11,
      "z": -1,
      "name": "Wood_Dry_Branch_Long"
    },
    {
      "x": 2,
      "y": 12,
      "z": -1,
      "name": "Wood_Dry_Branch_Corner",
      "rotation": 10
    },
    {
      "x": 2,
      "y": 13,
      "z": -1,
      "name": "Plant_Leaves_Dry"
    },
    {
      "x": 2,
      "y": 9,
      "z": 1,
      "name": "Wood_Dry_Branch_Corner",
      "rotation": 1
    },
    {
      "x": 2,
      "y": 10,
      "z": 1,
      "name": "Wood_Dry_Branch_Long"
    },
    {
      "x": 2,
      "y": 11,
      "z": 1,
      "name": "Wood_Dry_Branch_Corner",
      "rotation": 8
    },
    {
      "x": 2,
      "y": 12,
      "z": 1,
      "name": "Plant_Leaves_Dry"
    },
    {
      "x": 2,
      "y": 13,
      "z": 1,
      "name": "Plant_Leaves_Dry"
    },
    {
      "x": 2,
      "y": 11,
      "z": 2,
      "name": "Wood_Dry_Branch_Long",
      "rotation": 4
    },
    {
      "x": 2,
      "y": 12,
      "z": 2,
      "name": "Plant_Leaves_Dry"
    },
    {
      "x": 2,
      "y": 11,
      "z": 3,
      "name": "Wood_Dry_Branch_Long",
      "rotation": 4
    },
    {
      "x": 2,
      "y": 12,
      "z": 3,
      "name": "Plant_Leaves_Dry"
    },
    {
      "x": 2,
      "y": 11,
      "z": 4,
      "name": "Plant_Leaves_Dry"
    },
    {
      "x": 2,
      "y": 11,
      "z": 5,
      "name": "Plant_Leaves_Dry"
    },
    {
      "x": 3,
      "y": 12,
      "z": -4,
      "name": "Plant_Leaves_Dry"
    },
    {
      "x": 3,
      "y": 12,
      "z": -3,
      "name": "Plant_Leaves_Dry"
    },
    {
      "x": 3,
      "y": 12,
      "z": -2,
      "name": "Plant_Leaves_Dry"
    },
    {
      "x": 3,
      "y": 11,
      "z": 1,
      "name": "Plant_Leaves_Dry"
    },
    {
      "x": 3,
      "y": 12,
      "z": 1,
      "name": "Plant_Leaves_Dry"
    },
    {
      "x": 3,
      "y": 13,
      "z": 1,
      "name": "Plant_Leaves_Dry"
    },
    {
      "x": 3,
      "y": 11,
      "z": 2,
      "name": "Plant_Leaves_Dry"
    },
    {
      "x": 3,
      "y": 11,
      "z": 3,
      "name": "Plant_Leaves_Dry"
    },
    {
      "x": 3,
      "y": 12,
      "z": 3,
      "name": "Plant_Leaves_Dry"
    },
    {
      "x": 3,
      "y": 11,
      "z": 4,
      "name": "Plant_Leaves_Dry"
    },
    {
      "x": 3,
      "y": 12,
      "z": 4,
      "name": "Plant_Leaves_Dry"
    },
    {
      "x": 3,
      "y": 11,
      "z": 5,
      "name": "Plant_Leaves_Dry"
    },
    {
      "x": 4,
      "y": 12,
      "z": -3,
      "name": "Plant_Leaves_Dry"
    },
    {
      "x": 4,
      "y": 11,
      "z": 2,
      "name": "Plant_Leaves_Dry"
    },
    {
      "x": 4,
      "y": 12,
      "z": 2,
      "name": "Plant_Leaves_Dry"
    },
    {
      "x": 4,
      "y": 11,
      "z": 3,
      "name": "Plant_Leaves_Dry"
    },
    {
      "x": 4,
      "y": 11,
      "z": 4,
      "name": "Plant_Leaves_Dry"
    },
    {
      "x": 5,
      "y": 11,
      "z": 3,
      "name": "Plant_Leaves_Dry"
    }
  ]
}