{
  "version": 8,
  "blockIdVersion": 11,
  "anchorX": 16,
  "anchorY": 9,
  "anchorZ": 12,
  "blocks": [
    {
      "x": 9,
      "y": 19,
      "z": 7,
      "name": "Plant_Leaves_Bottle"
    },
    {
      "x": 9,
      "y": 19,
      "z": 8,
      "name": "Plant_Leaves_Bottle"
    },
    {
      "x": 9,
      "y": 18,
      "z": 16,
      "name": "Plant_Leaves_Bottle"
    },
    {
      "x": 9,
      "y": 18,
      "z": 17,
      "name": "Plant_Leaves_Bottle"
    },
    {
      "x": 10,
      "y": 19,
      "z": 6,
      "name": "Plant_Leaves_Bottle"
    },
    {
      "x": 10,
      "y": 19,
      "z": 7,
      "name": "Plant_Leaves_Bottle"
    },
    {
      "x": 10,
      "y": 19,
      "z": 8,
      "name": "Plant_Leaves_Bottle"
    },
    {
      "x": 10,
      "y": 18,
      "z": 11,
      "name": "Plant_Leaves_Bottle"
    },
    {
      "x": 10,
      "y": 18,
      "z": 12,
      "name": "Plant_Leaves_Bottle"
    },
    {
      "x": 10,
      "y": 18,
      "z": 13,
      "name": "Plant_Leaves_Bottle"
    },
    {
      "x": 10,
      "y": 18,
      "z": 15,
      "name": "Plant_Leaves_Bottle"
    },
    {
      "x": 10,
      "y": 18,
      "z": 16,
      "name": "Plant_Leaves_Bottle"
    },
    {
      "x": 10,
      "y": 19,
      "z": 16,
      "name": "Plant_Leaves_Bottle"
    },
    {
      "x": 10,
      "y": 18,
      "z": 17,
      "name": "Plant_Leaves_Bottle"
    },
    {
      "x": 10,
      "y": 19,
      "z": 17,
      "name": "Plant_Leaves_Bottle"
    },
    {
      "x": 10,
      "y": 18,
      "z": 18,
      "name": "Plant_Leaves_Bottle"
    },
    {
      "x": 11,
      "y": 19,
      "z": 5,
      "name": "Plant_Leaves_Bottle"
    },
    {
      "x": 11,
      "y": 19,
      "z": 6,
      "name": "Plant_Leaves_Bottle"
    },
    {
      "x": 11,
      "y": 20,
      "z": 6,
      "name": "Plant_Leaves_Bottle"
    },
    {
      "x": 11,
      "y": 18,
      "z": 7,
      "name": "Wood_Gumboab_Branch_Long",
      "rotation": 5
    },
    {
      "x": 11,
      "y": 19,
      "z": 7,
      "name": "Plant_Leaves_Bottle"
    },
    {
      "x": 11,
      "y": 20,
      "z": 7,
      "name": "Plant_Leaves_Bottle"
    },
    {
      "x": 11,
      "y": 19,
      "z": 8,
      "name": "Plant_Leaves_Bottle"
    },
    {
      "x": 11,
      "y": 20,
      "z": 8,
      "name": "Plant_Leaves_Bottle"
    },
    {
      "x": 11,
      "y": 19,
      "z": 9,
      "name": "Plant_Leaves_Bottle"
    },
    {
      "x": 11,
      "y": 18,
      "z": 10,
      "name": "Plant_Leaves_Bottle"
    },
    {
      "x": 11,
      "y": 18,
      "z": 11,
      "name": "Plant_Leaves_Bottle"
    },
    {
      "x": 11,
      "y": 19,
      "z": 11,
      "name": "Plant_Leaves_Bottle"
    },
    {
      "x": 11,
      "y": 18,
      "z": 12,
      "name": "Wood_Gumboab_Branch_Long",
      "rotation": 5
    },
    {
      "x": 11,
      "y": 19,
      "z": 12,
      "name": "Plant_Leaves_Bottle"
    },
    {
      "x": 11,
      "y": 5,
      "z": 13,
      "name": "Wood_Gumboab_Trunk_Full"
    },
    {
      "x": 11,
      "y": 18,
      "z": 13,
      "name": "Plant_Leaves_Bottle"
    },
    {
      "x": 11,
      "y": 19,
      "z": 13,
      "name": "Plant_Leaves_Bottle"
    },
    {
      "x": 11,
      "y": 18,
      "z": 14,
      "name": "Plant_Leaves_Bottle"
    },
    {
      "x": 11,
      "y": 17,
      "z": 16,
      "name": "Wood_Gumboab_Trunk_Full"
    },
    {
      "x": 11,
      "y": 18,
      "z": 16,
      "name": "Wood_Gumboab_Trunk_Full"
    },
    {
      "x": 11,
      "y": 19,
      "z": 16,
      "name": "Plant_Leaves_Bottle"
    },
    {
      "x": 11,
      "y": 17,
      "z": 17,
      "name": "Wood_Gumboab_Branch_Long",
      "rotation": 4
    },
    {
      "x": 11,
      "y": 18,
      "z": 17,
      "name": "Plant_Leaves_Bottle"
    },
    {
      "x": 11,
      "y": 19,
      "z": 17,
      "name": "Plant_Leaves_Bottle"
    },
    {
      "x": 11,
      "y": 18,
      "z": 18,
      "name": "Plant_Leaves_Bottle"
    },
    {
      "x": 11,
      "y": 18,
      "z": 19,
      "name": "Plant_Leaves_Bottle"
    },
    {
      "x": 12,
      "y": 19,
      "z": 5,
      "name": "Plant_Leaves_Bottle"
    },
    {
      "x": 12,
      "y": 19,
      "z": 6,
      "name": "Plant_Leaves_Bottle"
    },
    {
      "x": 12,
      "y": 20,
      "z": 6,
      "name": "Plant_Leaves_Bottle"
    },
    {
      "x": 12,
      "y": 18,
      "z": 7,
      "name": "Wood_Gumboab_Trunk_Full"
    },
    {
      "x": 12,
      "y": 19,
      "z": 7,
      "name": "Wood_Gumboab_Trunk_Full"
    },
    {
      "x": 12,
      "y": 20,
      "z": 7,
      "name": "Plant_Leaves_Bottle"
    },
    {
      "x": 12,
      "y": 18,
      "z": 8,
      "name": "Wood_Gumboab_Trunk_Full"
    },
    {
      "x": 12,
      "y": 20,
      "z": 8,
      "name": "Plant_Leaves_Bottle"
    },
    {
      "x": 12,
      "y": 20,
      "z": 9,
      "name": "Plant_Leaves_Bottle"
    },
    {
      "x": 12,
      "y": 19,
      "z": 10,
      "name": "Plant_Leaves_Bottle"
    },
    {
      "x": 12,
      "y": 18,
      "z": 11,
      "name": "Plant_Leaves_Bottle"
    },
    {
      "x": 12,
      "y": 19,
      "z": 11,
      "name": "Plant_Leaves_Bottle"
    },
    {
      "x": 12,
      "y": 17,
      "z": 12,
      "name": "Wood_Gumboab_Trunk_Full"
    },
    {
      "x": 12,
      "y": 18,
      "z": 12,
      "name": "Wood_Gumboab_Trunk_Full"
    },
    {
      "x": 12,
      "y": 5,
      "z": 13,
      "name": "Wood_Gumboab_Trunk_Full"
    },
    {
      "x": 12,
      "y": 16,
      "z": 13,
      "name": "Wood_Gumboab_Trunk_Full"
    },
    {
      "x": 12,
      "y": 17,
      "z": 13,
      "name": "Wood_Gumboab_Trunk_Full"
    },
    {
      "x": 12,
      "y": 21,
      "z": 13,
      "name": "Plant_Leaves_Bottle"
    },
    {
      "x": 12,
      "y": 16,
      "z": 14,
      "name": "Wood_Gumboab_Trunk_Full"
    },
    {
      "x": 12,
      "y": 17,
      "z": 14,
      "name": "Wood_Gumboab_Trunk_Full"
    },
    {
      "x": 12,
      "y": 21,
      "z": 14,
      "name": "Plant_Leaves_Bottle"
    },
    {
      "x": 12,
      "y": 22,
      "z": 14,
      "name": "Plant_Leaves_Bottle"
    },
    {
      "x": 12,
      "y": 17,
      "z": 15,
      "name": "Wood_Gumboab_Trunk_Full"
    },
    {
      "x": 12,
      "y": 19,
      "z": 15,
      "name": "Plant_Leaves_Bottle"
    },
    {
      "x": 12,
      "y": 21,
      "z": 15,
      "name": "Plant_Leaves_Bottle"
    },
    {
      "x": 12,
      "y": 17,
      "z": 16,
      "name": "Wood_Gumboab_Trunk_Full"
    },
    {
      "x": 12,
      "y": 19,
      "z": 16,
      "name": "Plant_Leaves_Bottle"
    },
    {
      "x": 12,
      "y": 18,
      "z": 17,
      "name": "Plant_Leaves_Bottle"
    },
    {
      "x": 12,
      "y": 19,
      "z": 17,
      "name": "Plant_Leaves_Bottle"
    },
    {
      "x": 12,
      "y": 18,
      "z": 18,
      "name": "Plant_Leaves_Bottle"
    },
    {
      "x": 12,
      "y": 18,
      "z": 19,
      "name": "Plant_Leaves_Bottle"
    },
    {
      "x": 13,
      "y": 19,
      "z": 6,
      "name": "Plant_Leaves_Bottle"
    },
    {
      "x": 13,
      "y": 17,
      "z": 8,
      "name": "Wood_Gumboab_Trunk_Full"
    },
    {
      "x": 13,
      "y": 18,
      "z": 8,
      "name": "Wood_Gumboab_Trunk_Full"
    },
    {
      "x": 13,
      "y": 20,
      "z": 8,
      "name": "Plant_Leaves_Bottle"
    },
    {
      "x": 13,
      "y": 9,
      "z": 10,
      "name": "Wood_Gumboab_Trunk_Full"
    },
    {
      "x": 13,
      "y": 10,
      "z": 10,
      "name": "Wood_Gumboab_Trunk_Full"
    },
    {
      "x": 13,
      "y": 8,
      "z": 11,
      "name": "Wood_Gumboab_Trunk_Full"
    },
    {
      "x": 13,
      "y": 9,
      "z": 11,
      "name": "Wood_Gumboab_Trunk"
    },
    {
      "x": 13,
      "y": 10,
      "z": 11,
      "name": "Wood_Gumboab_Trunk_Full"
    },
    {
      "x": 13,
      "y": 5,
      "z": 12,
      "name": "Wood_Gumboab_Trunk_Full"
    },
    {
      "x": 13,
      "y": 6,
      "z": 12,
      "name": "Wood_Gumboab_Trunk_Full"
    },
    {
      "x": 13,
      "y": 8,
      "z": 12,
      "name": "Wood_Gumboab_Trunk_Full"
    },
    {
      "x": 13,
      "y": 9,
      "z": 12,
      "name": "Wood_Gumboab_Trunk_Full"
    },
    {
      "x": 13,
      "y": 21,
      "z": 12,
      "name": "Plant_Leaves_Bottle"
    },
    {
      "x": 13,
      "y": 5,
      "z": 13,
      "name": "Wood_Gumboab_Trunk_Full"
    },
    {
      "x": 13,
      "y": 6,
      "z": 13,
      "name": "Wood_Gumboab_Trunk"
    },
    {
      "x": 13,
      "y": 7,
      "z": 13,
      "name": "Wood_Gumboab_Trunk_Full"
    },
    {
      "x": 13,
      "y": 21,
      "z": 13,
      "name": "Wood_Gumboab_Trunk_Full"
    },
    {
      "x": 13,
      "y": 22,
      "z": 13,
      "name": "Plant_Leaves_Bottle"
    },
    {
      "x": 13,
      "y": 16,
      "z": 14,
      "name": "Wood_Gumboab_Trunk_Full"
    },
    {
      "x": 13,
      "y": 21,
      "z": 14,
      "name": "Plant_Leaves_Bottle"
    },
    {
      "x": 13,
      "y": 22,
      "z": 14,
      "name": "Plant_Leaves_Bottle"
    },
    {
      "x": 13,
      "y": 21,
      "z": 15,
      "name": "Plant_Leaves_Bottle"
    },
    {
      "x": 13,
      "y": 22,
      "z": 15,
      "name": "Plant_Leaves_Bottle"
    },
    {
      "x": 13,
      "y": 19,
      "z": 16,
      "name": "Plant_Leaves_Bottle"
    },
    {
      "x": 13,
      "y": 21,
      "z": 16,
      "name": "Plant_Leaves_Bottle"
    },
    {
      "x": 13,
      "y": 18,
      "z": 17,
      "name": "Plant_Leaves_Bottle"
    },
    {
      "x": 13,
      "y": 20,
      "z": 17,
      "name": "Plant_Leaves_Bottle"
    },
    {
      "x": 13,
      "y": 21,
      "z": 17,
      "name": "Plant_Leaves_Bottle"
    },
    {
      "x": 14,
      "y": 19,
      "z": 7,
      "name": "Plant_Leaves_Bottle"
    },
    {
      "x": 14,
      "y": 17,
      "z": 8,
      "name": "Wood_Gumboab_Trunk_Full"
    },
    {
      "x": 14,
      "y": 17,
      "z": 9,
      "name": "Wood_Gumboab_Trunk_Full"
    },
    {
      "x": 14,
      "y": 8,
      "z": 10,
      "name": "Wood_Gumboab_Trunk_Full"
    },
    {
      "x": 14,
      "y": 9,
      "z": 10,
      "name": "Wood_Gumboab_Trunk"
    },
    {
      "x": 14,
      "y": 10,
      "z": 10,
      "name": "Wood_Gumboab_Trunk"
    },
    {
      "x": 14,
      "y": 11,
      "z": 10,
      "name": "Wood_Gumboab_Trunk_Full"
    },
    {
      "x": 14,
      "y": 17,
      "z": 10,
      "name": "Wood_Gumboab_Trunk_Full"
    },
    {
      "x": 14,
      "y": 7,
      "z": 11,
      "name": "Wood_Gumboab_Trunk_Full"
    },
    {
      "x": 14,
      "y": 8,
      "z": 11,
      "name": "Wood_Gumboab_Trunk"
    },
    {
      "x": 14,
      "y": 9,
      "z": 11,
      "name": "Wood_Gumboab_Trunk"
    },
    {
      "x": 14,
      "y": 10,
      "z": 11,
      "name": "Wood_Gumboab_Trunk"
    },
    {
      "x": 14,
      "y": 11,
      "z": 11,
      "name": "Wood_Gumboab_Trunk"
    },
    {
      "x": 14,
      "y": 12,
      "z": 11,
      "name": "Wood_Gumboab_Trunk"
    },
    {
      "x": 14,
      "y": 13,
      "z": 11,
      "name": "Wood_Gumboab_Trunk"
    },
    {
      "x": 14,
      "y": 14,
      "z": 11,
      "name": "Wood_Gumboab_Trunk"
    },
    {
      "x": 14,
      "y": 15,
      "z": 11,
      "name": "Wood_Gumboab_Trunk_Full"
    },
    {
      "x": 14,
      "y": 6,
      "z": 12,
      "name": "Wood_Gumboab_Trunk_Full"
    },
    {
      "x": 14,
      "y": 7,
      "z": 12,
      "name": "Wood_Gumboab_Trunk"
    },
    {
      "x": 14,
      "y": 8,
      "z": 12,
      "name": "Wood_Gumboab_Trunk"
    },
    {
      "x": 14,
      "y": 9,
      "z": 12,
      "name": "Wood_Gumboab_Trunk"
    },
    {
      "x": 14,
      "y": 10,
      "z": 12,
      "name": "Wood_Gumboab_Trunk"
    },
    {
      "x": 14,
      "y": 11,
      "z": 12,
      "name": "Wood_Gumboab_Trunk"
    },
    {
      "x": 14,
      "y": 12,
      "z": 12,
      "name": "Wood_Gumboab_Trunk"
    },
    {
      "x": 14,
      "y": 13,
      "z": 12,
      "name": "Wood_Gumboab_Trunk"
    },
    {
      "x": 14,
      "y": 14,
      "z": 12,
      "name": "Wood_Gumboab_Trunk"
    },
    {
      "x": 14,
      "y": 15,
      "z": 12,
      "name": "Wood_Gumboab_Trunk"
    },
    {
      "x": 14,
      "y": 16,
      "z": 12,
      "name": "Wood_Gumboab_Trunk"
    },
    {
      "x": 14,
      "y": 17,
      "z": 12,
      "name": "Wood_Gumboab_Trunk_Full"
    },
    {
      "x": 14,
      "y": 21,
      "z": 12,
      "name": "Plant_Leaves_Bottle"
    },
    {
      "x": 14,
      "y": 22,
      "z": 12,
      "name": "Plant_Leaves_Bottle"
    },
    {
      "x": 14,
      "y": 7,
      "z": 13,
      "name": "Wood_Gumboab_Trunk_Full"
    },
    {
      "x": 14,
      "y": 8,
      "z": 13,
      "name": "Wood_Gumboab_Trunk_Full"
    },
    {
      "x": 14,
      "y": 10,
      "z": 13,
      "name": "Wood_Gumboab_Trunk"
    },
    {
      "x": 14,
      "y": 11,
      "z": 13,
      "name": "Wood_Gumboab_Trunk"
    },
    {
      "x": 14,
      "y": 12,
      "z": 13,
      "name": "Wood_Gumboab_Trunk"
    },
    {
      "x": 14,
      "y": 13,
      "z": 13,
      "name": "Wood_Gumboab_Trunk"
    },
    {
      "x": 14,
      "y": 14,
      "z": 13,
      "name": "Wood_Gumboab_Trunk"
    },
    {
      "x": 14,
      "y": 15,
      "z": 13,
      "name": "Wood_Gumboab_Trunk"
    },
    {
      "x": 14,
      "y": 16,
      "z": 13,
      "name": "Wood_Gumboab_Trunk_Full"
    },
    {
      "x": 14,
      "y": 17,
      "z": 13,
      "name": "Wood_Gumboab_Trunk_Full"
    },
    {
      "x": 14,
      "y": 20,
      "z": 13,
      "name": "Wood_Gumboab_Trunk_Full"
    },
    {
      "x": 14,
      "y": 21,
      "z": 13,
      "name": "Wood_Gumboab_Trunk_Full"
    },
    {
      "x": 14,
      "y": 22,
      "z": 13,
      "name": "Plant_Leaves_Bottle"
    },
    {
      "x": 14,
      "y": 15,
      "z": 14,
      "name": "Wood_Gumboab_Trunk_Full"
    },
    {
      "x": 14,
      "y": 16,
      "z": 14,
      "name": "Wood_Gumboab_Trunk_Full"
    },
    {
      "x": 14,
      "y": 21,
      "z": 14,
      "name": "Wood_Gumboab_Trunk_Full"
    },
    {
      "x": 14,
      "y": 22,
      "z": 14,
      "name": "Plant_Leaves_Bottle"
    },
    {
      "x": 14,
      "y": 21,
      "z": 15,
      "name": "Wood_Gumboab_Trunk_Full"
    },
    {
      "x": 14,
      "y": 22,
      "z": 15,
      "name": "Plant_Leaves_Bottle"
    },
    {
      "x": 14,
      "y": 20,
      "z": 16,
      "name": "Plant_Leaves_Bottle"
    },
    {
      "x": 14,
      "y": 21,
      "z": 16,
      "name": "Wood_Gumboab_Branch_Long",
      "rotation": 4
    },
    {
      "x": 14,
      "y": 22,
      "z": 16,
      "name": "Plant_Leaves_Bottle"
    },
    {
      "x": 14,
      "y": 20,
      "z": 17,
      "name": "Plant_Leaves_Bottle"
    },
    {
      "x": 14,
      "y": 21,
      "z": 17,
      "name": "Plant_Leaves_Bottle"
    },
    {
      "x": 14,
      "y": 20,
      "z": 18,
      "name": "Plant_Leaves_Bottle"
    },
    {
      "x": 15,
      "y": 5,
      "z": 6,
      "name": "Wood_Gumboab_Roots"
    },
    {
      "x": 15,
      "y": 6,
      "z": 6,
      "name": "Wood_Gumboab_Trunk_Full"
    },
    {
      "x": 15,
      "y": 19,
      "z": 6,
      "name": "Plant_Leaves_Bottle"
    },
    {
      "x": 15,
      "y": 6,
      "z": 7,
      "name": "Wood_Gumboab_Trunk_Full"
    },
    {
      "x": 15,
      "y": 19,
      "z": 7,
      "name": "Plant_Leaves_Bottle"
    },
    {
      "x": 15,
      "y": 20,
      "z": 7,
      "name": "Plant_Leaves_Bottle"
    },
    {
      "x": 15,
      "y": 6,
      "z": 8,
      "name": "Wood_Gumboab_Trunk_Full"
    },
    {
      "x": 15,
      "y": 17,
      "z": 8,
      "name": "Wood_Gumboab_Trunk_Full"
    },
    {
      "x": 15,
      "y": 18,
      "z": 8,
      "name": "Wood_Gumboab_Trunk_Full"
    },
    {
      "x": 15,
      "y": 5,
      "z": 9,
      "name": "Wood_Gumboab_Trunk"
    },
    {
      "x": 15,
      "y": 6,
      "z": 9,
      "name": "Wood_Gumboab_Trunk_Full"
    },
    {
      "x": 15,
      "y": 7,
      "z": 9,
      "name": "Wood_Gumboab_Trunk_Full"
    },
    {
      "x": 15,
      "y": 6,
      "z": 10,
      "name": "Wood_Gumboab_Trunk_Full"
    },
    {
      "x": 15,
      "y": 7,
      "z": 10,
      "name": "Wood_Gumboab_Trunk"
    },
    {
      "x": 15,
      "y": 8,
      "z": 10,
      "name": "Wood_Gumboab_Trunk"
    },
    {
      "x": 15,
      "y": 9,
      "z": 10,
      "name": "Wood_Gumboab_Trunk"
    },
    {
      "x": 15,
      "y": 10,
      "z": 10,
      "name": "Wood_Gumboab_Trunk"
    },
    {
      "x": 15,
      "y": 11,
      "z": 10,
      "name": "Wood_Gumboab_Trunk"
    },
    {
      "x": 15,
      "y": 12,
      "z": 10,
      "name": "Wood_Gumboab_Trunk"
    },
    {
      "x": 15,
      "y": 13,
      "z": 10,
      "name": "Wood_Gumboab_Trunk"
    },
    {
      "x": 15,
      "y": 14,
      "z": 10,
      "name": "Wood_Gumboab_Trunk"
    },
    {
      "x": 15,
      "y": 15,
      "z": 10,
      "name": "Wood_Gumboab_Trunk"
    },
    {
      "x": 15,
      "y": 16,
      "z": 10,
      "name": "Wood_Gumboab_Trunk_Full"
    },
    {
      "x": 15,
      "y": 17,
      "z": 10,
      "name": "Wood_Gumboab_Trunk_Full"
    },
    {
      "x": 15,
      "y": 18,
      "z": 10,
      "name": "Wood_Gumboab_Trunk_Full"
    },
    {
      "x": 15,
      "y": 6,
      "z": 11,
      "name": "Wood_Gumboab_Trunk_Full"
    },
    {
      "x": 15,
      "y": 7,
      "z": 11,
      "name": "Wood_Gumboab_Trunk"
    },
    {
      "x": 15,
      "y": 8,
      "z": 11,
      "name": "Wood_Gumboab_Trunk"
    },
    {
      "x": 15,
      "y": 9,
      "z": 11,
      "name": "Wood_Gumboab_Trunk"
    },
    {
      "x": 15,
      "y": 10,
      "z": 11,
      "name": "Wood_Gumboab_Trunk"
    },
    {
      "x": 15,
      "y": 11,
      "z": 11,
      "name": "Wood_Gumboab_Trunk"
    },
    {
      "x": 15,
      "y": 12,
      "z": 11,
      "name": "Wood_Gumboab_Trunk"
    },
    {
      "x": 15,
      "y": 13,
      "z": 11,
      "name": "Wood_Gumboab_Trunk"
    },
    {
      "x": 15,
      "y": 14,
      "z": 11,
      "name": "Wood_Gumboab_Trunk"
    },
    {
      "x": 15,
      "y": 15,
      "z": 11,
      "name": "Wood_Gumboab_Trunk"
    },
    {
      "x": 15,
      "y": 16,
      "z": 11,
      "name": "Wood_Gumboab_Trunk"
    },
    {
      "x": 15,
      "y": 17,
      "z": 11,
      "name": "Wood_Gumboab_Trunk_Full"
    },
    {
      "x": 15,
      "y": 6,
      "z": 12,
      "name": "Wood_Gumboab_Trunk_Full"
    },
    {
      "x": 15,
      "y": 7,
      "z": 12,
      "name": "Wood_Gumboab_Trunk"
    },
    {
      "x": 15,
      "y": 8,
      "z": 12,
      "name": "Wood_Gumboab_Trunk"
    },
    {
      "x": 15,
      "y": 9,
      "z": 12,
      "name": "Wood_Gumboab_Trunk"
    },
    {
      "x": 15,
      "y": 10,
      "z": 12,
      "name": "Wood_Gumboab_Trunk"
    },
    {
      "x": 15,
      "y": 11,
      "z": 12,
      "name": "Wood_Gumboab_Trunk"
    },
    {
      "x": 15,
      "y": 12,
      "z": 12,
      "name": "Wood_Gumboab_Trunk"
    },
    {
      "x": 15,
      "y": 13,
      "z": 12,
      "name": "Wood_Gumboab_Trunk"
    },
    {
      "x": 15,
      "y": 14,
      "z": 12,
      "name": "Wood_Gumboab_Trunk"
    },
    {
      "x": 15,
      "y": 15,
      "z": 12,
      "name": "Wood_Gumboab_Trunk"
    },
    {
      "x": 15,
      "y": 16,
      "z": 12,
      "name": "Wood_Gumboab_Trunk"
    },
    {
      "x": 15,
      "y": 17,
      "z": 12,
      "name": "Wood_Gumboab_Trunk"
    },
    {
      "x": 15,
      "y": 18,
      "z": 12,
      "name": "Wood_Gumboab_Trunk_Full"
    },
    {
      "x": 15,
      "y": 6,
      "z": 13,
      "name": "Wood_Gumboab_Trunk_Full"
    },
    {
      "x": 15,
      "y": 7,
      "z": 13,
      "name": "Wood_Gumboab_Trunk"
    },
    {
      "x": 15,
      "y": 8,
      "z": 13,
      "name": "Wood_Gumboab_Trunk"
    },
    {
      "x": 15,
      "y": 9,
      "z": 13,
      "name": "Wood_Gumboab_Trunk"
    },
    {
      "x": 15,
      "y": 10,
      "z": 13,
      "name": "Wood_Gumboab_Trunk"
    },
    {
      "x": 15,
      "y": 11,
      "z": 13,
      "name": "Wood_Gumboab_Trunk"
    },
    {
      "x": 15,
      "y": 12,
      "z": 13,
      "name": "Wood_Gumboab_Trunk"
    },
    {
      "x": 15,
      "y": 13,
      "z": 13,
      "name": "Wood_Gumboab_Trunk"
    },
    {
      "x": 15,
      "y": 14,
      "z": 13,
      "name": "Wood_Gumboab_Trunk"
    },
    {
      "x": 15,
      "y": 15,
      "z": 13,
      "name": "Wood_Gumboab_Trunk"
    },
    {
      "x": 15,
      "y": 16,
      "z": 13,
      "name": "Wood_Gumboab_Trunk_Full"
    },
    {
      "x": 15,
      "y": 17,
      "z": 13,
      "name": "Wood_Gumboab_Trunk"
    },
    {
      "x": 15,
      "y": 18,
      "z": 13,
      "name": "Wood_Gumboab_Trunk"
    },
    {
      "x": 15,
      "y": 19,
      "z": 13,
      "name": "Wood_Gumboab_Trunk"
    },
    {
      "x": 15,
      "y": 20,
      "z": 13,
      "name": "Wood_Gumboab_Trunk_Full"
    },
    {
      "x": 15,
      "y": 10,
      "z": 14,
      "name": "Wood_Gumboab_Trunk_Full"
    },
    {
      "x": 15,
      "y": 11,
      "z": 14,
      "name": "Wood_Gumboab_Trunk"
    },
    {
      "x": 15,
      "y": 12,
      "z": 14,
      "name": "Wood_Gumboab_Trunk"
    },
    {
      "x": 15,
      "y": 13,
      "z": 14,
      "name": "Wood_Gumboab_Trunk"
    },
    {
      "x": 15,
      "y": 14,
      "z": 14,
      "name": "Wood_Gumboab_Trunk_Full"
    },
    {
      "x": 15,
      "y": 21,
      "z": 14,
      "name": "Plant_Leaves_Bottle"
    },
    {
      "x": 15,
      "y": 22,
      "z": 14,
      "name": "Plant_Leaves_Bottle"
    },
    {
      "x": 15,
      "y": 21,
      "z": 15,
      "name": "Plant_Leaves_Bottle"
    },
    {
      "x": 15,
      "y": 22,
      "z": 15,
      "name": "Plant_Leaves_Bottle"
    },
    {
      "x": 15,
      "y": 19,
      "z": 16,
      "name": "Wood_Gumboab_Trunk_Full"
    },
    {
      "x": 15,
      "y": 20,
      "z": 16,
      "name": "Wood_Gumboab_Trunk_Full"
    },
    {
      "x": 15,
      "y": 21,
      "z": 16,
      "name": "Plant_Leaves_Bottle"
    },
    {
      "x": 15,
      "y": 20,
      "z": 17,
      "name": "Wood_Gumboab_Branch_Long",
      "rotation": 4
    },
    {
      "x": 15,
      "y": 21,
      "z": 17,
      "name": "Plant_Leaves_Bottle"
    },
    {
      "x": 15,
      "y": 20,
      "z": 18,
      "name": "Plant_Leaves_Bottle"
    },
    {
      "x": 16,
      "y": 19,
      "z": 6,
      "name": "Plant_Leaves_Bottle"
    },
    {
      "x": 16,
      "y": 19,
      "z": 7,
      "name": "Wood_Gumboab_Branch_Long",
      "rotation": 4
    },
    {
      "x": 16,
      "y": 20,
      "z": 7,
      "name": "Plant_Leaves_Bottle"
    },
    {
      "x": 16,
      "y": 18,
      "z": 8,
      "name": "Wood_Gumboab_Trunk_Full"
    },
    {
      "x": 16,
      "y": 19,
      "z": 8,
      "name": "Wood_Gumboab_Trunk_Full"
    },
    {
      "x": 16,
      "y": 21,
      "z": 8,
      "name": "Plant_Leaves_Bottle"
    },
    {
      "x": 16,
      "y": 21,
      "z": 9,
      "name": "Plant_Leaves_Bottle"
    },
    {
      "x": 16,
      "y": 22,
      "z": 9,
      "name": "Plant_Leaves_Bottle"
    },
    {
      "x": 16,
      "y": 7,
      "z": 10,
      "name": "Wood_Gumboab_Trunk_Full"
    },
    {
      "x": 16,
      "y": 8,
      "z": 10,
      "name": "Wood_Gumboab_Trunk"
    },
    {
      "x": 16,
      "y": 9,
      "z": 10,
      "name": "Wood_Gumboab_Trunk"
    },
    {
      "x": 16,
      "y": 10,
      "z": 10,
      "name": "Wood_Gumboab_Trunk"
    },
    {
      "x": 16,
      "y": 11,
      "z": 10,
      "name": "Wood_Gumboab_Trunk"
    },
    {
      "x": 16,
      "y": 12,
      "z": 10,
      "name": "Wood_Gumboab_Trunk"
    },
    {
      "x": 16,
      "y": 13,
      "z": 10,
      "name": "Wood_Gumboab_Trunk"
    },
    {
      "x": 16,
      "y": 14,
      "z": 10,
      "name": "Wood_Gumboab_Trunk"
    },
    {
      "x": 16,
      "y": 15,
      "z": 10,
      "name": "Wood_Gumboab_Trunk"
    },
    {
      "x": 16,
      "y": 16,
      "z": 10,
      "name": "Wood_Gumboab_Trunk"
    },
    {
      "x": 16,
      "y": 17,
      "z": 10,
      "name": "Wood_Gumboab_Trunk_Full"
    },
    {
      "x": 16,
      "y": 21,
      "z": 10,
      "name": "Plant_Leaves_Bottle"
    },
    {
      "x": 16,
      "y": 22,
      "z": 10,
      "name": "Plant_Leaves_Bottle"
    },
    {
      "x": 16,
      "y": 6,
      "z": 11,
      "name": "Wood_Gumboab_Trunk_Full"
    },
    {
      "x": 16,
      "y": 7,
      "z": 11,
      "name": "Wood_Gumboab_Trunk"
    },
    {
      "x": 16,
      "y": 8,
      "z": 11,
      "name": "Wood_Gumboab_Trunk"
    },
    {
      "x": 16,
      "y": 9,
      "z": 11,
      "name": "Wood_Gumboab_Trunk"
    },
    {
      "x": 16,
      "y": 10,
      "z": 11,
      "name": "Wood_Gumboab_Trunk"
    },
    {
      "x": 16,
      "y": 11,
      "z": 11,
      "name": "Wood_Gumboab_Trunk"
    },
    {
      "x": 16,
      "y": 12,
      "z": 11,
      "name": "Wood_Gumboab_Trunk"
    },
    {
      "x": 16,
      "y": 13,
      "z": 11,
      "name": "Wood_Gumboab_Trunk"
    },
    {
      "x": 16,
      "y": 14,
      "z": 11,
      "name": "Wood_Gumboab_Trunk"
    },
    {
      "x": 16,
      "y": 15,
      "z": 11,
      "name": "Wood_Gumboab_Trunk"
    },
    {
      "x": 16,
      "y": 16,
      "z": 11,
      "name": "Wood_Gumboab_Trunk"
    },
    {
      "x": 16,
      "y": 17,
      "z": 11,
      "name": "Wood_Gumboab_Trunk"
    },
    {
      "x": 16,
      "y": 18,
      "z": 11,
      "name": "Wood_Gumboab_Trunk"
    },
    {
      "x": 16,
      "y": 19,
      "z": 11,
      "name": "Wood_Gumboab_Trunk"
    },
    {
      "x": 16,
      "y": 20,
      "z": 11,
      "name": "Wood_Gumboab_Trunk_Full"
    },
    {
      "x": 16,
      "y": 6,
      "z": 12,
      "name": "Wood_Gumboab_Trunk_Full"
    },
    {
      "x": 16,
      "y": 7,
      "z": 12,
      "name": "Wood_Gumboab_Trunk"
    },
    {
      "x": 16,
      "y": 8,
      "z": 12,
      "name": "Wood_Gumboab_Trunk"
    },
    {
      "x": 16,
      "y": 9,
      "z": 12,
      "name": "Wood_Gumboab_Trunk"
    },
    {
      "x": 16,
      "y": 10,
      "z": 12,
      "name": "Wood_Gumboab_Trunk"
    },
    {
      "x": 16,
      "y": 11,
      "z": 12,
      "name": "Wood_Gumboab_Trunk"
    },
    {
      "x": 16,
      "y": 12,
      "z": 12,
      "name": "Wood_Gumboab_Trunk"
    },
    {
      "x": 16,
      "y": 13,
      "z": 12,
      "name": "Wood_Gumboab_Trunk"
    },
    {
      "x": 16,
      "y": 14,
      "z": 12,
      "name": "Wood_Gumboab_Trunk"
    },
    {
      "x": 16,
      "y": 15,
      "z": 12,
      "name": "Wood_Gumboab_Trunk"
    },
    {
      "x": 16,
      "y": 16,
      "z": 12,
      "name": "Wood_Gumboab_Trunk"
    },
    {
      "x": 16,
      "y": 17,
      "z": 12,
      "name": "Wood_Gumboab_Trunk"
    },
    {
      "x": 16,
      "y": 18,
      "z": 12,
      "name": "Wood_Gumboab_Trunk_Full"
    },
    {
      "x": 16,
      "y": 6,
      "z": 13,
      "name": "Wood_Gumboab_Trunk_Full"
    },
    {
      "x": 16,
      "y": 7,
      "z": 13,
      "name": "Wood_Gumboab_Trunk"
    },
    {
      "x": 16,
      "y": 8,
      "z": 13,
      "name": "Wood_Gumboab_Trunk"
    },
    {
      "x": 16,
      "y": 9,
      "z": 13,
      "name": "Wood_Gumboab_Trunk"
    },
    {
      "x": 16,
      "y": 10,
      "z": 13,
      "name": "Wood_Gumboab_Trunk"
    },
    {
      "x": 16,
      "y": 11,
      "z": 13,
      "name": "Wood_Gumboab_Trunk"
    },
    {
      "x": 16,
      "y": 12,
      "z": 13,
      "name": "Wood_Gumboab_Trunk"
    },
    {
      "x": 16,
      "y": 13,
      "z": 13,
      "name": "Wood_Gumboab_Trunk"
    },
    {
      "x": 16,
      "y": 14,
      "z": 13,
      "name": "Wood_Gumboab_Trunk"
    },
    {
      "x": 16,
      "y": 15,
      "z": 13,
      "name": "Wood_Gumboab_Trunk"
    },
    {
      "x": 16,
      "y": 16,
      "z": 13,
      "name": "Wood_Gumboab_Trunk"
    },
    {
      "x": 16,
      "y": 17,
      "z": 13,
      "name": "Wood_Gumboab_Trunk"
    },
    {
      "x": 16,
      "y": 18,
      "z": 13,
      "name": "Wood_Gumboab_Trunk_Full"
    },
    {
      "x": 16,
      "y": 7,
      "z": 14,
      "name": "Wood_Gumboab_Trunk_Full"
    },
    {
      "x": 16,
      "y": 9,
      "z": 14,
      "name": "Wood_Gumboab_Trunk_Full"
    },
    {
      "x": 16,
      "y": 10,
      "z": 14,
      "name": "Wood_Gumboab_Trunk"
    },
    {
      "x": 16,
      "y": 11,
      "z": 14,
      "name": "Wood_Gumboab_Trunk"
    },
    {
      "x": 16,
      "y": 12,
      "z": 14,
      "name": "Wood_Gumboab_Trunk"
    },
    {
      "x": 16,
      "y": 13,
      "z": 14,
      "name": "Wood_Gumboab_Trunk"
    },
    {
      "x": 16,
      "y": 14,
      "z": 14,
      "name": "Wood_Gumboab_Trunk"
    },
    {
      "x": 16,
      "y": 15,
      "z": 14,
      "name": "Wood_Gumboab_Trunk"
    },
    {
      "x": 16,
      "y": 16,
      "z": 14,
      "name": "Wood_Gumboab_Trunk_Full"
    },
    {
      "x": 16,
      "y": 18,
      "z": 14,
      "name": "Wood_Gumboab_Trunk_Full"
    },
    {
      "x": 16,
      "y": 19,
      "z": 14,
      "name": "Wood_Gumboab_Trunk_Full"
    },
    {
      "x": 16,
      "y": 19,
      "z": 16,
      "name": "Wood_Gumboab_Trunk_Full"
    },
    {
      "x": 16,
      "y": 20,
      "z": 17,
      "name": "Plant_Leaves_Bottle"
    },
    {
      "x": 16,
      "y": 21,
      "z": 17,
      "name": "Plant_Leaves_Bottle"
    },
    {
      "x": 16,
      "y": 20,
      "z": 18,
      "name": "Plant_Leaves_Bottle"
    },
    {
      "x": 17,
      "y": 19,
      "z": 6,
      "name": "Plant_Leaves_Bottle"
    },
    {
      "x": 17,
      "y": 19,
      "z": 7,
      "name": "Plant_Leaves_Bottle"
    },
    {
      "x": 17,
      "y": 20,
      "z": 7,
      "name": "Plant_Leaves_Bottle"
    },
    {
      "x": 17,
      "y": 21,
      "z": 7,
      "name": "Plant_Leaves_Bottle"
    },
    {
      "x": 17,
      "y": 19,
      "z": 8,
      "name": "Plant_Leaves_Bottle"
    },
    {
      "x": 17,
      "y": 20,
      "z": 8,
      "name": "Plant_Leaves_Bottle"
    },
    {
      "x": 17,
      "y": 21,
      "z": 8,
      "name": "Wood_Gumboab_Branch_Long",
      "rotation": 4
    },
    {
      "x": 17,
      "y": 22,
      "z": 8,
      "name": "Plant_Leaves_Bottle"
    },
    {
      "x": 17,
      "y": 21,
      "z": 9,
      "name": "Wood_Gumboab_Trunk_Full"
    },
    {
      "x": 17,
      "y": 22,
      "z": 9,
      "name": "Plant_Leaves_Bottle"
    },
    {
      "x": 17,
      "y": 7,
      "z": 10,
      "name": "Wood_Gumboab_Trunk_Full"
    },
    {
      "x": 17,
      "y": 8,
      "z": 10,
      "name": "Wood_Gumboab_Trunk_Full"
    },
    {
      "x": 17,
      "y": 9,
      "z": 10,
      "name": "Wood_Gumboab_Trunk"
    },
    {
      "x": 17,
      "y": 10,
      "z": 10,
      "name": "Wood_Gumboab_Trunk"
    },
    {
      "x": 17,
      "y": 11,
      "z": 10,
      "name": "Wood_Gumboab_Trunk"
    },
    {
      "x": 17,
      "y": 12,
      "z": 10,
      "name": "Wood_Gumboab_Trunk"
    },
    {
      "x": 17,
      "y": 13,
      "z": 10,
      "name": "Wood_Gumboab_Trunk"
    },
    {
      "x": 17,
      "y": 14,
      "z": 10,
      "name": "Wood_Gumboab_Trunk"
    },
    {
      "x": 17,
      "y": 15,
      "z": 10,
      "name": "Wood_Gumboab_Trunk"
    },
    {
      "x": 17,
      "y": 16,
      "z": 10,
      "name": "Wood_Gumboab_Trunk_Full"
    },
    {
      "x": 17,
      "y": 21,
      "z": 10,
      "name": "Wood_Gumboab_Trunk_Full"
    },
    {
      "x": 17,
      "y": 22,
      "z": 10,
      "name": "Plant_Leaves_Bottle"
    },
    {
      "x": 17,
      "y": 5,
      "z": 11,
      "name": "Wood_Gumboab_Trunk_Full"
    },
    {
      "x": 17,
      "y": 6,
      "z": 11,
      "name": "Wood_Gumboab_Trunk"
    },
    {
      "x": 17,
      "y": 7,
      "z": 11,
      "name": "Wood_Gumboab_Trunk"
    },
    {
      "x": 17,
      "y": 8,
      "z": 11,
      "name": "Wood_Gumboab_Trunk"
    },
    {
      "x": 17,
      "y": 9,
      "z": 11,
      "name": "Wood_Gumboab_Trunk"
    },
    {
      "x": 17,
      "y": 10,
      "z": 11,
      "name": "Wood_Gumboab_Trunk"
    },
    {
      "x": 17,
      "y": 11,
      "z": 11,
      "name": "Wood_Gumboab_Trunk"
    },
    {
      "x": 17,
      "y": 12,
      "z": 11,
      "name": "Wood_Gumboab_Trunk"
    },
    {
      "x": 17,
      "y": 13,
      "z": 11,
      "name": "Wood_Gumboab_Trunk"
    },
    {
      "x": 17,
      "y": 14,
      "z": 11,
      "name": "Wood_Gumboab_Trunk"
    },
    {
      "x": 17,
      "y": 15,
      "z": 11,
      "name": "Wood_Gumboab_Trunk"
    },
    {
      "x": 17,
      "y": 16,
      "z": 11,
      "name": "Wood_Gumboab_Trunk"
    },
    {
      "x": 17,
      "y": 17,
      "z": 11,
      "name": "Wood_Gumboab_Trunk_Full"
    },
    {
      "x": 17,
      "y": 18,
      "z": 11,
      "name": "Wood_Gumboab_Trunk_Full"
    },
    {
      "x": 17,
      "y": 20,
      "z": 11,
      "name": "Wood_Gumboab_Trunk_Full"
    },
    {
      "x": 17,
      "y": 21,
      "z": 11,
      "name": "Wood_Gumboab_Trunk_Full"
    },
    {
      "x": 17,
      "y": 22,
      "z": 11,
      "name": "Plant_Leaves_Bottle"
    },
    {
      "x": 17,
      "y": 6,
      "z": 12,
      "name": "Wood_Gumboab_Trunk_Full"
    },
    {
      "x": 17,
      "y": 7,
      "z": 12,
      "name": "Wood_Gumboab_Trunk"
    },
    {
      "x": 17,
      "y": 8,
      "z": 12,
      "name": "Wood_Gumboab_Trunk"
    },
    {
      "x": 17,
      "y": 9,
      "z": 12,
      "name": "Wood_Gumboab_Trunk"
    },
    {
      "x": 17,
      "y": 10,
      "z": 12,
      "name": "Wood_Gumboab_Trunk"
    },
    {
      "x": 17,
      "y": 11,
      "z": 12,
      "name": "Wood_Gumboab_Trunk"
    },
    {
      "x": 17,
      "y": 12,
      "z": 12,
      "name": "Wood_Gumboab_Trunk"
    },
    {
      "x": 17,
      "y": 13,
      "z": 12,
      "name": "Wood_Gumboab_Trunk"
    },
    {
      "x": 17,
      "y": 14,
      "z": 12,
      "name": "Wood_Gumboab_Trunk"
    },
    {
      "x": 17,
      "y": 15,
      "z": 12,
      "name": "Wood_Gumboab_Trunk"
    },
    {
      "x": 17,
      "y": 16,
      "z": 12,
      "name": "Wood_Gumboab_Trunk"
    },
    {
      "x": 17,
      "y": 17,
      "z": 12,
      "name": "Wood_Gumboab_Trunk"
    },
    {
      "x": 17,
      "y": 18,
      "z": 12,
      "name": "Wood_Gumboab_Trunk_Full"
    },
    {
      "x": 17,
      "y": 21,
      "z": 12,
      "name": "Plant_Leaves_Bottle"
    },
    {
      "x": 17,
      "y": 22,
      "z": 12,
      "name": "Plant_Leaves_Bottle"
    },
    {
      "x": 17,
      "y": 6,
      "z": 13,
      "name": "Wood_Gumboab_Trunk_Full"
    },
    {
      "x": 17,
      "y": 7,
      "z": 13,
      "name": "Wood_Gumboab_Trunk"
    },
    {
      "x": 17,
      "y": 8,
      "z": 13,
      "name": "Wood_Gumboab_Trunk"
    },
    {
      "x": 17,
      "y": 9,
      "z": 13,
      "name": "Wood_Gumboab_Trunk"
    },
    {
      "x": 17,
      "y": 10,
      "z": 13,
      "name": "Wood_Gumboab_Trunk"
    },
    {
      "x": 17,
      "y": 11,
      "z": 13,
      "name": "Wood_Gumboab_Trunk"
    },
    {
      "x": 17,
      "y": 12,
      "z": 13,
      "name": "Wood_Gumboab_Trunk"
    },
    {
      "x": 17,
      "y": 13,
      "z": 13,
      "name": "Wood_Gumboab_Trunk"
    },
    {
      "x": 17,
      "y": 14,
      "z": 13,
      "name": "Wood_Gumboab_Trunk"
    },
    {
      "x": 17,
      "y": 15,
      "z": 13,
      "name": "Wood_Gumboab_Trunk"
    },
    {
      "x": 17,
      "y": 16,
      "z": 13,
      "name": "Wood_Gumboab_Trunk"
    },
    {
      "x": 17,
      "y": 17,
      "z": 13,
      "name": "Wood_Gumboab_Trunk_Full"
    },
    {
      "x": 17,
      "y": 6,
      "z": 14,
      "name": "Wood_Gumboab_Trunk_Full"
    },
    {
      "x": 17,
      "y": 7,
      "z": 14,
      "name": "Wood_Gumboab_Trunk_Full"
    },
    {
      "x": 17,
      "y": 9,
      "z": 14,
      "name": "Wood_Gumboab_Trunk_Full"
    },
    {
      "x": 17,
      "y": 10,
      "z": 14,
      "name": "Wood_Gumboab_Trunk"
    },
    {
      "x": 17,
      "y": 11,
      "z": 14,
      "name": "Wood_Gumboab_Trunk"
    },
    {
      "x": 17,
      "y": 12,
      "z": 14,
      "name": "Wood_Gumboab_Trunk"
    },
    {
      "x": 17,
      "y": 13,
      "z": 14,
      "name": "Wood_Gumboab_Trunk"
    },
    {
      "x": 17,
      "y": 14,
      "z": 14,
      "name": "Wood_Gumboab_Trunk"
    },
    {
      "x": 17,
      "y": 15,
      "z": 14,
      "name": "Wood_Gumboab_Trunk"
    },
    {
      "x": 17,
      "y": 16,
      "z": 14,
      "name": "Wood_Gumboab_Trunk_Full"
    },
    {
      "x": 17,
      "y": 19,
      "z": 14,
      "name": "Wood_Gumboab_Trunk_Full"
    },
    {
      "x": 17,
      "y": 5,
      "z": 15,
      "name": "Wood_Gumboab_Trunk_Full"
    },
    {
      "x": 17,
      "y": 6,
      "z": 15,
      "name": "Wood_Gumboab_Trunk"
    },
    {
      "x": 17,
      "y": 7,
      "z": 15,
      "name": "Wood_Gumboab_Trunk_Full"
    },
    {
      "x": 17,
      "y": 19,
      "z": 15,
      "name": "Wood_Gumboab_Trunk_Full"
    },
    {
      "x": 17,
      "y": 5,
      "z": 16,
      "name": "Wood_Gumboab_Trunk_Full"
    },
    {
      "x": 17,
      "y": 18,
      "z": 16,
      "name": "Plant_Leaves_Bottle"
    },
    {
      "x": 17,
      "y": 19,
      "z": 16,
      "name": "Wood_Gumboab_Trunk_Full"
    },
    {
      "x": 17,
      "y": 5,
      "z": 17,
      "name": "Wood_Gumboab_Trunk_Full"
    },
    {
      "x": 17,
      "y": 20,
      "z": 17,
      "name": "Plant_Leaves_Bottle"
    },
    {
      "x": 17,
      "y": 5,
      "z": 18,
      "name": "Wood_Gumboab_Trunk_Full"
    },
    {
      "x": 17,
      "y": 5,
      "z": 19,
      "name": "Wood_Gumboab_Trunk_Full"
    },
    {
      "x": 18,
      "y": 19,
      "z": 7,
      "name": "Plant_Leaves_Bottle"
    },
    {
      "x": 18,
      "y": 21,
      "z": 7,
      "name": "Plant_Leaves_Bottle"
    },
    {
      "x": 18,
      "y": 20,
      "z": 8,
      "name": "Plant_Leaves_Bottle"
    },
    {
      "x": 18,
      "y": 21,
      "z": 8,
      "name": "Plant_Leaves_Bottle"
    },
    {
      "x": 18,
      "y": 21,
      "z": 9,
      "name": "Plant_Leaves_Bottle"
    },
    {
      "x": 18,
      "y": 22,
      "z": 9,
      "name": "Plant_Leaves_Bottle"
    },
    {
      "x": 18,
      "y": 6,
      "z": 10,
      "name": "Wood_Gumboab_Trunk_Full"
    },
    {
      "x": 18,
      "y": 7,
      "z": 10,
      "name": "Wood_Gumboab_Trunk_Full"
    },
    {
      "x": 18,
      "y": 9,
      "z": 10,
      "name": "Wood_Gumboab_Trunk_Full"
    },
    {
      "x": 18,
      "y": 10,
      "z": 10,
      "name": "Wood_Gumboab_Trunk_Full"
    },
    {
      "x": 18,
      "y": 21,
      "z": 10,
      "name": "Plant_Leaves_Bottle"
    },
    {
      "x": 18,
      "y": 22,
      "z": 10,
      "name": "Plant_Leaves_Bottle"
    },
    {
      "x": 18,
      "y": 8,
      "z": 11,
      "name": "Wood_Gumboab_Trunk_Full"
    },
    {
      "x": 18,
      "y": 9,
      "z": 11,
      "name": "Wood_Gumboab_Trunk"
    },
    {
      "x": 18,
      "y": 10,
      "z": 11,
      "name": "Wood_Gumboab_Trunk"
    },
    {
      "x": 18,
      "y": 11,
      "z": 11,
      "name": "Wood_Gumboab_Trunk"
    },
    {
      "x": 18,
      "y": 12,
      "z": 11,
      "name": "Wood_Gumboab_Trunk"
    },
    {
      "x": 18,
      "y": 13,
      "z": 11,
      "name": "Wood_Gumboab_Trunk"
    },
    {
      "x": 18,
      "y": 14,
      "z": 11,
      "name": "Wood_Gumboab_Trunk"
    },
    {
      "x": 18,
      "y": 15,
      "z": 11,
      "name": "Wood_Gumboab_Trunk"
    },
    {
      "x": 18,
      "y": 16,
      "z": 11,
      "name": "Wood_Gumboab_Trunk"
    },
    {
      "x": 18,
      "y": 17,
      "z": 11,
      "name": "Wood_Gumboab_Trunk_Full"
    },
    {
      "x": 18,
      "y": 21,
      "z": 11,
      "name": "Wood_Gumboab_Trunk_Full"
    },
    {
      "x": 18,
      "y": 22,
      "z": 11,
      "name": "Plant_Leaves_Bottle"
    },
    {
      "x": 18,
      "y": 9,
      "z": 12,
      "name": "Wood_Gumboab_Trunk_Full"
    },
    {
      "x": 18,
      "y": 10,
      "z": 12,
      "name": "Wood_Gumboab_Trunk"
    },
    {
      "x": 18,
      "y": 11,
      "z": 12,
      "name": "Wood_Gumboab_Trunk"
    },
    {
      "x": 18,
      "y": 12,
      "z": 12,
      "name": "Wood_Gumboab_Trunk"
    },
    {
      "x": 18,
      "y": 13,
      "z": 12,
      "name": "Wood_Gumboab_Trunk"
    },
    {
      "x": 18,
      "y": 14,
      "z": 12,
      "name": "Wood_Gumboab_Trunk"
    },
    {
      "x": 18,
      "y": 15,
      "z": 12,
      "name": "Wood_Gumboab_Trunk"
    },
    {
      "x": 18,
      "y": 16,
      "z": 12,
      "name": "Wood_Gumboab_Trunk"
    },
    {
      "x": 18,
      "y": 17,
      "z": 12,
      "name": "Wood_Gumboab_Trunk_Full"
    },
    {
      "x": 18,
      "y": 18,
      "z": 12,
      "name": "Wood_Gumboab_Trunk_Full"
    },
    {
      "x": 18,
      "y": 21,
      "z": 12,
      "name": "Plant_Leaves_Bottle"
    },
    {
      "x": 18,
      "y": 10,
      "z": 13,
      "name": "Wood_Gumboab_Trunk_Full"
    },
    {
      "x": 18,
      "y": 11,
      "z": 13,
      "name": "Wood_Gumboab_Trunk"
    },
    {
      "x": 18,
      "y": 12,
      "z": 13,
      "name": "Wood_Gumboab_Trunk"
    },
    {
      "x": 18,
      "y": 13,
      "z": 13,
      "name": "Wood_Gumboab_Trunk"
    },
    {
      "x": 18,
      "y": 14,
      "z": 13,
      "name": "Wood_Gumboab_Trunk"
    },
    {
      "x": 18,
      "y": 15,
      "z": 13,
      "name": "Wood_Gumboab_Trunk"
    },
    {
      "x": 18,
      "y": 16,
      "z": 13,
      "name": "Wood_Gumboab_Trunk_Full"
    },
    {
      "x": 18,
      "y": 17,
      "z": 13,
      "name": "Wood_Gumboab_Trunk_Full"
    },
    {
      "x": 18,
      "y": 18,
      "z": 13,
      "name": "Wood_Gumboab_Trunk_Full"
    },
    {
      "x": 18,
      "y": 16,
      "z": 14,
      "name": "Wood_Gumboab_Trunk_Full"
    },
    {
      "x": 18,
      "y": 17,
      "z": 14,
      "name": "Wood_Gumboab_Trunk_Full"
    },
    {
      "x": 18,
      "y": 18,
      "z": 14,
      "name": "Wood_Gumboab_Trunk_Full"
    },
    {
      "x": 18,
      "y": 19,
      "z": 14,
      "name": "Plant_Leaves_Bottle"
    },
    {
      "x": 18,
      "y": 5,
      "z": 15,
      "name": "Wood_Gumboab_Trunk_Full"
    },
    {
      "x": 18,
      "y": 18,
      "z": 15,
      "name": "Plant_Leaves_Bottle"
    },
    {
      "x": 18,
      "y": 19,
      "z": 15,
      "name": "Plant_Leaves_Bottle"
    },
    {
      "x": 18,
      "y": 5,
      "z": 16,
      "name": "Wood_Gumboab_Trunk_Full"
    },
    {
      "x": 18,
      "y": 18,
      "z": 16,
      "name": "Plant_Leaves_Bottle"
    },
    {
      "x": 18,
      "y": 19,
      "z": 16,
      "name": "Wood_Gumboab_Trunk_Full"
    },
    {
      "x": 18,
      "y": 21,
      "z": 16,
      "name": "Plant_Leaves_Bottle"
    },
    {
      "x": 18,
      "y": 20,
      "z": 18,
      "name": "Plant_Leaves_Bottle"
    },
    {
      "x": 19,
      "y": 21,
      "z": 9,
      "name": "Plant_Leaves_Bottle"
    },
    {
      "x": 19,
      "y": 5,
      "z": 10,
      "name": "Wood_Gumboab_Trunk_Full"
    },
    {
      "x": 19,
      "y": 6,
      "z": 10,
      "name": "Wood_Gumboab_Trunk_Full"
    },
    {
      "x": 19,
      "y": 21,
      "z": 10,
      "name": "Plant_Leaves_Bottle"
    },
    {
      "x": 19,
      "y": 22,
      "z": 10,
      "name": "Plant_Leaves_Bottle"
    },
    {
      "x": 19,
      "y": 18,
      "z": 11,
      "name": "Wood_Gumboab_Trunk_Full"
    },
    {
      "x": 19,
      "y": 20,
      "z": 11,
      "name": "Plant_Leaves_Bottle"
    },
    {
      "x": 19,
      "y": 21,
      "z": 11,
      "name": "Plant_Leaves_Bottle"
    },
    {
      "x": 19,
      "y": 18,
      "z": 12,
      "name": "Wood_Gumboab_Trunk_Full"
    },
    {
      "x": 19,
      "y": 17,
      "z": 14,
      "name": "Wood_Gumboab_Trunk_Full"
    },
    {
      "x": 19,
      "y": 18,
      "z": 14,
      "name": "Wood_Gumboab_Trunk_Full"
    },
    {
      "x": 19,
      "y": 5,
      "z": 15,
      "name": "Wood_Gumboab_Trunk_Full"
    },
    {
      "x": 19,
      "y": 18,
      "z": 15,
      "name": "Wood_Gumboab_Trunk_Full"
    },
    {
      "x": 19,
      "y": 19,
      "z": 15,
      "name": "Plant_Leaves_Bottle"
    },
    {
      "x": 19,
      "y": 21,
      "z": 15,
      "name": "Plant_Leaves_Bottle"
    },
    {
      "x": 19,
      "y": 18,
      "z": 16,
      "name": "Plant_Leaves_Bottle"
    },
    {
      "x": 19,
      "y": 19,
      "z": 16,
      "name": "Plant_Leaves_Bottle"
    },
    {
      "x": 19,
      "y": 21,
      "z": 16,
      "name": "Plant_Leaves_Bottle"
    },
    {
      "x": 19,
      "y": 18,
      "z": 17,
      "name": "Plant_Leaves_Bottle"
    },
    {
      "x": 19,
      "y": 19,
      "z": 17,
      "name": "Wood_Gumboab_Trunk_Full"
    },
    {
      "x": 19,
      "y": 20,
      "z": 17,
      "name": "Wood_Gumboab_Trunk_Full"
    },
    {
      "x": 19,
      "y": 21,
      "z": 17,
      "name": "Plant_Leaves_Bottle"
    },
    {
      "x": 19,
      "y": 20,
      "z": 18,
      "name": "Plant_Leaves_Bottle"
    },
    {
      "x": 19,
      "y": 21,
      "z": 18,
      "name": "Plant_Leaves_Bottle"
    },
    {
      "x": 19,
      "y": 20,
      "z": 19,
      "name": "Plant_Leaves_Bottle"
    },
    {
      "x": 20,
      "y": 19,
      "z": 9,
      "name": "Plant_Leaves_Bottle"
    },
    {
      "x": 20,
      "y": 5,
      "z": 10,
      "name": "Wood_Gumboab_Trunk_Full"
    },
    {
      "x": 20,
      "y": 19,
      "z": 10,
      "name": "Plant_Leaves_Bottle"
    },
    {
      "x": 20,
      "y": 20,
      "z": 10,
      "name": "Plant_Leaves_Bottle"
    },
    {
      "x": 20,
      "y": 18,
      "z": 11,
      "name": "Wood_Gumboab_Trunk_Full"
    },
    {
      "x": 20,
      "y": 19,
      "z": 11,
      "name": "Wood_Gumboab_Trunk_Full"
    },
    {
      "x": 20,
      "y": 20,
      "z": 11,
      "name": "Plant_Leaves_Bottle"
    },
    {
      "x": 20,
      "y": 20,
      "z": 12,
      "name": "Plant_Leaves_Bottle"
    },
    {
      "x": 20,
      "y": 19,
      "z": 14,
      "name": "Plant_Leaves_Bottle"
    },
    {
      "x": 20,
      "y": 5,
      "z": 15,
      "name": "Wood_Gumboab_Trunk_Full"
    },
    {
      "x": 20,
      "y": 18,
      "z": 15,
      "name": "Wood_Gumboab_Branch_Long",
      "rotation": 5
    },
    {
      "x": 20,
      "y": 19,
      "z": 15,
      "name": "Plant_Leaves_Bottle"
    },
    {
      "x": 20,
      "y": 20,
      "z": 15,
      "name": "Plant_Leaves_Bottle"
    },
    {
      "x": 20,
      "y": 18,
      "z": 16,
      "name": "Plant_Leaves_Bottle"
    },
    {
      "x": 20,
      "y": 20,
      "z": 16,
      "name": "Plant_Leaves_Bottle"
    },
    {
      "x": 20,
      "y": 21,
      "z": 16,
      "name": "Plant_Leaves_Bottle"
    },
    {
      "x": 20,
      "y": 18,
      "z": 17,
      "name": "Plant_Leaves_Bottle"
    },
    {
      "x": 20,
      "y": 19,
      "z": 17,
      "name": "Wood_Gumboab_Branch_Long",
      "rotation": 5
    },
    {
      "x": 20,
      "y": 20,
      "z": 17,
      "name": "Plant_Leaves_Bottle"
    },
    {
      "x": 20,
      "y": 21,
      "z": 17,
      "name": "Plant_Leaves_Bottle"
    },
    {
      "x": 20,
      "y": 20,
      "z": 18,
      "name": "Plant_Leaves_Bottle"
    },
    {
      "x": 20,
      "y": 21,
      "z": 18,
      "name": "Plant_Leaves_Bottle"
    },
    {
      "x": 20,
      "y": 20,
      "z": 19,
      "name": "Plant_Leaves_Bottle"
    },
    {
      "x": 21,
      "y": 19,
      "z": 9,
      "name": "Plant_Leaves_Bottle"
    },
    {
      "x": 21,
      "y": 20,
      "z": 9,
      "name": "Plant_Leaves_Bottle"
    },
    {
      "x": 21,
      "y": 5,
      "z": 10,
      "name": "Wood_Gumboab_Trunk_Full"
    },
    {
      "x": 21,
      "y": 19,
      "z": 10,
      "name": "Wood_Gumboab_Branch_Long",
      "rotation": 4
    },
    {
      "x": 21,
      "y": 20,
      "z": 10,
      "name": "Plant_Leaves_Bottle"
    },
    {
      "x": 21,
      "y": 19,
      "z": 11,
      "name": "Wood_Gumboab_Trunk_Full"
    },
    {
      "x": 21,
      "y": 20,
      "z": 11,
      "name": "Plant_Leaves_Bottle"
    },
    {
      "x": 21,
      "y": 19,
      "z": 12,
      "name": "Plant_Leaves_Bottle"
    },
    {
      "x": 21,
      "y": 18,
      "z": 14,
      "name": "Plant_Leaves_Bottle"
    },
    {
      "x": 21,
      "y": 19,
      "z": 14,
      "name": "Plant_Leaves_Bottle"
    },
    {
      "x": 21,
      "y": 18,
      "z": 15,
      "name": "Plant_Leaves_Bottle"
    },
    {
      "x": 21,
      "y": 18,
      "z": 16,
      "name": "Plant_Leaves_Bottle"
    },
    {
      "x": 21,
      "y": 20,
      "z": 16,
      "name": "Plant_Leaves_Bottle"
    },
    {
      "x": 21,
      "y": 20,
      "z": 17,
      "name": "Plant_Leaves_Bottle"
    },
    {
      "x": 21,
      "y": 20,
      "z": 18,
      "name": "Plant_Leaves_Bottle"
    },
    {
      "x": 22,
      "y": 19,
      "z": 9,
      "name": "Plant_Leaves_Bottle"
    },
    {
      "x": 22,
      "y": 5,
      "z": 10,
      "name": "Wood_Gumboab_Trunk_Full"
    },
    {
      "x": 22,
      "y": 18,
      "z": 10,
      "name": "Plant_Leaves_Bottle"
    },
    {
      "x": 22,
      "y": 19,
      "z": 10,
      "name": "Plant_Leaves_Bottle"
    },
    {
      "x": 22,
      "y": 20,
      "z": 10,
      "name": "Plant_Leaves_Bottle"
    },
    {
      "x": 22,
      "y": 19,
      "z": 11,
      "name": "Wood_Gumboab_Trunk_Full"
    },
    {
      "x": 22,
      "y": 20,
      "z": 11,
      "name": "Plant_Leaves_Bottle"
    },
    {
      "x": 22,
      "y": 19,
      "z": 12,
      "name": "Plant_Leaves_Bottle"
    },
    {
      "x": 22,
      "y": 20,
      "z": 12,
      "name": "Plant_Leaves_Bottle"
    },
    {
      "x": 22,
      "y": 19,
      "z": 13,
      "name": "Plant_Leaves_Bottle"
    },
    {
      "x": 22,
      "y": 20,
      "z": 13,
      "name": "Plant_Leaves_Bottle"
    },
    {
      "x": 22,
      "y": 18,
      "z": 14,
      "name": "Plant_Leaves_Bottle"
    },
    {
      "x": 22,
      "y": 20,
      "z": 16,
      "name": "Plant_Leaves_Bottle"
    },
    {
      "x": 22,
      "y": 20,
      "z": 17,
      "name": "Plant_Leaves_Bottle"
    },
    {
      "x": 23,
      "y": 18,
      "z": 9,
      "name": "Plant_Leaves_Bottle"
    },
    {
      "x": 23,
      "y": 18,
      "z": 10,
      "name": "Plant_Leaves_Bottle"
    },
    {
      "x": 23,
      "y": 19,
      "z": 10,
      "name": "Plant_Leaves_Bottle"
    },
    {
      "x": 23,
      "y": 19,
      "z": 11,
      "name": "Wood_Gumboab_Branch_Long",
      "rotation": 5
    },
    {
      "x": 23,
      "y": 20,
      "z": 11,
      "name": "Plant_Leaves_Bottle"
    },
    {
      "x": 23,
      "y": 18,
      "z": 12,
      "name": "Plant_Leaves_Bottle"
    },
    {
      "x": 23,
      "y": 19,
      "z": 12,
      "name": "Plant_Leaves_Bottle"
    },
    {
      "x": 23,
      "y": 19,
      "z": 13,
      "name": "Plant_Leaves_Bottle"
    },
    {
      "x": 24,
      "y": 18,
      "z": 10,
      "name": "Plant_Leaves_Bottle"
    },
    {
      "x": 24,
      "y": 18,
      "z": 11,
      "name": "Plant_Leaves_Bottle"
    },
    {
      "x": 24,
      "y": 19,
      "z": 11,
      "name": "Plant_Leaves_Bottle"
    },
    {
      "x": 24,
      "y": 18,
      "z": 12,
      "name": "Plant_Leaves_Bottle"
    },
    {
      "x": 24,
      "y": 19,
      "z": 12,
      "name": "Plant_Leaves_Bottle"
    },
    {
      "x": 24,
      "y": 18,
      "z": 13,
      "name": "Plant_Leaves_Bottle"
    },
    {
      "x": 24,
      "y": 18,
      "z": 14,
      "name": "Plant_Leaves_Bottle"
    },
    {
      "x": 25,
      "y": 18,
      "z": 11,
      "name": "Plant_Leaves_Bottle"
    },
    {
      "x": 25,
      "y": 18,
      "z": 12,
      "name": "Plant_Leaves_Bottle"
    }
  ]
}