{
  "version": 8,
  "blockIdVersion": 11,
  "anchorX": 1,
  "anchorY": 1,
  "anchorZ": 0,
  "blocks": [
    {
      "x": -1,
      "y": 4,
      "z": 0,
      "name": "Plant_Leaves_Spiral"
    },
    {
      "x": 0,
      "y": 4,
      "z": -1,
      "name": "Plant_Leaves_Spiral"
    },
    {
      "x": 0,
      "y": 3,
      "z": 0,
      "name": "Wood_Spiral_Branch_Corner",
      "rotation": 3
    },
    {
      "x": 0,
      "y": 4,
      "z": 0,
      "name": "Wood_Spiral_Branch_Long"
    },
    {
      "x": 0,
      "y": 5,
      "z": 0,
      "name": "Plant_Leaves_Spiral"
    },
    {
      "x": 0,
      "y": 3,
      "z": 1,
      "name": "Plant_Leaves_Spiral"
    },
    {
      "x": 0,
      "y": 4,
      "z": 1,
      "name": "Plant_Leaves_Spiral"
    },
    {
      "x": 0,
      "y": 6,
      "z": 1,
      "name": "Plant_Leaves_Spiral"
    },
    {
      "x": 1,
      "y": 2,
      "z": -1,
      "name": "Wood_Spiral_Branch_Corner",
      "rotation": 2
    },
    {
      "x": 1,
      "y": 3,
      "z": -1,
      "name": "Wood_Spiral_Branch_Corner",
      "rotation": 9
    },
    {
      "x": 1,
      "y": 1,
      "z": 0,
      "name": "Wood_Spiral_Trunk_Full"
    },
    {
      "x": 1,
      "y": 2,
      "z": 0,
      "name": "Wood_Spiral_Trunk_Full"
    },
    {
      "x": 1,
      "y": 3,
      "z": 0,
      "name": "Wood_Spiral_Trunk_Full"
    },
    {
      "x": 1,
      "y": 4,
      "z": 0,
      "name": "Plant_Leaves_Spiral"
    },
    {
      "x": 1,
      "y": 6,
      "z": 0,
      "name": "Plant_Leaves_Spiral"
    },
    {
      "x": 1,
      "y": 3,
      "z": 1,
      "name": "Wood_Spiral_Branch_Long",
      "rotation": 4
    },
    {
      "x": 1,
      "y": 4,
      "z": 1,
      "name": "Plant_Leaves_Spiral"
    },
    {
      "x": 1,
      "y": 6,
      "z": 1,
      "name": "Wood_Spiral_Branch_Corner",
      "rotation": 3
    },
    {
      "x": 1,
      "y": 7,
      "z": 1,
      "name": "Plant_Leaves_Spiral"
    },
    {
      "x": 1,
      "y": 3,
      "z": 2,
      "name": "Plant_Leaves_Spiral"
    },
    {
      "x": 1,
      "y": 6,
      "z": 2,
      "name": "Plant_Leaves_Spiral"
    },
    {
      "x": 2,
      "y": 3,
      "z": -1,
      "name": "Wood_Spiral_Branch_Corner",
      "rotation": 1
    },
    {
      "x": 2,
      "y": 4,
      "z": -1,
      "name": "Wood_Spiral_Branch_Corner",
      "rotation": 8
    },
    {
      "x": 2,
      "y": 4,
      "z": 0,
      "name": "Wood_Spiral_Branch_Corner"
    },
    {
      "x": 2,
      "y": 5,
      "z": 0,
      "name": "Wood_Spiral_Branch_Corner",
      "rotation": 8
    },
    {
      "x": 2,
      "y": 6,
      "z": 0,
      "name": "Plant_Leaves_Spiral"
    },
    {
      "x": 2,
      "y": 3,
      "z": 1,
      "name": "Plant_Leaves_Spiral"
    },
    {
      "x": 2,
      "y": 5,
      "z": 1,
      "name": "Wood_Spiral_Branch_Corner"
    },
    {
      "x": 2,
      "y": 6,
      "z": 1,
      "name": "Wood_Spiral_Branch_Corner",
      "rotation": 11
    },
    {
      "x": 2,
      "y": 7,
      "z": 1,
      "name": "Plant_Leaves_Spiral"
    },
    {
      "x": 2,
      "y": 6,
      "z": 2,
      "name": "Plant_Leaves_Spiral"
    },
    {
      "x": 3,
      "y": 6,
      "z": 1,
      "name": "Plant_Leaves_Spiral"
    }
  ]
}