{
  "version": 8,
  "blockIdVersion": 11,
  "anchorX": 0,
  "anchorY": 6,
  "anchorZ": 0,
  "blocks": [
    {
      "x": -6,
      "y": 7,
      "z": -6,
      "name": "*Wood_Hardwood_Fence_State_Definitions_Corner",
      "rotation": 1
    },
    {
      "x": -6,
      "y": 8,
      "z": -6,
      "name": "Empty"
    },
    {
      "x": -6,
      "y": 9,
      "z": -6,
      "name": "Empty"
    },
    {
      "x": -6,
      "y": 4,
      "z": -5,
      "name": "Soil_Dirt"
    },
    {
      "x": -6,
      "y": 5,
      "z": -5,
      "name": "Soil_Dirt"
    },
    {
      "x": -6,
      "y": 6,
      "z": -5,
      "name": "Soil_Leaves"
    },
    {
      "x": -6,
      "y": 7,
      "z": -5,
      "name": "Wood_Hardwood_Fence",
      "rotation": 3
    },
    {
      "x": -6,
      "y": 8,
      "z": -5,
      "name": "Empty"
    },
    {
      "x": -6,
      "y": 9,
      "z": -5,
      "name": "Empty"
    },
    {
      "x": -6,
      "y": 3,
      "z": -4,
      "name": "Soil_Dirt"
    },
    {
      "x": -6,
      "y": 4,
      "z": -4,
      "name": "Soil_Dirt"
    },
    {
      "x": -6,
      "y": 5,
      "z": -4,
      "name": "Soil_Dirt"
    },
    {
      "x": -6,
      "y": 6,
      "z": -4,
      "name": "Soil_Leaves"
    },
    {
      "x": -6,
      "y": 7,
      "z": -4,
      "name": "Wood_Hardwood_Fence",
      "rotation": 3
    },
    {
      "x": -6,
      "y": 8,
      "z": -4,
      "name": "Empty"
    },
    {
      "x": -6,
      "y": 9,
      "z": -4,
      "name": "Empty"
    },
    {
      "x": -6,
      "y": 3,
      "z": -3,
      "name": "Soil_Dirt"
    },
    {
      "x": -6,
      "y": 4,
      "z": -3,
      "name": "Soil_Dirt"
    },
    {
      "x": -6,
      "y": 5,
      "z": -3,
      "name": "Soil_Dirt"
    },
    {
      "x": -6,
      "y": 6,
      "z": -3,
      "name": "Soil_Grass_Deep"
    },
    {
      "x": -6,
      "y": 7,
      "z": -3,
      "name": "Wood_Hardwood_Fence",
      "rotation": 3
    },
    {
      "x": -6,
      "y": 8,
      "z": -3,
      "name": "Empty"
    },
    {
      "x": -6,
      "y": 9,
      "z": -3,
      "name": "Empty"
    },
    {
      "x": -6,
      "y": 2,
      "z": -2,
      "name": "Soil_Dirt"
    },
    {
      "x": -6,
      "y": 3,
      "z": -2,
      "name": "Soil_Dirt"
    },
    {
      "x": -6,
      "y": 4,
      "z": -2,
      "name": "Soil_Dirt"
    },
    {
      "x": -6,
      "y": 5,
      "z": -2,
      "name": "Soil_Dirt"
    },
    {
      "x": -6,
      "y": 6,
      "z": -2,
      "name": "Soil_Dirt"
    },
    {
      "x": -6,
      "y": 7,
      "z": -2,
      "name": "Wood_Hardwood_Fence",
      "rotation": 3
    },
    {
      "x": -6,
      "y": 8,
      "z": -2,
      "name": "Empty"
    },
    {
      "x": -6,
      "y": 9,
      "z": -2,
      "name": "Empty"
    },
    {
      "x": -6,
      "y": 2,
      "z": -1,
      "name": "Soil_Dirt"
    },
    {
      "x": -6,
      "y": 3,
      "z": -1,
      "name": "Soil_Dirt"
    },
    {
      "x": -6,
      "y": 4,
      "z": -1,
      "name": "Soil_Dirt"
    },
    {
      "x": -6,
      "y": 5,
      "z": -1,
      "name": "Soil_Dirt"
    },
    {
      "x": -6,
      "y": 6,
      "z": -1,
      "name": "Soil_Dirt"
    },
    {
      "x": -6,
      "y": 7,
      "z": -1,
      "name": "Wood_Hardwood_Fence",
      "rotation": 3
    },
    {
      "x": -6,
      "y": 8,
      "z": -1,
      "name": "Empty"
    },
    {
      "x": -6,
      "y": 9,
      "z": -1,
      "name": "Empty"
    },
    {
      "x": -6,
      "y": 2,
      "z": 0,
      "name": "Soil_Dirt"
    },
    {
      "x": -6,
      "y": 3,
      "z": 0,
      "name": "Soil_Dirt"
    },
    {
      "x": -6,
      "y": 4,
      "z": 0,
      "name": "Soil_Dirt"
    },
    {
      "x": -6,
      "y": 5,
      "z": 0,
      "name": "Soil_Dirt"
    },
    {
      "x": -6,
      "y": 6,
      "z": 0,
      "name": "Soil_Grass_Deep"
    },
    {
      "x": -6,
      "y": 7,
      "z": 0,
      "name": "Wood_Hardwood_Fence",
      "rotation": 3
    },
    {
      "x": -6,
      "y": 8,
      "z": 0,
      "name": "Empty"
    },
    {
      "x": -6,
      "y": 9,
      "z": 0,
      "name": "Empty"
    },
    {
      "x": -6,
      "y": 3,
      "z": 1,
      "name": "Soil_Dirt"
    },
    {
      "x": -6,
      "y": 4,
      "z": 1,
      "name": "Soil_Dirt"
    },
    {
      "x": -6,
      "y": 5,
      "z": 1,
      "name": "Soil_Dirt"
    },
    {
      "x": -6,
      "y": 6,
      "z": 1,
      "name": "Soil_Grass_Deep"
    },
    {
      "x": -6,
      "y": 7,
      "z": 1,
      "name": "*Wood_Hardwood_Fence_State_Definitions_Corner",
      "rotation": 2
    },
    {
      "x": -6,
      "y": 8,
      "z": 1,
      "name": "Empty"
    },
    {
      "x": -6,
      "y": 9,
      "z": 1,
      "name": "Empty"
    },
    {
      "x": -5,
      "y": 5,
      "z": -6,
      "name": "Soil_Dirt"
    },
    {
      "x": -5,
      "y": 6,
      "z": -6,
      "name": "Soil_Grass_Deep"
    },
    {
      "x": -5,
      "y": 7,
      "z": -6,
      "name": "Wood_Hardwood_Fence",
      "rotation": 2
    },
    {
      "x": -5,
      "y": 8,
      "z": -6,
      "name": "Empty"
    },
    {
      "x": -5,
      "y": 9,
      "z": -6,
      "name": "Empty"
    },
    {
      "x": -5,
      "y": 3,
      "z": -5,
      "name": "Soil_Dirt"
    },
    {
      "x": -5,
      "y": 4,
      "z": -5,
      "name": "Soil_Dirt"
    },
    {
      "x": -5,
      "y": 5,
      "z": -5,
      "name": "Soil_Dirt"
    },
    {
      "x": -5,
      "y": 6,
      "z": -5,
      "name": "Soil_Leaves"
    },
    {
      "x": -5,
      "y": 7,
      "z": -5,
      "name": "Empty"
    },
    {
      "x": -5,
      "y": 8,
      "z": -5,
      "name": "Empty"
    },
    {
      "x": -5,
      "y": 9,
      "z": -5,
      "name": "Empty"
    },
    {
      "x": -5,
      "y": 2,
      "z": -4,
      "name": "Soil_Dirt"
    },
    {
      "x": -5,
      "y": 3,
      "z": -4,
      "name": "Soil_Dirt"
    },
    {
      "x": -5,
      "y": 4,
      "z": -4,
      "name": "Soil_Dirt"
    },
    {
      "x": -5,
      "y": 5,
      "z": -4,
      "name": "Soil_Dirt"
    },
    {
      "x": -5,
      "y": 6,
      "z": -4,
      "name": "Soil_Grass_Deep"
    },
    {
      "x": -5,
      "y": 7,
      "z": -4,
      "name": "Empty"
    },
    {
      "x": -5,
      "y": 8,
      "z": -4,
      "name": "Empty"
    },
    {
      "x": -5,
      "y": 9,
      "z": -4,
      "name": "Empty"
    },
    {
      "x": -5,
      "y": 2,
      "z": -3,
      "name": "Soil_Dirt"
    },
    {
      "x": -5,
      "y": 3,
      "z": -3,
      "name": "Soil_Dirt"
    },
    {
      "x": -5,
      "y": 4,
      "z": -3,
      "name": "Soil_Dirt"
    },
    {
      "x": -5,
      "y": 5,
      "z": -3,
      "name": "Soil_Dirt"
    },
    {
      "x": -5,
      "y": 6,
      "z": -3,
      "name": "Soil_Dirt"
    },
    {
      "x": -5,
      "y": 7,
      "z": -3,
      "name": "Empty"
    },
    {
      "x": -5,
      "y": 8,
      "z": -3,
      "name": "Empty"
    },
    {
      "x": -5,
      "y": 9,
      "z": -3,
      "name": "Empty"
    },
    {
      "x": -5,
      "y": 1,
      "z": -2,
      "name": "Soil_Dirt"
    },
    {
      "x": -5,
      "y": 2,
      "z": -2,
      "name": "Soil_Dirt"
    },
    {
      "x": -5,
      "y": 3,
      "z": -2,
      "name": "Soil_Dirt"
    },
    {
      "x": -5,
      "y": 4,
      "z": -2,
      "name": "Soil_Dirt"
    },
    {
      "x": -5,
      "y": 5,
      "z": -2,
      "name": "Soil_Dirt"
    },
    {
      "x": -5,
      "y": 6,
      "z": -2,
      "name": "Soil_Dirt"
    },
    {
      "x": -5,
      "y": 7,
      "z": -2,
      "name": "Empty"
    },
    {
      "x": -5,
      "y": 8,
      "z": -2,
      "name": "Empty"
    },
    {
      "x": -5,
      "y": 9,
      "z": -2,
      "name": "Empty"
    },
    {
      "x": -5,
      "y": 1,
      "z": -1,
      "name": "Soil_Dirt"
    },
    {
      "x": -5,
      "y": 2,
      "z": -1,
      "name": "Soil_Dirt"
    },
    {
      "x": -5,
      "y": 3,
      "z": -1,
      "name": "Soil_Dirt"
    },
    {
      "x": -5,
      "y": 4,
      "z": -1,
      "name": "Soil_Dirt"
    },
    {
      "x": -5,
      "y": 5,
      "z": -1,
      "name": "Soil_Dirt"
    },
    {
      "x": -5,
      "y": 6,
      "z": -1,
      "name": "Soil_Dirt"
    },
    {
      "x": -5,
      "y": 7,
      "z": -1,
      "name": "Empty"
    },
    {
      "x": -5,
      "y": 8,
      "z": -1,
      "name": "Empty"
    },
    {
      "x": -5,
      "y": 9,
      "z": -1,
      "name": "Empty"
    },
    {
      "x": -5,
      "y": 1,
      "z": 0,
      "name": "Soil_Dirt"
    },
    {
      "x": -5,
      "y": 2,
      "z": 0,
      "name": "Soil_Dirt"
    },
    {
      "x": -5,
      "y": 3,
      "z": 0,
      "name": "Soil_Dirt"
    },
    {
      "x": -5,
      "y": 4,
      "z": 0,
      "name": "Soil_Dirt"
    },
    {
      "x": -5,
      "y": 5,
      "z": 0,
      "name": "Soil_Dirt"
    },
    {
      "x": -5,
      "y": 6,
      "z": 0,
      "name": "Soil_Grass_Deep"
    },
    {
      "x": -5,
      "y": 7,
      "z": 0,
      "name": "Plant_Grass_Sharp_Tall"
    },
    {
      "x": -5,
      "y": 8,
      "z": 0,
      "name": "Plant_Grass_Sharp_Tall",
      "filler": 1024
    },
    {
      "x": -5,
      "y": 9,
      "z": 0,
      "name": "Empty"
    },
    {
      "x": -5,
      "y": 3,
      "z": 1,
      "name": "Soil_Dirt"
    },
    {
      "x": -5,
      "y": 4,
      "z": 1,
      "name": "Soil_Dirt"
    },
    {
      "x": -5,
      "y": 5,
      "z": 1,
      "name": "Soil_Dirt"
    },
    {
      "x": -5,
      "y": 6,
      "z": 1,
      "name": "Soil_Grass_Deep"
    },
    {
      "x": -5,
      "y": 7,
      "z": 1,
      "name": "*Wood_Hardwood_Fence_State_Definitions_Corner"
    },
    {
      "x": -5,
      "y": 8,
      "z": 1,
      "name": "Empty"
    },
    {
      "x": -5,
      "y": 9,
      "z": 1,
      "name": "Empty"
    },
    {
      "x": -5,
      "y": 5,
      "z": 2,
      "name": "Soil_Dirt"
    },
    {
      "x": -5,
      "y": 6,
      "z": 2,
      "name": "Soil_Leaves"
    },
    {
      "x": -5,
      "y": 7,
      "z": 2,
      "name": "*Wood_Hardwood_Fence_State_Definitions_Corner",
      "rotation": 2
    },
    {
      "x": -5,
      "y": 8,
      "z": 2,
      "name": "Empty"
    },
    {
      "x": -5,
      "y": 9,
      "z": 2,
      "name": "Empty"
    },
    {
      "x": -4,
      "y": 4,
      "z": -6,
      "name": "Soil_Dirt"
    },
    {
      "x": -4,
      "y": 5,
      "z": -6,
      "name": "Soil_Dirt"
    },
    {
      "x": -4,
      "y": 6,
      "z": -6,
      "name": "Soil_Grass_Deep"
    },
    {
      "x": -4,
      "y": 7,
      "z": -6,
      "name": "Wood_Hardwood_Fence",
      "rotation": 2
    },
    {
      "x": -4,
      "y": 8,
      "z": -6,
      "name": "Empty"
    },
    {
      "x": -4,
      "y": 9,
      "z": -6,
      "name": "Empty"
    },
    {
      "x": -4,
      "y": 3,
      "z": -5,
      "name": "Soil_Dirt"
    },
    {
      "x": -4,
      "y": 4,
      "z": -5,
      "name": "Soil_Dirt"
    },
    {
      "x": -4,
      "y": 5,
      "z": -5,
      "name": "Soil_Dirt"
    },
    {
      "x": -4,
      "y": 6,
      "z": -5,
      "name": "Soil_Leaves"
    },
    {
      "x": -4,
      "y": 7,
      "z": -5,
      "name": "Empty"
    },
    {
      "x": -4,
      "y": 8,
      "z": -5,
      "name": "Empty"
    },
    {
      "x": -4,
      "y": 9,
      "z": -5,
      "name": "Empty"
    },
    {
      "x": -4,
      "y": 1,
      "z": -4,
      "name": "Soil_Dirt"
    },
    {
      "x": -4,
      "y": 2,
      "z": -4,
      "name": "Soil_Dirt"
    },
    {
      "x": -4,
      "y": 3,
      "z": -4,
      "name": "Soil_Dirt"
    },
    {
      "x": -4,
      "y": 4,
      "z": -4,
      "name": "Soil_Dirt"
    },
    {
      "x": -4,
      "y": 5,
      "z": -4,
      "name": "Soil_Dirt"
    },
    {
      "x": -4,
      "y": 6,
      "z": -4,
      "name": "Soil_Dirt"
    },
    {
      "x": -4,
      "y": 7,
      "z": -4,
      "name": "Empty"
    },
    {
      "x": -4,
      "y": 8,
      "z": -4,
      "name": "Empty"
    },
    {
      "x": -4,
      "y": 9,
      "z": -4,
      "name": "Empty"
    },
    {
      "x": -4,
      "y": 1,
      "z": -3,
      "name": "Soil_Dirt"
    },
    {
      "x": -4,
      "y": 2,
      "z": -3,
      "name": "Soil_Dirt"
    },
    {
      "x": -4,
      "y": 3,
      "z": -3,
      "name": "Soil_Dirt"
    },
    {
      "x": -4,
      "y": 4,
      "z": -3,
      "name": "Soil_Dirt"
    },
    {
      "x": -4,
      "y": 5,
      "z": -3,
      "name": "Soil_Dirt"
    },
    {
      "x": -4,
      "y": 6,
      "z": -3,
      "name": "Soil_Dirt"
    },
    {
      "x": -4,
      "y": 7,
      "z": -3,
      "name": "Empty"
    },
    {
      "x": -4,
      "y": 8,
      "z": -3,
      "name": "Empty"
    },
    {
      "x": -4,
      "y": 9,
      "z": -3,
      "name": "Empty"
    },
    {
      "x": -4,
      "y": 1,
      "z": -2,
      "name": "Soil_Dirt"
    },
    {
      "x": -4,
      "y": 2,
      "z": -2,
      "name": "Soil_Dirt"
    },
    {
      "x": -4,
      "y": 3,
      "z": -2,
      "name": "Soil_Dirt"
    },
    {
      "x": -4,
      "y": 4,
      "z": -2,
      "name": "Soil_Dirt"
    },
    {
      "x": -4,
      "y": 5,
      "z": -2,
      "name": "Soil_Dirt"
    },
    {
      "x": -4,
      "y": 6,
      "z": -2,
      "name": "Soil_Mud_Dry"
    },
    {
      "x": -4,
      "y": 7,
      "z": -2,
      "name": "Empty"
    },
    {
      "x": -4,
      "y": 8,
      "z": -2,
      "name": "Empty"
    },
    {
      "x": -4,
      "y": 9,
      "z": -2,
      "name": "Empty"
    },
    {
      "x": -4,
      "y": 1,
      "z": -1,
      "name": "Soil_Dirt"
    },
    {
      "x": -4,
      "y": 2,
      "z": -1,
      "name": "Soil_Dirt"
    },
    {
      "x": -4,
      "y": 3,
      "z": -1,
      "name": "Soil_Dirt"
    },
    {
      "x": -4,
      "y": 4,
      "z": -1,
      "name": "Soil_Dirt"
    },
    {
      "x": -4,
      "y": 5,
      "z": -1,
      "name": "Soil_Dirt"
    },
    {
      "x": -4,
      "y": 6,
      "z": -1,
      "name": "Soil_Mud_Dry"
    },
    {
      "x": -4,
      "y": 7,
      "z": -1,
      "name": "Empty"
    },
    {
      "x": -4,
      "y": 8,
      "z": -1,
      "name": "Empty"
    },
    {
      "x": -4,
      "y": 9,
      "z": -1,
      "name": "Empty"
    },
    {
      "x": -4,
      "y": 1,
      "z": 0,
      "name": "Soil_Dirt"
    },
    {
      "x": -4,
      "y": 2,
      "z": 0,
      "name": "Soil_Dirt"
    },
    {
      "x": -4,
      "y": 3,
      "z": 0,
      "name": "Soil_Dirt"
    },
    {
      "x": -4,
      "y": 4,
      "z": 0,
      "name": "Soil_Dirt"
    },
    {
      "x": -4,
      "y": 5,
      "z": 0,
      "name": "Soil_Dirt"
    },
    {
      "x": -4,
      "y": 6,
      "z": 0,
      "name": "Soil_Grass_Deep"
    },
    {
      "x": -4,
      "y": 7,
      "z": 0,
      "name": "Plant_Grass_Sharp_Tall"
    },
    {
      "x": -4,
      "y": 8,
      "z": 0,
      "name": "Plant_Grass_Sharp_Tall",
      "filler": 1024
    },
    {
      "x": -4,
      "y": 9,
      "z": 0,
      "name": "Empty"
    },
    {
      "x": -4,
      "y": 2,
      "z": 1,
      "name": "Soil_Dirt"
    },
    {
      "x": -4,
      "y": 3,
      "z": 1,
      "name": "Soil_Dirt"
    },
    {
      "x": -4,
      "y": 4,
      "z": 1,
      "name": "Soil_Dirt"
    },
    {
      "x": -4,
      "y": 5,
      "z": 1,
      "name": "Soil_Dirt"
    },
    {
      "x": -4,
      "y": 6,
      "z": 1,
      "name": "Soil_Leaves"
    },
    {
      "x": -4,
      "y": 7,
      "z": 1,
      "name": "Plant_Grass_Lush"
    },
    {
      "x": -4,
      "y": 8,
      "z": 1,
      "name": "Empty"
    },
    {
      "x": -4,
      "y": 9,
      "z": 1,
      "name": "Empty"
    },
    {
      "x": -4,
      "y": 3,
      "z": 2,
      "name": "Soil_Dirt"
    },
    {
      "x": -4,
      "y": 4,
      "z": 2,
      "name": "Soil_Dirt"
    },
    {
      "x": -4,
      "y": 5,
      "z": 2,
      "name": "Soil_Dirt"
    },
    {
      "x": -4,
      "y": 6,
      "z": 2,
      "name": "Soil_Leaves"
    },
    {
      "x": -4,
      "y": 7,
      "z": 2,
      "name": "Wood_Hardwood_Fence"
    },
    {
      "x": -4,
      "y": 8,
      "z": 2,
      "name": "Empty"
    },
    {
      "x": -4,
      "y": 9,
      "z": 2,
      "name": "Empty"
    },
    {
      "x": -3,
      "y": 3,
      "z": -6,
      "name": "Soil_Dirt"
    },
    {
      "x": -3,
      "y": 4,
      "z": -6,
      "name": "Soil_Dirt"
    },
    {
      "x": -3,
      "y": 5,
      "z": -6,
      "name": "Soil_Dirt"
    },
    {
      "x": -3,
      "y": 6,
      "z": -6,
      "name": "Soil_Dirt"
    },
    {
      "x": -3,
      "y": 7,
      "z": -6,
      "name": "Wood_Hardwood_Fence",
      "rotation": 2
    },
    {
      "x": -3,
      "y": 8,
      "z": -6,
      "name": "Empty"
    },
    {
      "x": -3,
      "y": 9,
      "z": -6,
      "name": "Empty"
    },
    {
      "x": -3,
      "y": 2,
      "z": -5,
      "name": "Soil_Dirt"
    },
    {
      "x": -3,
      "y": 3,
      "z": -5,
      "name": "Soil_Dirt"
    },
    {
      "x": -3,
      "y": 4,
      "z": -5,
      "name": "Soil_Dirt"
    },
    {
      "x": -3,
      "y": 5,
      "z": -5,
      "name": "Soil_Dirt"
    },
    {
      "x": -3,
      "y": 6,
      "z": -5,
      "name": "Soil_Dirt"
    },
    {
      "x": -3,
      "y": 7,
      "z": -5,
      "name": "Empty"
    },
    {
      "x": -3,
      "y": 8,
      "z": -5,
      "name": "Empty"
    },
    {
      "x": -3,
      "y": 9,
      "z": -5,
      "name": "Empty"
    },
    {
      "x": -3,
      "y": 1,
      "z": -4,
      "name": "Soil_Dirt"
    },
    {
      "x": -3,
      "y": 2,
      "z": -4,
      "name": "Soil_Dirt"
    },
    {
      "x": -3,
      "y": 3,
      "z": -4,
      "name": "Soil_Dirt"
    },
    {
      "x": -3,
      "y": 4,
      "z": -4,
      "name": "Soil_Dirt"
    },
    {
      "x": -3,
      "y": 5,
      "z": -4,
      "name": "Soil_Dirt"
    },
    {
      "x": -3,
      "y": 6,
      "z": -4,
      "name": "Soil_Mud_Dry"
    },
    {
      "x": -3,
      "y": 7,
      "z": -4,
      "name": "Empty"
    },
    {
      "x": -3,
      "y": 8,
      "z": -4,
      "name": "Empty"
    },
    {
      "x": -3,
      "y": 9,
      "z": -4,
      "name": "Empty"
    },
    {
      "x": -3,
      "y": 1,
      "z": -3,
      "name": "Soil_Dirt"
    },
    {
      "x": -3,
      "y": 2,
      "z": -3,
      "name": "Soil_Dirt"
    },
    {
      "x": -3,
      "y": 3,
      "z": -3,
      "name": "Soil_Dirt"
    },
    {
      "x": -3,
      "y": 4,
      "z": -3,
      "name": "Soil_Dirt"
    },
    {
      "x": -3,
      "y": 5,
      "z": -3,
      "name": "Soil_Dirt"
    },
    {
      "x": -3,
      "y": 6,
      "z": -3,
      "name": "Soil_Mud_Dry"
    },
    {
      "x": -3,
      "y": 7,
      "z": -3,
      "name": "Empty"
    },
    {
      "x": -3,
      "y": 8,
      "z": -3,
      "name": "Empty"
    },
    {
      "x": -3,
      "y": 9,
      "z": -3,
      "name": "Empty"
    },
    {
      "x": -3,
      "y": 1,
      "z": -2,
      "name": "Soil_Dirt"
    },
    {
      "x": -3,
      "y": 2,
      "z": -2,
      "name": "Soil_Dirt"
    },
    {
      "x": -3,
      "y": 3,
      "z": -2,
      "name": "Soil_Dirt"
    },
    {
      "x": -3,
      "y": 4,
      "z": -2,
      "name": "Soil_Dirt"
    },
    {
      "x": -3,
      "y": 5,
      "z": -2,
      "name": "Soil_Dirt"
    },
    {
      "x": -3,
      "y": 6,
      "z": -2,
      "name": "Soil_Mud_Dry"
    },
    {
      "x": -3,
      "y": 7,
      "z": -2,
      "name": "Empty"
    },
    {
      "x": -3,
      "y": 8,
      "z": -2,
      "name": "Empty"
    },
    {
      "x": -3,
      "y": 9,
      "z": -2,
      "name": "Empty"
    },
    {
      "x": -3,
      "y": 1,
      "z": -1,
      "name": "Soil_Dirt"
    },
    {
      "x": -3,
      "y": 2,
      "z": -1,
      "name": "Soil_Dirt"
    },
    {
      "x": -3,
      "y": 3,
      "z": -1,
      "name": "Soil_Dirt"
    },
    {
      "x": -3,
      "y": 4,
      "z": -1,
      "name": "Soil_Dirt"
    },
    {
      "x": -3,
      "y": 5,
      "z": -1,
      "name": "Soil_Dirt"
    },
    {
      "x": -3,
      "y": 6,
      "z": -1,
      "name": "Soil_Mud_Dry"
    },
    {
      "x": -3,
      "y": 7,
      "z": -1,
      "name": "Empty"
    },
    {
      "x": -3,
      "y": 8,
      "z": -1,
      "name": "Empty"
    },
    {
      "x": -3,
      "y": 9,
      "z": -1,
      "name": "Empty"
    },
    {
      "x": -3,
      "y": 1,
      "z": 0,
      "name": "Soil_Dirt"
    },
    {
      "x": -3,
      "y": 2,
      "z": 0,
      "name": "Soil_Dirt"
    },
    {
      "x": -3,
      "y": 3,
      "z": 0,
      "name": "Soil_Dirt"
    },
    {
      "x": -3,
      "y": 4,
      "z": 0,
      "name": "Soil_Dirt"
    },
    {
      "x": -3,
      "y": 5,
      "z": 0,
      "name": "Soil_Dirt"
    },
    {
      "x": -3,
      "y": 6,
      "z": 0,
      "name": "Soil_Dirt"
    },
    {
      "x": -3,
      "y": 7,
      "z": 0,
      "name": "Empty"
    },
    {
      "x": -3,
      "y": 8,
      "z": 0,
      "name": "Empty"
    },
    {
      "x": -3,
      "y": 9,
      "z": 0,
      "name": "Empty"
    },
    {
      "x": -3,
      "y": 1,
      "z": 1,
      "name": "Soil_Dirt"
    },
    {
      "x": -3,
      "y": 2,
      "z": 1,
      "name": "Soil_Dirt"
    },
    {
      "x": -3,
      "y": 3,
      "z": 1,
      "name": "Soil_Dirt"
    },
    {
      "x": -3,
      "y": 4,
      "z": 1,
      "name": "Soil_Dirt"
    },
    {
      "x": -3,
      "y": 5,
      "z": 1,
      "name": "Soil_Dirt"
    },
    {
      "x": -3,
      "y": 6,
      "z": 1,
      "name": "Soil_Grass_Deep"
    },
    {
      "x": -3,
      "y": 7,
      "z": 1,
      "name": "Empty"
    },
    {
      "x": -3,
      "y": 8,
      "z": 1,
      "name": "Empty"
    },
    {
      "x": -3,
      "y": 9,
      "z": 1,
      "name": "Empty"
    },
    {
      "x": -3,
      "y": 2,
      "z": 2,
      "name": "Soil_Dirt"
    },
    {
      "x": -3,
      "y": 3,
      "z": 2,
      "name": "Soil_Dirt"
    },
    {
      "x": -3,
      "y": 4,
      "z": 2,
      "name": "Soil_Dirt"
    },
    {
      "x": -3,
      "y": 5,
      "z": 2,
      "name": "Soil_Dirt"
    },
    {
      "x": -3,
      "y": 6,
      "z": 2,
      "name": "Soil_Grass_Deep"
    },
    {
      "x": -3,
      "y": 7,
      "z": 2,
      "name": "Wood_Hardwood_Fence"
    },
    {
      "x": -3,
      "y": 8,
      "z": 2,
      "name": "Empty"
    },
    {
      "x": -3,
      "y": 9,
      "z": 2,
      "name": "Empty"
    },
    {
      "x": -2,
      "y": 2,
      "z": -6,
      "name": "Soil_Dirt"
    },
    {
      "x": -2,
      "y": 3,
      "z": -6,
      "name": "Soil_Dirt"
    },
    {
      "x": -2,
      "y": 4,
      "z": -6,
      "name": "Soil_Dirt"
    },
    {
      "x": -2,
      "y": 5,
      "z": -6,
      "name": "Soil_Dirt"
    },
    {
      "x": -2,
      "y": 6,
      "z": -6,
      "name": "Soil_Dirt"
    },
    {
      "x": -2,
      "y": 7,
      "z": -6,
      "name": "Wood_Hardwood_Fence",
      "rotation": 2
    },
    {
      "x": -2,
      "y": 8,
      "z": -6,
      "name": "Empty"
    },
    {
      "x": -2,
      "y": 9,
      "z": -6,
      "name": "Empty"
    },
    {
      "x": -2,
      "y": 1,
      "z": -5,
      "name": "Soil_Dirt"
    },
    {
      "x": -2,
      "y": 2,
      "z": -5,
      "name": "Soil_Dirt"
    },
    {
      "x": -2,
      "y": 3,
      "z": -5,
      "name": "Soil_Dirt"
    },
    {
      "x": -2,
      "y": 4,
      "z": -5,
      "name": "Soil_Dirt"
    },
    {
      "x": -2,
      "y": 5,
      "z": -5,
      "name": "Soil_Dirt"
    },
    {
      "x": -2,
      "y": 6,
      "z": -5,
      "name": "Soil_Dirt_Tilled",
      "components": {
        "Components": {
          "TilledSoil": {
            "Version": 1,
            "DecayTime": "0001-01-02T22:45:01Z"
          }
        }
      }
    },
    {
      "x": -2,
      "y": 7,
      "z": -5,
      "name": "Empty"
    },
    {
      "x": -2,
      "y": 8,
      "z": -5,
      "name": "Empty"
    },
    {
      "x": -2,
      "y": 9,
      "z": -5,
      "name": "Empty"
    },
    {
      "x": -2,
      "y": 1,
      "z": -4,
      "name": "Soil_Dirt"
    },
    {
      "x": -2,
      "y": 2,
      "z": -4,
      "name": "Soil_Dirt"
    },
    {
      "x": -2,
      "y": 3,
      "z": -4,
      "name": "Soil_Dirt"
    },
    {
      "x": -2,
      "y": 4,
      "z": -4,
      "name": "Soil_Dirt"
    },
    {
      "x": -2,
      "y": 5,
      "z": -4,
      "name": "Soil_Dirt"
    },
    {
      "x": -2,
      "y": 6,
      "z": -4,
      "name": "Soil_Mud_Dry"
    },
    {
      "x": -2,
      "y": 7,
      "z": -4,
      "name": "Empty"
    },
    {
      "x": -2,
      "y": 8,
      "z": -4,
      "name": "Empty"
    },
    {
      "x": -2,
      "y": 9,
      "z": -4,
      "name": "Empty"
    },
    {
      "x": -2,
      "y": 1,
      "z": -3,
      "name": "Soil_Dirt"
    },
    {
      "x": -2,
      "y": 2,
      "z": -3,
      "name": "Soil_Dirt"
    },
    {
      "x": -2,
      "y": 3,
      "z": -3,
      "name": "Soil_Dirt"
    },
    {
      "x": -2,
      "y": 4,
      "z": -3,
      "name": "Soil_Dirt"
    },
    {
      "x": -2,
      "y": 5,
      "z": -3,
      "name": "Soil_Dirt"
    },
    {
      "x": -2,
      "y": 6,
      "z": -3,
      "name": "Soil_Mud_Dry"
    },
    {
      "x": -2,
      "y": 7,
      "z": -3,
      "name": "Empty"
    },
    {
      "x": -2,
      "y": 8,
      "z": -3,
      "name": "Empty"
    },
    {
      "x": -2,
      "y": 9,
      "z": -3,
      "name": "Empty"
    },
    {
      "x": -2,
      "y": 1,
      "z": -2,
      "name": "Soil_Dirt"
    },
    {
      "x": -2,
      "y": 2,
      "z": -2,
      "name": "Soil_Dirt"
    },
    {
      "x": -2,
      "y": 3,
      "z": -2,
      "name": "Soil_Dirt"
    },
    {
      "x": -2,
      "y": 4,
      "z": -2,
      "name": "Soil_Dirt"
    },
    {
      "x": -2,
      "y": 5,
      "z": -2,
      "name": "Soil_Dirt"
    },
    {
      "x": -2,
      "y": 6,
      "z": -2,
      "name": "Soil_Mud_Dry"
    },
    {
      "x": -2,
      "y": 7,
      "z": -2,
      "name": "Empty"
    },
    {
      "x": -2,
      "y": 8,
      "z": -2,
      "name": "Empty"
    },
    {
      "x": -2,
      "y": 9,
      "z": -2,
      "name": "Empty"
    },
    {
      "x": -2,
      "y": 1,
      "z": -1,
      "name": "Soil_Dirt"
    },
    {
      "x": -2,
      "y": 2,
      "z": -1,
      "name": "Soil_Dirt"
    },
    {
      "x": -2,
      "y": 3,
      "z": -1,
      "name": "Soil_Dirt"
    },
    {
      "x": -2,
      "y": 4,
      "z": -1,
      "name": "Soil_Dirt"
    },
    {
      "x": -2,
      "y": 5,
      "z": -1,
      "name": "Soil_Dirt"
    },
    {
      "x": -2,
      "y": 6,
      "z": -1,
      "name": "Soil_Mud_Dry"
    },
    {
      "x": -2,
      "y": 7,
      "z": -1,
      "name": "Empty"
    },
    {
      "x": -2,
      "y": 8,
      "z": -1,
      "name": "Empty"
    },
    {
      "x": -2,
      "y": 9,
      "z": -1,
      "name": "Empty"
    },
    {
      "x": -2,
      "y": 1,
      "z": 0,
      "name": "Soil_Dirt"
    },
    {
      "x": -2,
      "y": 2,
      "z": 0,
      "name": "Soil_Dirt"
    },
    {
      "x": -2,
      "y": 3,
      "z": 0,
      "name": "Soil_Dirt"
    },
    {
      "x": -2,
      "y": 4,
      "z": 0,
      "name": "Soil_Dirt"
    },
    {
      "x": -2,
      "y": 5,
      "z": 0,
      "name": "Soil_Dirt"
    },
    {
      "x": -2,
      "y": 6,
      "z": 0,
      "name": "Soil_Dirt"
    },
    {
      "x": -2,
      "y": 7,
      "z": 0,
      "name": "Empty"
    },
    {
      "x": -2,
      "y": 8,
      "z": 0,
      "name": "Empty"
    },
    {
      "x": -2,
      "y": 9,
      "z": 0,
      "name": "Empty"
    },
    {
      "x": -2,
      "y": 1,
      "z": 1,
      "name": "Soil_Dirt"
    },
    {
      "x": -2,
      "y": 2,
      "z": 1,
      "name": "Soil_Dirt"
    },
    {
      "x": -2,
      "y": 3,
      "z": 1,
      "name": "Soil_Dirt"
    },
    {
      "x": -2,
      "y": 4,
      "z": 1,
      "name": "Soil_Dirt"
    },
    {
      "x": -2,
      "y": 5,
      "z": 1,
      "name": "Soil_Dirt"
    },
    {
      "x": -2,
      "y": 6,
      "z": 1,
      "name": "Soil_Dirt"
    },
    {
      "x": -2,
      "y": 7,
      "z": 1,
      "name": "Empty"
    },
    {
      "x": -2,
      "y": 8,
      "z": 1,
      "name": "Empty"
    },
    {
      "x": -2,
      "y": 9,
      "z": 1,
      "name": "Empty"
    },
    {
      "x": -2,
      "y": 2,
      "z": 2,
      "name": "Soil_Dirt"
    },
    {
      "x": -2,
      "y": 3,
      "z": 2,
      "name": "Soil_Dirt"
    },
    {
      "x": -2,
      "y": 4,
      "z": 2,
      "name": "Soil_Dirt"
    },
    {
      "x": -2,
      "y": 5,
      "z": 2,
      "name": "Soil_Dirt"
    },
    {
      "x": -2,
      "y": 6,
      "z": 2,
      "name": "Soil_Dirt"
    },
    {
      "x": -2,
      "y": 7,
      "z": 2,
      "name": "Wood_Hardwood_Fence"
    },
    {
      "x": -2,
      "y": 8,
      "z": 2,
      "name": "Empty"
    },
    {
      "x": -2,
      "y": 9,
      "z": 2,
      "name": "Empty"
    },
    {
      "x": -1,
      "y": 4,
      "z": -7,
      "name": "Soil_Dirt"
    },
    {
      "x": -1,
      "y": 5,
      "z": -7,
      "name": "Soil_Dirt"
    },
    {
      "x": -1,
      "y": 6,
      "z": -7,
      "name": "Soil_Dirt_Tilled",
      "components": {
        "Components": {
          "TilledSoil": {
            "Version": 1,
            "DecayTime": "0001-01-02T23:46:50Z"
          }
        }
      }
    },
    {
      "x": -1,
      "y": 2,
      "z": -6,
      "name": "Soil_Dirt"
    },
    {
      "x": -1,
      "y": 3,
      "z": -6,
      "name": "Soil_Dirt"
    },
    {
      "x": -1,
      "y": 4,
      "z": -6,
      "name": "Soil_Dirt"
    },
    {
      "x": -1,
      "y": 5,
      "z": -6,
      "name": "Soil_Dirt"
    },
    {
      "x": -1,
      "y": 6,
      "z": -6,
      "name": "Soil_Dirt_Tilled",
      "components": {
        "Components": {
          "TilledSoil": {
            "Version": 1,
            "DecayTime": "0001-01-02T23:13:47Z"
          }
        }
      }
    },
    {
      "x": -1,
      "y": 7,
      "z": -6,
      "name": "Wood_Hardwood_Fence",
      "rotation": 2
    },
    {
      "x": -1,
      "y": 8,
      "z": -6,
      "name": "Empty"
    },
    {
      "x": -1,
      "y": 9,
      "z": -6,
      "name": "Empty"
    },
    {
      "x": -1,
      "y": 1,
      "z": -5,
      "name": "Soil_Dirt"
    },
    {
      "x": -1,
      "y": 2,
      "z": -5,
      "name": "Soil_Dirt"
    },
    {
      "x": -1,
      "y": 3,
      "z": -5,
      "name": "Soil_Dirt"
    },
    {
      "x": -1,
      "y": 4,
      "z": -5,
      "name": "Soil_Dirt"
    },
    {
      "x": -1,
      "y": 5,
      "z": -5,
      "name": "Soil_Dirt"
    },
    {
      "x": -1,
      "y": 6,
      "z": -5,
      "name": "Soil_Dirt_Tilled",
      "components": {
        "Components": {
          "TilledSoil": {
            "Version": 1,
            "DecayTime": "0001-01-02T17:11:00Z"
          }
        }
      }
    },
    {
      "x": -1,
      "y": 7,
      "z": -5,
      "name": "Empty"
    },
    {
      "x": -1,
      "y": 8,
      "z": -5,
      "name": "Empty"
    },
    {
      "x": -1,
      "y": 9,
      "z": -5,
      "name": "Empty"
    },
    {
      "x": -1,
      "y": 1,
      "z": -4,
      "name": "Soil_Dirt"
    },
    {
      "x": -1,
      "y": 2,
      "z": -4,
      "name": "Soil_Dirt"
    },
    {
      "x": -1,
      "y": 3,
      "z": -4,
      "name": "Soil_Dirt"
    },
    {
      "x": -1,
      "y": 4,
      "z": -4,
      "name": "Soil_Dirt"
    },
    {
      "x": -1,
      "y": 5,
      "z": -4,
      "name": "Soil_Dirt"
    },
    {
      "x": -1,
      "y": 6,
      "z": -4,
      "name": "Soil_Mud_Dry"
    },
    {
      "x": -1,
      "y": 7,
      "z": -4,
      "name": "Empty"
    },
    {
      "x": -1,
      "y": 8,
      "z": -4,
      "name": "Empty"
    },
    {
      "x": -1,
      "y": 9,
      "z": -4,
      "name": "Empty"
    },
    {
      "x": -1,
      "y": 1,
      "z": -3,
      "name": "Soil_Dirt"
    },
    {
      "x": -1,
      "y": 2,
      "z": -3,
      "name": "Soil_Dirt"
    },
    {
      "x": -1,
      "y": 3,
      "z": -3,
      "name": "Soil_Dirt"
    },
    {
      "x": -1,
      "y": 4,
      "z": -3,
      "name": "Soil_Dirt"
    },
    {
      "x": -1,
      "y": 5,
      "z": -3,
      "name": "Soil_Dirt"
    },
    {
      "x": -1,
      "y": 6,
      "z": -3,
      "name": "Soil_Mud_Dry"
    },
    {
      "x": -1,
      "y": 7,
      "z": -3,
      "name": "Empty"
    },
    {
      "x": -1,
      "y": 8,
      "z": -3,
      "name": "Empty"
    },
    {
      "x": -1,
      "y": 9,
      "z": -3,
      "name": "Empty"
    },
    {
      "x": -1,
      "y": 1,
      "z": -2,
      "name": "Soil_Dirt"
    },
    {
      "x": -1,
      "y": 2,
      "z": -2,
      "name": "Soil_Dirt"
    },
    {
      "x": -1,
      "y": 3,
      "z": -2,
      "name": "Soil_Dirt"
    },
    {
      "x": -1,
      "y": 4,
      "z": -2,
      "name": "Soil_Dirt"
    },
    {
      "x": -1,
      "y": 5,
      "z": -2,
      "name": "Soil_Dirt"
    },
    {
      "x": -1,
      "y": 6,
      "z": -2,
      "name": "Soil_Mud_Dry"
    },
    {
      "x": -1,
      "y": 7,
      "z": -2,
      "name": "Empty"
    },
    {
      "x": -1,
      "y": 8,
      "z": -2,
      "name": "Empty"
    },
    {
      "x": -1,
      "y": 9,
      "z": -2,
      "name": "Empty"
    },
    {
      "x": -1,
      "y": 1,
      "z": -1,
      "name": "Soil_Dirt"
    },
    {
      "x": -1,
      "y": 2,
      "z": -1,
      "name": "Soil_Dirt"
    },
    {
      "x": -1,
      "y": 3,
      "z": -1,
      "name": "Soil_Dirt"
    },
    {
      "x": -1,
      "y": 4,
      "z": -1,
      "name": "Soil_Dirt"
    },
    {
      "x": -1,
      "y": 5,
      "z": -1,
      "name": "Soil_Dirt"
    },
    {
      "x": -1,
      "y": 6,
      "z": -1,
      "name": "Soil_Mud_Dry"
    },
    {
      "x": -1,
      "y": 7,
      "z": -1,
      "name": "Empty"
    },
    {
      "x": -1,
      "y": 8,
      "z": -1,
      "name": "Empty"
    },
    {
      "x": -1,
      "y": 9,
      "z": -1,
      "name": "Empty"
    },
    {
      "x": -1,
      "y": 1,
      "z": 0,
      "name": "Soil_Dirt"
    },
    {
      "x": -1,
      "y": 2,
      "z": 0,
      "name": "Soil_Dirt"
    },
    {
      "x": -1,
      "y": 3,
      "z": 0,
      "name": "Soil_Dirt"
    },
    {
      "x": -1,
      "y": 4,
      "z": 0,
      "name": "Soil_Dirt"
    },
    {
      "x": -1,
      "y": 5,
      "z": 0,
      "name": "Soil_Dirt"
    },
    {
      "x": -1,
      "y": 6,
      "z": 0,
      "name": "Soil_Mud_Dry"
    },
    {
      "x": -1,
      "y": 7,
      "z": 0,
      "name": "Empty"
    },
    {
      "x": -1,
      "y": 8,
      "z": 0,
      "name": "Empty"
    },
    {
      "x": -1,
      "y": 9,
      "z": 0,
      "name": "Empty"
    },
    {
      "x": -1,
      "y": 1,
      "z": 1,
      "name": "Soil_Dirt"
    },
    {
      "x": -1,
      "y": 2,
      "z": 1,
      "name": "Soil_Dirt"
    },
    {
      "x": -1,
      "y": 3,
      "z": 1,
      "name": "Soil_Dirt"
    },
    {
      "x": -1,
      "y": 4,
      "z": 1,
      "name": "Soil_Dirt"
    },
    {
      "x": -1,
      "y": 5,
      "z": 1,
      "name": "Soil_Dirt"
    },
    {
      "x": -1,
      "y": 6,
      "z": 1,
      "name": "Soil_Dirt"
    },
    {
      "x": -1,
      "y": 7,
      "z": 1,
      "name": "Empty"
    },
    {
      "x": -1,
      "y": 8,
      "z": 1,
      "name": "Empty"
    },
    {
      "x": -1,
      "y": 9,
      "z": 1,
      "name": "Empty"
    },
    {
      "x": -1,
      "y": 1,
      "z": 2,
      "name": "Soil_Dirt"
    },
    {
      "x": -1,
      "y": 2,
      "z": 2,
      "name": "Soil_Dirt"
    },
    {
      "x": -1,
      "y": 3,
      "z": 2,
      "name": "Soil_Dirt"
    },
    {
      "x": -1,
      "y": 4,
      "z": 2,
      "name": "Soil_Dirt"
    },
    {
      "x": -1,
      "y": 5,
      "z": 2,
      "name": "Soil_Dirt"
    },
    {
      "x": -1,
      "y": 6,
      "z": 2,
      "name": "Soil_Dirt_Tilled",
      "components": {
        "Components": {
          "TilledSoil": {
            "Version": 1,
            "DecayTime": "0001-01-02T19:02:54Z"
          }
        }
      }
    },
    {
      "x": -1,
      "y": 7,
      "z": 2,
      "name": "*Wood_Hardwood_Fence_State_Definitions_Corner"
    },
    {
      "x": -1,
      "y": 8,
      "z": 2,
      "name": "Empty"
    },
    {
      "x": -1,
      "y": 9,
      "z": 2,
      "name": "Empty"
    },
    {
      "x": -1,
      "y": 1,
      "z": 3,
      "name": "Soil_Dirt"
    },
    {
      "x": -1,
      "y": 2,
      "z": 3,
      "name": "Soil_Dirt"
    },
    {
      "x": -1,
      "y": 3,
      "z": 3,
      "name": "Soil_Dirt"
    },
    {
      "x": -1,
      "y": 4,
      "z": 3,
      "name": "Soil_Dirt"
    },
    {
      "x": -1,
      "y": 5,
      "z": 3,
      "name": "Soil_Dirt"
    },
    {
      "x": -1,
      "y": 6,
      "z": 3,
      "name": "Soil_Dirt_Tilled",
      "components": {
        "Components": {
          "TilledSoil": {
            "Version": 1,
            "DecayTime": "0001-01-02T17:51:06Z"
          }
        }
      }
    },
    {
      "x": -1,
      "y": 7,
      "z": 3,
      "name": "Wood_Hardwood_Fence",
      "rotation": 3
    },
    {
      "x": -1,
      "y": 8,
      "z": 3,
      "name": "Empty"
    },
    {
      "x": -1,
      "y": 9,
      "z": 3,
      "name": "Empty"
    },
    {
      "x": -1,
      "y": 2,
      "z": 4,
      "name": "Soil_Dirt"
    },
    {
      "x": -1,
      "y": 3,
      "z": 4,
      "name": "Soil_Dirt"
    },
    {
      "x": -1,
      "y": 4,
      "z": 4,
      "name": "Soil_Dirt"
    },
    {
      "x": -1,
      "y": 5,
      "z": 4,
      "name": "Soil_Dirt"
    },
    {
      "x": -1,
      "y": 6,
      "z": 4,
      "name": "Soil_Dirt_Tilled",
      "components": {
        "Components": {
          "TilledSoil": {
            "Version": 1,
            "DecayTime": "0001-01-02T19:53:59Z"
          }
        }
      }
    },
    {
      "x": -1,
      "y": 7,
      "z": 4,
      "name": "Wood_Hardwood_Fence",
      "rotation": 3
    },
    {
      "x": -1,
      "y": 8,
      "z": 4,
      "name": "Empty"
    },
    {
      "x": -1,
      "y": 9,
      "z": 4,
      "name": "Empty"
    },
    {
      "x": -1,
      "y": 3,
      "z": 5,
      "name": "Soil_Dirt"
    },
    {
      "x": -1,
      "y": 4,
      "z": 5,
      "name": "Soil_Dirt"
    },
    {
      "x": -1,
      "y": 5,
      "z": 5,
      "name": "Soil_Dirt"
    },
    {
      "x": -1,
      "y": 6,
      "z": 5,
      "name": "Soil_Dirt_Tilled",
      "components": {
        "Components": {
          "TilledSoil": {
            "Version": 1,
            "DecayTime": "0001-01-02T18:26:55Z"
          }
        }
      }
    },
    {
      "x": -1,
      "y": 7,
      "z": 5,
      "name": "Wood_Hardwood_Fence",
      "rotation": 3
    },
    {
      "x": -1,
      "y": 8,
      "z": 5,
      "name": "Empty"
    },
    {
      "x": -1,
      "y": 9,
      "z": 5,
      "name": "Empty"
    },
    {
      "x": -1,
      "y": 4,
      "z": 6,
      "name": "Soil_Dirt"
    },
    {
      "x": -1,
      "y": 5,
      "z": 6,
      "name": "Soil_Dirt"
    },
    {
      "x": -1,
      "y": 6,
      "z": 6,
      "name": "Soil_Dirt"
    },
    {
      "x": -1,
      "y": 7,
      "z": 6,
      "name": "*Wood_Hardwood_Fence_State_Definitions_Corner",
      "rotation": 2
    },
    {
      "x": -1,
      "y": 8,
      "z": 6,
      "name": "Empty"
    },
    {
      "x": -1,
      "y": 9,
      "z": 6,
      "name": "Empty"
    },
    {
      "x": 0,
      "y": 3,
      "z": -7,
      "name": "Soil_Dirt"
    },
    {
      "x": 0,
      "y": 4,
      "z": -7,
      "name": "Soil_Dirt"
    },
    {
      "x": 0,
      "y": 5,
      "z": -7,
      "name": "Soil_Dirt"
    },
    {
      "x": 0,
      "y": 6,
      "z": -7,
      "name": "Soil_Dirt_Tilled",
      "components": {
        "Components": {
          "TilledSoil": {
            "Version": 1,
            "DecayTime": "0001-01-02T17:16:01Z"
          }
        }
      }
    },
    {
      "x": 0,
      "y": 3,
      "z": -6,
      "name": "Soil_Dirt"
    },
    {
      "x": 0,
      "y": 4,
      "z": -6,
      "name": "Soil_Dirt"
    },
    {
      "x": 0,
      "y": 5,
      "z": -6,
      "name": "Soil_Dirt"
    },
    {
      "x": 0,
      "y": 6,
      "z": -6,
      "name": "Soil_Dirt_Tilled",
      "components": {
        "Components": {
          "TilledSoil": {
            "Version": 1,
            "DecayTime": "0001-01-02T19:01:49Z"
          }
        }
      }
    },
    {
      "x": 0,
      "y": 7,
      "z": -6,
      "name": "Wood_Hardwood_Fence",
      "rotation": 2
    },
    {
      "x": 0,
      "y": 8,
      "z": -6,
      "name": "Empty"
    },
    {
      "x": 0,
      "y": 9,
      "z": -6,
      "name": "Empty"
    },
    {
      "x": 0,
      "y": 2,
      "z": -5,
      "name": "Soil_Dirt"
    },
    {
      "x": 0,
      "y": 3,
      "z": -5,
      "name": "Soil_Dirt"
    },
    {
      "x": 0,
      "y": 4,
      "z": -5,
      "name": "Soil_Dirt"
    },
    {
      "x": 0,
      "y": 5,
      "z": -5,
      "name": "Soil_Dirt"
    },
    {
      "x": 0,
      "y": 6,
      "z": -5,
      "name": "Soil_Dirt_Tilled",
      "components": {
        "Components": {
          "TilledSoil": {
            "Version": 1,
            "DecayTime": "0001-01-02T18:34:21Z"
          }
        }
      }
    },
    {
      "x": 0,
      "y": 7,
      "z": -5,
      "name": "*Plant_Crop_Carrot_Block_State_Definitions_Stage1",
      "components": {
        "Components": {
          "FarmingBlock": {
            "GrowthProgress": 1.0,
            "LastTickGameTime": "0001-01-01T12:00:00Z"
          }
        }
      }
    },
    {
      "x": 0,
      "y": 8,
      "z": -5,
      "name": "Empty"
    },
    {
      "x": 0,
      "y": 9,
      "z": -5,
      "name": "Empty"
    },
    {
      "x": 0,
      "y": 1,
      "z": -4,
      "name": "Soil_Dirt"
    },
    {
      "x": 0,
      "y": 2,
      "z": -4,
      "name": "Soil_Dirt"
    },
    {
      "x": 0,
      "y": 3,
      "z": -4,
      "name": "Soil_Dirt"
    },
    {
      "x": 0,
      "y": 4,
      "z": -4,
      "name": "Soil_Dirt"
    },
    {
      "x": 0,
      "y": 5,
      "z": -4,
      "name": "Soil_Dirt"
    },
    {
      "x": 0,
      "y": 6,
      "z": -4,
      "name": "Soil_Dirt_Tilled",
      "components": {
        "Components": {
          "TilledSoil": {
            "Version": 1,
            "DecayTime": "0001-01-02T19:27:41Z"
          }
        }
      }
    },
    {
      "x": 0,
      "y": 7,
      "z": -4,
      "name": "Empty"
    },
    {
      "x": 0,
      "y": 8,
      "z": -4,
      "name": "Empty"
    },
    {
      "x": 0,
      "y": 9,
      "z": -4,
      "name": "Empty"
    },
    {
      "x": 0,
      "y": 1,
      "z": -3,
      "name": "Soil_Dirt"
    },
    {
      "x": 0,
      "y": 2,
      "z": -3,
      "name": "Soil_Dirt"
    },
    {
      "x": 0,
      "y": 3,
      "z": -3,
      "name": "Soil_Dirt"
    },
    {
      "x": 0,
      "y": 4,
      "z": -3,
      "name": "Soil_Dirt"
    },
    {
      "x": 0,
      "y": 5,
      "z": -3,
      "name": "Soil_Dirt"
    },
    {
      "x": 0,
      "y": 6,
      "z": -3,
      "name": "Soil_Dirt_Tilled",
      "components": {
        "Components": {
          "TilledSoil": {
            "Version": 1,
            "DecayTime": "0001-01-02T19:27:08Z"
          }
        }
      }
    },
    {
      "x": 0,
      "y": 7,
      "z": -3,
      "name": "*Plant_Crop_Carrot_Block_State_Definitions_Stage1",
      "components": {
        "Components": {
          "FarmingBlock": {
            "GrowthProgress": 1.0,
            "LastTickGameTime": "0001-01-01T12:00:00Z"
          }
        }
      }
    },
    {
      "x": 0,
      "y": 8,
      "z": -3,
      "name": "Empty"
    },
    {
      "x": 0,
      "y": 9,
      "z": -3,
      "name": "Empty"
    },
    {
      "x": 0,
      "y": 1,
      "z": -2,
      "name": "Soil_Dirt"
    },
    {
      "x": 0,
      "y": 2,
      "z": -2,
      "name": "Soil_Dirt"
    },
    {
      "x": 0,
      "y": 3,
      "z": -2,
      "name": "Soil_Dirt"
    },
    {
      "x": 0,
      "y": 4,
      "z": -2,
      "name": "Soil_Dirt"
    },
    {
      "x": 0,
      "y": 5,
      "z": -2,
      "name": "Soil_Dirt"
    },
    {
      "x": 0,
      "y": 6,
      "z": -2,
      "name": "Soil_Mud_Dry"
    },
    {
      "x": 0,
      "y": 7,
      "z": -2,
      "name": "Empty"
    },
    {
      "x": 0,
      "y": 8,
      "z": -2,
      "name": "Empty"
    },
    {
      "x": 0,
      "y": 9,
      "z": -2,
      "name": "Empty"
    },
    {
      "x": 0,
      "y": 1,
      "z": -1,
      "name": "Soil_Dirt"
    },
    {
      "x": 0,
      "y": 2,
      "z": -1,
      "name": "Soil_Dirt"
    },
    {
      "x": 0,
      "y": 3,
      "z": -1,
      "name": "Soil_Dirt"
    },
    {
      "x": 0,
      "y": 4,
      "z": -1,
      "name": "Soil_Dirt"
    },
    {
      "x": 0,
      "y": 5,
      "z": -1,
      "name": "Soil_Dirt"
    },
    {
      "x": 0,
      "y": 6,
      "z": -1,
      "name": "Soil_Mud_Dry"
    },
    {
      "x": 0,
      "y": 7,
      "z": -1,
      "name": "Empty"
    },
    {
      "x": 0,
      "y": 8,
      "z": -1,
      "name": "Empty"
    },
    {
      "x": 0,
      "y": 9,
      "z": -1,
      "name": "Empty"
    },
    {
      "x": 0,
      "y": 1,
      "z": 0,
      "name": "Soil_Dirt"
    },
    {
      "x": 0,
      "y": 2,
      "z": 0,
      "name": "Soil_Dirt"
    },
    {
      "x": 0,
      "y": 3,
      "z": 0,
      "name": "Soil_Dirt"
    },
    {
      "x": 0,
      "y": 4,
      "z": 0,
      "name": "Soil_Dirt"
    },
    {
      "x": 0,
      "y": 5,
      "z": 0,
      "name": "Soil_Dirt"
    },
    {
      "x": 0,
      "y": 6,
      "z": 0,
      "name": "Soil_Dirt"
    },
    {
      "x": 0,
      "y": 7,
      "z": 0,
      "name": "Empty"
    },
    {
      "x": 0,
      "y": 8,
      "z": 0,
      "name": "Empty"
    },
    {
      "x": 0,
      "y": 9,
      "z": 0,
      "name": "Empty"
    },
    {
      "x": 0,
      "y": 1,
      "z": 1,
      "name": "Soil_Dirt"
    },
    {
      "x": 0,
      "y": 2,
      "z": 1,
      "name": "Soil_Dirt"
    },
    {
      "x": 0,
      "y": 3,
      "z": 1,
      "name": "Soil_Dirt"
    },
    {
      "x": 0,
      "y": 4,
      "z": 1,
      "name": "Soil_Dirt"
    },
    {
      "x": 0,
      "y": 5,
      "z": 1,
      "name": "Soil_Dirt"
    },
    {
      "x": 0,
      "y": 6,
      "z": 1,
      "name": "Soil_Dirt"
    },
    {
      "x": 0,
      "y": 7,
      "z": 1,
      "name": "Empty"
    },
    {
      "x": 0,
      "y": 8,
      "z": 1,
      "name": "Empty"
    },
    {
      "x": 0,
      "y": 9,
      "z": 1,
      "name": "Empty"
    },
    {
      "x": 0,
      "y": 1,
      "z": 2,
      "name": "Soil_Dirt"
    },
    {
      "x": 0,
      "y": 2,
      "z": 2,
      "name": "Soil_Dirt"
    },
    {
      "x": 0,
      "y": 3,
      "z": 2,
      "name": "Soil_Dirt"
    },
    {
      "x": 0,
      "y": 4,
      "z": 2,
      "name": "Soil_Dirt"
    },
    {
      "x": 0,
      "y": 5,
      "z": 2,
      "name": "Soil_Dirt"
    },
    {
      "x": 0,
      "y": 6,
      "z": 2,
      "name": "Soil_Dirt_Tilled",
      "components": {
        "Components": {
          "TilledSoil": {
            "Version": 1,
            "DecayTime": "0001-01-02T21:26:10Z"
          }
        }
      }
    },
    {
      "x": 0,
      "y": 7,
      "z": 2,
      "name": "Empty"
    },
    {
      "x": 0,
      "y": 8,
      "z": 2,
      "name": "Empty"
    },
    {
      "x": 0,
      "y": 9,
      "z": 2,
      "name": "Empty"
    },
    {
      "x": 0,
      "y": 1,
      "z": 3,
      "name": "Soil_Dirt"
    },
    {
      "x": 0,
      "y": 2,
      "z": 3,
      "name": "Soil_Dirt"
    },
    {
      "x": 0,
      "y": 3,
      "z": 3,
      "name": "Soil_Dirt"
    },
    {
      "x": 0,
      "y": 4,
      "z": 3,
      "name": "Soil_Dirt"
    },
    {
      "x": 0,
      "y": 5,
      "z": 3,
      "name": "Soil_Dirt"
    },
    {
      "x": 0,
      "y": 6,
      "z": 3,
      "name": "Soil_Dirt_Tilled",
      "components": {
        "Components": {
          "TilledSoil": {
            "Version": 1,
            "DecayTime": "0001-01-02T22:19:43Z"
          }
        }
      }
    },
    {
      "x": 0,
      "y": 7,
      "z": 3,
      "name": "*Plant_Crop_Carrot_Block_State_Definitions_Stage2",
      "components": {
        "Components": {
          "FarmingBlock": {
            "GrowthProgress": 2.0,
            "LastTickGameTime": "0001-01-01T12:00:00Z"
          }
        }
      }
    },
    {
      "x": 0,
      "y": 8,
      "z": 3,
      "name": "Empty"
    },
    {
      "x": 0,
      "y": 9,
      "z": 3,
      "name": "Empty"
    },
    {
      "x": 0,
      "y": 1,
      "z": 4,
      "name": "Soil_Dirt"
    },
    {
      "x": 0,
      "y": 2,
      "z": 4,
      "name": "Soil_Dirt"
    },
    {
      "x": 0,
      "y": 3,
      "z": 4,
      "name": "Soil_Dirt"
    },
    {
      "x": 0,
      "y": 4,
      "z": 4,
      "name": "Soil_Dirt"
    },
    {
      "x": 0,
      "y": 5,
      "z": 4,
      "name": "Soil_Dirt"
    },
    {
      "x": 0,
      "y": 6,
      "z": 4,
      "name": "Soil_Dirt_Tilled",
      "components": {
        "Components": {
          "TilledSoil": {
            "Version": 1,
            "DecayTime": "0001-01-02T23:11:01Z"
          }
        }
      }
    },
    {
      "x": 0,
      "y": 7,
      "z": 4,
      "name": "*Plant_Crop_Carrot_Block_State_Definitions_StageFinal"
    },
    {
      "x": 0,
      "y": 8,
      "z": 4,
      "name": "Empty"
    },
    {
      "x": 0,
      "y": 9,
      "z": 4,
      "name": "Empty"
    },
    {
      "x": 0,
      "y": 2,
      "z": 5,
      "name": "Soil_Dirt"
    },
    {
      "x": 0,
      "y": 3,
      "z": 5,
      "name": "Soil_Dirt"
    },
    {
      "x": 0,
      "y": 4,
      "z": 5,
      "name": "Soil_Dirt"
    },
    {
      "x": 0,
      "y": 5,
      "z": 5,
      "name": "Soil_Dirt"
    },
    {
      "x": 0,
      "y": 6,
      "z": 5,
      "name": "Soil_Dirt"
    },
    {
      "x": 0,
      "y": 7,
      "z": 5,
      "name": "Empty"
    },
    {
      "x": 0,
      "y": 8,
      "z": 5,
      "name": "Empty"
    },
    {
      "x": 0,
      "y": 9,
      "z": 5,
      "name": "Empty"
    },
    {
      "x": 0,
      "y": 4,
      "z": 6,
      "name": "Soil_Dirt"
    },
    {
      "x": 0,
      "y": 5,
      "z": 6,
      "name": "Soil_Dirt"
    },
    {
      "x": 0,
      "y": 6,
      "z": 6,
      "name": "Soil_Dirt"
    },
    {
      "x": 0,
      "y": 7,
      "z": 6,
      "name": "Wood_Hardwood_Fence"
    },
    {
      "x": 0,
      "y": 8,
      "z": 6,
      "name": "Empty"
    },
    {
      "x": 0,
      "y": 9,
      "z": 6,
      "name": "Empty"
    },
    {
      "x": 1,
      "y": 3,
      "z": -6,
      "name": "Soil_Dirt"
    },
    {
      "x": 1,
      "y": 4,
      "z": -6,
      "name": "Soil_Dirt"
    },
    {
      "x": 1,
      "y": 5,
      "z": -6,
      "name": "Soil_Dirt"
    },
    {
      "x": 1,
      "y": 6,
      "z": -6,
      "name": "Soil_Dirt_Tilled",
      "components": {
        "Components": {
          "TilledSoil": {
            "Version": 1,
            "DecayTime": "0001-01-02T20:16:24Z"
          }
        }
      }
    },
    {
      "x": 1,
      "y": 7,
      "z": -6,
      "name": "Wood_Hardwood_Fence",
      "rotation": 2
    },
    {
      "x": 1,
      "y": 8,
      "z": -6,
      "name": "Empty"
    },
    {
      "x": 1,
      "y": 9,
      "z": -6,
      "name": "Empty"
    },
    {
      "x": 1,
      "y": 2,
      "z": -5,
      "name": "Soil_Dirt"
    },
    {
      "x": 1,
      "y": 3,
      "z": -5,
      "name": "Soil_Dirt"
    },
    {
      "x": 1,
      "y": 4,
      "z": -5,
      "name": "Soil_Dirt"
    },
    {
      "x": 1,
      "y": 5,
      "z": -5,
      "name": "Soil_Dirt"
    },
    {
      "x": 1,
      "y": 6,
      "z": -5,
      "name": "Soil_Dirt_Tilled",
      "components": {
        "Components": {
          "TilledSoil": {
            "Version": 1,
            "DecayTime": "0001-01-02T23:15:59Z"
          }
        }
      }
    },
    {
      "x": 1,
      "y": 7,
      "z": -5,
      "name": "*Plant_Crop_Carrot_Block_State_Definitions_StageFinal"
    },
    {
      "x": 1,
      "y": 8,
      "z": -5,
      "name": "Empty"
    },
    {
      "x": 1,
      "y": 9,
      "z": -5,
      "name": "Empty"
    },
    {
      "x": 1,
      "y": 1,
      "z": -4,
      "name": "Soil_Dirt"
    },
    {
      "x": 1,
      "y": 2,
      "z": -4,
      "name": "Soil_Dirt"
    },
    {
      "x": 1,
      "y": 3,
      "z": -4,
      "name": "Soil_Dirt"
    },
    {
      "x": 1,
      "y": 4,
      "z": -4,
      "name": "Soil_Dirt"
    },
    {
      "x": 1,
      "y": 5,
      "z": -4,
      "name": "Soil_Dirt"
    },
    {
      "x": 1,
      "y": 6,
      "z": -4,
      "name": "Soil_Dirt_Tilled",
      "components": {
        "Components": {
          "TilledSoil": {
            "Version": 1,
            "DecayTime": "0001-01-02T22:00:08Z"
          }
        }
      }
    },
    {
      "x": 1,
      "y": 7,
      "z": -4,
      "name": "*Plant_Crop_Carrot_Block_State_Definitions_StageFinal"
    },
    {
      "x": 1,
      "y": 8,
      "z": -4,
      "name": "Empty"
    },
    {
      "x": 1,
      "y": 9,
      "z": -4,
      "name": "Empty"
    },
    {
      "x": 1,
      "y": 1,
      "z": -3,
      "name": "Soil_Dirt"
    },
    {
      "x": 1,
      "y": 2,
      "z": -3,
      "name": "Soil_Dirt"
    },
    {
      "x": 1,
      "y": 3,
      "z": -3,
      "name": "Soil_Dirt"
    },
    {
      "x": 1,
      "y": 4,
      "z": -3,
      "name": "Soil_Dirt"
    },
    {
      "x": 1,
      "y": 5,
      "z": -3,
      "name": "Soil_Dirt"
    },
    {
      "x": 1,
      "y": 6,
      "z": -3,
      "name": "Soil_Dirt_Tilled",
      "components": {
        "Components": {
          "TilledSoil": {
            "Version": 1,
            "DecayTime": "0001-01-02T20:50:17Z"
          }
        }
      }
    },
    {
      "x": 1,
      "y": 7,
      "z": -3,
      "name": "Empty"
    },
    {
      "x": 1,
      "y": 8,
      "z": -3,
      "name": "Empty"
    },
    {
      "x": 1,
      "y": 9,
      "z": -3,
      "name": "Empty"
    },
    {
      "x": 1,
      "y": 1,
      "z": -2,
      "name": "Soil_Dirt"
    },
    {
      "x": 1,
      "y": 2,
      "z": -2,
      "name": "Soil_Dirt"
    },
    {
      "x": 1,
      "y": 3,
      "z": -2,
      "name": "Soil_Dirt"
    },
    {
      "x": 1,
      "y": 4,
      "z": -2,
      "name": "Soil_Dirt"
    },
    {
      "x": 1,
      "y": 5,
      "z": -2,
      "name": "Soil_Dirt"
    },
    {
      "x": 1,
      "y": 6,
      "z": -2,
      "name": "Soil_Mud_Dry"
    },
    {
      "x": 1,
      "y": 7,
      "z": -2,
      "name": "Empty"
    },
    {
      "x": 1,
      "y": 8,
      "z": -2,
      "name": "Empty"
    },
    {
      "x": 1,
      "y": 9,
      "z": -2,
      "name": "Empty"
    },
    {
      "x": 1,
      "y": 1,
      "z": -1,
      "name": "Soil_Dirt"
    },
    {
      "x": 1,
      "y": 2,
      "z": -1,
      "name": "Soil_Dirt"
    },
    {
      "x": 1,
      "y": 3,
      "z": -1,
      "name": "Soil_Dirt"
    },
    {
      "x": 1,
      "y": 4,
      "z": -1,
      "name": "Soil_Dirt"
    },
    {
      "x": 1,
      "y": 5,
      "z": -1,
      "name": "Soil_Dirt"
    },
    {
      "x": 1,
      "y": 6,
      "z": -1,
      "name": "Soil_Mud_Dry"
    },
    {
      "x": 1,
      "y": 7,
      "z": -1,
      "name": "Empty"
    },
    {
      "x": 1,
      "y": 8,
      "z": -1,
      "name": "Empty"
    },
    {
      "x": 1,
      "y": 9,
      "z": -1,
      "name": "Empty"
    },
    {
      "x": 1,
      "y": 1,
      "z": 0,
      "name": "Soil_Dirt"
    },
    {
      "x": 1,
      "y": 2,
      "z": 0,
      "name": "Soil_Dirt"
    },
    {
      "x": 1,
      "y": 3,
      "z": 0,
      "name": "Soil_Dirt"
    },
    {
      "x": 1,
      "y": 4,
      "z": 0,
      "name": "Soil_Dirt"
    },
    {
      "x": 1,
      "y": 5,
      "z": 0,
      "name": "Soil_Dirt"
    },
    {
      "x": 1,
      "y": 6,
      "z": 0,
      "name": "Soil_Dirt"
    },
    {
      "x": 1,
      "y": 7,
      "z": 0,
      "name": "Empty"
    },
    {
      "x": 1,
      "y": 8,
      "z": 0,
      "name": "Empty"
    },
    {
      "x": 1,
      "y": 9,
      "z": 0,
      "name": "Empty"
    },
    {
      "x": 1,
      "y": 1,
      "z": 1,
      "name": "Soil_Dirt"
    },
    {
      "x": 1,
      "y": 2,
      "z": 1,
      "name": "Soil_Dirt"
    },
    {
      "x": 1,
      "y": 3,
      "z": 1,
      "name": "Soil_Dirt"
    },
    {
      "x": 1,
      "y": 4,
      "z": 1,
      "name": "Soil_Dirt"
    },
    {
      "x": 1,
      "y": 5,
      "z": 1,
      "name": "Soil_Dirt"
    },
    {
      "x": 1,
      "y": 6,
      "z": 1,
      "name": "Soil_Dirt"
    },
    {
      "x": 1,
      "y": 7,
      "z": 1,
      "name": "Empty"
    },
    {
      "x": 1,
      "y": 8,
      "z": 1,
      "name": "Empty"
    },
    {
      "x": 1,
      "y": 9,
      "z": 1,
      "name": "Empty"
    },
    {
      "x": 1,
      "y": 1,
      "z": 2,
      "name": "Soil_Dirt"
    },
    {
      "x": 1,
      "y": 2,
      "z": 2,
      "name": "Soil_Dirt"
    },
    {
      "x": 1,
      "y": 3,
      "z": 2,
      "name": "Soil_Dirt"
    },
    {
      "x": 1,
      "y": 4,
      "z": 2,
      "name": "Soil_Dirt"
    },
    {
      "x": 1,
      "y": 5,
      "z": 2,
      "name": "Soil_Dirt"
    },
    {
      "x": 1,
      "y": 6,
      "z": 2,
      "name": "Soil_Dirt"
    },
    {
      "x": 1,
      "y": 7,
      "z": 2,
      "name": "Empty"
    },
    {
      "x": 1,
      "y": 8,
      "z": 2,
      "name": "Empty"
    },
    {
      "x": 1,
      "y": 9,
      "z": 2,
      "name": "Empty"
    },
    {
      "x": 1,
      "y": 1,
      "z": 3,
      "name": "Soil_Dirt"
    },
    {
      "x": 1,
      "y": 2,
      "z": 3,
      "name": "Soil_Dirt"
    },
    {
      "x": 1,
      "y": 3,
      "z": 3,
      "name": "Soil_Dirt"
    },
    {
      "x": 1,
      "y": 4,
      "z": 3,
      "name": "Soil_Dirt"
    },
    {
      "x": 1,
      "y": 5,
      "z": 3,
      "name": "Soil_Dirt"
    },
    {
      "x": 1,
      "y": 6,
      "z": 3,
      "name": "Soil_Dirt_Tilled",
      "components": {
        "Components": {
          "TilledSoil": {
            "Version": 1,
            "DecayTime": "0001-01-02T20:43:01Z"
          }
        }
      }
    },
    {
      "x": 1,
      "y": 7,
      "z": 3,
      "name": "Empty"
    },
    {
      "x": 1,
      "y": 8,
      "z": 3,
      "name": "Empty"
    },
    {
      "x": 1,
      "y": 9,
      "z": 3,
      "name": "Empty"
    },
    {
      "x": 1,
      "y": 1,
      "z": 4,
      "name": "Soil_Dirt"
    },
    {
      "x": 1,
      "y": 2,
      "z": 4,
      "name": "Soil_Dirt"
    },
    {
      "x": 1,
      "y": 3,
      "z": 4,
      "name": "Soil_Dirt"
    },
    {
      "x": 1,
      "y": 4,
      "z": 4,
      "name": "Soil_Dirt"
    },
    {
      "x": 1,
      "y": 5,
      "z": 4,
      "name": "Soil_Dirt"
    },
    {
      "x": 1,
      "y": 6,
      "z": 4,
      "name": "Soil_Dirt_Tilled",
      "components": {
        "Components": {
          "TilledSoil": {
            "Version": 1,
            "DecayTime": "0001-01-02T22:10:43Z"
          }
        }
      }
    },
    {
      "x": 1,
      "y": 7,
      "z": 4,
      "name": "Empty"
    },
    {
      "x": 1,
      "y": 8,
      "z": 4,
      "name": "Empty"
    },
    {
      "x": 1,
      "y": 9,
      "z": 4,
      "name": "Empty"
    },
    {
      "x": 1,
      "y": 2,
      "z": 5,
      "name": "Soil_Dirt"
    },
    {
      "x": 1,
      "y": 3,
      "z": 5,
      "name": "Soil_Dirt"
    },
    {
      "x": 1,
      "y": 4,
      "z": 5,
      "name": "Soil_Dirt"
    },
    {
      "x": 1,
      "y": 5,
      "z": 5,
      "name": "Soil_Dirt"
    },
    {
      "x": 1,
      "y": 6,
      "z": 5,
      "name": "Soil_Mud_Dry"
    },
    {
      "x": 1,
      "y": 7,
      "z": 5,
      "name": "Empty"
    },
    {
      "x": 1,
      "y": 8,
      "z": 5,
      "name": "Empty"
    },
    {
      "x": 1,
      "y": 9,
      "z": 5,
      "name": "Empty"
    },
    {
      "x": 1,
      "y": 3,
      "z": 6,
      "name": "Soil_Dirt"
    },
    {
      "x": 1,
      "y": 4,
      "z": 6,
      "name": "Soil_Dirt"
    },
    {
      "x": 1,
      "y": 5,
      "z": 6,
      "name": "Soil_Dirt"
    },
    {
      "x": 1,
      "y": 6,
      "z": 6,
      "name": "Soil_Mud_Dry"
    },
    {
      "x": 1,
      "y": 7,
      "z": 6,
      "name": "Wood_Hardwood_Fence"
    },
    {
      "x": 1,
      "y": 8,
      "z": 6,
      "name": "Empty"
    },
    {
      "x": 1,
      "y": 9,
      "z": 6,
      "name": "Empty"
    },
    {
      "x": 2,
      "y": 3,
      "z": -6,
      "name": "Soil_Dirt"
    },
    {
      "x": 2,
      "y": 4,
      "z": -6,
      "name": "Soil_Dirt"
    },
    {
      "x": 2,
      "y": 5,
      "z": -6,
      "name": "Soil_Dirt"
    },
    {
      "x": 2,
      "y": 6,
      "z": -6,
      "name": "Soil_Dirt"
    },
    {
      "x": 2,
      "y": 7,
      "z": -6,
      "name": "*Wood_Hardwood_Fence_State_Definitions_Corner"
    },
    {
      "x": 2,
      "y": 8,
      "z": -6,
      "name": "Empty"
    },
    {
      "x": 2,
      "y": 9,
      "z": -6,
      "name": "Empty"
    },
    {
      "x": 2,
      "y": 2,
      "z": -5,
      "name": "Soil_Dirt"
    },
    {
      "x": 2,
      "y": 3,
      "z": -5,
      "name": "Soil_Dirt"
    },
    {
      "x": 2,
      "y": 4,
      "z": -5,
      "name": "Soil_Dirt"
    },
    {
      "x": 2,
      "y": 5,
      "z": -5,
      "name": "Soil_Dirt"
    },
    {
      "x": 2,
      "y": 6,
      "z": -5,
      "name": "Soil_Dirt_Tilled",
      "components": {
        "Components": {
          "TilledSoil": {
            "Version": 1,
            "DecayTime": "0001-01-02T22:58:24Z"
          }
        }
      }
    },
    {
      "x": 2,
      "y": 7,
      "z": -5,
      "name": "*Wood_Hardwood_Fence_State_Definitions_Corner",
      "rotation": 2
    },
    {
      "x": 2,
      "y": 8,
      "z": -5,
      "name": "Empty"
    },
    {
      "x": 2,
      "y": 9,
      "z": -5,
      "name": "Empty"
    },
    {
      "x": 2,
      "y": 1,
      "z": -4,
      "name": "Soil_Dirt"
    },
    {
      "x": 2,
      "y": 2,
      "z": -4,
      "name": "Soil_Dirt"
    },
    {
      "x": 2,
      "y": 3,
      "z": -4,
      "name": "Soil_Dirt"
    },
    {
      "x": 2,
      "y": 4,
      "z": -4,
      "name": "Soil_Dirt"
    },
    {
      "x": 2,
      "y": 5,
      "z": -4,
      "name": "Soil_Dirt"
    },
    {
      "x": 2,
      "y": 6,
      "z": -4,
      "name": "Soil_Dirt_Tilled",
      "components": {
        "Components": {
          "TilledSoil": {
            "Version": 1,
            "DecayTime": "0001-01-02T17:32:34Z"
          }
        }
      }
    },
    {
      "x": 2,
      "y": 7,
      "z": -4,
      "name": "*Plant_Crop_Carrot_Block_State_Definitions_Stage1",
      "components": {
        "Components": {
          "FarmingBlock": {
            "GrowthProgress": 1.0,
            "LastTickGameTime": "0001-01-01T12:00:00Z"
          }
        }
      }
    },
    {
      "x": 2,
      "y": 8,
      "z": -4,
      "name": "Empty"
    },
    {
      "x": 2,
      "y": 9,
      "z": -4,
      "name": "Empty"
    },
    {
      "x": 2,
      "y": 1,
      "z": -3,
      "name": "Soil_Dirt"
    },
    {
      "x": 2,
      "y": 2,
      "z": -3,
      "name": "Soil_Dirt"
    },
    {
      "x": 2,
      "y": 3,
      "z": -3,
      "name": "Soil_Dirt"
    },
    {
      "x": 2,
      "y": 4,
      "z": -3,
      "name": "Soil_Dirt"
    },
    {
      "x": 2,
      "y": 5,
      "z": -3,
      "name": "Soil_Dirt"
    },
    {
      "x": 2,
      "y": 6,
      "z": -3,
      "name": "Soil_Dirt_Tilled",
      "components": {
        "Components": {
          "TilledSoil": {
            "Version": 1,
            "DecayTime": "0001-01-02T19:10:00Z"
          }
        }
      }
    },
    {
      "x": 2,
      "y": 7,
      "z": -3,
      "name": "Empty"
    },
    {
      "x": 2,
      "y": 8,
      "z": -3,
      "name": "Empty"
    },
    {
      "x": 2,
      "y": 9,
      "z": -3,
      "name": "Empty"
    },
    {
      "x": 2,
      "y": 1,
      "z": -2,
      "name": "Soil_Dirt"
    },
    {
      "x": 2,
      "y": 2,
      "z": -2,
      "name": "Soil_Dirt"
    },
    {
      "x": 2,
      "y": 3,
      "z": -2,
      "name": "Soil_Dirt"
    },
    {
      "x": 2,
      "y": 4,
      "z": -2,
      "name": "Soil_Dirt"
    },
    {
      "x": 2,
      "y": 5,
      "z": -2,
      "name": "Soil_Dirt"
    },
    {
      "x": 2,
      "y": 6,
      "z": -2,
      "name": "Soil_Dirt_Tilled",
      "components": {
        "Components": {
          "TilledSoil": {
            "Version": 1,
            "DecayTime": "0001-01-02T22:37:25Z"
          }
        }
      }
    },
    {
      "x": 2,
      "y": 7,
      "z": -2,
      "name": "Empty"
    },
    {
      "x": 2,
      "y": 8,
      "z": -2,
      "name": "Empty"
    },
    {
      "x": 2,
      "y": 9,
      "z": -2,
      "name": "Empty"
    },
    {
      "x": 2,
      "y": 1,
      "z": -1,
      "name": "Soil_Dirt"
    },
    {
      "x": 2,
      "y": 2,
      "z": -1,
      "name": "Soil_Dirt"
    },
    {
      "x": 2,
      "y": 3,
      "z": -1,
      "name": "Soil_Dirt"
    },
    {
      "x": 2,
      "y": 4,
      "z": -1,
      "name": "Soil_Dirt"
    },
    {
      "x": 2,
      "y": 5,
      "z": -1,
      "name": "Soil_Dirt"
    },
    {
      "x": 2,
      "y": 6,
      "z": -1,
      "name": "Soil_Dirt"
    },
    {
      "x": 2,
      "y": 7,
      "z": -1,
      "name": "Empty"
    },
    {
      "x": 2,
      "y": 8,
      "z": -1,
      "name": "Empty"
    },
    {
      "x": 2,
      "y": 9,
      "z": -1,
      "name": "Empty"
    },
    {
      "x": 2,
      "y": 1,
      "z": 0,
      "name": "Soil_Dirt"
    },
    {
      "x": 2,
      "y": 2,
      "z": 0,
      "name": "Soil_Dirt"
    },
    {
      "x": 2,
      "y": 3,
      "z": 0,
      "name": "Soil_Dirt"
    },
    {
      "x": 2,
      "y": 4,
      "z": 0,
      "name": "Soil_Dirt"
    },
    {
      "x": 2,
      "y": 5,
      "z": 0,
      "name": "Soil_Dirt"
    },
    {
      "x": 2,
      "y": 6,
      "z": 0,
      "name": "Soil_Dirt"
    },
    {
      "x": 2,
      "y": 7,
      "z": 0,
      "name": "Empty"
    },
    {
      "x": 2,
      "y": 8,
      "z": 0,
      "name": "Empty"
    },
    {
      "x": 2,
      "y": 9,
      "z": 0,
      "name": "Empty"
    },
    {
      "x": 2,
      "y": 1,
      "z": 1,
      "name": "Soil_Dirt"
    },
    {
      "x": 2,
      "y": 2,
      "z": 1,
      "name": "Soil_Dirt"
    },
    {
      "x": 2,
      "y": 3,
      "z": 1,
      "name": "Soil_Dirt"
    },
    {
      "x": 2,
      "y": 4,
      "z": 1,
      "name": "Soil_Dirt"
    },
    {
      "x": 2,
      "y": 5,
      "z": 1,
      "name": "Soil_Dirt"
    },
    {
      "x": 2,
      "y": 6,
      "z": 1,
      "name": "Soil_Dirt"
    },
    {
      "x": 2,
      "y": 7,
      "z": 1,
      "name": "Empty"
    },
    {
      "x": 2,
      "y": 8,
      "z": 1,
      "name": "Empty"
    },
    {
      "x": 2,
      "y": 9,
      "z": 1,
      "name": "Empty"
    },
    {
      "x": 2,
      "y": 1,
      "z": 2,
      "name": "Soil_Dirt"
    },
    {
      "x": 2,
      "y": 2,
      "z": 2,
      "name": "Soil_Dirt"
    },
    {
      "x": 2,
      "y": 3,
      "z": 2,
      "name": "Soil_Dirt"
    },
    {
      "x": 2,
      "y": 4,
      "z": 2,
      "name": "Soil_Dirt"
    },
    {
      "x": 2,
      "y": 5,
      "z": 2,
      "name": "Soil_Dirt"
    },
    {
      "x": 2,
      "y": 6,
      "z": 2,
      "name": "Soil_Dirt"
    },
    {
      "x": 2,
      "y": 7,
      "z": 2,
      "name": "Empty"
    },
    {
      "x": 2,
      "y": 8,
      "z": 2,
      "name": "Empty"
    },
    {
      "x": 2,
      "y": 9,
      "z": 2,
      "name": "Empty"
    },
    {
      "x": 2,
      "y": 1,
      "z": 3,
      "name": "Soil_Dirt"
    },
    {
      "x": 2,
      "y": 2,
      "z": 3,
      "name": "Soil_Dirt"
    },
    {
      "x": 2,
      "y": 3,
      "z": 3,
      "name": "Soil_Dirt"
    },
    {
      "x": 2,
      "y": 4,
      "z": 3,
      "name": "Soil_Dirt"
    },
    {
      "x": 2,
      "y": 5,
      "z": 3,
      "name": "Soil_Dirt"
    },
    {
      "x": 2,
      "y": 6,
      "z": 3,
      "name": "Soil_Mud_Dry"
    },
    {
      "x": 2,
      "y": 7,
      "z": 3,
      "name": "Empty"
    },
    {
      "x": 2,
      "y": 8,
      "z": 3,
      "name": "Empty"
    },
    {
      "x": 2,
      "y": 9,
      "z": 3,
      "name": "Empty"
    },
    {
      "x": 2,
      "y": 1,
      "z": 4,
      "name": "Soil_Dirt"
    },
    {
      "x": 2,
      "y": 2,
      "z": 4,
      "name": "Soil_Dirt"
    },
    {
      "x": 2,
      "y": 3,
      "z": 4,
      "name": "Soil_Dirt"
    },
    {
      "x": 2,
      "y": 4,
      "z": 4,
      "name": "Soil_Dirt"
    },
    {
      "x": 2,
      "y": 5,
      "z": 4,
      "name": "Soil_Dirt"
    },
    {
      "x": 2,
      "y": 6,
      "z": 4,
      "name": "Soil_Mud_Dry"
    },
    {
      "x": 2,
      "y": 7,
      "z": 4,
      "name": "Empty"
    },
    {
      "x": 2,
      "y": 8,
      "z": 4,
      "name": "Empty"
    },
    {
      "x": 2,
      "y": 9,
      "z": 4,
      "name": "Empty"
    },
    {
      "x": 2,
      "y": 2,
      "z": 5,
      "name": "Soil_Dirt"
    },
    {
      "x": 2,
      "y": 3,
      "z": 5,
      "name": "Soil_Dirt"
    },
    {
      "x": 2,
      "y": 4,
      "z": 5,
      "name": "Soil_Dirt"
    },
    {
      "x": 2,
      "y": 5,
      "z": 5,
      "name": "Soil_Dirt"
    },
    {
      "x": 2,
      "y": 6,
      "z": 5,
      "name": "Soil_Mud_Dry"
    },
    {
      "x": 2,
      "y": 7,
      "z": 5,
      "name": "Empty"
    },
    {
      "x": 2,
      "y": 8,
      "z": 5,
      "name": "Empty"
    },
    {
      "x": 2,
      "y": 9,
      "z": 5,
      "name": "Empty"
    },
    {
      "x": 2,
      "y": 3,
      "z": 6,
      "name": "Soil_Dirt"
    },
    {
      "x": 2,
      "y": 4,
      "z": 6,
      "name": "Soil_Dirt"
    },
    {
      "x": 2,
      "y": 5,
      "z": 6,
      "name": "Soil_Dirt"
    },
    {
      "x": 2,
      "y": 6,
      "z": 6,
      "name": "Soil_Mud_Dry"
    },
    {
      "x": 2,
      "y": 7,
      "z": 6,
      "name": "Wood_Hardwood_Fence"
    },
    {
      "x": 2,
      "y": 8,
      "z": 6,
      "name": "Empty"
    },
    {
      "x": 2,
      "y": 9,
      "z": 6,
      "name": "Empty"
    },
    {
      "x": 3,
      "y": 3,
      "z": -5,
      "name": "Soil_Dirt"
    },
    {
      "x": 3,
      "y": 4,
      "z": -5,
      "name": "Soil_Dirt"
    },
    {
      "x": 3,
      "y": 5,
      "z": -5,
      "name": "Soil_Dirt"
    },
    {
      "x": 3,
      "y": 6,
      "z": -5,
      "name": "Soil_Dirt_Tilled",
      "components": {
        "Components": {
          "TilledSoil": {
            "Version": 1,
            "DecayTime": "0001-01-02T19:37:07Z"
          }
        }
      }
    },
    {
      "x": 3,
      "y": 7,
      "z": -5,
      "name": "Wood_Hardwood_Fence",
      "rotation": 2
    },
    {
      "x": 3,
      "y": 8,
      "z": -5,
      "name": "Empty"
    },
    {
      "x": 3,
      "y": 9,
      "z": -5,
      "name": "Empty"
    },
    {
      "x": 3,
      "y": 2,
      "z": -4,
      "name": "Soil_Dirt"
    },
    {
      "x": 3,
      "y": 3,
      "z": -4,
      "name": "Soil_Dirt"
    },
    {
      "x": 3,
      "y": 4,
      "z": -4,
      "name": "Soil_Dirt"
    },
    {
      "x": 3,
      "y": 5,
      "z": -4,
      "name": "Soil_Dirt"
    },
    {
      "x": 3,
      "y": 6,
      "z": -4,
      "name": "Soil_Dirt_Tilled",
      "components": {
        "Components": {
          "TilledSoil": {
            "Version": 1,
            "DecayTime": "0001-01-02T19:16:56Z"
          }
        }
      }
    },
    {
      "x": 3,
      "y": 7,
      "z": -4,
      "name": "Empty"
    },
    {
      "x": 3,
      "y": 8,
      "z": -4,
      "name": "Empty"
    },
    {
      "x": 3,
      "y": 9,
      "z": -4,
      "name": "Empty"
    },
    {
      "x": 3,
      "y": 1,
      "z": -3,
      "name": "Soil_Dirt"
    },
    {
      "x": 3,
      "y": 2,
      "z": -3,
      "name": "Soil_Dirt"
    },
    {
      "x": 3,
      "y": 3,
      "z": -3,
      "name": "Soil_Dirt"
    },
    {
      "x": 3,
      "y": 4,
      "z": -3,
      "name": "Soil_Dirt"
    },
    {
      "x": 3,
      "y": 5,
      "z": -3,
      "name": "Soil_Dirt"
    },
    {
      "x": 3,
      "y": 6,
      "z": -3,
      "name": "Soil_Mud_Dry"
    },
    {
      "x": 3,
      "y": 7,
      "z": -3,
      "name": "Empty"
    },
    {
      "x": 3,
      "y": 8,
      "z": -3,
      "name": "Empty"
    },
    {
      "x": 3,
      "y": 9,
      "z": -3,
      "name": "Empty"
    },
    {
      "x": 3,
      "y": 1,
      "z": -2,
      "name": "Soil_Dirt"
    },
    {
      "x": 3,
      "y": 2,
      "z": -2,
      "name": "Soil_Dirt"
    },
    {
      "x": 3,
      "y": 3,
      "z": -2,
      "name": "Soil_Dirt"
    },
    {
      "x": 3,
      "y": 4,
      "z": -2,
      "name": "Soil_Dirt"
    },
    {
      "x": 3,
      "y": 5,
      "z": -2,
      "name": "Soil_Dirt"
    },
    {
      "x": 3,
      "y": 6,
      "z": -2,
      "name": "Soil_Mud_Dry"
    },
    {
      "x": 3,
      "y": 7,
      "z": -2,
      "name": "Empty"
    },
    {
      "x": 3,
      "y": 8,
      "z": -2,
      "name": "Empty"
    },
    {
      "x": 3,
      "y": 9,
      "z": -2,
      "name": "Empty"
    },
    {
      "x": 3,
      "y": 1,
      "z": -1,
      "name": "Soil_Dirt"
    },
    {
      "x": 3,
      "y": 2,
      "z": -1,
      "name": "Soil_Dirt"
    },
    {
      "x": 3,
      "y": 3,
      "z": -1,
      "name": "Soil_Dirt"
    },
    {
      "x": 3,
      "y": 4,
      "z": -1,
      "name": "Soil_Dirt"
    },
    {
      "x": 3,
      "y": 5,
      "z": -1,
      "name": "Soil_Dirt"
    },
    {
      "x": 3,
      "y": 6,
      "z": -1,
      "name": "Soil_Dirt"
    },
    {
      "x": 3,
      "y": 7,
      "z": -1,
      "name": "Empty"
    },
    {
      "x": 3,
      "y": 8,
      "z": -1,
      "name": "Empty"
    },
    {
      "x": 3,
      "y": 9,
      "z": -1,
      "name": "Empty"
    },
    {
      "x": 3,
      "y": 1,
      "z": 0,
      "name": "Soil_Dirt"
    },
    {
      "x": 3,
      "y": 2,
      "z": 0,
      "name": "Soil_Dirt"
    },
    {
      "x": 3,
      "y": 3,
      "z": 0,
      "name": "Soil_Dirt"
    },
    {
      "x": 3,
      "y": 4,
      "z": 0,
      "name": "Soil_Dirt"
    },
    {
      "x": 3,
      "y": 5,
      "z": 0,
      "name": "Soil_Dirt"
    },
    {
      "x": 3,
      "y": 6,
      "z": 0,
      "name": "Soil_Dirt"
    },
    {
      "x": 3,
      "y": 7,
      "z": 0,
      "name": "Empty"
    },
    {
      "x": 3,
      "y": 8,
      "z": 0,
      "name": "Empty"
    },
    {
      "x": 3,
      "y": 9,
      "z": 0,
      "name": "Empty"
    },
    {
      "x": 3,
      "y": 1,
      "z": 1,
      "name": "Soil_Dirt"
    },
    {
      "x": 3,
      "y": 2,
      "z": 1,
      "name": "Soil_Dirt"
    },
    {
      "x": 3,
      "y": 3,
      "z": 1,
      "name": "Soil_Dirt"
    },
    {
      "x": 3,
      "y": 4,
      "z": 1,
      "name": "Soil_Dirt"
    },
    {
      "x": 3,
      "y": 5,
      "z": 1,
      "name": "Soil_Dirt"
    },
    {
      "x": 3,
      "y": 6,
      "z": 1,
      "name": "Soil_Mud_Dry"
    },
    {
      "x": 3,
      "y": 7,
      "z": 1,
      "name": "Empty"
    },
    {
      "x": 3,
      "y": 8,
      "z": 1,
      "name": "Empty"
    },
    {
      "x": 3,
      "y": 9,
      "z": 1,
      "name": "Empty"
    },
    {
      "x": 3,
      "y": 1,
      "z": 2,
      "name": "Soil_Dirt"
    },
    {
      "x": 3,
      "y": 2,
      "z": 2,
      "name": "Soil_Dirt"
    },
    {
      "x": 3,
      "y": 3,
      "z": 2,
      "name": "Soil_Dirt"
    },
    {
      "x": 3,
      "y": 4,
      "z": 2,
      "name": "Soil_Dirt"
    },
    {
      "x": 3,
      "y": 5,
      "z": 2,
      "name": "Soil_Dirt"
    },
    {
      "x": 3,
      "y": 6,
      "z": 2,
      "name": "Soil_Mud_Dry"
    },
    {
      "x": 3,
      "y": 7,
      "z": 2,
      "name": "Empty"
    },
    {
      "x": 3,
      "y": 8,
      "z": 2,
      "name": "Empty"
    },
    {
      "x": 3,
      "y": 9,
      "z": 2,
      "name": "Empty"
    },
    {
      "x": 3,
      "y": 1,
      "z": 3,
      "name": "Soil_Dirt"
    },
    {
      "x": 3,
      "y": 2,
      "z": 3,
      "name": "Soil_Dirt"
    },
    {
      "x": 3,
      "y": 3,
      "z": 3,
      "name": "Soil_Dirt"
    },
    {
      "x": 3,
      "y": 4,
      "z": 3,
      "name": "Soil_Dirt"
    },
    {
      "x": 3,
      "y": 5,
      "z": 3,
      "name": "Soil_Dirt"
    },
    {
      "x": 3,
      "y": 6,
      "z": 3,
      "name": "Soil_Mud_Dry"
    },
    {
      "x": 3,
      "y": 7,
      "z": 3,
      "name": "Empty"
    },
    {
      "x": 3,
      "y": 8,
      "z": 3,
      "name": "Empty"
    },
    {
      "x": 3,
      "y": 9,
      "z": 3,
      "name": "Empty"
    },
    {
      "x": 3,
      "y": 1,
      "z": 4,
      "name": "Soil_Dirt"
    },
    {
      "x": 3,
      "y": 2,
      "z": 4,
      "name": "Soil_Dirt"
    },
    {
      "x": 3,
      "y": 3,
      "z": 4,
      "name": "Soil_Dirt"
    },
    {
      "x": 3,
      "y": 4,
      "z": 4,
      "name": "Soil_Dirt"
    },
    {
      "x": 3,
      "y": 5,
      "z": 4,
      "name": "Soil_Dirt"
    },
    {
      "x": 3,
      "y": 6,
      "z": 4,
      "name": "Soil_Mud_Dry"
    },
    {
      "x": 3,
      "y": 7,
      "z": 4,
      "name": "Empty"
    },
    {
      "x": 3,
      "y": 8,
      "z": 4,
      "name": "Empty"
    },
    {
      "x": 3,
      "y": 9,
      "z": 4,
      "name": "Empty"
    },
    {
      "x": 3,
      "y": 2,
      "z": 5,
      "name": "Soil_Dirt"
    },
    {
      "x": 3,
      "y": 3,
      "z": 5,
      "name": "Soil_Dirt"
    },
    {
      "x": 3,
      "y": 4,
      "z": 5,
      "name": "Soil_Dirt"
    },
    {
      "x": 3,
      "y": 5,
      "z": 5,
      "name": "Soil_Dirt"
    },
    {
      "x": 3,
      "y": 6,
      "z": 5,
      "name": "Soil_Mud_Dry"
    },
    {
      "x": 3,
      "y": 7,
      "z": 5,
      "name": "Empty"
    },
    {
      "x": 3,
      "y": 8,
      "z": 5,
      "name": "Empty"
    },
    {
      "x": 3,
      "y": 9,
      "z": 5,
      "name": "Empty"
    },
    {
      "x": 3,
      "y": 2,
      "z": 6,
      "name": "Soil_Dirt"
    },
    {
      "x": 3,
      "y": 3,
      "z": 6,
      "name": "Soil_Dirt"
    },
    {
      "x": 3,
      "y": 4,
      "z": 6,
      "name": "Soil_Dirt"
    },
    {
      "x": 3,
      "y": 5,
      "z": 6,
      "name": "Soil_Dirt"
    },
    {
      "x": 3,
      "y": 6,
      "z": 6,
      "name": "Soil_Dirt"
    },
    {
      "x": 3,
      "y": 7,
      "z": 6,
      "name": "Wood_Hardwood_Fence"
    },
    {
      "x": 3,
      "y": 8,
      "z": 6,
      "name": "Empty"
    },
    {
      "x": 3,
      "y": 9,
      "z": 6,
      "name": "Empty"
    },
    {
      "x": 4,
      "y": 3,
      "z": -5,
      "name": "Soil_Dirt"
    },
    {
      "x": 4,
      "y": 4,
      "z": -5,
      "name": "Soil_Dirt"
    },
    {
      "x": 4,
      "y": 5,
      "z": -5,
      "name": "Soil_Dirt"
    },
    {
      "x": 4,
      "y": 6,
      "z": -5,
      "name": "Soil_Dirt"
    },
    {
      "x": 4,
      "y": 7,
      "z": -5,
      "name": "Wood_Hardwood_Fence",
      "rotation": 2
    },
    {
      "x": 4,
      "y": 8,
      "z": -5,
      "name": "Empty"
    },
    {
      "x": 4,
      "y": 9,
      "z": -5,
      "name": "Empty"
    },
    {
      "x": 4,
      "y": 2,
      "z": -4,
      "name": "Soil_Dirt"
    },
    {
      "x": 4,
      "y": 3,
      "z": -4,
      "name": "Soil_Dirt"
    },
    {
      "x": 4,
      "y": 4,
      "z": -4,
      "name": "Soil_Dirt"
    },
    {
      "x": 4,
      "y": 5,
      "z": -4,
      "name": "Soil_Dirt"
    },
    {
      "x": 4,
      "y": 6,
      "z": -4,
      "name": "Soil_Dirt_Tilled",
      "components": {
        "Components": {
          "TilledSoil": {
            "Version": 1,
            "DecayTime": "0001-01-02T20:18:23Z"
          }
        }
      }
    },
    {
      "x": 4,
      "y": 7,
      "z": -4,
      "name": "*Plant_Crop_Carrot_Block_State_Definitions_Stage1",
      "components": {
        "Components": {
          "FarmingBlock": {
            "GrowthProgress": 1.0,
            "LastTickGameTime": "0001-01-01T12:00:00Z"
          }
        }
      }
    },
    {
      "x": 4,
      "y": 8,
      "z": -4,
      "name": "Empty"
    },
    {
      "x": 4,
      "y": 9,
      "z": -4,
      "name": "Empty"
    },
    {
      "x": 4,
      "y": 1,
      "z": -3,
      "name": "Soil_Dirt"
    },
    {
      "x": 4,
      "y": 2,
      "z": -3,
      "name": "Soil_Dirt"
    },
    {
      "x": 4,
      "y": 3,
      "z": -3,
      "name": "Soil_Dirt"
    },
    {
      "x": 4,
      "y": 4,
      "z": -3,
      "name": "Soil_Dirt"
    },
    {
      "x": 4,
      "y": 5,
      "z": -3,
      "name": "Soil_Dirt"
    },
    {
      "x": 4,
      "y": 6,
      "z": -3,
      "name": "Soil_Mud_Dry"
    },
    {
      "x": 4,
      "y": 7,
      "z": -3,
      "name": "Empty"
    },
    {
      "x": 4,
      "y": 8,
      "z": -3,
      "name": "Empty"
    },
    {
      "x": 4,
      "y": 9,
      "z": -3,
      "name": "Empty"
    },
    {
      "x": 4,
      "y": 1,
      "z": -2,
      "name": "Soil_Dirt"
    },
    {
      "x": 4,
      "y": 2,
      "z": -2,
      "name": "Soil_Dirt"
    },
    {
      "x": 4,
      "y": 3,
      "z": -2,
      "name": "Soil_Dirt"
    },
    {
      "x": 4,
      "y": 4,
      "z": -2,
      "name": "Soil_Dirt"
    },
    {
      "x": 4,
      "y": 5,
      "z": -2,
      "name": "Soil_Dirt"
    },
    {
      "x": 4,
      "y": 6,
      "z": -2,
      "name": "Soil_Mud_Dry"
    },
    {
      "x": 4,
      "y": 7,
      "z": -2,
      "name": "Empty"
    },
    {
      "x": 4,
      "y": 8,
      "z": -2,
      "name": "Empty"
    },
    {
      "x": 4,
      "y": 9,
      "z": -2,
      "name": "Empty"
    },
    {
      "x": 4,
      "y": 1,
      "z": -1,
      "name": "Soil_Dirt"
    },
    {
      "x": 4,
      "y": 2,
      "z": -1,
      "name": "Soil_Dirt"
    },
    {
      "x": 4,
      "y": 3,
      "z": -1,
      "name": "Soil_Dirt"
    },
    {
      "x": 4,
      "y": 4,
      "z": -1,
      "name": "Soil_Dirt"
    },
    {
      "x": 4,
      "y": 5,
      "z": -1,
      "name": "Soil_Dirt"
    },
    {
      "x": 4,
      "y": 6,
      "z": -1,
      "name": "Soil_Mud_Dry"
    },
    {
      "x": 4,
      "y": 7,
      "z": -1,
      "name": "Empty"
    },
    {
      "x": 4,
      "y": 8,
      "z": -1,
      "name": "Empty"
    },
    {
      "x": 4,
      "y": 9,
      "z": -1,
      "name": "Empty"
    },
    {
      "x": 4,
      "y": 1,
      "z": 0,
      "name": "Soil_Dirt"
    },
    {
      "x": 4,
      "y": 2,
      "z": 0,
      "name": "Soil_Dirt"
    },
    {
      "x": 4,
      "y": 3,
      "z": 0,
      "name": "Soil_Dirt"
    },
    {
      "x": 4,
      "y": 4,
      "z": 0,
      "name": "Soil_Dirt"
    },
    {
      "x": 4,
      "y": 5,
      "z": 0,
      "name": "Soil_Dirt"
    },
    {
      "x": 4,
      "y": 6,
      "z": 0,
      "name": "Soil_Mud_Dry"
    },
    {
      "x": 4,
      "y": 7,
      "z": 0,
      "name": "Empty"
    },
    {
      "x": 4,
      "y": 8,
      "z": 0,
      "name": "Empty"
    },
    {
      "x": 4,
      "y": 9,
      "z": 0,
      "name": "Empty"
    },
    {
      "x": 4,
      "y": 1,
      "z": 1,
      "name": "Soil_Dirt"
    },
    {
      "x": 4,
      "y": 2,
      "z": 1,
      "name": "Soil_Dirt"
    },
    {
      "x": 4,
      "y": 3,
      "z": 1,
      "name": "Soil_Dirt"
    },
    {
      "x": 4,
      "y": 4,
      "z": 1,
      "name": "Soil_Dirt"
    },
    {
      "x": 4,
      "y": 5,
      "z": 1,
      "name": "Soil_Dirt"
    },
    {
      "x": 4,
      "y": 6,
      "z": 1,
      "name": "Soil_Mud_Dry"
    },
    {
      "x": 4,
      "y": 7,
      "z": 1,
      "name": "Empty"
    },
    {
      "x": 4,
      "y": 8,
      "z": 1,
      "name": "Empty"
    },
    {
      "x": 4,
      "y": 9,
      "z": 1,
      "name": "Empty"
    },
    {
      "x": 4,
      "y": 1,
      "z": 2,
      "name": "Soil_Dirt"
    },
    {
      "x": 4,
      "y": 2,
      "z": 2,
      "name": "Soil_Dirt"
    },
    {
      "x": 4,
      "y": 3,
      "z": 2,
      "name": "Soil_Dirt"
    },
    {
      "x": 4,
      "y": 4,
      "z": 2,
      "name": "Soil_Dirt"
    },
    {
      "x": 4,
      "y": 5,
      "z": 2,
      "name": "Soil_Dirt"
    },
    {
      "x": 4,
      "y": 6,
      "z": 2,
      "name": "Soil_Mud_Dry"
    },
    {
      "x": 4,
      "y": 7,
      "z": 2,
      "name": "Empty"
    },
    {
      "x": 4,
      "y": 8,
      "z": 2,
      "name": "Empty"
    },
    {
      "x": 4,
      "y": 9,
      "z": 2,
      "name": "Empty"
    },
    {
      "x": 4,
      "y": 2,
      "z": 3,
      "name": "Soil_Dirt"
    },
    {
      "x": 4,
      "y": 3,
      "z": 3,
      "name": "Soil_Dirt"
    },
    {
      "x": 4,
      "y": 4,
      "z": 3,
      "name": "Soil_Dirt"
    },
    {
      "x": 4,
      "y": 5,
      "z": 3,
      "name": "Soil_Dirt"
    },
    {
      "x": 4,
      "y": 6,
      "z": 3,
      "name": "Soil_Mud_Dry"
    },
    {
      "x": 4,
      "y": 7,
      "z": 3,
      "name": "Empty"
    },
    {
      "x": 4,
      "y": 8,
      "z": 3,
      "name": "Empty"
    },
    {
      "x": 4,
      "y": 9,
      "z": 3,
      "name": "Empty"
    },
    {
      "x": 4,
      "y": 2,
      "z": 4,
      "name": "Soil_Dirt"
    },
    {
      "x": 4,
      "y": 3,
      "z": 4,
      "name": "Soil_Dirt"
    },
    {
      "x": 4,
      "y": 4,
      "z": 4,
      "name": "Soil_Dirt"
    },
    {
      "x": 4,
      "y": 5,
      "z": 4,
      "name": "Soil_Dirt"
    },
    {
      "x": 4,
      "y": 6,
      "z": 4,
      "name": "Soil_Mud_Dry"
    },
    {
      "x": 4,
      "y": 7,
      "z": 4,
      "name": "Empty"
    },
    {
      "x": 4,
      "y": 8,
      "z": 4,
      "name": "Empty"
    },
    {
      "x": 4,
      "y": 9,
      "z": 4,
      "name": "Empty"
    },
    {
      "x": 4,
      "y": 2,
      "z": 5,
      "name": "Soil_Dirt"
    },
    {
      "x": 4,
      "y": 3,
      "z": 5,
      "name": "Soil_Dirt"
    },
    {
      "x": 4,
      "y": 4,
      "z": 5,
      "name": "Soil_Dirt"
    },
    {
      "x": 4,
      "y": 5,
      "z": 5,
      "name": "Soil_Dirt"
    },
    {
      "x": 4,
      "y": 6,
      "z": 5,
      "name": "Soil_Grass_Deep"
    },
    {
      "x": 4,
      "y": 7,
      "z": 5,
      "name": "Plant_Grass_Lush"
    },
    {
      "x": 4,
      "y": 8,
      "z": 5,
      "name": "Empty"
    },
    {
      "x": 4,
      "y": 9,
      "z": 5,
      "name": "Empty"
    },
    {
      "x": 4,
      "y": 3,
      "z": 6,
      "name": "Soil_Dirt"
    },
    {
      "x": 4,
      "y": 4,
      "z": 6,
      "name": "Soil_Dirt"
    },
    {
      "x": 4,
      "y": 5,
      "z": 6,
      "name": "Soil_Dirt"
    },
    {
      "x": 4,
      "y": 6,
      "z": 6,
      "name": "Soil_Grass_Deep"
    },
    {
      "x": 4,
      "y": 7,
      "z": 6,
      "name": "Wood_Hardwood_Fence"
    },
    {
      "x": 4,
      "y": 8,
      "z": 6,
      "name": "Empty"
    },
    {
      "x": 4,
      "y": 9,
      "z": 6,
      "name": "Empty"
    },
    {
      "x": 5,
      "y": 4,
      "z": -5,
      "name": "Soil_Dirt"
    },
    {
      "x": 5,
      "y": 5,
      "z": -5,
      "name": "Soil_Dirt"
    },
    {
      "x": 5,
      "y": 6,
      "z": -5,
      "name": "Soil_Leaves"
    },
    {
      "x": 5,
      "y": 7,
      "z": -5,
      "name": "Wood_Hardwood_Fence",
      "rotation": 2
    },
    {
      "x": 5,
      "y": 8,
      "z": -5,
      "name": "Empty"
    },
    {
      "x": 5,
      "y": 9,
      "z": -5,
      "name": "Empty"
    },
    {
      "x": 5,
      "y": 2,
      "z": -4,
      "name": "Soil_Dirt"
    },
    {
      "x": 5,
      "y": 3,
      "z": -4,
      "name": "Soil_Dirt"
    },
    {
      "x": 5,
      "y": 4,
      "z": -4,
      "name": "Soil_Dirt"
    },
    {
      "x": 5,
      "y": 5,
      "z": -4,
      "name": "Soil_Dirt"
    },
    {
      "x": 5,
      "y": 6,
      "z": -4,
      "name": "Soil_Leaves"
    },
    {
      "x": 5,
      "y": 7,
      "z": -4,
      "name": "Plant_Grass_Sharp_Tall"
    },
    {
      "x": 5,
      "y": 8,
      "z": -4,
      "name": "Plant_Grass_Sharp_Tall",
      "filler": 1024
    },
    {
      "x": 5,
      "y": 9,
      "z": -4,
      "name": "Empty"
    },
    {
      "x": 5,
      "y": 2,
      "z": -3,
      "name": "Soil_Dirt"
    },
    {
      "x": 5,
      "y": 3,
      "z": -3,
      "name": "Soil_Dirt"
    },
    {
      "x": 5,
      "y": 4,
      "z": -3,
      "name": "Soil_Dirt"
    },
    {
      "x": 5,
      "y": 5,
      "z": -3,
      "name": "Soil_Dirt"
    },
    {
      "x": 5,
      "y": 6,
      "z": -3,
      "name": "Soil_Dirt"
    },
    {
      "x": 5,
      "y": 7,
      "z": -3,
      "name": "Empty"
    },
    {
      "x": 5,
      "y": 8,
      "z": -3,
      "name": "Empty"
    },
    {
      "x": 5,
      "y": 9,
      "z": -3,
      "name": "Empty"
    },
    {
      "x": 5,
      "y": 2,
      "z": -2,
      "name": "Soil_Dirt"
    },
    {
      "x": 5,
      "y": 3,
      "z": -2,
      "name": "Soil_Dirt"
    },
    {
      "x": 5,
      "y": 4,
      "z": -2,
      "name": "Soil_Dirt"
    },
    {
      "x": 5,
      "y": 5,
      "z": -2,
      "name": "Soil_Dirt"
    },
    {
      "x": 5,
      "y": 6,
      "z": -2,
      "name": "Soil_Mud_Dry"
    },
    {
      "x": 5,
      "y": 7,
      "z": -2,
      "name": "Empty"
    },
    {
      "x": 5,
      "y": 8,
      "z": -2,
      "name": "Empty"
    },
    {
      "x": 5,
      "y": 9,
      "z": -2,
      "name": "Empty"
    },
    {
      "x": 5,
      "y": 2,
      "z": -1,
      "name": "Soil_Dirt"
    },
    {
      "x": 5,
      "y": 3,
      "z": -1,
      "name": "Soil_Dirt"
    },
    {
      "x": 5,
      "y": 4,
      "z": -1,
      "name": "Soil_Dirt"
    },
    {
      "x": 5,
      "y": 5,
      "z": -1,
      "name": "Soil_Dirt"
    },
    {
      "x": 5,
      "y": 6,
      "z": -1,
      "name": "Soil_Mud_Dry"
    },
    {
      "x": 5,
      "y": 7,
      "z": -1,
      "name": "Empty"
    },
    {
      "x": 5,
      "y": 8,
      "z": -1,
      "name": "Empty"
    },
    {
      "x": 5,
      "y": 9,
      "z": -1,
      "name": "Empty"
    },
    {
      "x": 5,
      "y": 2,
      "z": 0,
      "name": "Soil_Dirt"
    },
    {
      "x": 5,
      "y": 3,
      "z": 0,
      "name": "Soil_Dirt"
    },
    {
      "x": 5,
      "y": 4,
      "z": 0,
      "name": "Soil_Dirt"
    },
    {
      "x": 5,
      "y": 5,
      "z": 0,
      "name": "Soil_Dirt"
    },
    {
      "x": 5,
      "y": 6,
      "z": 0,
      "name": "Soil_Mud_Dry"
    },
    {
      "x": 5,
      "y": 7,
      "z": 0,
      "name": "*Wood_Hardwood_Fence_State_Definitions_Corner",
      "rotation": 1
    },
    {
      "x": 5,
      "y": 8,
      "z": 0,
      "name": "Empty"
    },
    {
      "x": 5,
      "y": 9,
      "z": 0,
      "name": "Empty"
    },
    {
      "x": 5,
      "y": 2,
      "z": 1,
      "name": "Soil_Dirt"
    },
    {
      "x": 5,
      "y": 3,
      "z": 1,
      "name": "Soil_Dirt"
    },
    {
      "x": 5,
      "y": 4,
      "z": 1,
      "name": "Soil_Dirt"
    },
    {
      "x": 5,
      "y": 5,
      "z": 1,
      "name": "Soil_Dirt"
    },
    {
      "x": 5,
      "y": 6,
      "z": 1,
      "name": "Soil_Mud_Dry"
    },
    {
      "x": 5,
      "y": 7,
      "z": 1,
      "name": "Wood_Hardwood_Fence",
      "rotation": 1
    },
    {
      "x": 5,
      "y": 8,
      "z": 1,
      "name": "Empty"
    },
    {
      "x": 5,
      "y": 9,
      "z": 1,
      "name": "Empty"
    },
    {
      "x": 5,
      "y": 2,
      "z": 2,
      "name": "Soil_Dirt"
    },
    {
      "x": 5,
      "y": 3,
      "z": 2,
      "name": "Soil_Dirt"
    },
    {
      "x": 5,
      "y": 4,
      "z": 2,
      "name": "Soil_Dirt"
    },
    {
      "x": 5,
      "y": 5,
      "z": 2,
      "name": "Soil_Dirt"
    },
    {
      "x": 5,
      "y": 6,
      "z": 2,
      "name": "Soil_Mud_Dry"
    },
    {
      "x": 5,
      "y": 7,
      "z": 2,
      "name": "Wood_Hardwood_Fence",
      "rotation": 1
    },
    {
      "x": 5,
      "y": 8,
      "z": 2,
      "name": "Empty"
    },
    {
      "x": 5,
      "y": 9,
      "z": 2,
      "name": "Empty"
    },
    {
      "x": 5,
      "y": 3,
      "z": 3,
      "name": "Soil_Dirt"
    },
    {
      "x": 5,
      "y": 4,
      "z": 3,
      "name": "Soil_Dirt"
    },
    {
      "x": 5,
      "y": 5,
      "z": 3,
      "name": "Soil_Dirt"
    },
    {
      "x": 5,
      "y": 6,
      "z": 3,
      "name": "Soil_Mud_Dry"
    },
    {
      "x": 5,
      "y": 7,
      "z": 3,
      "name": "Wood_Hardwood_Fence",
      "rotation": 1
    },
    {
      "x": 5,
      "y": 8,
      "z": 3,
      "name": "Empty"
    },
    {
      "x": 5,
      "y": 9,
      "z": 3,
      "name": "Empty"
    },
    {
      "x": 5,
      "y": 3,
      "z": 4,
      "name": "Soil_Dirt"
    },
    {
      "x": 5,
      "y": 4,
      "z": 4,
      "name": "Soil_Dirt"
    },
    {
      "x": 5,
      "y": 5,
      "z": 4,
      "name": "Soil_Dirt"
    },
    {
      "x": 5,
      "y": 6,
      "z": 4,
      "name": "Soil_Grass_Deep"
    },
    {
      "x": 5,
      "y": 7,
      "z": 4,
      "name": "Wood_Hardwood_Fence",
      "rotation": 1
    },
    {
      "x": 5,
      "y": 8,
      "z": 4,
      "name": "Empty"
    },
    {
      "x": 5,
      "y": 9,
      "z": 4,
      "name": "Empty"
    },
    {
      "x": 5,
      "y": 4,
      "z": 5,
      "name": "Soil_Dirt"
    },
    {
      "x": 5,
      "y": 5,
      "z": 5,
      "name": "Soil_Dirt"
    },
    {
      "x": 5,
      "y": 6,
      "z": 5,
      "name": "Soil_Grass_Deep"
    },
    {
      "x": 5,
      "y": 7,
      "z": 5,
      "name": "Wood_Hardwood_Fence",
      "rotation": 1
    },
    {
      "x": 5,
      "y": 8,
      "z": 5,
      "name": "Empty"
    },
    {
      "x": 5,
      "y": 9,
      "z": 5,
      "name": "Empty"
    },
    {
      "x": 5,
      "y": 6,
      "z": 6,
      "name": "Soil_Grass_Deep"
    },
    {
      "x": 5,
      "y": 7,
      "z": 6,
      "name": "*Wood_Hardwood_Fence_State_Definitions_Corner",
      "rotation": 3
    },
    {
      "x": 5,
      "y": 8,
      "z": 6,
      "name": "Empty"
    },
    {
      "x": 5,
      "y": 9,
      "z": 6,
      "name": "Empty"
    },
    {
      "x": 6,
      "y": 5,
      "z": -5,
      "name": "Soil_Dirt"
    },
    {
      "x": 6,
      "y": 6,
      "z": -5,
      "name": "Soil_Leaves"
    },
    {
      "x": 6,
      "y": 7,
      "z": -5,
      "name": "*Wood_Hardwood_Fence_State_Definitions_Corner"
    },
    {
      "x": 6,
      "y": 8,
      "z": -5,
      "name": "Empty"
    },
    {
      "x": 6,
      "y": 9,
      "z": -5,
      "name": "Empty"
    },
    {
      "x": 6,
      "y": 4,
      "z": -4,
      "name": "Soil_Dirt"
    },
    {
      "x": 6,
      "y": 5,
      "z": -4,
      "name": "Soil_Dirt"
    },
    {
      "x": 6,
      "y": 6,
      "z": -4,
      "name": "Soil_Leaves"
    },
    {
      "x": 6,
      "y": 7,
      "z": -4,
      "name": "Wood_Hardwood_Fence",
      "rotation": 1
    },
    {
      "x": 6,
      "y": 8,
      "z": -4,
      "name": "Empty"
    },
    {
      "x": 6,
      "y": 9,
      "z": -4,
      "name": "Empty"
    },
    {
      "x": 6,
      "y": 3,
      "z": -3,
      "name": "Soil_Dirt"
    },
    {
      "x": 6,
      "y": 4,
      "z": -3,
      "name": "Soil_Dirt"
    },
    {
      "x": 6,
      "y": 5,
      "z": -3,
      "name": "Soil_Dirt"
    },
    {
      "x": 6,
      "y": 6,
      "z": -3,
      "name": "Soil_Grass_Deep"
    },
    {
      "x": 6,
      "y": 7,
      "z": -3,
      "name": "Wood_Hardwood_Fence",
      "rotation": 1
    },
    {
      "x": 6,
      "y": 8,
      "z": -3,
      "name": "Empty"
    },
    {
      "x": 6,
      "y": 9,
      "z": -3,
      "name": "Empty"
    },
    {
      "x": 6,
      "y": 4,
      "z": -2,
      "name": "Soil_Dirt"
    },
    {
      "x": 6,
      "y": 5,
      "z": -2,
      "name": "Soil_Dirt"
    },
    {
      "x": 6,
      "y": 6,
      "z": -2,
      "name": "Soil_Mud_Dry"
    },
    {
      "x": 6,
      "y": 7,
      "z": -2,
      "name": "Wood_Hardwood_Fence",
      "rotation": 1
    },
    {
      "x": 6,
      "y": 8,
      "z": -2,
      "name": "Empty"
    },
    {
      "x": 6,
      "y": 9,
      "z": -2,
      "name": "Empty"
    },
    {
      "x": 6,
      "y": 4,
      "z": -1,
      "name": "Soil_Dirt"
    },
    {
      "x": 6,
      "y": 5,
      "z": -1,
      "name": "Soil_Dirt"
    },
    {
      "x": 6,
      "y": 6,
      "z": -1,
      "name": "Soil_Mud_Dry"
    },
    {
      "x": 6,
      "y": 7,
      "z": -1,
      "name": "Wood_Hardwood_Fence",
      "rotation": 1
    },
    {
      "x": 6,
      "y": 8,
      "z": -1,
      "name": "Empty"
    },
    {
      "x": 6,
      "y": 9,
      "z": -1,
      "name": "Empty"
    },
    {
      "x": 6,
      "y": 5,
      "z": 0,
      "name": "Soil_Dirt"
    },
    {
      "x": 6,
      "y": 6,
      "z": 0,
      "name": "Soil_Mud_Dry"
    },
    {
      "x": 6,
      "y": 7,
      "z": 0,
      "name": "*Wood_Hardwood_Fence_State_Definitions_Corner",
      "rotation": 3
    },
    {
      "x": 6,
      "y": 8,
      "z": 0,
      "name": "Empty"
    },
    {
      "x": 6,
      "y": 9,
      "z": 0,
      "name": "Empty"
    }
  ],
  "entities": [
    {
      "Components": {
        "Nameplate": {
          "Text": "Kweebec_Rabbit"
        },
        "HiddenFromAdventurePlayer": {},
        "SpawnMarkerComponent": {
          "SpawnMarker": "Kweebec_Rabbit",
          "RespawnTime": 0.0,
          "SpawnCount": 0,
          "NPCReferences": [],
          "PersistedFlock": {},
          "SpawnPosition": {
            "X": 0.0,
            "Y": 0.0,
            "Z": 0.0
          }
        },
        "Transform": {
          "Position": {
            "X": -1.5232467651367188,
            "Y": 7.175048828125,
            "Z": 0.16461181640625
          },
