{
  "version": 8,
  "blockIdVersion": 11,
  "anchorX": 0,
  "anchorY": 0,
  "anchorZ": 0,
  "blocks": [
    {
      "x": -2,
      "y": 3,
      "z": 0,
      "name": "Plant_Leaves_Apple"
    },
    {
      "x": -1,
      "y": 3,
      "z": -1,
      "name": "Plant_Leaves_Apple"
    },
    {
      "x": -1,
      "y": 4,
      "z": -1,
      "name": "Plant_Leaves_Apple"
    },
    {
      "x": -1,
      "y": 3,
      "z": 0,
      "name": "Wood_Apple_Branch_Long",
      "rotation": 5
    },
    {
      "x": -1,
      "y": 4,
      "z": 0,
      "name": "Plant_Leaves_Apple"
    },
    {
      "x": -1,
      "y": 4,
      "z": 1,
      "name": "Plant_Leaves_Apple"
    },
    {
      "x": 0,
      "y": 3,
      "z": -2,
      "name": "Plant_Leaves_Apple"
    },
    {
      "x": 0,
      "y": 3,
      "z": -1,
      "name": "Wood_Apple_Branch_Long",
      "rotation": 4
    },
    {
      "x": 0,
      "y": 4,
      "z": -1,
      "name": "Plant_Leaves_Apple"
    },
    {
      "x": 0,
      "y": 0,
      "z": 0,
      "name": "Wood_Apple_Trunk"
    },
    {
      "x": 0,
      "y": 1,
      "z": 0,
      "name": "Wood_Apple_Trunk"
    },
    {
      "x": 0,
      "y": 2,
      "z": 0,
      "name": "Wood_Apple_Trunk"
    },
    {
      "x": 0,
      "y": 3,
      "z": 0,
      "name": "Wood_Apple_Trunk"
    },
    {
      "x": 0,
      "y": 4,
      "z": 0,
      "name": "Plant_Leaves_Apple"
    },
    {
      "x": 0,
      "y": 5,
      "z": 0,
      "name": "Plant_Leaves_Apple"
    },
    {
      "x": 0,
      "y": 2,
      "z": 1,
      "name": "Wood_Apple_Branch_Long",
      "rotation": 4
    },
    {
      "x": 0,
      "y": 3,
      "z": 1,
      "name": "Plant_Leaves_Apple"
    },
    {
      "x": 0,
      "y": 4,
      "z": 1,
      "name": "Plant_Leaves_Apple"
    },
    {
      "x": 0,
      "y": 2,
      "z": 2,
      "name": "Plant_Leaves_Apple"
    },
    {
      "x": 0,
      "y": 3,
      "z": 2,
      "name": "Plant_Leaves_Apple"
    },
    {
      "x": 1,
      "y": 3,
      "z": -1,
      "name": "Plant_Leaves_Apple"
    },
    {
      "x": 1,
      "y": 4,
      "z": -1,
      "name": "Plant_Leaves_Apple"
    },
    {
      "x": 1,
      "y": 2,
      "z": 0,
      "name": "Wood_Apple_Branch_Long",
      "rotation": 5
    },
    {
      "x": 1,
      "y": 4,
      "z": 0,
      "name": "Plant_Leaves_Apple"
    },
    {
      "x": 1,
      "y": 5,
      "z": 0,
      "name": "Plant_Leaves_Apple"
    },
    {
      "x": 1,
      "y": 3,
      "z": 1,
      "name": "Plant_Leaves_Apple"
    },
    {
      "x": 2,
      "y": 4,
      "z": -1,
      "name": "Plant_Leaves_Apple"
    },
    {
      "x": 2,
      "y": 2,
      "z": 0,
      "name": "Plant_Leaves_Apple"
    },
    {
      "x": 2,
      "y": 3,
      "z": 0,
      "name": "Plant_Leaves_Apple"
    },
    {
      "x": 2,
      "y": 4,
      "z": 0,
      "name": "Plant_Leaves_Apple"
    }
  ]
}