{
  "version": 8,
  "blockIdVersion": 11,
  "anchorX": 0,
  "anchorY": 0,
  "anchorZ": 0,
  "blocks": [
    {
      "x": -4,
      "y": 6,
      "z": 0,
      "name": "Plant_Leaves_Fig_Blue"
    },
    {
      "x": -3,
      "y": 6,
      "z": -1,
      "name": "Plant_Leaves_Fig_Blue"
    },
    {
      "x": -3,
      "y": 6,
      "z": 0,
      "name": "Plant_Leaves_Fig_Blue"
    },
    {
      "x": -3,
      "y": 7,
      "z": 0,
      "name": "Plant_Leaves_Fig_Blue"
    },
    {
      "x": -3,
      "y": 6,
      "z": 1,
      "name": "Plant_Leaves_Fig_Blue"
    },
    {
      "x": -3,
      "y": 6,
      "z": 2,
      "name": "Plant_Leaves_Fig_Blue"
    },
    {
      "x": -2,
      "y": 5,
      "z": -4,
      "name": "Plant_Leaves_Fig_Blue"
    },
    {
      "x": -2,
      "y": 4,
      "z": -3,
      "name": "Plant_Leaves_Fig_Blue"
    },
    {
      "x": -2,
      "y": 5,
      "z": -3,
      "name": "Plant_Leaves_Fig_Blue"
    },
    {
      "x": -2,
      "y": 6,
      "z": -1,
      "name": "Plant_Leaves_Fig_Blue"
    },
    {
      "x": -2,
      "y": 6,
      "z": 0,
      "name": "Wood_Fig_Blue_Branch_Long",
      "rotation": 5
    },
    {
      "x": -2,
      "y": 7,
      "z": 0,
      "name": "Plant_Leaves_Fig_Blue"
    },
    {
      "x": -2,
      "y": 6,
      "z": 1,
      "name": "Plant_Leaves_Fig_Blue"
    },
    {
      "x": -2,
      "y": 7,
      "z": 1,
      "name": "Plant_Leaves_Fig_Blue"
    },
    {
      "x": -1,
      "y": 4,
      "z": -4,
      "name": "Plant_Leaves_Fig_Blue"
    },
    {
      "x": -1,
      "y": 5,
      "z": -4,
      "name": "Plant_Leaves_Fig_Blue"
    },
    {
      "x": -1,
      "y": 4,
      "z": -3,
      "name": "Plant_Leaves_Fig_Blue"
    },
    {
      "x": -1,
      "y": 5,
      "z": -3,
      "name": "Plant_Leaves_Fig_Blue"
    },
    {
      "x": -1,
      "y": 6,
      "z": -3,
      "name": "Plant_Leaves_Fig_Blue"
    },
    {
      "x": -1,
      "y": 7,
      "z": -1,
      "name": "Plant_Leaves_Fig_Blue"
    },
    {
      "x": -1,
      "y": 0,
      "z": 0,
      "name": "Wood_Fig_Blue_Trunk_Full"
    },
    {
      "x": -1,
      "y": 1,
      "z": 0,
      "name": "Wood_Fig_Blue_Branch_Long"
    },
    {
      "x": -1,
      "y": 2,
      "z": 0,
      "name": "Wood_Fig_Blue_Branch_Corner",
      "rotation": 9
    },
    {
      "x": -1,
      "y": 6,
      "z": 0,
      "name": "Wood_Fig_Blue_Branch_Long",
      "rotation": 5
    },
    {
      "x": -1,
      "y": 7,
      "z": 0,
      "name": "Plant_Leaves_Fig_Blue"
    },
    {
      "x": -1,
      "y": 8,
      "z": 0,
      "name": "Plant_Leaves_Fig_Blue"
    },
    {
      "x": -1,
      "y": 7,
      "z": 1,
      "name": "Plant_Leaves_Fig_Blue"
    },
    {
      "x": -1,
      "y": 6,
      "z": 2,
      "name": "Plant_Leaves_Fig_Blue"
    },
    {
      "x": -1,
      "y": 6,
      "z": 3,
      "name": "Plant_Leaves_Fig_Blue"
    },
    {
      "x": 0,
      "y": 4,
      "z": -4,
      "name": "Plant_Leaves_Fig_Blue"
    },
    {
      "x": 0,
      "y": 5,
      "z": -4,
      "name": "Plant_Leaves_Fig_Blue"
    },
    {
      "x": 0,
      "y": 5,
      "z": -3,
      "name": "Wood_Fig_Blue_Branch_Long",
      "rotation": 4
    },
    {
      "x": 0,
      "y": 6,
      "z": -3,
      "name": "Plant_Leaves_Fig_Blue"
    },
    {
      "x": 0,
      "y": 5,
      "z": -2,
      "name": "Wood_Fig_Blue_Branch_Long",
      "rotation": 4
    },
    {
      "x": 0,
      "y": 6,
      "z": -2,
      "name": "Plant_Leaves_Fig_Blue"
    },
    {
      "x": 0,
      "y": 7,
      "z": -2,
      "name": "Plant_Leaves_Fig_Blue"
    },
    {
      "x": 0,
      "y": 0,
      "z": -1,
      "name": "Wood_Fig_Blue_Trunk_Full"
    },
    {
      "x": 0,
      "y": 1,
      "z": -1,
      "name": "Wood_Fig_Blue_Branch_Long"
    },
    {
      "x": 0,
      "y": 2,
      "z": -1,
      "name": "Wood_Fig_Blue_Branch_Corner",
      "rotation": 8
    },
    {
      "x": 0,
      "y": 5,
      "z": -1,
      "name": "Wood_Fig_Blue_Trunk_Full"
    },
    {
      "x": 0,
      "y": 7,
      "z": -1,
      "name": "Plant_Leaves_Fig_Blue"
    },
    {
      "x": 0,
      "y": 8,
      "z": -1,
      "name": "Plant_Leaves_Fig_Blue"
    },
    {
      "x": 0,
      "y": 0,
      "z": 0,
      "name": "Wood_Fig_Blue_Trunk_Full"
    },
    {
      "x": 0,
      "y": 1,
      "z": 0,
      "name": "Wood_Fig_Blue_Trunk"
    },
    {
      "x": 0,
      "y": 2,
      "z": 0,
      "name": "Wood_Fig_Blue_Trunk"
    },
    {
      "x": 0,
      "y": 3,
      "z": 0,
      "name": "Wood_Fig_Blue_Trunk"
    },
    {
      "x": 0,
      "y": 4,
      "z": 0,
      "name": "Wood_Fig_Blue_Trunk"
    },
    {
      "x": 0,
      "y": 5,
      "z": 0,
      "name": "Wood_Fig_Blue_Trunk_Full"
    },
    {
      "x": 0,
      "y": 6,
      "z": 0,
      "name": "Wood_Fig_Blue_Trunk_Full"
    },
    {
      "x": 0,
      "y": 7,
      "z": 0,
      "name": "Wood_Fig_Blue_Branch_Long"
    },
    {
      "x": 0,
      "y": 8,
      "z": 0,
      "name": "Plant_Leaves_Fig_Blue"
    },
    {
      "x": 0,
      "y": 0,
      "z": 1,
      "name": "Wood_Fig_Blue_Trunk_Full"
    },
    {
      "x": 0,
      "y": 1,
      "z": 1,
      "name": "Wood_Fig_Blue_Branch_Long"
    },
    {
      "x": 0,
      "y": 2,
      "z": 1,
      "name": "Wood_Fig_Blue_Branch_Long"
    },
    {
      "x": 0,
      "y": 3,
      "z": 1,
      "name": "Wood_Fig_Blue_Branch_Corner",
      "rotation": 10
    },
    {
      "x": 0,
      "y": 6,
      "z": 1,
      "name": "Wood_Fig_Blue_Trunk_Full"
    },
    {
      "x": 0,
      "y": 7,
      "z": 1,
      "name": "Plant_Leaves_Fig_Blue"
    },
    {
      "x": 0,
      "y": 6,
      "z": 2,
      "name": "Wood_Fig_Blue_Branch_Long",
      "rotation": 4
    },
    {
      "x": 0,
      "y": 7,
      "z": 2,
      "name": "Plant_Leaves_Fig_Blue"
    },
    {
      "x": 0,
      "y": 6,
      "z": 3,
      "name": "Plant_Leaves_Fig_Blue"
    },
    {
      "x": 0,
      "y": 7,
      "z": 3,
      "name": "Plant_Leaves_Fig_Blue"
    },
    {
      "x": 0,
      "y": 6,
      "z": 4,
      "name": "Plant_Leaves_Fig_Blue"
    },
    {
      "x": 1,
      "y": 4,
      "z": -4,
      "name": "Plant_Leaves_Fig_Blue"
    },
    {
      "x": 1,
      "y": 5,
      "z": -4,
      "name": "Plant_Leaves_Fig_Blue"
    },
    {
      "x": 1,
      "y": 5,
      "z": -3,
      "name": "Plant_Leaves_Fig_Blue"
    },
    {
      "x": 1,
      "y": 6,
      "z": -3,
      "name": "Plant_Leaves_Fig_Blue"
    },
    {
      "x": 1,
      "y": 7,
      "z": -1,
      "name": "Plant_Leaves_Fig_Blue"
    },
    {
      "x": 1,
      "y": 0,
      "z": 0,
      "name": "Wood_Fig_Blue_Trunk_Full"
    },
    {
      "x": 1,
      "y": 1,
      "z": 0,
      "name": "Wood_Fig_Blue_Trunk_Full"
    },
    {
      "x": 1,
      "y": 2,
      "z": 0,
      "name": "Wood_Fig_Blue_Branch_Long"
    },
    {
      "x": 1,
      "y": 3,
      "z": 0,
      "name": "Wood_Fig_Blue_Branch_Corner",
      "rotation": 11
    },
    {
      "x": 1,
      "y": 6,
      "z": 0,
      "name": "Wood_Fig_Blue_Branch_Long",
      "rotation": 5
    },
    {
      "x": 1,
      "y": 7,
      "z": 0,
      "name": "Plant_Leaves_Fig_Blue"
    },
    {
      "x": 1,
      "y": 8,
      "z": 0,
      "name": "Plant_Leaves_Fig_Blue"
    },
    {
      "x": 1,
      "y": 6,
      "z": 2,
      "name": "Plant_Leaves_Fig_Blue"
    },
    {
      "x": 1,
      "y": 6,
      "z": 3,
      "name": "Plant_Leaves_Fig_Blue"
    },
    {
      "x": 1,
      "y": 7,
      "z": 3,
      "name": "Plant_Leaves_Fig_Blue"
    },
    {
      "x": 1,
      "y": 6,
      "z": 4,
      "name": "Plant_Leaves_Fig_Blue"
    },
    {
      "x": 2,
      "y": 5,
      "z": -3,
      "name": "Plant_Leaves_Fig_Blue"
    },
    {
      "x": 2,
      "y": 6,
      "z": -1,
      "name": "Plant_Leaves_Fig_Blue"
    },
    {
      "x": 2,
      "y": 6,
      "z": 0,
      "name": "Wood_Fig_Blue_Branch_Long",
      "rotation": 5
    },
    {
      "x": 2,
      "y": 7,
      "z": 0,
      "name": "Plant_Leaves_Fig_Blue"
    },
    {
      "x": 2,
      "y": 6,
      "z": 1,
      "name": "Plant_Leaves_Fig_Blue"
    },
    {
      "x": 2,
      "y": 7,
      "z": 1,
      "name": "Plant_Leaves_Fig_Blue"
    },
    {
      "x": 2,
      "y": 6,
      "z": 3,
      "name": "Plant_Leaves_Fig_Blue"
    },
    {
      "x": 3,
      "y": 6,
      "z": -1,
      "name": "Plant_Leaves_Fig_Blue"
    },
    {
      "x": 3,
      "y": 5,
      "z": 0,
      "name": "Plant_Leaves_Fig_Blue"
    },
    {
      "x": 3,
      "y": 6,
      "z": 0,
      "name": "Plant_Leaves_Fig_Blue"
    },
    {
      "x": 3,
      "y": 6,
      "z": 1,
      "name": "Plant_Leaves_Fig_Blue"
    }
  ]
}