{
  "version": 8,
  "blockIdVersion": 11,
  "anchorX": -3,
  "anchorY": 9,
  "anchorZ": -6,
  "blocks": [
    {
      "x": -6,
      "y": 12,
      "z": -7,
      "name": "Plant_Leaves_Jungle"
    },
    {
      "x": -5,
      "y": 12,
      "z": -8,
      "name": "Plant_Leaves_Jungle"
    },
    {
      "x": -5,
      "y": 12,
      "z": -7,
      "name": "Wood_Jungle_Branch_Long",
      "rotation": 5
    },
    {
      "x": -5,
      "y": 13,
      "z": -7,
      "name": "Plant_Leaves_Jungle"
    },
    {
      "x": -5,
      "y": 12,
      "z": -6,
      "name": "Plant_Leaves_Jungle"
    },
    {
      "x": -4,
      "y": 11,
      "z": -8,
      "name": "Plant_Leaves_Jungle"
    },
    {
      "x": -4,
      "y": 12,
      "z": -8,
      "name": "Plant_Leaves_Jungle"
    },
    {
      "x": -4,
      "y": 13,
      "z": -8,
      "name": "Plant_Leaves_Jungle"
    },
    {
      "x": -4,
      "y": 14,
      "z": -8,
      "name": "Plant_Leaves_Jungle"
    },
    {
      "x": -4,
      "y": 12,
      "z": -7,
      "name": "Wood_Jungle_Branch_Long",
      "rotation": 5
    },
    {
      "x": -4,
      "y": 13,
      "z": -7,
      "name": "Plant_Leaves_Jungle"
    },
    {
      "x": -4,
      "y": 14,
      "z": -7,
      "name": "Plant_Leaves_Jungle"
    },
    {
      "x": -4,
      "y": 15,
      "z": -7,
      "name": "Plant_Leaves_Jungle"
    },
    {
      "x": -4,
      "y": 12,
      "z": -6,
      "name": "Plant_Leaves_Jungle"
    },
    {
      "x": -4,
      "y": 14,
      "z": -5,
      "name": "Plant_Leaves_Jungle"
    },
    {
      "x": -4,
      "y": 12,
      "z": -4,
      "name": "Plant_Leaves_Jungle"
    },
    {
      "x": -4,
      "y": 13,
      "z": -4,
      "name": "Plant_Leaves_Jungle"
    },
    {
      "x": -4,
      "y": 14,
      "z": -4,
      "name": "Plant_Leaves_Jungle"
    },
    {
      "x": -4,
      "y": 13,
      "z": -3,
      "name": "Plant_Leaves_Jungle"
    },
    {
      "x": -4,
      "y": 13,
      "z": -2,
      "name": "Plant_Leaves_Jungle"
    },
    {
      "x": -3,
      "y": 12,
      "z": -10,
      "name": "Plant_Leaves_Jungle"
    },
    {
      "x": -3,
      "y": 12,
      "z": -9,
      "name": "Plant_Leaves_Jungle"
    },
    {
      "x": -3,
      "y": 13,
      "z": -9,
      "name": "Plant_Leaves_Jungle"
    },
    {
      "x": -3,
      "y": 12,
      "z": -8,
      "name": "Wood_Jungle_Branch_Long",
      "rotation": 4
    },
    {
      "x": -3,
      "y": 13,
      "z": -8,
      "name": "Plant_Leaves_Jungle"
    },
    {
      "x": -3,
      "y": 14,
      "z": -8,
      "name": "Plant_Leaves_Jungle"
    },
    {
      "x": -3,
      "y": 8,
      "z": -7,
      "name": "Wood_Jungle_Trunk_Full"
    },
    {
      "x": -3,
      "y": 9,
      "z": -7,
      "name": "Wood_Jungle_Branch_Corner",
      "rotation": 8
    },
    {
      "x": -3,
      "y": 12,
      "z": -7,
      "name": "Wood_Jungle_Trunk_Full",
      "rotation": 4
    },
    {
      "x": -3,
      "y": 13,
      "z": -7,
      "name": "Wood_Jungle_Branch_Corner",
      "rotation": 2
    },
    {
      "x": -3,
      "y": 14,
      "z": -7,
      "name": "Wood_Jungle_Branch_Long"
    },
    {
      "x": -3,
      "y": 15,
      "z": -7,
      "name": "Plant_Leaves_Jungle"
    },
    {
      "x": -3,
      "y": 8,
      "z": -6,
      "name": "Wood_Jungle_Trunk_Full"
    },
    {
      "x": -3,
      "y": 9,
      "z": -6,
      "name": "Wood_Jungle_Trunk"
    },
    {
      "x": -3,
      "y": 10,
      "z": -6,
      "name": "Wood_Jungle_Trunk"
    },
    {
      "x": -3,
      "y": 11,
      "z": -6,
      "name": "Wood_Jungle_Trunk"
    },
    {
      "x": -3,
      "y": 12,
      "z": -6,
      "name": "Wood_Jungle_Trunk"
    },
    {
      "x": -3,
      "y": 13,
      "z": -6,
      "name": "Wood_Jungle_Trunk_Full"
    },
    {
      "x": -3,
      "y": 8,
      "z": -5,
      "name": "Wood_Jungle_Trunk_Full"
    },
    {
      "x": -3,
      "y": 9,
      "z": -5,
      "name": "Wood_Jungle_Branch_Long"
    },
    {
      "x": -3,
      "y": 10,
      "z": -5,
      "name": "Wood_Jungle_Branch_Corner",
      "rotation": 10
    },
    {
      "x": -3,
      "y": 13,
      "z": -5,
      "name": "Wood_Jungle_Trunk_Full"
    },
    {
      "x": -3,
      "y": 14,
      "z": -5,
      "name": "Wood_Jungle_Branch_Long"
    },
    {
      "x": -3,
      "y": 15,
      "z": -5,
      "name": "Plant_Leaves_Jungle"
    },
    {
      "x": -3,
      "y": 13,
      "z": -4,
      "name": "Wood_Jungle_Branch_Long",
      "rotation": 4
    },
    {
      "x": -3,
      "y": 14,
      "z": -4,
      "name": "Plant_Leaves_Jungle"
    },
    {
      "x": -3,
      "y": 13,
      "z": -3,
      "name": "Wood_Jungle_Branch_Long",
      "rotation": 4
    },
    {
      "x": -3,
      "y": 14,
      "z": -3,
      "name": "Plant_Leaves_Jungle"
    },
    {
      "x": -3,
      "y": 13,
      "z": -2,
      "name": "Plant_Leaves_Jungle"
    },
    {
      "x": -2,
      "y": 11,
      "z": -9,
      "name": "Plant_Leaves_Jungle"
    },
    {
      "x": -2,
      "y": 12,
      "z": -9,
      "name": "Plant_Leaves_Jungle"
    },
    {
      "x": -2,
      "y": 12,
      "z": -8,
      "name": "Plant_Leaves_Jungle"
    },
    {
      "x": -2,
      "y": 14,
      "z": -8,
      "name": "Plant_Leaves_Jungle"
    },
    {
      "x": -2,
      "y": 13,
      "z": -7,
      "name": "Plant_Leaves_Jungle"
    },
    {
      "x": -2,
      "y": 14,
      "z": -7,
      "name": "Plant_Leaves_Jungle"
    },
    {
      "x": -2,
      "y": 8,
      "z": -6,
      "name": "Wood_Jungle_Trunk_Full"
    },
    {
      "x": -2,
      "y": 13,
      "z": -6,
      "name": "Wood_Jungle_Branch_Long",
      "rotation": 5
    },
    {
      "x": -2,
      "y": 14,
      "z": -6,
      "name": "Plant_Leaves_Jungle"
    },
    {
      "x": -2,
      "y": 12,
      "z": -5,
      "name": "Plant_Leaves_Jungle"
    },
    {
      "x": -2,
      "y": 13,
      "z": -5,
      "name": "Plant_Leaves_Jungle"
    },
    {
      "x": -2,
      "y": 14,
      "z": -5,
      "name": "Plant_Leaves_Jungle"
    },
    {
      "x": -2,
      "y": 13,
      "z": -4,
      "name": "Plant_Leaves_Jungle"
    },
    {
      "x": -2,
      "y": 12,
      "z": -3,
      "name": "Plant_Leaves_Jungle"
    },
    {
      "x": -2,
      "y": 13,
      "z": -3,
      "name": "Plant_Leaves_Jungle"
    },
    {
      "x": -2,
      "y": 14,
      "z": -3,
      "name": "Plant_Leaves_Jungle"
    },
    {
      "x": -2,
      "y": 13,
      "z": -2,
      "name": "Plant_Leaves_Jungle"
    },
    {
      "x": -1,
      "y": 13,
      "z": -7,
      "name": "Plant_Leaves_Jungle"
    },
    {
      "x": -1,
      "y": 13,
      "z": -6,
      "name": "Wood_Jungle_Branch_Long",
      "rotation": 5
    },
    {
      "x": -1,
      "y": 14,
      "z": -6,
      "name": "Plant_Leaves_Jungle"
    },
    {
      "x": -1,
      "y": 13,
      "z": -5,
      "name": "Plant_Leaves_Jungle"
    },
    {
      "x": 0,
      "y": 12,
      "z": -7,
      "name": "Plant_Leaves_Jungle"
    },
    {
      "x": 0,
      "y": 13,
      "z": -7,
      "name": "Plant_Leaves_Jungle"
    },
    {
      "x": 0,
      "y": 13,
      "z": -6,
      "name": "Plant_Leaves_Jungle"
    },
    {
      "x": 0,
      "y": 14,
      "z": -6,
      "name": "Plant_Leaves_Jungle"
    },
    {
      "x": 0,
      "y": 13,
      "z": -5,
      "name": "Plant_Leaves_Jungle"
    }
  ]
}