{
  "version": 8,
  "blockIdVersion": 11,
  "anchorX": 10,
  "anchorY": 3,
  "anchorZ": 3,
  "blocks": [
    {
      "x": 8,
      "y": 9,
      "z": 1,
      "name": "Plant_Leaves_Poisoned"
    },
    {
      "x": 8,
      "y": 9,
      "z": 2,
      "name": "Plant_Leaves_Poisoned"
    },
    {
      "x": 9,
      "y": 9,
      "z": 0,
      "name": "Plant_Leaves_Poisoned"
    },
    {
      "x": 9,
      "y": 9,
      "z": 1,
      "name": "Plant_Leaves_Poisoned"
    },
    {
      "x": 9,
      "y": 10,
      "z": 1,
      "name": "Plant_Leaves_Poisoned"
    },
    {
      "x": 9,
      "y": 8,
      "z": 2,
      "name": "Plant_Leaves_Poisoned"
    },
    {
      "x": 9,
      "y": 9,
      "z": 2,
      "name": "Plant_Leaves_Poisoned"
    },
    {
      "x": 9,
      "y": 8,
      "z": 4,
      "name": "Plant_Leaves_Poisoned"
    },
    {
      "x": 9,
      "y": 9,
      "z": 4,
      "name": "Plant_Leaves_Poisoned"
    },
    {
      "x": 9,
      "y": 9,
      "z": 5,
      "name": "Plant_Leaves_Poisoned"
    },
    {
      "x": 10,
      "y": 9,
      "z": 0,
      "name": "Plant_Leaves_Poisoned"
    },
    {
      "x": 10,
      "y": 8,
      "z": 1,
      "name": "Plant_Leaves_Poisoned"
    },
    {
      "x": 10,
      "y": 9,
      "z": 1,
      "name": "Plant_Leaves_Poisoned"
    },
    {
      "x": 10,
      "y": 10,
      "z": 1,
      "name": "Plant_Leaves_Poisoned"
    },
    {
      "x": 10,
      "y": 7,
      "z": 2,
      "name": "Wood_Poisoned_Trunk_Full"
    },
    {
      "x": 10,
      "y": 8,
      "z": 2,
      "name": "Wood_Poisoned_Trunk_Full"
    },
    {
      "x": 10,
      "y": 9,
      "z": 2,
      "name": "Wood_Poisoned_Branch_Long"
    },
    {
      "x": 10,
      "y": 10,
      "z": 2,
      "name": "Plant_Leaves_Poisoned"
    },
    {
      "x": 10,
      "y": 3,
      "z": 3,
      "name": "Wood_Poisoned_Trunk"
    },
    {
      "x": 10,
      "y": 4,
      "z": 3,
      "name": "Wood_Poisoned_Trunk"
    },
    {
      "x": 10,
      "y": 5,
      "z": 3,
      "name": "Wood_Poisoned_Trunk"
    },
    {
      "x": 10,
      "y": 6,
      "z": 3,
      "name": "Wood_Poisoned_Trunk"
    },
    {
      "x": 10,
      "y": 7,
      "z": 3,
      "name": "Wood_Poisoned_Trunk_Full"
    },
    {
      "x": 10,
      "y": 8,
      "z": 3,
      "name": "Plant_Leaves_Poisoned"
    },
    {
      "x": 10,
      "y": 9,
      "z": 3,
      "name": "Plant_Leaves_Poisoned"
    },
    {
      "x": 10,
      "y": 10,
      "z": 3,
      "name": "Plant_Leaves_Poisoned"
    },
    {
      "x": 10,
      "y": 7,
      "z": 4,
      "name": "Wood_Poisoned_Branch_Corner"
    },
    {
      "x": 10,
      "y": 8,
      "z": 4,
      "name": "Wood_Poisoned_Branch_Long"
    },
    {
      "x": 10,
      "y": 9,
      "z": 4,
      "name": "Wood_Poisoned_Branch_Long"
    },
    {
      "x": 10,
      "y": 10,
      "z": 4,
      "name": "Plant_Leaves_Poisoned"
    },
    {
      "x": 10,
      "y": 9,
      "z": 5,
      "name": "Plant_Leaves_Poisoned"
    },
    {
      "x": 11,
      "y": 9,
      "z": 0,
      "name": "Plant_Leaves_Poisoned"
    },
    {
      "x": 11,
      "y": 9,
      "z": 1,
      "name": "Plant_Leaves_Poisoned"
    },
    {
      "x": 11,
      "y": 10,
      "z": 1,
      "name": "Plant_Leaves_Poisoned"
    },
    {
      "x": 11,
      "y": 8,
      "z": 2,
      "name": "Plant_Leaves_Poisoned"
    },
    {
      "x": 11,
      "y": 9,
      "z": 2,
      "name": "Plant_Leaves_Poisoned"
    },
    {
      "x": 11,
      "y": 7,
      "z": 3,
      "name": "Plant_Leaves_Poisoned"
    },
    {
      "x": 11,
      "y": 7,
      "z": 4,
      "name": "Plant_Leaves_Poisoned"
    },
    {
      "x": 11,
      "y": 9,
      "z": 4,
      "name": "Plant_Leaves_Poisoned"
    },
    {
      "x": 11,
      "y": 10,
      "z": 4,
      "name": "Plant_Leaves_Poisoned"
    },
    {
      "x": 12,
      "y": 10,
      "z": 1,
      "name": "Plant_Leaves_Poisoned"
    }
  ]
}